Traceback (most recent call last):
  File "/home/ubuntu/trends-script/scraper.py", line 260, in <module>
    main()
  File "/home/ubuntu/trends-script/scraper.py", line 253, in main
    htmlstring = get_html_from_site()
  File "/home/ubuntu/trends-script/scraper.py", line 28, in get_html_from_site
    driver = webdriver.Chrome(options=options)
  File "/home/ubuntu/.local/lib/python3.8/site-packages/selenium/webdriver/chrome/webdriver.py", line 73, in __init__
    self.service.start()
  File "/home/ubuntu/.local/lib/python3.8/site-packages/selenium/webdriver/common/service.py", line 104, in start
    raise WebDriverException("Can not connect to the Service %s" % self.path)
selenium.common.exceptions.WebDriverException: Message: Can not connect to the Service chromedriver

Traceback (most recent call last):
  File "/home/ubuntu/trends-script/scraper.py", line 260, in <module>
    main()
  File "/home/ubuntu/trends-script/scraper.py", line 253, in main
    htmlstring = get_html_from_site()
  File "/home/ubuntu/trends-script/scraper.py", line 31, in get_html_from_site
    driver.get(start_url)
  File "/home/ubuntu/.local/lib/python3.8/site-packages/selenium/webdriver/remote/webdriver.py", line 333, in get
    self.execute(Command.GET, {'url': url})
  File "/home/ubuntu/.local/lib/python3.8/site-packages/selenium/webdriver/remote/webdriver.py", line 321, in execute
    self.error_handler.check_response(response)
  File "/home/ubuntu/.local/lib/python3.8/site-packages/selenium/webdriver/remote/errorhandler.py", line 242, in check_response
    raise exception_class(message, screen, stacktrace)
selenium.common.exceptions.TimeoutException: Message: timeout: Timed out receiving message from renderer: 293.985
  (Session info: headless chrome=87.0.4280.88)

Traceback (most recent call last):
  File "/home/ubuntu/trends-script/scraper.py", line 260, in <module>
    main()
  File "/home/ubuntu/trends-script/scraper.py", line 253, in main
    htmlstring = get_html_from_site()
  File "/home/ubuntu/trends-script/scraper.py", line 28, in get_html_from_site
    driver = webdriver.Chrome(options=options)
  File "/home/ubuntu/.local/lib/python3.8/site-packages/selenium/webdriver/chrome/webdriver.py", line 73, in __init__
    self.service.start()
  File "/home/ubuntu/.local/lib/python3.8/site-packages/selenium/webdriver/common/service.py", line 104, in start
    raise WebDriverException("Can not connect to the Service %s" % self.path)
selenium.common.exceptions.WebDriverException: Message: Can not connect to the Service chromedriver

Traceback (most recent call last):
  File "/home/ubuntu/trends-script/scraper.py", line 260, in <module>
    main()
  File "/home/ubuntu/trends-script/scraper.py", line 253, in main
    htmlstring = get_html_from_site()
  File "/home/ubuntu/trends-script/scraper.py", line 31, in get_html_from_site
    driver.get(start_url)
  File "/home/ubuntu/.local/lib/python3.8/site-packages/selenium/webdriver/remote/webdriver.py", line 333, in get
    self.execute(Command.GET, {'url': url})
  File "/home/ubuntu/.local/lib/python3.8/site-packages/selenium/webdriver/remote/webdriver.py", line 321, in execute
    self.error_handler.check_response(response)
  File "/home/ubuntu/.local/lib/python3.8/site-packages/selenium/webdriver/remote/errorhandler.py", line 242, in check_response
    raise exception_class(message, screen, stacktrace)
selenium.common.exceptions.TimeoutException: Message: timeout: Timed out receiving message from renderer: 294.234
  (Session info: headless chrome=87.0.4280.88)

Traceback (most recent call last):
  File "/home/ubuntu/trends-script/scraper.py", line 260, in <module>
    main()
  File "/home/ubuntu/trends-script/scraper.py", line 253, in main
    htmlstring = get_html_from_site()
  File "/home/ubuntu/trends-script/scraper.py", line 28, in get_html_from_site
    driver = webdriver.Chrome(options=options)
  File "/home/ubuntu/.local/lib/python3.8/site-packages/selenium/webdriver/chrome/webdriver.py", line 73, in __init__
    self.service.start()
  File "/home/ubuntu/.local/lib/python3.8/site-packages/selenium/webdriver/common/service.py", line 104, in start
    raise WebDriverException("Can not connect to the Service %s" % self.path)
selenium.common.exceptions.WebDriverException: Message: Can not connect to the Service chromedriver

Traceback (most recent call last):
  File "/home/ubuntu/trends-script/scraper.py", line 260, in <module>
    main()
  File "/home/ubuntu/trends-script/scraper.py", line 253, in main
    htmlstring = get_html_from_site()
  File "/home/ubuntu/trends-script/scraper.py", line 31, in get_html_from_site
    driver.get(start_url)
  File "/home/ubuntu/.local/lib/python3.8/site-packages/selenium/webdriver/remote/webdriver.py", line 333, in get
    self.execute(Command.GET, {'url': url})
  File "/home/ubuntu/.local/lib/python3.8/site-packages/selenium/webdriver/remote/webdriver.py", line 321, in execute
    self.error_handler.check_response(response)
  File "/home/ubuntu/.local/lib/python3.8/site-packages/selenium/webdriver/remote/errorhandler.py", line 242, in check_response
    raise exception_class(message, screen, stacktrace)
selenium.common.exceptions.TimeoutException: Message: timeout: Timed out receiving message from renderer: 295.307
  (Session info: headless chrome=87.0.4280.88)

Traceback (most recent call last):
  File "/home/ubuntu/trends-script/scraper.py", line 260, in <module>
    main()
  File "/home/ubuntu/trends-script/scraper.py", line 253, in main
    htmlstring = get_html_from_site()
  File "/home/ubuntu/trends-script/scraper.py", line 28, in get_html_from_site
    driver = webdriver.Chrome(options=options)
  File "/home/ubuntu/.local/lib/python3.8/site-packages/selenium/webdriver/chrome/webdriver.py", line 73, in __init__
    self.service.start()
  File "/home/ubuntu/.local/lib/python3.8/site-packages/selenium/webdriver/common/service.py", line 104, in start
    raise WebDriverException("Can not connect to the Service %s" % self.path)
selenium.common.exceptions.WebDriverException: Message: Can not connect to the Service chromedriver

Traceback (most recent call last):
  File "/home/ubuntu/trends-script/scraper.py", line 260, in <module>
    main()
  File "/home/ubuntu/trends-script/scraper.py", line 253, in main
    htmlstring = get_html_from_site()
  File "/home/ubuntu/trends-script/scraper.py", line 31, in get_html_from_site
    driver.get(start_url)
  File "/home/ubuntu/.local/lib/python3.8/site-packages/selenium/webdriver/remote/webdriver.py", line 333, in get
    self.execute(Command.GET, {'url': url})
  File "/home/ubuntu/.local/lib/python3.8/site-packages/selenium/webdriver/remote/webdriver.py", line 321, in execute
    self.error_handler.check_response(response)
  File "/home/ubuntu/.local/lib/python3.8/site-packages/selenium/webdriver/remote/errorhandler.py", line 242, in check_response
    raise exception_class(message, screen, stacktrace)
selenium.common.exceptions.TimeoutException: Message: timeout: Timed out receiving message from renderer: 293.985
  (Session info: headless chrome=87.0.4280.88)

Traceback (most recent call last):
  File "/home/ubuntu/trends-script/scraper.py", line 260, in <module>
    main()
  File "/home/ubuntu/trends-script/scraper.py", line 253, in main
    htmlstring = get_html_from_site()
  File "/home/ubuntu/trends-script/scraper.py", line 28, in get_html_from_site
    driver = webdriver.Chrome(options=options)
  File "/home/ubuntu/.local/lib/python3.8/site-packages/selenium/webdriver/chrome/webdriver.py", line 73, in __init__
    self.service.start()
  File "/home/ubuntu/.local/lib/python3.8/site-packages/selenium/webdriver/common/service.py", line 104, in start
    raise WebDriverException("Can not connect to the Service %s" % self.path)
selenium.common.exceptions.WebDriverException: Message: Can not connect to the Service chromedriver

Traceback (most recent call last):
  File "/home/ubuntu/trends-script/scraper.py", line 260, in <module>
    main()
  File "/home/ubuntu/trends-script/scraper.py", line 253, in main
    htmlstring = get_html_from_site()
  File "/home/ubuntu/trends-script/scraper.py", line 31, in get_html_from_site
    driver.get(start_url)
  File "/home/ubuntu/.local/lib/python3.8/site-packages/selenium/webdriver/remote/webdriver.py", line 333, in get
    self.execute(Command.GET, {'url': url})
  File "/home/ubuntu/.local/lib/python3.8/site-packages/selenium/webdriver/remote/webdriver.py", line 321, in execute
    self.error_handler.check_response(response)
  File "/home/ubuntu/.local/lib/python3.8/site-packages/selenium/webdriver/remote/errorhandler.py", line 242, in check_response
    raise exception_class(message, screen, stacktrace)
selenium.common.exceptions.TimeoutException: Message: timeout: Timed out receiving message from renderer: 294.406
  (Session info: headless chrome=87.0.4280.88)

Traceback (most recent call last):
  File "/home/ubuntu/trends-script/scraper.py", line 260, in <module>
    main()
  File "/home/ubuntu/trends-script/scraper.py", line 253, in main
    htmlstring = get_html_from_site()
  File "/home/ubuntu/trends-script/scraper.py", line 28, in get_html_from_site
    driver = webdriver.Chrome(options=options)
  File "/home/ubuntu/.local/lib/python3.8/site-packages/selenium/webdriver/chrome/webdriver.py", line 73, in __init__
    self.service.start()
  File "/home/ubuntu/.local/lib/python3.8/site-packages/selenium/webdriver/common/service.py", line 104, in start
    raise WebDriverException("Can not connect to the Service %s" % self.path)
selenium.common.exceptions.WebDriverException: Message: Can not connect to the Service chromedriver

Traceback (most recent call last):
  File "/home/ubuntu/trends-script/scraper.py", line 260, in <module>
    main()
  File "/home/ubuntu/trends-script/scraper.py", line 253, in main
    htmlstring = get_html_from_site()
  File "/home/ubuntu/trends-script/scraper.py", line 31, in get_html_from_site
    driver.get(start_url)
  File "/home/ubuntu/.local/lib/python3.8/site-packages/selenium/webdriver/remote/webdriver.py", line 333, in get
    self.execute(Command.GET, {'url': url})
  File "/home/ubuntu/.local/lib/python3.8/site-packages/selenium/webdriver/remote/webdriver.py", line 321, in execute
    self.error_handler.check_response(response)
  File "/home/ubuntu/.local/lib/python3.8/site-packages/selenium/webdriver/remote/errorhandler.py", line 242, in check_response
    raise exception_class(message, screen, stacktrace)
selenium.common.exceptions.TimeoutException: Message: timeout: Timed out receiving message from renderer: 293.711
  (Session info: headless chrome=87.0.4280.88)

Traceback (most recent call last):
  File "/home/ubuntu/trends-script/scraper.py", line 260, in <module>
    main()
  File "/home/ubuntu/trends-script/scraper.py", line 253, in main
    htmlstring = get_html_from_site()
  File "/home/ubuntu/trends-script/scraper.py", line 28, in get_html_from_site
    driver = webdriver.Chrome(options=options)
  File "/home/ubuntu/.local/lib/python3.8/site-packages/selenium/webdriver/chrome/webdriver.py", line 73, in __init__
    self.service.start()
  File "/home/ubuntu/.local/lib/python3.8/site-packages/selenium/webdriver/common/service.py", line 104, in start
    raise WebDriverException("Can not connect to the Service %s" % self.path)
selenium.common.exceptions.WebDriverException: Message: Can not connect to the Service chromedriver

Traceback (most recent call last):
  File "/home/ubuntu/trends-script/scraper.py", line 260, in <module>
    main()
  File "/home/ubuntu/trends-script/scraper.py", line 253, in main
    htmlstring = get_html_from_site()
  File "/home/ubuntu/trends-script/scraper.py", line 31, in get_html_from_site
    driver.get(start_url)
  File "/home/ubuntu/.local/lib/python3.8/site-packages/selenium/webdriver/remote/webdriver.py", line 333, in get
    self.execute(Command.GET, {'url': url})
  File "/home/ubuntu/.local/lib/python3.8/site-packages/selenium/webdriver/remote/webdriver.py", line 321, in execute
    self.error_handler.check_response(response)
  File "/home/ubuntu/.local/lib/python3.8/site-packages/selenium/webdriver/remote/errorhandler.py", line 242, in check_response
    raise exception_class(message, screen, stacktrace)
selenium.common.exceptions.TimeoutException: Message: timeout: Timed out receiving message from renderer: 294.299
  (Session info: headless chrome=87.0.4280.88)

Traceback (most recent call last):
  File "/home/ubuntu/trends-script/scraper.py", line 260, in <module>
    main()
  File "/home/ubuntu/trends-script/scraper.py", line 253, in main
    htmlstring = get_html_from_site()
  File "/home/ubuntu/trends-script/scraper.py", line 28, in get_html_from_site
    driver = webdriver.Chrome(options=options)
  File "/home/ubuntu/.local/lib/python3.8/site-packages/selenium/webdriver/chrome/webdriver.py", line 73, in __init__
    self.service.start()
  File "/home/ubuntu/.local/lib/python3.8/site-packages/selenium/webdriver/common/service.py", line 104, in start
    raise WebDriverException("Can not connect to the Service %s" % self.path)
selenium.common.exceptions.WebDriverException: Message: Can not connect to the Service chromedriver

Traceback (most recent call last):
  File "/home/ubuntu/trends-script/scraper.py", line 260, in <module>
    main()
  File "/home/ubuntu/trends-script/scraper.py", line 253, in main
    htmlstring = get_html_from_site()
  File "/home/ubuntu/trends-script/scraper.py", line 31, in get_html_from_site
    driver.get(start_url)
  File "/home/ubuntu/.local/lib/python3.8/site-packages/selenium/webdriver/remote/webdriver.py", line 333, in get
    self.execute(Command.GET, {'url': url})
  File "/home/ubuntu/.local/lib/python3.8/site-packages/selenium/webdriver/remote/webdriver.py", line 321, in execute
    self.error_handler.check_response(response)
  File "/home/ubuntu/.local/lib/python3.8/site-packages/selenium/webdriver/remote/errorhandler.py", line 242, in check_response
    raise exception_class(message, screen, stacktrace)
selenium.common.exceptions.TimeoutException: Message: timeout: Timed out receiving message from renderer: 293.364
  (Session info: headless chrome=87.0.4280.88)

Traceback (most recent call last):
  File "/home/ubuntu/trends-script/scraper.py", line 260, in <module>
    main()
  File "/home/ubuntu/trends-script/scraper.py", line 253, in main
    htmlstring = get_html_from_site()
  File "/home/ubuntu/trends-script/scraper.py", line 28, in get_html_from_site
    driver = webdriver.Chrome(options=options)
  File "/home/ubuntu/.local/lib/python3.8/site-packages/selenium/webdriver/chrome/webdriver.py", line 73, in __init__
    self.service.start()
  File "/home/ubuntu/.local/lib/python3.8/site-packages/selenium/webdriver/common/service.py", line 104, in start
    raise WebDriverException("Can not connect to the Service %s" % self.path)
selenium.common.exceptions.WebDriverException: Message: Can not connect to the Service chromedriver

Traceback (most recent call last):
  File "/home/ubuntu/trends-script/scraper.py", line 260, in <module>
    main()
  File "/home/ubuntu/trends-script/scraper.py", line 253, in main
    htmlstring = get_html_from_site()
  File "/home/ubuntu/trends-script/scraper.py", line 31, in get_html_from_site
    driver.get(start_url)
  File "/home/ubuntu/.local/lib/python3.8/site-packages/selenium/webdriver/remote/webdriver.py", line 333, in get
    self.execute(Command.GET, {'url': url})
  File "/home/ubuntu/.local/lib/python3.8/site-packages/selenium/webdriver/remote/webdriver.py", line 321, in execute
    self.error_handler.check_response(response)
  File "/home/ubuntu/.local/lib/python3.8/site-packages/selenium/webdriver/remote/errorhandler.py", line 242, in check_response
    raise exception_class(message, screen, stacktrace)
selenium.common.exceptions.TimeoutException: Message: timeout: Timed out receiving message from renderer: 293.083
  (Session info: headless chrome=87.0.4280.88)

Traceback (most recent call last):
  File "/home/ubuntu/trends-script/scraper.py", line 260, in <module>
    main()
  File "/home/ubuntu/trends-script/scraper.py", line 253, in main
    htmlstring = get_html_from_site()
  File "/home/ubuntu/trends-script/scraper.py", line 28, in get_html_from_site
    driver = webdriver.Chrome(options=options)
  File "/home/ubuntu/.local/lib/python3.8/site-packages/selenium/webdriver/chrome/webdriver.py", line 73, in __init__
    self.service.start()
  File "/home/ubuntu/.local/lib/python3.8/site-packages/selenium/webdriver/common/service.py", line 104, in start
    raise WebDriverException("Can not connect to the Service %s" % self.path)
selenium.common.exceptions.WebDriverException: Message: Can not connect to the Service chromedriver

Traceback (most recent call last):
  File "/home/ubuntu/trends-script/scraper.py", line 260, in <module>
    main()
  File "/home/ubuntu/trends-script/scraper.py", line 253, in main
    htmlstring = get_html_from_site()
  File "/home/ubuntu/trends-script/scraper.py", line 28, in get_html_from_site
    driver = webdriver.Chrome(options=options)
  File "/home/ubuntu/.local/lib/python3.8/site-packages/selenium/webdriver/chrome/webdriver.py", line 73, in __init__
    self.service.start()
  File "/home/ubuntu/.local/lib/python3.8/site-packages/selenium/webdriver/common/service.py", line 104, in start
    raise WebDriverException("Can not connect to the Service %s" % self.path)
selenium.common.exceptions.WebDriverException: Message: Can not connect to the Service chromedriver

Traceback (most recent call last):
  File "/home/ubuntu/trends-script/scraper.py", line 260, in <module>
    main()
  File "/home/ubuntu/trends-script/scraper.py", line 253, in main
    htmlstring = get_html_from_site()
  File "/home/ubuntu/trends-script/scraper.py", line 31, in get_html_from_site
    driver.get(start_url)
  File "/home/ubuntu/.local/lib/python3.8/site-packages/selenium/webdriver/remote/webdriver.py", line 333, in get
    self.execute(Command.GET, {'url': url})
  File "/home/ubuntu/.local/lib/python3.8/site-packages/selenium/webdriver/remote/webdriver.py", line 321, in execute
    self.error_handler.check_response(response)
  File "/home/ubuntu/.local/lib/python3.8/site-packages/selenium/webdriver/remote/errorhandler.py", line 242, in check_response
    raise exception_class(message, screen, stacktrace)
selenium.common.exceptions.TimeoutException: Message: timeout: Timed out receiving message from renderer: 292.239
  (Session info: headless chrome=87.0.4280.88)

Traceback (most recent call last):
  File "/home/ubuntu/trends-script/scraper.py", line 260, in <module>
    main()
  File "/home/ubuntu/trends-script/scraper.py", line 253, in main
    htmlstring = get_html_from_site()
  File "/home/ubuntu/trends-script/scraper.py", line 28, in get_html_from_site
    driver = webdriver.Chrome(options=options)
  File "/home/ubuntu/.local/lib/python3.8/site-packages/selenium/webdriver/chrome/webdriver.py", line 73, in __init__
    self.service.start()
  File "/home/ubuntu/.local/lib/python3.8/site-packages/selenium/webdriver/common/service.py", line 104, in start
    raise WebDriverException("Can not connect to the Service %s" % self.path)
selenium.common.exceptions.WebDriverException: Message: Can not connect to the Service chromedriver

Traceback (most recent call last):
  File "/home/ubuntu/trends-script/scraper.py", line 260, in <module>
    main()
  File "/home/ubuntu/trends-script/scraper.py", line 253, in main
    htmlstring = get_html_from_site()
  File "/home/ubuntu/trends-script/scraper.py", line 31, in get_html_from_site
    driver.get(start_url)
  File "/home/ubuntu/.local/lib/python3.8/site-packages/selenium/webdriver/remote/webdriver.py", line 333, in get
    self.execute(Command.GET, {'url': url})
  File "/home/ubuntu/.local/lib/python3.8/site-packages/selenium/webdriver/remote/webdriver.py", line 321, in execute
    self.error_handler.check_response(response)
  File "/home/ubuntu/.local/lib/python3.8/site-packages/selenium/webdriver/remote/errorhandler.py", line 242, in check_response
    raise exception_class(message, screen, stacktrace)
selenium.common.exceptions.TimeoutException: Message: timeout: Timed out receiving message from renderer: 294.010
  (Session info: headless chrome=87.0.4280.88)

Traceback (most recent call last):
  File "/home/ubuntu/trends-script/scraper.py", line 260, in <module>
    main()
  File "/home/ubuntu/trends-script/scraper.py", line 253, in main
    htmlstring = get_html_from_site()
  File "/home/ubuntu/trends-script/scraper.py", line 28, in get_html_from_site
    driver = webdriver.Chrome(options=options)
  File "/home/ubuntu/.local/lib/python3.8/site-packages/selenium/webdriver/chrome/webdriver.py", line 73, in __init__
    self.service.start()
  File "/home/ubuntu/.local/lib/python3.8/site-packages/selenium/webdriver/common/service.py", line 104, in start
    raise WebDriverException("Can not connect to the Service %s" % self.path)
selenium.common.exceptions.WebDriverException: Message: Can not connect to the Service chromedriver

Traceback (most recent call last):
  File "/home/ubuntu/trends-script/scraper.py", line 260, in <module>
    main()
  File "/home/ubuntu/trends-script/scraper.py", line 253, in main
    htmlstring = get_html_from_site()
  File "/home/ubuntu/trends-script/scraper.py", line 31, in get_html_from_site
    driver.get(start_url)
  File "/home/ubuntu/.local/lib/python3.8/site-packages/selenium/webdriver/remote/webdriver.py", line 333, in get
    self.execute(Command.GET, {'url': url})
  File "/home/ubuntu/.local/lib/python3.8/site-packages/selenium/webdriver/remote/webdriver.py", line 321, in execute
    self.error_handler.check_response(response)
  File "/home/ubuntu/.local/lib/python3.8/site-packages/selenium/webdriver/remote/errorhandler.py", line 242, in check_response
    raise exception_class(message, screen, stacktrace)
selenium.common.exceptions.TimeoutException: Message: timeout: Timed out receiving message from renderer: 293.442
  (Session info: headless chrome=87.0.4280.88)

Traceback (most recent call last):
  File "/home/ubuntu/trends-script/scraper.py", line 260, in <module>
    main()
  File "/home/ubuntu/trends-script/scraper.py", line 253, in main
    htmlstring = get_html_from_site()
  File "/home/ubuntu/trends-script/scraper.py", line 28, in get_html_from_site
    driver = webdriver.Chrome(options=options)
  File "/home/ubuntu/.local/lib/python3.8/site-packages/selenium/webdriver/chrome/webdriver.py", line 73, in __init__
    self.service.start()
  File "/home/ubuntu/.local/lib/python3.8/site-packages/selenium/webdriver/common/service.py", line 104, in start
    raise WebDriverException("Can not connect to the Service %s" % self.path)
selenium.common.exceptions.WebDriverException: Message: Can not connect to the Service chromedriver

Traceback (most recent call last):
  File "/home/ubuntu/trends-script/scraper.py", line 260, in <module>
    main()
  File "/home/ubuntu/trends-script/scraper.py", line 253, in main
    htmlstring = get_html_from_site()
  File "/home/ubuntu/trends-script/scraper.py", line 31, in get_html_from_site
    driver.get(start_url)
  File "/home/ubuntu/.local/lib/python3.8/site-packages/selenium/webdriver/remote/webdriver.py", line 333, in get
    self.execute(Command.GET, {'url': url})
  File "/home/ubuntu/.local/lib/python3.8/site-packages/selenium/webdriver/remote/webdriver.py", line 321, in execute
    self.error_handler.check_response(response)
  File "/home/ubuntu/.local/lib/python3.8/site-packages/selenium/webdriver/remote/errorhandler.py", line 242, in check_response
    raise exception_class(message, screen, stacktrace)
selenium.common.exceptions.TimeoutException: Message: timeout: Timed out receiving message from renderer: 293.917
  (Session info: headless chrome=87.0.4280.88)

Traceback (most recent call last):
  File "/home/ubuntu/trends-script/scraper.py", line 260, in <module>
    main()
  File "/home/ubuntu/trends-script/scraper.py", line 253, in main
    htmlstring = get_html_from_site()
  File "/home/ubuntu/trends-script/scraper.py", line 28, in get_html_from_site
    driver = webdriver.Chrome(options=options)
  File "/home/ubuntu/.local/lib/python3.8/site-packages/selenium/webdriver/chrome/webdriver.py", line 73, in __init__
    self.service.start()
  File "/home/ubuntu/.local/lib/python3.8/site-packages/selenium/webdriver/common/service.py", line 104, in start
    raise WebDriverException("Can not connect to the Service %s" % self.path)
selenium.common.exceptions.WebDriverException: Message: Can not connect to the Service chromedriver

Traceback (most recent call last):
  File "/home/ubuntu/trends-script/scraper.py", line 260, in <module>
    main()
  File "/home/ubuntu/trends-script/scraper.py", line 253, in main
    htmlstring = get_html_from_site()
  File "/home/ubuntu/trends-script/scraper.py", line 31, in get_html_from_site
    driver.get(start_url)
  File "/home/ubuntu/.local/lib/python3.8/site-packages/selenium/webdriver/remote/webdriver.py", line 333, in get
    self.execute(Command.GET, {'url': url})
  File "/home/ubuntu/.local/lib/python3.8/site-packages/selenium/webdriver/remote/webdriver.py", line 321, in execute
    self.error_handler.check_response(response)
  File "/home/ubuntu/.local/lib/python3.8/site-packages/selenium/webdriver/remote/errorhandler.py", line 242, in check_response
    raise exception_class(message, screen, stacktrace)
selenium.common.exceptions.TimeoutException: Message: timeout: Timed out receiving message from renderer: 289.862
  (Session info: headless chrome=87.0.4280.88)

Traceback (most recent call last):
  File "/home/ubuntu/trends-script/scraper.py", line 260, in <module>
    main()
  File "/home/ubuntu/trends-script/scraper.py", line 253, in main
    htmlstring = get_html_from_site()
  File "/home/ubuntu/trends-script/scraper.py", line 28, in get_html_from_site
    driver = webdriver.Chrome(options=options)
  File "/home/ubuntu/.local/lib/python3.8/site-packages/selenium/webdriver/chrome/webdriver.py", line 73, in __init__
    self.service.start()
  File "/home/ubuntu/.local/lib/python3.8/site-packages/selenium/webdriver/common/service.py", line 104, in start
    raise WebDriverException("Can not connect to the Service %s" % self.path)
selenium.common.exceptions.WebDriverException: Message: Can not connect to the Service chromedriver

Traceback (most recent call last):
  File "/home/ubuntu/trends-script/scraper.py", line 260, in <module>
    main()
  File "/home/ubuntu/trends-script/scraper.py", line 253, in main
    htmlstring = get_html_from_site()
  File "/home/ubuntu/trends-script/scraper.py", line 31, in get_html_from_site
    driver.get(start_url)
  File "/home/ubuntu/.local/lib/python3.8/site-packages/selenium/webdriver/remote/webdriver.py", line 333, in get
    self.execute(Command.GET, {'url': url})
  File "/home/ubuntu/.local/lib/python3.8/site-packages/selenium/webdriver/remote/webdriver.py", line 321, in execute
    self.error_handler.check_response(response)
  File "/home/ubuntu/.local/lib/python3.8/site-packages/selenium/webdriver/remote/errorhandler.py", line 242, in check_response
    raise exception_class(message, screen, stacktrace)
selenium.common.exceptions.TimeoutException: Message: timeout: Timed out receiving message from renderer: 289.750
  (Session info: headless chrome=87.0.4280.88)

Traceback (most recent call last):
  File "/home/ubuntu/trends-script/scraper.py", line 260, in <module>
    main()
  File "/home/ubuntu/trends-script/scraper.py", line 253, in main
    htmlstring = get_html_from_site()
  File "/home/ubuntu/trends-script/scraper.py", line 28, in get_html_from_site
    driver = webdriver.Chrome(options=options)
  File "/home/ubuntu/.local/lib/python3.8/site-packages/selenium/webdriver/chrome/webdriver.py", line 73, in __init__
    self.service.start()
  File "/home/ubuntu/.local/lib/python3.8/site-packages/selenium/webdriver/common/service.py", line 104, in start
    raise WebDriverException("Can not connect to the Service %s" % self.path)
selenium.common.exceptions.WebDriverException: Message: Can not connect to the Service chromedriver

Traceback (most recent call last):
  File "/home/ubuntu/trends-script/scraper.py", line 260, in <module>
    main()
  File "/home/ubuntu/trends-script/scraper.py", line 253, in main
    htmlstring = get_html_from_site()
  File "/home/ubuntu/trends-script/scraper.py", line 31, in get_html_from_site
    driver.get(start_url)
  File "/home/ubuntu/.local/lib/python3.8/site-packages/selenium/webdriver/remote/webdriver.py", line 333, in get
    self.execute(Command.GET, {'url': url})
  File "/home/ubuntu/.local/lib/python3.8/site-packages/selenium/webdriver/remote/webdriver.py", line 321, in execute
    self.error_handler.check_response(response)
  File "/home/ubuntu/.local/lib/python3.8/site-packages/selenium/webdriver/remote/errorhandler.py", line 242, in check_response
    raise exception_class(message, screen, stacktrace)
selenium.common.exceptions.WebDriverException: Message: unknown error: session deleted because of page crash
from tab crashed
  (Session info: headless chrome=87.0.4280.88)

Traceback (most recent call last):
  File "/home/ubuntu/trends-script/scraper.py", line 260, in <module>
    main()
  File "/home/ubuntu/trends-script/scraper.py", line 253, in main
    htmlstring = get_html_from_site()
  File "/home/ubuntu/trends-script/scraper.py", line 28, in get_html_from_site
    driver = webdriver.Chrome(options=options)
  File "/home/ubuntu/.local/lib/python3.8/site-packages/selenium/webdriver/chrome/webdriver.py", line 73, in __init__
    self.service.start()
  File "/home/ubuntu/.local/lib/python3.8/site-packages/selenium/webdriver/common/service.py", line 104, in start
    raise WebDriverException("Can not connect to the Service %s" % self.path)
selenium.common.exceptions.WebDriverException: Message: Can not connect to the Service chromedriver

Traceback (most recent call last):
  File "/home/ubuntu/trends-script/scraper.py", line 260, in <module>
    main()
  File "/home/ubuntu/trends-script/scraper.py", line 253, in main
    htmlstring = get_html_from_site()
  File "/home/ubuntu/trends-script/scraper.py", line 31, in get_html_from_site
    driver.get(start_url)
  File "/home/ubuntu/.local/lib/python3.8/site-packages/selenium/webdriver/remote/webdriver.py", line 333, in get
    self.execute(Command.GET, {'url': url})
  File "/home/ubuntu/.local/lib/python3.8/site-packages/selenium/webdriver/remote/webdriver.py", line 321, in execute
    self.error_handler.check_response(response)
  File "/home/ubuntu/.local/lib/python3.8/site-packages/selenium/webdriver/remote/errorhandler.py", line 242, in check_response
    raise exception_class(message, screen, stacktrace)
selenium.common.exceptions.TimeoutException: Message: timeout: Timed out receiving message from renderer: 293.321
  (Session info: headless chrome=87.0.4280.88)

Traceback (most recent call last):
  File "/home/ubuntu/trends-script/scraper.py", line 260, in <module>
    main()
  File "/home/ubuntu/trends-script/scraper.py", line 253, in main
    htmlstring = get_html_from_site()
  File "/home/ubuntu/trends-script/scraper.py", line 28, in get_html_from_site
    driver = webdriver.Chrome(options=options)
  File "/home/ubuntu/.local/lib/python3.8/site-packages/selenium/webdriver/chrome/webdriver.py", line 73, in __init__
    self.service.start()
  File "/home/ubuntu/.local/lib/python3.8/site-packages/selenium/webdriver/common/service.py", line 104, in start
    raise WebDriverException("Can not connect to the Service %s" % self.path)
selenium.common.exceptions.WebDriverException: Message: Can not connect to the Service chromedriver

Traceback (most recent call last):
  File "/home/ubuntu/trends-script/scraper.py", line 260, in <module>
    main()
  File "/home/ubuntu/trends-script/scraper.py", line 253, in main
    htmlstring = get_html_from_site()
  File "/home/ubuntu/trends-script/scraper.py", line 31, in get_html_from_site
    driver.get(start_url)
  File "/home/ubuntu/.local/lib/python3.8/site-packages/selenium/webdriver/remote/webdriver.py", line 333, in get
    self.execute(Command.GET, {'url': url})
  File "/home/ubuntu/.local/lib/python3.8/site-packages/selenium/webdriver/remote/webdriver.py", line 321, in execute
    self.error_handler.check_response(response)
  File "/home/ubuntu/.local/lib/python3.8/site-packages/selenium/webdriver/remote/errorhandler.py", line 242, in check_response
    raise exception_class(message, screen, stacktrace)
selenium.common.exceptions.TimeoutException: Message: timeout: Timed out receiving message from renderer: 290.004
  (Session info: headless chrome=87.0.4280.88)

Traceback (most recent call last):
  File "/home/ubuntu/trends-script/scraper.py", line 260, in <module>
    main()
  File "/home/ubuntu/trends-script/scraper.py", line 253, in main
    htmlstring = get_html_from_site()
  File "/home/ubuntu/trends-script/scraper.py", line 28, in get_html_from_site
    driver = webdriver.Chrome(options=options)
  File "/home/ubuntu/.local/lib/python3.8/site-packages/selenium/webdriver/chrome/webdriver.py", line 73, in __init__
    self.service.start()
  File "/home/ubuntu/.local/lib/python3.8/site-packages/selenium/webdriver/common/service.py", line 104, in start
    raise WebDriverException("Can not connect to the Service %s" % self.path)
selenium.common.exceptions.WebDriverException: Message: Can not connect to the Service chromedriver

Traceback (most recent call last):
  File "/home/ubuntu/trends-script/scraper.py", line 260, in <module>
    main()
  File "/home/ubuntu/trends-script/scraper.py", line 253, in main
    htmlstring = get_html_from_site()
  File "/home/ubuntu/trends-script/scraper.py", line 31, in get_html_from_site
    driver.get(start_url)
  File "/home/ubuntu/.local/lib/python3.8/site-packages/selenium/webdriver/remote/webdriver.py", line 333, in get
    self.execute(Command.GET, {'url': url})
  File "/home/ubuntu/.local/lib/python3.8/site-packages/selenium/webdriver/remote/webdriver.py", line 321, in execute
    self.error_handler.check_response(response)
  File "/home/ubuntu/.local/lib/python3.8/site-packages/selenium/webdriver/remote/errorhandler.py", line 242, in check_response
    raise exception_class(message, screen, stacktrace)
selenium.common.exceptions.TimeoutException: Message: timeout: Timed out receiving message from renderer: 289.055
  (Session info: headless chrome=87.0.4280.88)

Traceback (most recent call last):
  File "/home/ubuntu/trends-script/scraper.py", line 260, in <module>
    main()
  File "/home/ubuntu/trends-script/scraper.py", line 253, in main
    htmlstring = get_html_from_site()
  File "/home/ubuntu/trends-script/scraper.py", line 28, in get_html_from_site
    driver = webdriver.Chrome(options=options)
  File "/home/ubuntu/.local/lib/python3.8/site-packages/selenium/webdriver/chrome/webdriver.py", line 73, in __init__
    self.service.start()
  File "/home/ubuntu/.local/lib/python3.8/site-packages/selenium/webdriver/common/service.py", line 104, in start
    raise WebDriverException("Can not connect to the Service %s" % self.path)
selenium.common.exceptions.WebDriverException: Message: Can not connect to the Service chromedriver

Traceback (most recent call last):
  File "/home/ubuntu/trends-script/scraper.py", line 260, in <module>
    main()
  File "/home/ubuntu/trends-script/scraper.py", line 253, in main
    htmlstring = get_html_from_site()
  File "/home/ubuntu/trends-script/scraper.py", line 31, in get_html_from_site
    driver.get(start_url)
  File "/home/ubuntu/.local/lib/python3.8/site-packages/selenium/webdriver/remote/webdriver.py", line 333, in get
    self.execute(Command.GET, {'url': url})
  File "/home/ubuntu/.local/lib/python3.8/site-packages/selenium/webdriver/remote/webdriver.py", line 321, in execute
    self.error_handler.check_response(response)
  File "/home/ubuntu/.local/lib/python3.8/site-packages/selenium/webdriver/remote/errorhandler.py", line 242, in check_response
    raise exception_class(message, screen, stacktrace)
selenium.common.exceptions.TimeoutException: Message: timeout: Timed out receiving message from renderer: 290.519
  (Session info: headless chrome=87.0.4280.88)

Traceback (most recent call last):
  File "/home/ubuntu/trends-script/scraper.py", line 260, in <module>
    main()
  File "/home/ubuntu/trends-script/scraper.py", line 253, in main
    htmlstring = get_html_from_site()
  File "/home/ubuntu/trends-script/scraper.py", line 28, in get_html_from_site
    driver = webdriver.Chrome(options=options)
  File "/home/ubuntu/.local/lib/python3.8/site-packages/selenium/webdriver/chrome/webdriver.py", line 73, in __init__
    self.service.start()
  File "/home/ubuntu/.local/lib/python3.8/site-packages/selenium/webdriver/common/service.py", line 104, in start
    raise WebDriverException("Can not connect to the Service %s" % self.path)
selenium.common.exceptions.WebDriverException: Message: Can not connect to the Service chromedriver

Traceback (most recent call last):
  File "/home/ubuntu/trends-script/scraper.py", line 260, in <module>
    main()
  File "/home/ubuntu/trends-script/scraper.py", line 253, in main
    htmlstring = get_html_from_site()
  File "/home/ubuntu/trends-script/scraper.py", line 31, in get_html_from_site
    driver.get(start_url)
  File "/home/ubuntu/.local/lib/python3.8/site-packages/selenium/webdriver/remote/webdriver.py", line 333, in get
    self.execute(Command.GET, {'url': url})
  File "/home/ubuntu/.local/lib/python3.8/site-packages/selenium/webdriver/remote/webdriver.py", line 321, in execute
    self.error_handler.check_response(response)
  File "/home/ubuntu/.local/lib/python3.8/site-packages/selenium/webdriver/remote/errorhandler.py", line 242, in check_response
    raise exception_class(message, screen, stacktrace)
selenium.common.exceptions.TimeoutException: Message: timeout: Timed out receiving message from renderer: 286.509
  (Session info: headless chrome=87.0.4280.88)

Traceback (most recent call last):
  File "/home/ubuntu/trends-script/scraper.py", line 260, in <module>
    main()
  File "/home/ubuntu/trends-script/scraper.py", line 253, in main
    htmlstring = get_html_from_site()
  File "/home/ubuntu/trends-script/scraper.py", line 28, in get_html_from_site
    driver = webdriver.Chrome(options=options)
  File "/home/ubuntu/.local/lib/python3.8/site-packages/selenium/webdriver/chrome/webdriver.py", line 73, in __init__
    self.service.start()
  File "/home/ubuntu/.local/lib/python3.8/site-packages/selenium/webdriver/common/service.py", line 104, in start
    raise WebDriverException("Can not connect to the Service %s" % self.path)
selenium.common.exceptions.WebDriverException: Message: Can not connect to the Service chromedriver

Traceback (most recent call last):
  File "/home/ubuntu/trends-script/scraper.py", line 260, in <module>
    main()
  File "/home/ubuntu/trends-script/scraper.py", line 253, in main
    htmlstring = get_html_from_site()
  File "/home/ubuntu/trends-script/scraper.py", line 31, in get_html_from_site
    driver.get(start_url)
  File "/home/ubuntu/.local/lib/python3.8/site-packages/selenium/webdriver/remote/webdriver.py", line 333, in get
    self.execute(Command.GET, {'url': url})
  File "/home/ubuntu/.local/lib/python3.8/site-packages/selenium/webdriver/remote/webdriver.py", line 321, in execute
    self.error_handler.check_response(response)
  File "/home/ubuntu/.local/lib/python3.8/site-packages/selenium/webdriver/remote/errorhandler.py", line 242, in check_response
    raise exception_class(message, screen, stacktrace)
selenium.common.exceptions.TimeoutException: Message: timeout: Timed out receiving message from renderer: 290.397
  (Session info: headless chrome=87.0.4280.88)

Traceback (most recent call last):
  File "/home/ubuntu/trends-script/scraper.py", line 260, in <module>
    main()
  File "/home/ubuntu/trends-script/scraper.py", line 253, in main
    htmlstring = get_html_from_site()
  File "/home/ubuntu/trends-script/scraper.py", line 28, in get_html_from_site
    driver = webdriver.Chrome(options=options)
  File "/home/ubuntu/.local/lib/python3.8/site-packages/selenium/webdriver/chrome/webdriver.py", line 73, in __init__
    self.service.start()
  File "/home/ubuntu/.local/lib/python3.8/site-packages/selenium/webdriver/common/service.py", line 104, in start
    raise WebDriverException("Can not connect to the Service %s" % self.path)
selenium.common.exceptions.WebDriverException: Message: Can not connect to the Service chromedriver

Traceback (most recent call last):
  File "/home/ubuntu/trends-script/scraper.py", line 260, in <module>
    main()
  File "/home/ubuntu/trends-script/scraper.py", line 253, in main
    htmlstring = get_html_from_site()
  File "/home/ubuntu/trends-script/scraper.py", line 31, in get_html_from_site
    driver.get(start_url)
  File "/home/ubuntu/.local/lib/python3.8/site-packages/selenium/webdriver/remote/webdriver.py", line 333, in get
    self.execute(Command.GET, {'url': url})
  File "/home/ubuntu/.local/lib/python3.8/site-packages/selenium/webdriver/remote/webdriver.py", line 321, in execute
    self.error_handler.check_response(response)
  File "/home/ubuntu/.local/lib/python3.8/site-packages/selenium/webdriver/remote/errorhandler.py", line 242, in check_response
    raise exception_class(message, screen, stacktrace)
selenium.common.exceptions.TimeoutException: Message: timeout: Timed out receiving message from renderer: 289.908
  (Session info: headless chrome=87.0.4280.88)

Traceback (most recent call last):
  File "/home/ubuntu/trends-script/scraper.py", line 260, in <module>
    main()
  File "/home/ubuntu/trends-script/scraper.py", line 253, in main
    htmlstring = get_html_from_site()
  File "/home/ubuntu/trends-script/scraper.py", line 28, in get_html_from_site
    driver = webdriver.Chrome(options=options)
  File "/home/ubuntu/.local/lib/python3.8/site-packages/selenium/webdriver/chrome/webdriver.py", line 73, in __init__
    self.service.start()
  File "/home/ubuntu/.local/lib/python3.8/site-packages/selenium/webdriver/common/service.py", line 104, in start
    raise WebDriverException("Can not connect to the Service %s" % self.path)
selenium.common.exceptions.WebDriverException: Message: Can not connect to the Service chromedriver

Traceback (most recent call last):
  File "/home/ubuntu/trends-script/scraper.py", line 260, in <module>
    main()
  File "/home/ubuntu/trends-script/scraper.py", line 253, in main
    htmlstring = get_html_from_site()
  File "/home/ubuntu/trends-script/scraper.py", line 31, in get_html_from_site
    driver.get(start_url)
  File "/home/ubuntu/.local/lib/python3.8/site-packages/selenium/webdriver/remote/webdriver.py", line 333, in get
    self.execute(Command.GET, {'url': url})
  File "/home/ubuntu/.local/lib/python3.8/site-packages/selenium/webdriver/remote/webdriver.py", line 321, in execute
    self.error_handler.check_response(response)
  File "/home/ubuntu/.local/lib/python3.8/site-packages/selenium/webdriver/remote/errorhandler.py", line 242, in check_response
    raise exception_class(message, screen, stacktrace)
selenium.common.exceptions.TimeoutException: Message: timeout: Timed out receiving message from renderer: 291.031
  (Session info: headless chrome=87.0.4280.88)

Traceback (most recent call last):
  File "/home/ubuntu/trends-script/scraper.py", line 260, in <module>
    main()
  File "/home/ubuntu/trends-script/scraper.py", line 253, in main
    htmlstring = get_html_from_site()
  File "/home/ubuntu/trends-script/scraper.py", line 28, in get_html_from_site
    driver = webdriver.Chrome(options=options)
  File "/home/ubuntu/.local/lib/python3.8/site-packages/selenium/webdriver/chrome/webdriver.py", line 73, in __init__
    self.service.start()
  File "/home/ubuntu/.local/lib/python3.8/site-packages/selenium/webdriver/common/service.py", line 104, in start
    raise WebDriverException("Can not connect to the Service %s" % self.path)
selenium.common.exceptions.WebDriverException: Message: Can not connect to the Service chromedriver

Traceback (most recent call last):
  File "/home/ubuntu/trends-script/scraper.py", line 260, in <module>
    main()
  File "/home/ubuntu/trends-script/scraper.py", line 253, in main
    htmlstring = get_html_from_site()
  File "/home/ubuntu/trends-script/scraper.py", line 31, in get_html_from_site
    driver.get(start_url)
  File "/home/ubuntu/.local/lib/python3.8/site-packages/selenium/webdriver/remote/webdriver.py", line 333, in get
    self.execute(Command.GET, {'url': url})
  File "/home/ubuntu/.local/lib/python3.8/site-packages/selenium/webdriver/remote/webdriver.py", line 321, in execute
    self.error_handler.check_response(response)
  File "/home/ubuntu/.local/lib/python3.8/site-packages/selenium/webdriver/remote/errorhandler.py", line 242, in check_response
    raise exception_class(message, screen, stacktrace)
selenium.common.exceptions.TimeoutException: Message: timeout: Timed out receiving message from renderer: 290.812
  (Session info: headless chrome=87.0.4280.88)

Traceback (most recent call last):
  File "/home/ubuntu/trends-script/scraper.py", line 260, in <module>
    main()
  File "/home/ubuntu/trends-script/scraper.py", line 253, in main
    htmlstring = get_html_from_site()
  File "/home/ubuntu/trends-script/scraper.py", line 28, in get_html_from_site
    driver = webdriver.Chrome(options=options)
  File "/home/ubuntu/.local/lib/python3.8/site-packages/selenium/webdriver/chrome/webdriver.py", line 73, in __init__
    self.service.start()
  File "/home/ubuntu/.local/lib/python3.8/site-packages/selenium/webdriver/common/service.py", line 104, in start
    raise WebDriverException("Can not connect to the Service %s" % self.path)
selenium.common.exceptions.WebDriverException: Message: Can not connect to the Service chromedriver

Traceback (most recent call last):
  File "/home/ubuntu/trends-script/scraper.py", line 260, in <module>
    main()
  File "/home/ubuntu/trends-script/scraper.py", line 253, in main
    htmlstring = get_html_from_site()
  File "/home/ubuntu/trends-script/scraper.py", line 31, in get_html_from_site
    driver.get(start_url)
  File "/home/ubuntu/.local/lib/python3.8/site-packages/selenium/webdriver/remote/webdriver.py", line 333, in get
    self.execute(Command.GET, {'url': url})
  File "/home/ubuntu/.local/lib/python3.8/site-packages/selenium/webdriver/remote/webdriver.py", line 321, in execute
    self.error_handler.check_response(response)
  File "/home/ubuntu/.local/lib/python3.8/site-packages/selenium/webdriver/remote/errorhandler.py", line 242, in check_response
    raise exception_class(message, screen, stacktrace)
selenium.common.exceptions.TimeoutException: Message: timeout: Timed out receiving message from renderer: 291.871
  (Session info: headless chrome=87.0.4280.88)

Traceback (most recent call last):
  File "/home/ubuntu/trends-script/scraper.py", line 260, in <module>
    main()
  File "/home/ubuntu/trends-script/scraper.py", line 253, in main
    htmlstring = get_html_from_site()
  File "/home/ubuntu/trends-script/scraper.py", line 28, in get_html_from_site
    driver = webdriver.Chrome(options=options)
  File "/home/ubuntu/.local/lib/python3.8/site-packages/selenium/webdriver/chrome/webdriver.py", line 73, in __init__
    self.service.start()
  File "/home/ubuntu/.local/lib/python3.8/site-packages/selenium/webdriver/common/service.py", line 104, in start
    raise WebDriverException("Can not connect to the Service %s" % self.path)
selenium.common.exceptions.WebDriverException: Message: Can not connect to the Service chromedriver

Traceback (most recent call last):
  File "/home/ubuntu/trends-script/scraper.py", line 260, in <module>
    main()
  File "/home/ubuntu/trends-script/scraper.py", line 253, in main
    htmlstring = get_html_from_site()
  File "/home/ubuntu/trends-script/scraper.py", line 31, in get_html_from_site
    driver.get(start_url)
  File "/home/ubuntu/.local/lib/python3.8/site-packages/selenium/webdriver/remote/webdriver.py", line 333, in get
    self.execute(Command.GET, {'url': url})
  File "/home/ubuntu/.local/lib/python3.8/site-packages/selenium/webdriver/remote/webdriver.py", line 321, in execute
    self.error_handler.check_response(response)
  File "/home/ubuntu/.local/lib/python3.8/site-packages/selenium/webdriver/remote/errorhandler.py", line 242, in check_response
    raise exception_class(message, screen, stacktrace)
selenium.common.exceptions.TimeoutException: Message: timeout: Timed out receiving message from renderer: 291.103
  (Session info: headless chrome=87.0.4280.88)

Traceback (most recent call last):
  File "/home/ubuntu/trends-script/scraper.py", line 260, in <module>
    main()
  File "/home/ubuntu/trends-script/scraper.py", line 253, in main
    htmlstring = get_html_from_site()
  File "/home/ubuntu/trends-script/scraper.py", line 28, in get_html_from_site
    driver = webdriver.Chrome(options=options)
  File "/home/ubuntu/.local/lib/python3.8/site-packages/selenium/webdriver/chrome/webdriver.py", line 73, in __init__
    self.service.start()
  File "/home/ubuntu/.local/lib/python3.8/site-packages/selenium/webdriver/common/service.py", line 104, in start
    raise WebDriverException("Can not connect to the Service %s" % self.path)
selenium.common.exceptions.WebDriverException: Message: Can not connect to the Service chromedriver

Traceback (most recent call last):
  File "/home/ubuntu/trends-script/scraper.py", line 260, in <module>
    main()
  File "/home/ubuntu/trends-script/scraper.py", line 253, in main
    htmlstring = get_html_from_site()
  File "/home/ubuntu/trends-script/scraper.py", line 31, in get_html_from_site
    driver.get(start_url)
  File "/home/ubuntu/.local/lib/python3.8/site-packages/selenium/webdriver/remote/webdriver.py", line 333, in get
    self.execute(Command.GET, {'url': url})
  File "/home/ubuntu/.local/lib/python3.8/site-packages/selenium/webdriver/remote/webdriver.py", line 321, in execute
    self.error_handler.check_response(response)
  File "/home/ubuntu/.local/lib/python3.8/site-packages/selenium/webdriver/remote/errorhandler.py", line 242, in check_response
    raise exception_class(message, screen, stacktrace)
selenium.common.exceptions.TimeoutException: Message: timeout: Timed out receiving message from renderer: 290.928
  (Session info: headless chrome=87.0.4280.88)

Traceback (most recent call last):
  File "/home/ubuntu/trends-script/scraper.py", line 260, in <module>
    main()
  File "/home/ubuntu/trends-script/scraper.py", line 253, in main
    htmlstring = get_html_from_site()
  File "/home/ubuntu/trends-script/scraper.py", line 28, in get_html_from_site
    driver = webdriver.Chrome(options=options)
  File "/home/ubuntu/.local/lib/python3.8/site-packages/selenium/webdriver/chrome/webdriver.py", line 73, in __init__
    self.service.start()
  File "/home/ubuntu/.local/lib/python3.8/site-packages/selenium/webdriver/common/service.py", line 104, in start
    raise WebDriverException("Can not connect to the Service %s" % self.path)
selenium.common.exceptions.WebDriverException: Message: Can not connect to the Service chromedriver

Traceback (most recent call last):
  File "/home/ubuntu/trends-script/scraper.py", line 260, in <module>
    main()
  File "/home/ubuntu/trends-script/scraper.py", line 253, in main
    htmlstring = get_html_from_site()
  File "/home/ubuntu/trends-script/scraper.py", line 31, in get_html_from_site
    driver.get(start_url)
  File "/home/ubuntu/.local/lib/python3.8/site-packages/selenium/webdriver/remote/webdriver.py", line 333, in get
    self.execute(Command.GET, {'url': url})
  File "/home/ubuntu/.local/lib/python3.8/site-packages/selenium/webdriver/remote/webdriver.py", line 321, in execute
    self.error_handler.check_response(response)
  File "/home/ubuntu/.local/lib/python3.8/site-packages/selenium/webdriver/remote/errorhandler.py", line 242, in check_response
    raise exception_class(message, screen, stacktrace)
selenium.common.exceptions.TimeoutException: Message: timeout: Timed out receiving message from renderer: 289.240
  (Session info: headless chrome=87.0.4280.88)

Traceback (most recent call last):
  File "/home/ubuntu/trends-script/scraper.py", line 260, in <module>
    main()
  File "/home/ubuntu/trends-script/scraper.py", line 253, in main
    htmlstring = get_html_from_site()
  File "/home/ubuntu/trends-script/scraper.py", line 28, in get_html_from_site
    driver = webdriver.Chrome(options=options)
  File "/home/ubuntu/.local/lib/python3.8/site-packages/selenium/webdriver/chrome/webdriver.py", line 73, in __init__
    self.service.start()
  File "/home/ubuntu/.local/lib/python3.8/site-packages/selenium/webdriver/common/service.py", line 104, in start
    raise WebDriverException("Can not connect to the Service %s" % self.path)
selenium.common.exceptions.WebDriverException: Message: Can not connect to the Service chromedriver

Traceback (most recent call last):
  File "/home/ubuntu/trends-script/scraper.py", line 260, in <module>
    main()
  File "/home/ubuntu/trends-script/scraper.py", line 253, in main
    htmlstring = get_html_from_site()
  File "/home/ubuntu/trends-script/scraper.py", line 31, in get_html_from_site
    driver.get(start_url)
  File "/home/ubuntu/.local/lib/python3.8/site-packages/selenium/webdriver/remote/webdriver.py", line 333, in get
    self.execute(Command.GET, {'url': url})
  File "/home/ubuntu/.local/lib/python3.8/site-packages/selenium/webdriver/remote/webdriver.py", line 321, in execute
    self.error_handler.check_response(response)
  File "/home/ubuntu/.local/lib/python3.8/site-packages/selenium/webdriver/remote/errorhandler.py", line 242, in check_response
    raise exception_class(message, screen, stacktrace)
selenium.common.exceptions.TimeoutException: Message: timeout: Timed out receiving message from renderer: 286.850
  (Session info: headless chrome=87.0.4280.88)

Traceback (most recent call last):
  File "/home/ubuntu/trends-script/scraper.py", line 260, in <module>
    main()
  File "/home/ubuntu/trends-script/scraper.py", line 253, in main
    htmlstring = get_html_from_site()
  File "/home/ubuntu/trends-script/scraper.py", line 31, in get_html_from_site
    driver.get(start_url)
  File "/home/ubuntu/.local/lib/python3.8/site-packages/selenium/webdriver/remote/webdriver.py", line 333, in get
    self.execute(Command.GET, {'url': url})
  File "/home/ubuntu/.local/lib/python3.8/site-packages/selenium/webdriver/remote/webdriver.py", line 321, in execute
    self.error_handler.check_response(response)
  File "/home/ubuntu/.local/lib/python3.8/site-packages/selenium/webdriver/remote/errorhandler.py", line 242, in check_response
    raise exception_class(message, screen, stacktrace)
selenium.common.exceptions.WebDriverException: Message: unknown error: session deleted because of page crash
from unknown error: cannot determine loading status
from tab crashed
  (Session info: headless chrome=87.0.4280.88)

Traceback (most recent call last):
  File "/home/ubuntu/trends-script/scraper.py", line 260, in <module>
    main()
  File "/home/ubuntu/trends-script/scraper.py", line 253, in main
    htmlstring = get_html_from_site()
  File "/home/ubuntu/trends-script/scraper.py", line 28, in get_html_from_site
    driver = webdriver.Chrome(options=options)
  File "/home/ubuntu/.local/lib/python3.8/site-packages/selenium/webdriver/chrome/webdriver.py", line 73, in __init__
    self.service.start()
  File "/home/ubuntu/.local/lib/python3.8/site-packages/selenium/webdriver/common/service.py", line 104, in start
    raise WebDriverException("Can not connect to the Service %s" % self.path)
selenium.common.exceptions.WebDriverException: Message: Can not connect to the Service chromedriver

Traceback (most recent call last):
  File "/home/ubuntu/trends-script/scraper.py", line 260, in <module>
    main()
  File "/home/ubuntu/trends-script/scraper.py", line 253, in main
    htmlstring = get_html_from_site()
  File "/home/ubuntu/trends-script/scraper.py", line 31, in get_html_from_site
    driver.get(start_url)
  File "/home/ubuntu/.local/lib/python3.8/site-packages/selenium/webdriver/remote/webdriver.py", line 333, in get
    self.execute(Command.GET, {'url': url})
  File "/home/ubuntu/.local/lib/python3.8/site-packages/selenium/webdriver/remote/webdriver.py", line 321, in execute
    self.error_handler.check_response(response)
  File "/home/ubuntu/.local/lib/python3.8/site-packages/selenium/webdriver/remote/errorhandler.py", line 242, in check_response
    raise exception_class(message, screen, stacktrace)
selenium.common.exceptions.TimeoutException: Message: timeout: Timed out receiving message from renderer: 290.989
  (Session info: headless chrome=87.0.4280.88)

Traceback (most recent call last):
  File "/home/ubuntu/trends-script/scraper.py", line 260, in <module>
    main()
  File "/home/ubuntu/trends-script/scraper.py", line 253, in main
    htmlstring = get_html_from_site()
  File "/home/ubuntu/trends-script/scraper.py", line 28, in get_html_from_site
    driver = webdriver.Chrome(options=options)
  File "/home/ubuntu/.local/lib/python3.8/site-packages/selenium/webdriver/chrome/webdriver.py", line 73, in __init__
    self.service.start()
  File "/home/ubuntu/.local/lib/python3.8/site-packages/selenium/webdriver/common/service.py", line 104, in start
    raise WebDriverException("Can not connect to the Service %s" % self.path)
selenium.common.exceptions.WebDriverException: Message: Can not connect to the Service chromedriver

Traceback (most recent call last):
  File "/home/ubuntu/trends-script/scraper.py", line 260, in <module>
    main()
  File "/home/ubuntu/trends-script/scraper.py", line 253, in main
    htmlstring = get_html_from_site()
  File "/home/ubuntu/trends-script/scraper.py", line 31, in get_html_from_site
    driver.get(start_url)
  File "/home/ubuntu/.local/lib/python3.8/site-packages/selenium/webdriver/remote/webdriver.py", line 333, in get
    self.execute(Command.GET, {'url': url})
  File "/home/ubuntu/.local/lib/python3.8/site-packages/selenium/webdriver/remote/webdriver.py", line 321, in execute
    self.error_handler.check_response(response)
  File "/home/ubuntu/.local/lib/python3.8/site-packages/selenium/webdriver/remote/errorhandler.py", line 242, in check_response
    raise exception_class(message, screen, stacktrace)
selenium.common.exceptions.TimeoutException: Message: timeout: Timed out receiving message from renderer: 288.955
  (Session info: headless chrome=87.0.4280.88)

Traceback (most recent call last):
  File "/home/ubuntu/trends-script/scraper.py", line 260, in <module>
    main()
  File "/home/ubuntu/trends-script/scraper.py", line 253, in main
    htmlstring = get_html_from_site()
  File "/home/ubuntu/trends-script/scraper.py", line 28, in get_html_from_site
    driver = webdriver.Chrome(options=options)
  File "/home/ubuntu/.local/lib/python3.8/site-packages/selenium/webdriver/chrome/webdriver.py", line 73, in __init__
    self.service.start()
  File "/home/ubuntu/.local/lib/python3.8/site-packages/selenium/webdriver/common/service.py", line 104, in start
    raise WebDriverException("Can not connect to the Service %s" % self.path)
selenium.common.exceptions.WebDriverException: Message: Can not connect to the Service chromedriver

Traceback (most recent call last):
  File "/home/ubuntu/trends-script/scraper.py", line 260, in <module>
    main()
  File "/home/ubuntu/trends-script/scraper.py", line 253, in main
    htmlstring = get_html_from_site()
  File "/home/ubuntu/trends-script/scraper.py", line 31, in get_html_from_site
    driver.get(start_url)
  File "/home/ubuntu/.local/lib/python3.8/site-packages/selenium/webdriver/remote/webdriver.py", line 333, in get
    self.execute(Command.GET, {'url': url})
  File "/home/ubuntu/.local/lib/python3.8/site-packages/selenium/webdriver/remote/webdriver.py", line 321, in execute
    self.error_handler.check_response(response)
  File "/home/ubuntu/.local/lib/python3.8/site-packages/selenium/webdriver/remote/errorhandler.py", line 242, in check_response
    raise exception_class(message, screen, stacktrace)
selenium.common.exceptions.TimeoutException: Message: timeout: Timed out receiving message from renderer: 288.817
  (Session info: headless chrome=87.0.4280.88)

Traceback (most recent call last):
  File "/home/ubuntu/trends-script/scraper.py", line 260, in <module>
    main()
  File "/home/ubuntu/trends-script/scraper.py", line 253, in main
    htmlstring = get_html_from_site()
  File "/home/ubuntu/trends-script/scraper.py", line 28, in get_html_from_site
    driver = webdriver.Chrome(options=options)
  File "/home/ubuntu/.local/lib/python3.8/site-packages/selenium/webdriver/chrome/webdriver.py", line 73, in __init__
    self.service.start()
  File "/home/ubuntu/.local/lib/python3.8/site-packages/selenium/webdriver/common/service.py", line 104, in start
    raise WebDriverException("Can not connect to the Service %s" % self.path)
selenium.common.exceptions.WebDriverException: Message: Can not connect to the Service chromedriver

Traceback (most recent call last):
  File "/home/ubuntu/trends-script/scraper.py", line 260, in <module>
    main()
  File "/home/ubuntu/trends-script/scraper.py", line 253, in main
    htmlstring = get_html_from_site()
  File "/home/ubuntu/trends-script/scraper.py", line 31, in get_html_from_site
    driver.get(start_url)
  File "/home/ubuntu/.local/lib/python3.8/site-packages/selenium/webdriver/remote/webdriver.py", line 333, in get
    self.execute(Command.GET, {'url': url})
  File "/home/ubuntu/.local/lib/python3.8/site-packages/selenium/webdriver/remote/webdriver.py", line 321, in execute
    self.error_handler.check_response(response)
  File "/home/ubuntu/.local/lib/python3.8/site-packages/selenium/webdriver/remote/errorhandler.py", line 242, in check_response
    raise exception_class(message, screen, stacktrace)
selenium.common.exceptions.TimeoutException: Message: timeout: Timed out receiving message from renderer: 290.249
  (Session info: headless chrome=87.0.4280.88)

Traceback (most recent call last):
  File "/home/ubuntu/trends-script/scraper.py", line 260, in <module>
    main()
  File "/home/ubuntu/trends-script/scraper.py", line 253, in main
    htmlstring = get_html_from_site()
  File "/home/ubuntu/trends-script/scraper.py", line 28, in get_html_from_site
    driver = webdriver.Chrome(options=options)
  File "/home/ubuntu/.local/lib/python3.8/site-packages/selenium/webdriver/chrome/webdriver.py", line 73, in __init__
    self.service.start()
  File "/home/ubuntu/.local/lib/python3.8/site-packages/selenium/webdriver/common/service.py", line 104, in start
    raise WebDriverException("Can not connect to the Service %s" % self.path)
selenium.common.exceptions.WebDriverException: Message: Can not connect to the Service chromedriver

Traceback (most recent call last):
  File "/home/ubuntu/trends-script/scraper.py", line 260, in <module>
    main()
  File "/home/ubuntu/trends-script/scraper.py", line 253, in main
    htmlstring = get_html_from_site()
  File "/home/ubuntu/trends-script/scraper.py", line 31, in get_html_from_site
    driver.get(start_url)
  File "/home/ubuntu/.local/lib/python3.8/site-packages/selenium/webdriver/remote/webdriver.py", line 333, in get
    self.execute(Command.GET, {'url': url})
  File "/home/ubuntu/.local/lib/python3.8/site-packages/selenium/webdriver/remote/webdriver.py", line 321, in execute
    self.error_handler.check_response(response)
  File "/home/ubuntu/.local/lib/python3.8/site-packages/selenium/webdriver/remote/errorhandler.py", line 242, in check_response
    raise exception_class(message, screen, stacktrace)
selenium.common.exceptions.TimeoutException: Message: timeout: Timed out receiving message from renderer: 290.684
  (Session info: headless chrome=87.0.4280.88)

Traceback (most recent call last):
  File "/home/ubuntu/trends-script/scraper.py", line 260, in <module>
    main()
  File "/home/ubuntu/trends-script/scraper.py", line 253, in main
    htmlstring = get_html_from_site()
  File "/home/ubuntu/trends-script/scraper.py", line 28, in get_html_from_site
    driver = webdriver.Chrome(options=options)
  File "/home/ubuntu/.local/lib/python3.8/site-packages/selenium/webdriver/chrome/webdriver.py", line 73, in __init__
    self.service.start()
  File "/home/ubuntu/.local/lib/python3.8/site-packages/selenium/webdriver/common/service.py", line 104, in start
    raise WebDriverException("Can not connect to the Service %s" % self.path)
selenium.common.exceptions.WebDriverException: Message: Can not connect to the Service chromedriver

Traceback (most recent call last):
  File "/home/ubuntu/trends-script/scraper.py", line 260, in <module>
    main()
  File "/home/ubuntu/trends-script/scraper.py", line 253, in main
    htmlstring = get_html_from_site()
  File "/home/ubuntu/trends-script/scraper.py", line 31, in get_html_from_site
    driver.get(start_url)
  File "/home/ubuntu/.local/lib/python3.8/site-packages/selenium/webdriver/remote/webdriver.py", line 333, in get
    self.execute(Command.GET, {'url': url})
  File "/home/ubuntu/.local/lib/python3.8/site-packages/selenium/webdriver/remote/webdriver.py", line 321, in execute
    self.error_handler.check_response(response)
  File "/home/ubuntu/.local/lib/python3.8/site-packages/selenium/webdriver/remote/errorhandler.py", line 242, in check_response
    raise exception_class(message, screen, stacktrace)
selenium.common.exceptions.TimeoutException: Message: timeout: Timed out receiving message from renderer: 291.552
  (Session info: headless chrome=87.0.4280.88)

Traceback (most recent call last):
  File "/home/ubuntu/trends-script/scraper.py", line 260, in <module>
    main()
  File "/home/ubuntu/trends-script/scraper.py", line 253, in main
    htmlstring = get_html_from_site()
  File "/home/ubuntu/trends-script/scraper.py", line 28, in get_html_from_site
    driver = webdriver.Chrome(options=options)
  File "/home/ubuntu/.local/lib/python3.8/site-packages/selenium/webdriver/chrome/webdriver.py", line 73, in __init__
    self.service.start()
  File "/home/ubuntu/.local/lib/python3.8/site-packages/selenium/webdriver/common/service.py", line 104, in start
    raise WebDriverException("Can not connect to the Service %s" % self.path)
selenium.common.exceptions.WebDriverException: Message: Can not connect to the Service chromedriver

Traceback (most recent call last):
  File "/home/ubuntu/trends-script/scraper.py", line 260, in <module>
    main()
  File "/home/ubuntu/trends-script/scraper.py", line 253, in main
    htmlstring = get_html_from_site()
  File "/home/ubuntu/trends-script/scraper.py", line 31, in get_html_from_site
    driver.get(start_url)
  File "/home/ubuntu/.local/lib/python3.8/site-packages/selenium/webdriver/remote/webdriver.py", line 333, in get
    self.execute(Command.GET, {'url': url})
  File "/home/ubuntu/.local/lib/python3.8/site-packages/selenium/webdriver/remote/webdriver.py", line 321, in execute
    self.error_handler.check_response(response)
  File "/home/ubuntu/.local/lib/python3.8/site-packages/selenium/webdriver/remote/errorhandler.py", line 242, in check_response
    raise exception_class(message, screen, stacktrace)
selenium.common.exceptions.TimeoutException: Message: timeout: Timed out receiving message from renderer: 292.320
  (Session info: headless chrome=87.0.4280.88)

Traceback (most recent call last):
  File "/home/ubuntu/trends-script/scraper.py", line 260, in <module>
    main()
  File "/home/ubuntu/trends-script/scraper.py", line 253, in main
    htmlstring = get_html_from_site()
  File "/home/ubuntu/trends-script/scraper.py", line 28, in get_html_from_site
    driver = webdriver.Chrome(options=options)
  File "/home/ubuntu/.local/lib/python3.8/site-packages/selenium/webdriver/chrome/webdriver.py", line 73, in __init__
    self.service.start()
  File "/home/ubuntu/.local/lib/python3.8/site-packages/selenium/webdriver/common/service.py", line 104, in start
    raise WebDriverException("Can not connect to the Service %s" % self.path)
selenium.common.exceptions.WebDriverException: Message: Can not connect to the Service chromedriver

Traceback (most recent call last):
  File "/home/ubuntu/trends-script/scraper.py", line 260, in <module>
    main()
  File "/home/ubuntu/trends-script/scraper.py", line 253, in main
    htmlstring = get_html_from_site()
  File "/home/ubuntu/trends-script/scraper.py", line 31, in get_html_from_site
    driver.get(start_url)
  File "/home/ubuntu/.local/lib/python3.8/site-packages/selenium/webdriver/remote/webdriver.py", line 333, in get
    self.execute(Command.GET, {'url': url})
  File "/home/ubuntu/.local/lib/python3.8/site-packages/selenium/webdriver/remote/webdriver.py", line 321, in execute
    self.error_handler.check_response(response)
  File "/home/ubuntu/.local/lib/python3.8/site-packages/selenium/webdriver/remote/errorhandler.py", line 242, in check_response
    raise exception_class(message, screen, stacktrace)
selenium.common.exceptions.TimeoutException: Message: timeout: Timed out receiving message from renderer: 291.867
  (Session info: headless chrome=87.0.4280.88)

Traceback (most recent call last):
  File "/home/ubuntu/trends-script/scraper.py", line 260, in <module>
    main()
  File "/home/ubuntu/trends-script/scraper.py", line 253, in main
    htmlstring = get_html_from_site()
  File "/home/ubuntu/trends-script/scraper.py", line 28, in get_html_from_site
    driver = webdriver.Chrome(options=options)
  File "/home/ubuntu/.local/lib/python3.8/site-packages/selenium/webdriver/chrome/webdriver.py", line 73, in __init__
    self.service.start()
  File "/home/ubuntu/.local/lib/python3.8/site-packages/selenium/webdriver/common/service.py", line 104, in start
    raise WebDriverException("Can not connect to the Service %s" % self.path)
selenium.common.exceptions.WebDriverException: Message: Can not connect to the Service chromedriver

Traceback (most recent call last):
  File "/home/ubuntu/trends-script/scraper.py", line 260, in <module>
    main()
  File "/home/ubuntu/trends-script/scraper.py", line 253, in main
    htmlstring = get_html_from_site()
  File "/home/ubuntu/trends-script/scraper.py", line 31, in get_html_from_site
    driver.get(start_url)
  File "/home/ubuntu/.local/lib/python3.8/site-packages/selenium/webdriver/remote/webdriver.py", line 333, in get
    self.execute(Command.GET, {'url': url})
  File "/home/ubuntu/.local/lib/python3.8/site-packages/selenium/webdriver/remote/webdriver.py", line 321, in execute
    self.error_handler.check_response(response)
  File "/home/ubuntu/.local/lib/python3.8/site-packages/selenium/webdriver/remote/errorhandler.py", line 242, in check_response
    raise exception_class(message, screen, stacktrace)
selenium.common.exceptions.TimeoutException: Message: timeout: Timed out receiving message from renderer: 290.424
  (Session info: headless chrome=87.0.4280.88)

Traceback (most recent call last):
  File "/home/ubuntu/trends-script/scraper.py", line 260, in <module>
    main()
  File "/home/ubuntu/trends-script/scraper.py", line 253, in main
    htmlstring = get_html_from_site()
  File "/home/ubuntu/trends-script/scraper.py", line 28, in get_html_from_site
    driver = webdriver.Chrome(options=options)
  File "/home/ubuntu/.local/lib/python3.8/site-packages/selenium/webdriver/chrome/webdriver.py", line 73, in __init__
    self.service.start()
  File "/home/ubuntu/.local/lib/python3.8/site-packages/selenium/webdriver/common/service.py", line 104, in start
    raise WebDriverException("Can not connect to the Service %s" % self.path)
selenium.common.exceptions.WebDriverException: Message: Can not connect to the Service chromedriver

Traceback (most recent call last):
  File "/home/ubuntu/trends-script/scraper.py", line 260, in <module>
    main()
  File "/home/ubuntu/trends-script/scraper.py", line 253, in main
    htmlstring = get_html_from_site()
  File "/home/ubuntu/trends-script/scraper.py", line 31, in get_html_from_site
    driver.get(start_url)
  File "/home/ubuntu/.local/lib/python3.8/site-packages/selenium/webdriver/remote/webdriver.py", line 333, in get
    self.execute(Command.GET, {'url': url})
  File "/home/ubuntu/.local/lib/python3.8/site-packages/selenium/webdriver/remote/webdriver.py", line 321, in execute
    self.error_handler.check_response(response)
  File "/home/ubuntu/.local/lib/python3.8/site-packages/selenium/webdriver/remote/errorhandler.py", line 242, in check_response
    raise exception_class(message, screen, stacktrace)
selenium.common.exceptions.TimeoutException: Message: timeout: Timed out receiving message from renderer: 290.826
  (Session info: headless chrome=87.0.4280.88)

Traceback (most recent call last):
  File "/home/ubuntu/trends-script/scraper.py", line 260, in <module>
    main()
  File "/home/ubuntu/trends-script/scraper.py", line 253, in main
    htmlstring = get_html_from_site()
  File "/home/ubuntu/trends-script/scraper.py", line 28, in get_html_from_site
    driver = webdriver.Chrome(options=options)
  File "/home/ubuntu/.local/lib/python3.8/site-packages/selenium/webdriver/chrome/webdriver.py", line 73, in __init__
    self.service.start()
  File "/home/ubuntu/.local/lib/python3.8/site-packages/selenium/webdriver/common/service.py", line 104, in start
    raise WebDriverException("Can not connect to the Service %s" % self.path)
selenium.common.exceptions.WebDriverException: Message: Can not connect to the Service chromedriver

Traceback (most recent call last):
  File "/home/ubuntu/trends-script/scraper.py", line 260, in <module>
    main()
  File "/home/ubuntu/trends-script/scraper.py", line 253, in main
    htmlstring = get_html_from_site()
  File "/home/ubuntu/trends-script/scraper.py", line 31, in get_html_from_site
    driver.get(start_url)
  File "/home/ubuntu/.local/lib/python3.8/site-packages/selenium/webdriver/remote/webdriver.py", line 333, in get
    self.execute(Command.GET, {'url': url})
  File "/home/ubuntu/.local/lib/python3.8/site-packages/selenium/webdriver/remote/webdriver.py", line 321, in execute
    self.error_handler.check_response(response)
  File "/home/ubuntu/.local/lib/python3.8/site-packages/selenium/webdriver/remote/errorhandler.py", line 242, in check_response
    raise exception_class(message, screen, stacktrace)
selenium.common.exceptions.TimeoutException: Message: timeout: Timed out receiving message from renderer: 291.385
  (Session info: headless chrome=87.0.4280.88)

Traceback (most recent call last):
  File "/home/ubuntu/trends-script/scraper.py", line 260, in <module>
    main()
  File "/home/ubuntu/trends-script/scraper.py", line 253, in main
    htmlstring = get_html_from_site()
  File "/home/ubuntu/trends-script/scraper.py", line 28, in get_html_from_site
    driver = webdriver.Chrome(options=options)
  File "/home/ubuntu/.local/lib/python3.8/site-packages/selenium/webdriver/chrome/webdriver.py", line 73, in __init__
    self.service.start()
  File "/home/ubuntu/.local/lib/python3.8/site-packages/selenium/webdriver/common/service.py", line 104, in start
    raise WebDriverException("Can not connect to the Service %s" % self.path)
selenium.common.exceptions.WebDriverException: Message: Can not connect to the Service chromedriver

Traceback (most recent call last):
  File "/home/ubuntu/trends-script/scraper.py", line 260, in <module>
    main()
  File "/home/ubuntu/trends-script/scraper.py", line 253, in main
    htmlstring = get_html_from_site()
  File "/home/ubuntu/trends-script/scraper.py", line 31, in get_html_from_site
    driver.get(start_url)
  File "/home/ubuntu/.local/lib/python3.8/site-packages/selenium/webdriver/remote/webdriver.py", line 333, in get
    self.execute(Command.GET, {'url': url})
  File "/home/ubuntu/.local/lib/python3.8/site-packages/selenium/webdriver/remote/webdriver.py", line 321, in execute
    self.error_handler.check_response(response)
  File "/home/ubuntu/.local/lib/python3.8/site-packages/selenium/webdriver/remote/errorhandler.py", line 242, in check_response
    raise exception_class(message, screen, stacktrace)
selenium.common.exceptions.TimeoutException: Message: timeout: Timed out receiving message from renderer: 290.163
  (Session info: headless chrome=87.0.4280.88)

Traceback (most recent call last):
  File "/home/ubuntu/trends-script/scraper.py", line 260, in <module>
    main()
  File "/home/ubuntu/trends-script/scraper.py", line 253, in main
    htmlstring = get_html_from_site()
  File "/home/ubuntu/trends-script/scraper.py", line 28, in get_html_from_site
    driver = webdriver.Chrome(options=options)
  File "/home/ubuntu/.local/lib/python3.8/site-packages/selenium/webdriver/chrome/webdriver.py", line 73, in __init__
    self.service.start()
  File "/home/ubuntu/.local/lib/python3.8/site-packages/selenium/webdriver/common/service.py", line 104, in start
    raise WebDriverException("Can not connect to the Service %s" % self.path)
selenium.common.exceptions.WebDriverException: Message: Can not connect to the Service chromedriver

Traceback (most recent call last):
  File "/home/ubuntu/trends-script/scraper.py", line 260, in <module>
    main()
  File "/home/ubuntu/trends-script/scraper.py", line 253, in main
    htmlstring = get_html_from_site()
  File "/home/ubuntu/trends-script/scraper.py", line 31, in get_html_from_site
    driver.get(start_url)
  File "/home/ubuntu/.local/lib/python3.8/site-packages/selenium/webdriver/remote/webdriver.py", line 333, in get
    self.execute(Command.GET, {'url': url})
  File "/home/ubuntu/.local/lib/python3.8/site-packages/selenium/webdriver/remote/webdriver.py", line 321, in execute
    self.error_handler.check_response(response)
  File "/home/ubuntu/.local/lib/python3.8/site-packages/selenium/webdriver/remote/errorhandler.py", line 242, in check_response
    raise exception_class(message, screen, stacktrace)
selenium.common.exceptions.TimeoutException: Message: timeout: Timed out receiving message from renderer: 291.189
  (Session info: headless chrome=87.0.4280.88)

Traceback (most recent call last):
  File "/home/ubuntu/trends-script/scraper.py", line 260, in <module>
    main()
  File "/home/ubuntu/trends-script/scraper.py", line 253, in main
    htmlstring = get_html_from_site()
  File "/home/ubuntu/trends-script/scraper.py", line 28, in get_html_from_site
    driver = webdriver.Chrome(options=options)
  File "/home/ubuntu/.local/lib/python3.8/site-packages/selenium/webdriver/chrome/webdriver.py", line 73, in __init__
    self.service.start()
  File "/home/ubuntu/.local/lib/python3.8/site-packages/selenium/webdriver/common/service.py", line 104, in start
    raise WebDriverException("Can not connect to the Service %s" % self.path)
selenium.common.exceptions.WebDriverException: Message: Can not connect to the Service chromedriver

Traceback (most recent call last):
  File "/home/ubuntu/trends-script/scraper.py", line 260, in <module>
    main()
  File "/home/ubuntu/trends-script/scraper.py", line 253, in main
    htmlstring = get_html_from_site()
  File "/home/ubuntu/trends-script/scraper.py", line 31, in get_html_from_site
    driver.get(start_url)
  File "/home/ubuntu/.local/lib/python3.8/site-packages/selenium/webdriver/remote/webdriver.py", line 333, in get
    self.execute(Command.GET, {'url': url})
  File "/home/ubuntu/.local/lib/python3.8/site-packages/selenium/webdriver/remote/webdriver.py", line 321, in execute
    self.error_handler.check_response(response)
  File "/home/ubuntu/.local/lib/python3.8/site-packages/selenium/webdriver/remote/errorhandler.py", line 242, in check_response
    raise exception_class(message, screen, stacktrace)
selenium.common.exceptions.TimeoutException: Message: timeout: Timed out receiving message from renderer: 288.677
  (Session info: headless chrome=87.0.4280.88)

Traceback (most recent call last):
  File "/home/ubuntu/trends-script/scraper.py", line 260, in <module>
    main()
  File "/home/ubuntu/trends-script/scraper.py", line 253, in main
    htmlstring = get_html_from_site()
  File "/home/ubuntu/trends-script/scraper.py", line 28, in get_html_from_site
    driver = webdriver.Chrome(options=options)
  File "/home/ubuntu/.local/lib/python3.8/site-packages/selenium/webdriver/chrome/webdriver.py", line 73, in __init__
    self.service.start()
  File "/home/ubuntu/.local/lib/python3.8/site-packages/selenium/webdriver/common/service.py", line 104, in start
    raise WebDriverException("Can not connect to the Service %s" % self.path)
selenium.common.exceptions.WebDriverException: Message: Can not connect to the Service chromedriver

Traceback (most recent call last):
  File "/home/ubuntu/trends-script/scraper.py", line 260, in <module>
    main()
  File "/home/ubuntu/trends-script/scraper.py", line 253, in main
    htmlstring = get_html_from_site()
  File "/home/ubuntu/trends-script/scraper.py", line 31, in get_html_from_site
    driver.get(start_url)
  File "/home/ubuntu/.local/lib/python3.8/site-packages/selenium/webdriver/remote/webdriver.py", line 333, in get
    self.execute(Command.GET, {'url': url})
  File "/home/ubuntu/.local/lib/python3.8/site-packages/selenium/webdriver/remote/webdriver.py", line 321, in execute
    self.error_handler.check_response(response)
  File "/home/ubuntu/.local/lib/python3.8/site-packages/selenium/webdriver/remote/errorhandler.py", line 242, in check_response
    raise exception_class(message, screen, stacktrace)
selenium.common.exceptions.TimeoutException: Message: timeout: Timed out receiving message from renderer: 289.571
  (Session info: headless chrome=87.0.4280.88)

Traceback (most recent call last):
  File "/home/ubuntu/trends-script/scraper.py", line 260, in <module>
    main()
  File "/home/ubuntu/trends-script/scraper.py", line 253, in main
    htmlstring = get_html_from_site()
  File "/home/ubuntu/trends-script/scraper.py", line 28, in get_html_from_site
    driver = webdriver.Chrome(options=options)
  File "/home/ubuntu/.local/lib/python3.8/site-packages/selenium/webdriver/chrome/webdriver.py", line 73, in __init__
    self.service.start()
  File "/home/ubuntu/.local/lib/python3.8/site-packages/selenium/webdriver/common/service.py", line 104, in start
    raise WebDriverException("Can not connect to the Service %s" % self.path)
selenium.common.exceptions.WebDriverException: Message: Can not connect to the Service chromedriver

Traceback (most recent call last):
  File "/home/ubuntu/trends-script/scraper.py", line 260, in <module>
    main()
  File "/home/ubuntu/trends-script/scraper.py", line 253, in main
    htmlstring = get_html_from_site()
  File "/home/ubuntu/trends-script/scraper.py", line 31, in get_html_from_site
    driver.get(start_url)
  File "/home/ubuntu/.local/lib/python3.8/site-packages/selenium/webdriver/remote/webdriver.py", line 333, in get
    self.execute(Command.GET, {'url': url})
  File "/home/ubuntu/.local/lib/python3.8/site-packages/selenium/webdriver/remote/webdriver.py", line 321, in execute
    self.error_handler.check_response(response)
  File "/home/ubuntu/.local/lib/python3.8/site-packages/selenium/webdriver/remote/errorhandler.py", line 242, in check_response
    raise exception_class(message, screen, stacktrace)
selenium.common.exceptions.TimeoutException: Message: timeout: Timed out receiving message from renderer: 292.526
  (Session info: headless chrome=87.0.4280.88)

Traceback (most recent call last):
  File "/home/ubuntu/trends-script/scraper.py", line 260, in <module>
    main()
  File "/home/ubuntu/trends-script/scraper.py", line 253, in main
    htmlstring = get_html_from_site()
  File "/home/ubuntu/trends-script/scraper.py", line 28, in get_html_from_site
    driver = webdriver.Chrome(options=options)
  File "/home/ubuntu/.local/lib/python3.8/site-packages/selenium/webdriver/chrome/webdriver.py", line 73, in __init__
    self.service.start()
  File "/home/ubuntu/.local/lib/python3.8/site-packages/selenium/webdriver/common/service.py", line 104, in start
    raise WebDriverException("Can not connect to the Service %s" % self.path)
selenium.common.exceptions.WebDriverException: Message: Can not connect to the Service chromedriver

Traceback (most recent call last):
  File "/home/ubuntu/trends-script/scraper.py", line 260, in <module>
    main()
  File "/home/ubuntu/trends-script/scraper.py", line 253, in main
    htmlstring = get_html_from_site()
  File "/home/ubuntu/trends-script/scraper.py", line 31, in get_html_from_site
    driver.get(start_url)
  File "/home/ubuntu/.local/lib/python3.8/site-packages/selenium/webdriver/remote/webdriver.py", line 333, in get
    self.execute(Command.GET, {'url': url})
  File "/home/ubuntu/.local/lib/python3.8/site-packages/selenium/webdriver/remote/webdriver.py", line 321, in execute
    self.error_handler.check_response(response)
  File "/home/ubuntu/.local/lib/python3.8/site-packages/selenium/webdriver/remote/errorhandler.py", line 242, in check_response
    raise exception_class(message, screen, stacktrace)
selenium.common.exceptions.TimeoutException: Message: timeout: Timed out receiving message from renderer: 289.137
  (Session info: headless chrome=87.0.4280.88)

Traceback (most recent call last):
  File "/home/ubuntu/trends-script/scraper.py", line 260, in <module>
    main()
  File "/home/ubuntu/trends-script/scraper.py", line 253, in main
    htmlstring = get_html_from_site()
  File "/home/ubuntu/trends-script/scraper.py", line 28, in get_html_from_site
    driver = webdriver.Chrome(options=options)
  File "/home/ubuntu/.local/lib/python3.8/site-packages/selenium/webdriver/chrome/webdriver.py", line 73, in __init__
    self.service.start()
  File "/home/ubuntu/.local/lib/python3.8/site-packages/selenium/webdriver/common/service.py", line 104, in start
    raise WebDriverException("Can not connect to the Service %s" % self.path)
selenium.common.exceptions.WebDriverException: Message: Can not connect to the Service chromedriver

Traceback (most recent call last):
  File "/home/ubuntu/trends-script/scraper.py", line 260, in <module>
    main()
  File "/home/ubuntu/trends-script/scraper.py", line 253, in main
    htmlstring = get_html_from_site()
  File "/home/ubuntu/trends-script/scraper.py", line 31, in get_html_from_site
    driver.get(start_url)
  File "/home/ubuntu/.local/lib/python3.8/site-packages/selenium/webdriver/remote/webdriver.py", line 333, in get
    self.execute(Command.GET, {'url': url})
  File "/home/ubuntu/.local/lib/python3.8/site-packages/selenium/webdriver/remote/webdriver.py", line 321, in execute
    self.error_handler.check_response(response)
  File "/home/ubuntu/.local/lib/python3.8/site-packages/selenium/webdriver/remote/errorhandler.py", line 242, in check_response
    raise exception_class(message, screen, stacktrace)
selenium.common.exceptions.TimeoutException: Message: timeout: Timed out receiving message from renderer: 291.234
  (Session info: headless chrome=87.0.4280.88)

Traceback (most recent call last):
  File "/home/ubuntu/trends-script/scraper.py", line 260, in <module>
    main()
  File "/home/ubuntu/trends-script/scraper.py", line 253, in main
    htmlstring = get_html_from_site()
  File "/home/ubuntu/trends-script/scraper.py", line 28, in get_html_from_site
    driver = webdriver.Chrome(options=options)
  File "/home/ubuntu/.local/lib/python3.8/site-packages/selenium/webdriver/chrome/webdriver.py", line 73, in __init__
    self.service.start()
  File "/home/ubuntu/.local/lib/python3.8/site-packages/selenium/webdriver/common/service.py", line 104, in start
    raise WebDriverException("Can not connect to the Service %s" % self.path)
selenium.common.exceptions.WebDriverException: Message: Can not connect to the Service chromedriver

Traceback (most recent call last):
  File "/home/ubuntu/trends-script/scraper.py", line 260, in <module>
    main()
  File "/home/ubuntu/trends-script/scraper.py", line 253, in main
    htmlstring = get_html_from_site()
  File "/home/ubuntu/trends-script/scraper.py", line 31, in get_html_from_site
    driver.get(start_url)
  File "/home/ubuntu/.local/lib/python3.8/site-packages/selenium/webdriver/remote/webdriver.py", line 333, in get
    self.execute(Command.GET, {'url': url})
  File "/home/ubuntu/.local/lib/python3.8/site-packages/selenium/webdriver/remote/webdriver.py", line 321, in execute
    self.error_handler.check_response(response)
  File "/home/ubuntu/.local/lib/python3.8/site-packages/selenium/webdriver/remote/errorhandler.py", line 242, in check_response
    raise exception_class(message, screen, stacktrace)
selenium.common.exceptions.TimeoutException: Message: timeout: Timed out receiving message from renderer: 291.652
  (Session info: headless chrome=87.0.4280.88)

Traceback (most recent call last):
  File "/home/ubuntu/trends-script/scraper.py", line 260, in <module>
    main()
  File "/home/ubuntu/trends-script/scraper.py", line 253, in main
    htmlstring = get_html_from_site()
  File "/home/ubuntu/trends-script/scraper.py", line 28, in get_html_from_site
    driver = webdriver.Chrome(options=options)
  File "/home/ubuntu/.local/lib/python3.8/site-packages/selenium/webdriver/chrome/webdriver.py", line 73, in __init__
    self.service.start()
  File "/home/ubuntu/.local/lib/python3.8/site-packages/selenium/webdriver/common/service.py", line 104, in start
    raise WebDriverException("Can not connect to the Service %s" % self.path)
selenium.common.exceptions.WebDriverException: Message: Can not connect to the Service chromedriver

Traceback (most recent call last):
  File "/home/ubuntu/trends-script/scraper.py", line 260, in <module>
    main()
  File "/home/ubuntu/trends-script/scraper.py", line 253, in main
    htmlstring = get_html_from_site()
  File "/home/ubuntu/trends-script/scraper.py", line 31, in get_html_from_site
    driver.get(start_url)
  File "/home/ubuntu/.local/lib/python3.8/site-packages/selenium/webdriver/remote/webdriver.py", line 333, in get
    self.execute(Command.GET, {'url': url})
  File "/home/ubuntu/.local/lib/python3.8/site-packages/selenium/webdriver/remote/webdriver.py", line 321, in execute
    self.error_handler.check_response(response)
  File "/home/ubuntu/.local/lib/python3.8/site-packages/selenium/webdriver/remote/errorhandler.py", line 242, in check_response
    raise exception_class(message, screen, stacktrace)
selenium.common.exceptions.TimeoutException: Message: timeout: Timed out receiving message from renderer: 290.185
  (Session info: headless chrome=87.0.4280.88)

Traceback (most recent call last):
  File "/home/ubuntu/trends-script/scraper.py", line 260, in <module>
    main()
  File "/home/ubuntu/trends-script/scraper.py", line 253, in main
    htmlstring = get_html_from_site()
  File "/home/ubuntu/trends-script/scraper.py", line 28, in get_html_from_site
    driver = webdriver.Chrome(options=options)
  File "/home/ubuntu/.local/lib/python3.8/site-packages/selenium/webdriver/chrome/webdriver.py", line 73, in __init__
    self.service.start()
  File "/home/ubuntu/.local/lib/python3.8/site-packages/selenium/webdriver/common/service.py", line 104, in start
    raise WebDriverException("Can not connect to the Service %s" % self.path)
selenium.common.exceptions.WebDriverException: Message: Can not connect to the Service chromedriver

Traceback (most recent call last):
  File "/home/ubuntu/trends-script/scraper.py", line 260, in <module>
    main()
  File "/home/ubuntu/trends-script/scraper.py", line 253, in main
    htmlstring = get_html_from_site()
  File "/home/ubuntu/trends-script/scraper.py", line 31, in get_html_from_site
    driver.get(start_url)
  File "/home/ubuntu/.local/lib/python3.8/site-packages/selenium/webdriver/remote/webdriver.py", line 333, in get
    self.execute(Command.GET, {'url': url})
  File "/home/ubuntu/.local/lib/python3.8/site-packages/selenium/webdriver/remote/webdriver.py", line 321, in execute
    self.error_handler.check_response(response)
  File "/home/ubuntu/.local/lib/python3.8/site-packages/selenium/webdriver/remote/errorhandler.py", line 242, in check_response
    raise exception_class(message, screen, stacktrace)
selenium.common.exceptions.TimeoutException: Message: timeout: Timed out receiving message from renderer: 287.161
  (Session info: headless chrome=87.0.4280.88)

Traceback (most recent call last):
  File "/home/ubuntu/trends-script/scraper.py", line 260, in <module>
    main()
  File "/home/ubuntu/trends-script/scraper.py", line 253, in main
    htmlstring = get_html_from_site()
  File "/home/ubuntu/trends-script/scraper.py", line 28, in get_html_from_site
    driver = webdriver.Chrome(options=options)
  File "/home/ubuntu/.local/lib/python3.8/site-packages/selenium/webdriver/chrome/webdriver.py", line 73, in __init__
    self.service.start()
  File "/home/ubuntu/.local/lib/python3.8/site-packages/selenium/webdriver/common/service.py", line 104, in start
    raise WebDriverException("Can not connect to the Service %s" % self.path)
selenium.common.exceptions.WebDriverException: Message: Can not connect to the Service chromedriver

Traceback (most recent call last):
  File "/home/ubuntu/trends-script/scraper.py", line 260, in <module>
    main()
  File "/home/ubuntu/trends-script/scraper.py", line 253, in main
    htmlstring = get_html_from_site()
  File "/home/ubuntu/trends-script/scraper.py", line 31, in get_html_from_site
    driver.get(start_url)
  File "/home/ubuntu/.local/lib/python3.8/site-packages/selenium/webdriver/remote/webdriver.py", line 333, in get
    self.execute(Command.GET, {'url': url})
  File "/home/ubuntu/.local/lib/python3.8/site-packages/selenium/webdriver/remote/webdriver.py", line 321, in execute
    self.error_handler.check_response(response)
  File "/home/ubuntu/.local/lib/python3.8/site-packages/selenium/webdriver/remote/errorhandler.py", line 242, in check_response
    raise exception_class(message, screen, stacktrace)
selenium.common.exceptions.TimeoutException: Message: timeout: Timed out receiving message from renderer: 281.575
  (Session info: headless chrome=87.0.4280.88)

Traceback (most recent call last):
  File "/home/ubuntu/trends-script/scraper.py", line 260, in <module>
    main()
  File "/home/ubuntu/trends-script/scraper.py", line 253, in main
    htmlstring = get_html_from_site()
  File "/home/ubuntu/trends-script/scraper.py", line 28, in get_html_from_site
    driver = webdriver.Chrome(options=options)
  File "/home/ubuntu/.local/lib/python3.8/site-packages/selenium/webdriver/chrome/webdriver.py", line 73, in __init__
    self.service.start()
  File "/home/ubuntu/.local/lib/python3.8/site-packages/selenium/webdriver/common/service.py", line 104, in start
    raise WebDriverException("Can not connect to the Service %s" % self.path)
selenium.common.exceptions.WebDriverException: Message: Can not connect to the Service chromedriver

Traceback (most recent call last):
  File "/home/ubuntu/trends-script/scraper.py", line 260, in <module>
    main()
  File "/home/ubuntu/trends-script/scraper.py", line 253, in main
    htmlstring = get_html_from_site()
  File "/home/ubuntu/trends-script/scraper.py", line 31, in get_html_from_site
    driver.get(start_url)
  File "/home/ubuntu/.local/lib/python3.8/site-packages/selenium/webdriver/remote/webdriver.py", line 333, in get
    self.execute(Command.GET, {'url': url})
  File "/home/ubuntu/.local/lib/python3.8/site-packages/selenium/webdriver/remote/webdriver.py", line 321, in execute
    self.error_handler.check_response(response)
  File "/home/ubuntu/.local/lib/python3.8/site-packages/selenium/webdriver/remote/errorhandler.py", line 242, in check_response
    raise exception_class(message, screen, stacktrace)
selenium.common.exceptions.TimeoutException: Message: timeout: Timed out receiving message from renderer: 289.557
  (Session info: headless chrome=87.0.4280.88)

Traceback (most recent call last):
  File "/home/ubuntu/trends-script/scraper.py", line 260, in <module>
    main()
  File "/home/ubuntu/trends-script/scraper.py", line 253, in main
    htmlstring = get_html_from_site()
  File "/home/ubuntu/trends-script/scraper.py", line 28, in get_html_from_site
    driver = webdriver.Chrome(options=options)
  File "/home/ubuntu/.local/lib/python3.8/site-packages/selenium/webdriver/chrome/webdriver.py", line 73, in __init__
    self.service.start()
  File "/home/ubuntu/.local/lib/python3.8/site-packages/selenium/webdriver/common/service.py", line 104, in start
    raise WebDriverException("Can not connect to the Service %s" % self.path)
selenium.common.exceptions.WebDriverException: Message: Can not connect to the Service chromedriver

Traceback (most recent call last):
  File "/home/ubuntu/trends-script/scraper.py", line 260, in <module>
    main()
  File "/home/ubuntu/trends-script/scraper.py", line 253, in main
    htmlstring = get_html_from_site()
  File "/home/ubuntu/trends-script/scraper.py", line 31, in get_html_from_site
    driver.get(start_url)
  File "/home/ubuntu/.local/lib/python3.8/site-packages/selenium/webdriver/remote/webdriver.py", line 333, in get
    self.execute(Command.GET, {'url': url})
  File "/home/ubuntu/.local/lib/python3.8/site-packages/selenium/webdriver/remote/webdriver.py", line 321, in execute
    self.error_handler.check_response(response)
  File "/home/ubuntu/.local/lib/python3.8/site-packages/selenium/webdriver/remote/errorhandler.py", line 242, in check_response
    raise exception_class(message, screen, stacktrace)
selenium.common.exceptions.TimeoutException: Message: timeout: Timed out receiving message from renderer: 290.386
  (Session info: headless chrome=87.0.4280.88)

Traceback (most recent call last):
  File "/home/ubuntu/trends-script/scraper.py", line 260, in <module>
    main()
  File "/home/ubuntu/trends-script/scraper.py", line 253, in main
    htmlstring = get_html_from_site()
  File "/home/ubuntu/trends-script/scraper.py", line 28, in get_html_from_site
    driver = webdriver.Chrome(options=options)
  File "/home/ubuntu/.local/lib/python3.8/site-packages/selenium/webdriver/chrome/webdriver.py", line 73, in __init__
    self.service.start()
  File "/home/ubuntu/.local/lib/python3.8/site-packages/selenium/webdriver/common/service.py", line 104, in start
    raise WebDriverException("Can not connect to the Service %s" % self.path)
selenium.common.exceptions.WebDriverException: Message: Can not connect to the Service chromedriver

Traceback (most recent call last):
  File "/home/ubuntu/trends-script/scraper.py", line 14, in <module>
    from forex_screener_scrap import get_platinum_screener_list
  File "/home/ubuntu/trends-script/forex_screener_scrap.py", line 6, in <module>
    options.add_argument("--disable-dev-shm-usage")
NameError: name 'options' is not defined
Traceback (most recent call last):
  File "/home/ubuntu/trends-script/scraper.py", line 260, in <module>
    main()
  File "/home/ubuntu/trends-script/scraper.py", line 253, in main
    htmlstring = get_html_from_site()
  File "/home/ubuntu/trends-script/scraper.py", line 31, in get_html_from_site
    driver.get(start_url)
  File "/home/ubuntu/.local/lib/python3.8/site-packages/selenium/webdriver/remote/webdriver.py", line 333, in get
    self.execute(Command.GET, {'url': url})
  File "/home/ubuntu/.local/lib/python3.8/site-packages/selenium/webdriver/remote/webdriver.py", line 321, in execute
    self.error_handler.check_response(response)
  File "/home/ubuntu/.local/lib/python3.8/site-packages/selenium/webdriver/remote/errorhandler.py", line 242, in check_response
    raise exception_class(message, screen, stacktrace)
selenium.common.exceptions.TimeoutException: Message: timeout: Timed out receiving message from renderer: 291.195
  (Session info: headless chrome=87.0.4280.88)

Traceback (most recent call last):
  File "/home/ubuntu/trends-script/scraper.py", line 14, in <module>
    from forex_screener_scrap import get_platinum_screener_list
  File "/home/ubuntu/trends-script/forex_screener_scrap.py", line 6, in <module>
    options.add_argument("--disable-dev-shm-usage")
NameError: name 'options' is not defined
Traceback (most recent call last):
  File "/home/ubuntu/trends-script/scraper.py", line 14, in <module>
    from forex_screener_scrap import get_platinum_screener_list
  File "/home/ubuntu/trends-script/forex_screener_scrap.py", line 16
    options.add_argument("--disable-dev-shm-usage")
                                                  ^
TabError: inconsistent use of tabs and spaces in indentation
Traceback (most recent call last):
  File "/home/ubuntu/trends-script/scraper.py", line 14, in <module>
    from forex_screener_scrap import get_platinum_screener_list
  File "/home/ubuntu/trends-script/forex_screener_scrap.py", line 13
    options.add_argument("start-maximized")
                                          ^
IndentationError: unindent does not match any outer indentation level
Traceback (most recent call last):
  File "/home/ubuntu/trends-script/scraper.py", line 14, in <module>
    from forex_screener_scrap import get_platinum_screener_list
  File "/home/ubuntu/trends-script/forex_screener_scrap.py", line 13
    options.add_argument("start-maximized")
                                          ^
IndentationError: unindent does not match any outer indentation level
Traceback (most recent call last):
  File "/home/ubuntu/trends-script/scraper.py", line 14, in <module>
    from forex_screener_scrap import get_platinum_screener_list
  File "/home/ubuntu/trends-script/forex_screener_scrap.py", line 13
    options.add_argument("start-maximized")
                                          ^
IndentationError: unindent does not match any outer indentation level
Traceback (most recent call last):
  File "/home/ubuntu/trends-script/scraper.py", line 14, in <module>
    from forex_screener_scrap import get_platinum_screener_list
  File "/home/ubuntu/trends-script/forex_screener_scrap.py", line 13
    options.add_argument("start-maximized")
                                          ^
IndentationError: unindent does not match any outer indentation level
Traceback (most recent call last):
  File "/home/ubuntu/trends-script/scraper.py", line 14, in <module>
    from forex_screener_scrap import get_platinum_screener_list
  File "/home/ubuntu/trends-script/forex_screener_scrap.py", line 13
    options.add_argument("start-maximized")
                                          ^
IndentationError: unindent does not match any outer indentation level
Traceback (most recent call last):
  File "/home/ubuntu/trends-script/scraper.py", line 14, in <module>
    from forex_screener_scrap import get_platinum_screener_list
  File "/home/ubuntu/trends-script/forex_screener_scrap.py", line 13
    options.add_argument("start-maximized")
                                          ^
IndentationError: unindent does not match any outer indentation level
Traceback (most recent call last):
  File "/home/ubuntu/trends-script/scraper.py", line 14, in <module>
    from forex_screener_scrap import get_platinum_screener_list
  File "/home/ubuntu/trends-script/forex_screener_scrap.py", line 13
    options.add_argument("start-maximized")
                                          ^
IndentationError: unindent does not match any outer indentation level
Traceback (most recent call last):
  File "/home/ubuntu/trends-script/scraper.py", line 14, in <module>
    from forex_screener_scrap import get_platinum_screener_list
  File "/home/ubuntu/trends-script/forex_screener_scrap.py", line 13
    options.add_argument("start-maximized")
                                          ^
IndentationError: unindent does not match any outer indentation level
Traceback (most recent call last):
  File "/home/ubuntu/trends-script/scraper.py", line 14, in <module>
    from forex_screener_scrap import get_platinum_screener_list
  File "/home/ubuntu/trends-script/forex_screener_scrap.py", line 16
    options.add_argument("--disable-dev-shm-usage")
                                                  ^
TabError: inconsistent use of tabs and spaces in indentation
Traceback (most recent call last):
  File "/home/ubuntu/trends-script/scraper.py", line 14, in <module>
    from forex_screener_scrap import get_platinum_screener_list
  File "/home/ubuntu/trends-script/forex_screener_scrap.py", line 15
    options.add_argument("--window-size=1920x1080")
    ^
IndentationError: unexpected indent
Traceback (most recent call last):
  File "/home/ubuntu/trends-script/scraper.py", line 14, in <module>
    from forex_screener_scrap import get_platinum_screener_list
  File "/home/ubuntu/trends-script/forex_screener_scrap.py", line 15
    options.add_argument("--window-size=1920x1080")
    ^
IndentationError: unexpected indent
Traceback (most recent call last):
  File "/home/ubuntu/trends-script/scraper.py", line 14, in <module>
    from forex_screener_scrap import get_platinum_screener_list
  File "/home/ubuntu/trends-script/forex_screener_scrap.py", line 13
    options.add_argument("start-maximized")
    ^
IndentationError: unexpected indent
Traceback (most recent call last):
  File "/home/ubuntu/trends-script/scraper.py", line 14, in <module>
    from forex_screener_scrap import get_platinum_screener_list
  File "/home/ubuntu/trends-script/forex_screener_scrap.py", line 13
    options.add_argument("start-maximized")
                                          ^
TabError: inconsistent use of tabs and spaces in indentation
Traceback (most recent call last):
  File "/home/ubuntu/trends-script/scraper.py", line 14, in <module>
    from forex_screener_scrap import get_platinum_screener_list
  File "/home/ubuntu/trends-script/forex_screener_scrap.py", line 13
    options.add_argument("start-maximized")
                                          ^
TabError: inconsistent use of tabs and spaces in indentation
Traceback (most recent call last):
  File "/home/ubuntu/trends-script/scraper.py", line 14, in <module>
    from forex_screener_scrap import get_platinum_screener_list
  File "/home/ubuntu/trends-script/forex_screener_scrap.py", line 12
    options.add_argument("start-maximized")
                                          ^
TabError: inconsistent use of tabs and spaces in indentation
Traceback (most recent call last):
  File "/home/ubuntu/trends-script/scraper.py", line 14, in <module>
    from forex_screener_scrap import get_platinum_screener_list
  File "/home/ubuntu/trends-script/forex_screener_scrap.py", line 12
    options.add_argument("start-maximized")
                                          ^
TabError: inconsistent use of tabs and spaces in indentation
Traceback (most recent call last):
  File "/home/ubuntu/trends-script/scraper.py", line 14, in <module>
    from forex_screener_scrap import get_platinum_screener_list
  File "/home/ubuntu/trends-script/forex_screener_scrap.py", line 12
    options.add_argument("start-maximized")
                                          ^
TabError: inconsistent use of tabs and spaces in indentation
Traceback (most recent call last):
  File "/home/ubuntu/trends-script/scraper.py", line 14, in <module>
    from forex_screener_scrap import get_platinum_screener_list
  File "/home/ubuntu/trends-script/forex_screener_scrap.py", line 12
    options.add_argument("start-maximized")
                                          ^
TabError: inconsistent use of tabs and spaces in indentation
Traceback (most recent call last):
  File "/home/ubuntu/trends-script/scraper.py", line 14, in <module>
    from forex_screener_scrap import get_platinum_screener_list
  File "/home/ubuntu/trends-script/forex_screener_scrap.py", line 12
    options.add_argument("start-maximized")
                                          ^
TabError: inconsistent use of tabs and spaces in indentation
Traceback (most recent call last):
  File "/home/ubuntu/trends-script/scraper.py", line 14, in <module>
    from forex_screener_scrap import get_platinum_screener_list
  File "/home/ubuntu/trends-script/forex_screener_scrap.py", line 12
    options.add_argument("start-maximized")
                                          ^
TabError: inconsistent use of tabs and spaces in indentation
Traceback (most recent call last):
  File "/home/ubuntu/trends-script/scraper.py", line 14, in <module>
    from forex_screener_scrap import get_platinum_screener_list
  File "/home/ubuntu/trends-script/forex_screener_scrap.py", line 12
    options.add_argument("start-maximized")
                                          ^
TabError: inconsistent use of tabs and spaces in indentation
Traceback (most recent call last):
  File "/home/ubuntu/trends-script/scraper.py", line 14, in <module>
    from forex_screener_scrap import get_platinum_screener_list
  File "/home/ubuntu/trends-script/forex_screener_scrap.py", line 12
    options.add_argument("start-maximized")
                                          ^
TabError: inconsistent use of tabs and spaces in indentation
Traceback (most recent call last):
  File "/home/ubuntu/trends-script/scraper.py", line 14, in <module>
    from forex_screener_scrap import get_platinum_screener_list
  File "/home/ubuntu/trends-script/forex_screener_scrap.py", line 12
    options.add_argument("start-maximized")
                                          ^
TabError: inconsistent use of tabs and spaces in indentation
Traceback (most recent call last):
  File "/home/ubuntu/trends-script/scraper.py", line 14, in <module>
    from forex_screener_scrap import get_platinum_screener_list
  File "/home/ubuntu/trends-script/forex_screener_scrap.py", line 12
    options.add_argument("start-maximized")
                                          ^
TabError: inconsistent use of tabs and spaces in indentation
Traceback (most recent call last):
  File "/home/ubuntu/trends-script/scraper.py", line 14, in <module>
    from forex_screener_scrap import get_platinum_screener_list
  File "/home/ubuntu/trends-script/forex_screener_scrap.py", line 12
    options.add_argument("start-maximized")
                                          ^
TabError: inconsistent use of tabs and spaces in indentation
Traceback (most recent call last):
  File "/home/ubuntu/trends-script/scraper.py", line 14, in <module>
    from forex_screener_scrap import get_platinum_screener_list
  File "/home/ubuntu/trends-script/forex_screener_scrap.py", line 12
    options.add_argument("start-maximized")
                                          ^
TabError: inconsistent use of tabs and spaces in indentation
Traceback (most recent call last):
  File "/home/ubuntu/trends-script/scraper.py", line 14, in <module>
    from forex_screener_scrap import get_platinum_screener_list
  File "/home/ubuntu/trends-script/forex_screener_scrap.py", line 12
    options.add_argument("start-maximized")
                                          ^
TabError: inconsistent use of tabs and spaces in indentation
Traceback (most recent call last):
  File "/home/ubuntu/trends-script/scraper.py", line 14, in <module>
    from forex_screener_scrap import get_platinum_screener_list
  File "/home/ubuntu/trends-script/forex_screener_scrap.py", line 12
    options.add_argument("start-maximized")
                                          ^
TabError: inconsistent use of tabs and spaces in indentation
Traceback (most recent call last):
  File "/home/ubuntu/trends-script/scraper.py", line 14, in <module>
    from forex_screener_scrap import get_platinum_screener_list
  File "/home/ubuntu/trends-script/forex_screener_scrap.py", line 12
    options.add_argument("start-maximized")
                                          ^
TabError: inconsistent use of tabs and spaces in indentation
Traceback (most recent call last):
  File "/home/ubuntu/trends-script/scraper.py", line 14, in <module>
    from forex_screener_scrap import get_platinum_screener_list
  File "/home/ubuntu/trends-script/forex_screener_scrap.py", line 12
    options.add_argument("start-maximized")
                                          ^
TabError: inconsistent use of tabs and spaces in indentation
Traceback (most recent call last):
  File "/home/ubuntu/trends-script/scraper.py", line 14, in <module>
    from forex_screener_scrap import get_platinum_screener_list
  File "/home/ubuntu/trends-script/forex_screener_scrap.py", line 12
    options.add_argument("start-maximized")
                                          ^
TabError: inconsistent use of tabs and spaces in indentation
Traceback (most recent call last):
  File "/home/ubuntu/trends-script/scraper.py", line 14, in <module>
    from forex_screener_scrap import get_platinum_screener_list
  File "/home/ubuntu/trends-script/forex_screener_scrap.py", line 12
    options.add_argument("start-maximized")
                                          ^
TabError: inconsistent use of tabs and spaces in indentation
Traceback (most recent call last):
  File "/home/ubuntu/trends-script/scraper.py", line 14, in <module>
    from forex_screener_scrap import get_platinum_screener_list
  File "/home/ubuntu/trends-script/forex_screener_scrap.py", line 12
    options.add_argument("start-maximized")
                                          ^
TabError: inconsistent use of tabs and spaces in indentation
Traceback (most recent call last):
  File "/home/ubuntu/trends-script/scraper.py", line 14, in <module>
    from forex_screener_scrap import get_platinum_screener_list
  File "/home/ubuntu/trends-script/forex_screener_scrap.py", line 12
    options.add_argument("start-maximized")
                                          ^
TabError: inconsistent use of tabs and spaces in indentation
Traceback (most recent call last):
  File "/home/ubuntu/trends-script/scraper.py", line 14, in <module>
    from forex_screener_scrap import get_platinum_screener_list
  File "/home/ubuntu/trends-script/forex_screener_scrap.py", line 12
    options.add_argument("start-maximized")
                                          ^
TabError: inconsistent use of tabs and spaces in indentation
Traceback (most recent call last):
  File "/home/ubuntu/trends-script/scraper.py", line 14, in <module>
    from forex_screener_scrap import get_platinum_screener_list
  File "/home/ubuntu/trends-script/forex_screener_scrap.py", line 12
    options.add_argument("start-maximized")
                                          ^
TabError: inconsistent use of tabs and spaces in indentation
Traceback (most recent call last):
  File "/home/ubuntu/trends-script/scraper.py", line 14, in <module>
    from forex_screener_scrap import get_platinum_screener_list
  File "/home/ubuntu/trends-script/forex_screener_scrap.py", line 12
    options.add_argument("start-maximized")
                                          ^
TabError: inconsistent use of tabs and spaces in indentation
Traceback (most recent call last):
  File "/home/ubuntu/trends-script/scraper.py", line 14, in <module>
    from forex_screener_scrap import get_platinum_screener_list
  File "/home/ubuntu/trends-script/forex_screener_scrap.py", line 12
    options.add_argument("start-maximized")
                                          ^
TabError: inconsistent use of tabs and spaces in indentation
Traceback (most recent call last):
  File "/home/ubuntu/trends-script/scraper.py", line 14, in <module>
    from forex_screener_scrap import get_platinum_screener_list
  File "/home/ubuntu/trends-script/forex_screener_scrap.py", line 12
    options.add_argument("start-maximized")
                                          ^
TabError: inconsistent use of tabs and spaces in indentation
Traceback (most recent call last):
  File "/home/ubuntu/trends-script/scraper.py", line 14, in <module>
    from forex_screener_scrap import get_platinum_screener_list
  File "/home/ubuntu/trends-script/forex_screener_scrap.py", line 12
    options.add_argument("start-maximized")
                                          ^
TabError: inconsistent use of tabs and spaces in indentation
Traceback (most recent call last):
  File "/home/ubuntu/trends-script/scraper.py", line 14, in <module>
    from forex_screener_scrap import get_platinum_screener_list
  File "/home/ubuntu/trends-script/forex_screener_scrap.py", line 12
    options.add_argument("start-maximized")
                                          ^
TabError: inconsistent use of tabs and spaces in indentation
Traceback (most recent call last):
  File "/home/ubuntu/trends-script/scraper.py", line 14, in <module>
    from forex_screener_scrap import get_platinum_screener_list
  File "/home/ubuntu/trends-script/forex_screener_scrap.py", line 12
    options.add_argument("start-maximized")
                                          ^
TabError: inconsistent use of tabs and spaces in indentation
Traceback (most recent call last):
  File "/home/ubuntu/trends-script/scraper.py", line 14, in <module>
    from forex_screener_scrap import get_platinum_screener_list
  File "/home/ubuntu/trends-script/forex_screener_scrap.py", line 12
    options.add_argument("start-maximized")
                                          ^
TabError: inconsistent use of tabs and spaces in indentation
Traceback (most recent call last):
  File "/home/ubuntu/trends-script/scraper.py", line 14, in <module>
    from forex_screener_scrap import get_platinum_screener_list
  File "/home/ubuntu/trends-script/forex_screener_scrap.py", line 12
    options.add_argument("start-maximized")
                                          ^
TabError: inconsistent use of tabs and spaces in indentation
Traceback (most recent call last):
  File "/home/ubuntu/trends-script/scraper.py", line 14, in <module>
    from forex_screener_scrap import get_platinum_screener_list
  File "/home/ubuntu/trends-script/forex_screener_scrap.py", line 12
    options.add_argument("start-maximized")
                                          ^
TabError: inconsistent use of tabs and spaces in indentation
Traceback (most recent call last):
  File "/home/ubuntu/trends-script/scraper.py", line 14, in <module>
    from forex_screener_scrap import get_platinum_screener_list
  File "/home/ubuntu/trends-script/forex_screener_scrap.py", line 12
    options.add_argument("start-maximized")
                                          ^
TabError: inconsistent use of tabs and spaces in indentation
Traceback (most recent call last):
  File "/home/ubuntu/trends-script/scraper.py", line 14, in <module>
    from forex_screener_scrap import get_platinum_screener_list
  File "/home/ubuntu/trends-script/forex_screener_scrap.py", line 12
    options.add_argument("start-maximized")
                                          ^
TabError: inconsistent use of tabs and spaces in indentation
Traceback (most recent call last):
  File "/home/ubuntu/trends-script/scraper.py", line 14, in <module>
    from forex_screener_scrap import get_platinum_screener_list
  File "/home/ubuntu/trends-script/forex_screener_scrap.py", line 12
    options.add_argument("--start-maximized")
                                            ^
TabError: inconsistent use of tabs and spaces in indentation
Traceback (most recent call last):
  File "/home/ubuntu/trends-script/scraper.py", line 14, in <module>
    from forex_screener_scrap import get_platinum_screener_list
  File "/home/ubuntu/trends-script/forex_screener_scrap.py", line 12
    options.add_argument("--start-maximized")
                                            ^
TabError: inconsistent use of tabs and spaces in indentation
Traceback (most recent call last):
  File "/home/ubuntu/trends-script/scraper.py", line 14, in <module>
    from forex_screener_scrap import get_platinum_screener_list
  File "/home/ubuntu/trends-script/forex_screener_scrap.py", line 12
    options.add_argument("--start-maximized")
                                            ^
TabError: inconsistent use of tabs and spaces in indentation
Traceback (most recent call last):
  File "/home/ubuntu/trends-script/scraper.py", line 14, in <module>
    from forex_screener_scrap import get_platinum_screener_list
  File "/home/ubuntu/trends-script/forex_screener_scrap.py", line 12
    options.add_argument("--start-maximized")
                                            ^
TabError: inconsistent use of tabs and spaces in indentation
Traceback (most recent call last):
  File "/home/ubuntu/trends-script/scraper.py", line 14, in <module>
    from forex_screener_scrap import get_platinum_screener_list
  File "/home/ubuntu/trends-script/forex_screener_scrap.py", line 12
    options.add_argument("--start-maximized")
                                            ^
TabError: inconsistent use of tabs and spaces in indentation
Traceback (most recent call last):
  File "/home/ubuntu/trends-script/scraper.py", line 14, in <module>
    from forex_screener_scrap import get_platinum_screener_list
  File "/home/ubuntu/trends-script/forex_screener_scrap.py", line 12
    options.add_argument("--start-maximized")
                                            ^
TabError: inconsistent use of tabs and spaces in indentation
Traceback (most recent call last):
  File "/home/ubuntu/trends-script/scraper.py", line 14, in <module>
    from forex_screener_scrap import get_platinum_screener_list
  File "/home/ubuntu/trends-script/forex_screener_scrap.py", line 12
    options.add_argument("--start-maximized")
                                            ^
TabError: inconsistent use of tabs and spaces in indentation
Traceback (most recent call last):
  File "/home/ubuntu/trends-script/scraper.py", line 14, in <module>
    from forex_screener_scrap import get_platinum_screener_list
  File "/home/ubuntu/trends-script/forex_screener_scrap.py", line 12
    options.add_argument("--start-maximized")
                                            ^
TabError: inconsistent use of tabs and spaces in indentation
Traceback (most recent call last):
  File "/home/ubuntu/trends-script/scraper.py", line 14, in <module>
    from forex_screener_scrap import get_platinum_screener_list
  File "/home/ubuntu/trends-script/forex_screener_scrap.py", line 12
    options.add_argument("--start-maximized")
                                            ^
TabError: inconsistent use of tabs and spaces in indentation
Traceback (most recent call last):
  File "/home/ubuntu/trends-script/scraper.py", line 14, in <module>
    from forex_screener_scrap import get_platinum_screener_list
  File "/home/ubuntu/trends-script/forex_screener_scrap.py", line 12
    options.add_argument("--start-maximized")
                                            ^
TabError: inconsistent use of tabs and spaces in indentation
Traceback (most recent call last):
  File "/home/ubuntu/trends-script/scraper.py", line 14, in <module>
    from forex_screener_scrap import get_platinum_screener_list
  File "/home/ubuntu/trends-script/forex_screener_scrap.py", line 12
    options.add_argument("--start-maximized")
                                            ^
TabError: inconsistent use of tabs and spaces in indentation
Traceback (most recent call last):
  File "/home/ubuntu/trends-script/scraper.py", line 14, in <module>
    from forex_screener_scrap import get_platinum_screener_list
  File "/home/ubuntu/trends-script/forex_screener_scrap.py", line 12
    options.add_argument("--start-maximized")
                                            ^
TabError: inconsistent use of tabs and spaces in indentation
Traceback (most recent call last):
  File "/home/ubuntu/trends-script/scraper.py", line 14, in <module>
    from forex_screener_scrap import get_platinum_screener_list
  File "/home/ubuntu/trends-script/forex_screener_scrap.py", line 12
    options.add_argument("--start-maximized")
                                            ^
TabError: inconsistent use of tabs and spaces in indentation
Traceback (most recent call last):
  File "/home/ubuntu/trends-script/scraper.py", line 14, in <module>
    from forex_screener_scrap import get_platinum_screener_list
  File "/home/ubuntu/trends-script/forex_screener_scrap.py", line 12
    options.add_argument("--start-maximized")
                                            ^
TabError: inconsistent use of tabs and spaces in indentation
Traceback (most recent call last):
  File "/home/ubuntu/trends-script/scraper.py", line 260, in <module>
    main()
  File "/home/ubuntu/trends-script/scraper.py", line 253, in main
    htmlstring = get_html_from_site()
  File "/home/ubuntu/trends-script/scraper.py", line 28, in get_html_from_site
    driver = webdriver.Chrome(options=options)
  File "/home/ubuntu/.local/lib/python3.8/site-packages/selenium/webdriver/chrome/webdriver.py", line 73, in __init__
    self.service.start()
  File "/home/ubuntu/.local/lib/python3.8/site-packages/selenium/webdriver/common/service.py", line 104, in start
    raise WebDriverException("Can not connect to the Service %s" % self.path)
selenium.common.exceptions.WebDriverException: Message: Can not connect to the Service chromedriver

Traceback (most recent call last):
  File "/home/ubuntu/trends-script/scraper.py", line 260, in <module>
    main()
  File "/home/ubuntu/trends-script/scraper.py", line 253, in main
    htmlstring = get_html_from_site()
  File "/home/ubuntu/trends-script/scraper.py", line 31, in get_html_from_site
    driver.get(start_url)
  File "/home/ubuntu/.local/lib/python3.8/site-packages/selenium/webdriver/remote/webdriver.py", line 333, in get
    self.execute(Command.GET, {'url': url})
  File "/home/ubuntu/.local/lib/python3.8/site-packages/selenium/webdriver/remote/webdriver.py", line 321, in execute
    self.error_handler.check_response(response)
  File "/home/ubuntu/.local/lib/python3.8/site-packages/selenium/webdriver/remote/errorhandler.py", line 242, in check_response
    raise exception_class(message, screen, stacktrace)
selenium.common.exceptions.TimeoutException: Message: timeout: Timed out receiving message from renderer: 287.841
  (Session info: headless chrome=87.0.4280.88)

Traceback (most recent call last):
  File "/home/ubuntu/trends-script/scraper.py", line 260, in <module>
    main()
  File "/home/ubuntu/trends-script/scraper.py", line 253, in main
    htmlstring = get_html_from_site()
  File "/home/ubuntu/trends-script/scraper.py", line 28, in get_html_from_site
    driver = webdriver.Chrome(options=options)
  File "/home/ubuntu/.local/lib/python3.8/site-packages/selenium/webdriver/chrome/webdriver.py", line 73, in __init__
    self.service.start()
  File "/home/ubuntu/.local/lib/python3.8/site-packages/selenium/webdriver/common/service.py", line 104, in start
    raise WebDriverException("Can not connect to the Service %s" % self.path)
selenium.common.exceptions.WebDriverException: Message: Can not connect to the Service chromedriver

Traceback (most recent call last):
  File "/home/ubuntu/trends-script/scraper.py", line 260, in <module>
    main()
  File "/home/ubuntu/trends-script/scraper.py", line 253, in main
    htmlstring = get_html_from_site()
  File "/home/ubuntu/trends-script/scraper.py", line 31, in get_html_from_site
    driver.get(start_url)
  File "/home/ubuntu/.local/lib/python3.8/site-packages/selenium/webdriver/remote/webdriver.py", line 333, in get
    self.execute(Command.GET, {'url': url})
  File "/home/ubuntu/.local/lib/python3.8/site-packages/selenium/webdriver/remote/webdriver.py", line 321, in execute
    self.error_handler.check_response(response)
  File "/home/ubuntu/.local/lib/python3.8/site-packages/selenium/webdriver/remote/errorhandler.py", line 242, in check_response
    raise exception_class(message, screen, stacktrace)
selenium.common.exceptions.TimeoutException: Message: timeout: Timed out receiving message from renderer: 289.118
  (Session info: headless chrome=87.0.4280.88)

Traceback (most recent call last):
  File "/home/ubuntu/trends-script/scraper.py", line 260, in <module>
    main()
  File "/home/ubuntu/trends-script/scraper.py", line 253, in main
    htmlstring = get_html_from_site()
  File "/home/ubuntu/trends-script/scraper.py", line 31, in get_html_from_site
    driver.get(start_url)
  File "/home/ubuntu/.local/lib/python3.8/site-packages/selenium/webdriver/remote/webdriver.py", line 333, in get
    self.execute(Command.GET, {'url': url})
  File "/home/ubuntu/.local/lib/python3.8/site-packages/selenium/webdriver/remote/webdriver.py", line 321, in execute
    self.error_handler.check_response(response)
  File "/home/ubuntu/.local/lib/python3.8/site-packages/selenium/webdriver/remote/errorhandler.py", line 242, in check_response
    raise exception_class(message, screen, stacktrace)
selenium.common.exceptions.WebDriverException: Message: unknown error: net::ERR_CONNECTION_CLOSED
  (Session info: headless chrome=87.0.4280.88)

Traceback (most recent call last):
  File "/home/ubuntu/trends-script/scraper.py", line 260, in <module>
    main()
  File "/home/ubuntu/trends-script/scraper.py", line 253, in main
    htmlstring = get_html_from_site()
  File "/home/ubuntu/trends-script/scraper.py", line 28, in get_html_from_site
    driver = webdriver.Chrome(options=options)
  File "/home/ubuntu/.local/lib/python3.8/site-packages/selenium/webdriver/chrome/webdriver.py", line 73, in __init__
    self.service.start()
  File "/home/ubuntu/.local/lib/python3.8/site-packages/selenium/webdriver/common/service.py", line 104, in start
    raise WebDriverException("Can not connect to the Service %s" % self.path)
selenium.common.exceptions.WebDriverException: Message: Can not connect to the Service chromedriver

Traceback (most recent call last):
  File "/home/ubuntu/trends-script/scraper.py", line 260, in <module>
    main()
  File "/home/ubuntu/trends-script/scraper.py", line 253, in main
    htmlstring = get_html_from_site()
  File "/home/ubuntu/trends-script/scraper.py", line 31, in get_html_from_site
    driver.get(start_url)
  File "/home/ubuntu/.local/lib/python3.8/site-packages/selenium/webdriver/remote/webdriver.py", line 333, in get
    self.execute(Command.GET, {'url': url})
  File "/home/ubuntu/.local/lib/python3.8/site-packages/selenium/webdriver/remote/webdriver.py", line 321, in execute
    self.error_handler.check_response(response)
  File "/home/ubuntu/.local/lib/python3.8/site-packages/selenium/webdriver/remote/errorhandler.py", line 242, in check_response
    raise exception_class(message, screen, stacktrace)
selenium.common.exceptions.TimeoutException: Message: timeout: Timed out receiving message from renderer: 289.130
  (Session info: headless chrome=87.0.4280.88)

Traceback (most recent call last):
  File "/home/ubuntu/trends-script/scraper.py", line 260, in <module>
    main()
  File "/home/ubuntu/trends-script/scraper.py", line 253, in main
    htmlstring = get_html_from_site()
  File "/home/ubuntu/trends-script/scraper.py", line 28, in get_html_from_site
    driver = webdriver.Chrome(options=options)
  File "/home/ubuntu/.local/lib/python3.8/site-packages/selenium/webdriver/chrome/webdriver.py", line 73, in __init__
    self.service.start()
  File "/home/ubuntu/.local/lib/python3.8/site-packages/selenium/webdriver/common/service.py", line 104, in start
    raise WebDriverException("Can not connect to the Service %s" % self.path)
selenium.common.exceptions.WebDriverException: Message: Can not connect to the Service chromedriver

Traceback (most recent call last):
  File "/home/ubuntu/trends-script/scraper.py", line 260, in <module>
    main()
  File "/home/ubuntu/trends-script/scraper.py", line 253, in main
    htmlstring = get_html_from_site()
  File "/home/ubuntu/trends-script/scraper.py", line 31, in get_html_from_site
    driver.get(start_url)
  File "/home/ubuntu/.local/lib/python3.8/site-packages/selenium/webdriver/remote/webdriver.py", line 333, in get
    self.execute(Command.GET, {'url': url})
  File "/home/ubuntu/.local/lib/python3.8/site-packages/selenium/webdriver/remote/webdriver.py", line 321, in execute
    self.error_handler.check_response(response)
  File "/home/ubuntu/.local/lib/python3.8/site-packages/selenium/webdriver/remote/errorhandler.py", line 242, in check_response
    raise exception_class(message, screen, stacktrace)
selenium.common.exceptions.TimeoutException: Message: timeout: Timed out receiving message from renderer: 286.541
  (Session info: headless chrome=87.0.4280.88)

Traceback (most recent call last):
  File "/home/ubuntu/trends-script/scraper.py", line 260, in <module>
    main()
  File "/home/ubuntu/trends-script/scraper.py", line 253, in main
    htmlstring = get_html_from_site()
  File "/home/ubuntu/trends-script/scraper.py", line 28, in get_html_from_site
    driver = webdriver.Chrome(options=options)
  File "/home/ubuntu/.local/lib/python3.8/site-packages/selenium/webdriver/chrome/webdriver.py", line 73, in __init__
    self.service.start()
  File "/home/ubuntu/.local/lib/python3.8/site-packages/selenium/webdriver/common/service.py", line 104, in start
    raise WebDriverException("Can not connect to the Service %s" % self.path)
selenium.common.exceptions.WebDriverException: Message: Can not connect to the Service chromedriver

Traceback (most recent call last):
  File "/home/ubuntu/trends-script/scraper.py", line 260, in <module>
    main()
  File "/home/ubuntu/trends-script/scraper.py", line 253, in main
    htmlstring = get_html_from_site()
  File "/home/ubuntu/trends-script/scraper.py", line 31, in get_html_from_site
    driver.get(start_url)
  File "/home/ubuntu/.local/lib/python3.8/site-packages/selenium/webdriver/remote/webdriver.py", line 333, in get
    self.execute(Command.GET, {'url': url})
  File "/home/ubuntu/.local/lib/python3.8/site-packages/selenium/webdriver/remote/webdriver.py", line 321, in execute
    self.error_handler.check_response(response)
  File "/home/ubuntu/.local/lib/python3.8/site-packages/selenium/webdriver/remote/errorhandler.py", line 242, in check_response
    raise exception_class(message, screen, stacktrace)
selenium.common.exceptions.TimeoutException: Message: timeout: Timed out receiving message from renderer: 286.728
  (Session info: headless chrome=87.0.4280.88)

Traceback (most recent call last):
  File "/home/ubuntu/trends-script/scraper.py", line 260, in <module>
    main()
  File "/home/ubuntu/trends-script/scraper.py", line 253, in main
    htmlstring = get_html_from_site()
  File "/home/ubuntu/trends-script/scraper.py", line 28, in get_html_from_site
    driver = webdriver.Chrome(options=options)
  File "/home/ubuntu/.local/lib/python3.8/site-packages/selenium/webdriver/chrome/webdriver.py", line 73, in __init__
    self.service.start()
  File "/home/ubuntu/.local/lib/python3.8/site-packages/selenium/webdriver/common/service.py", line 104, in start
    raise WebDriverException("Can not connect to the Service %s" % self.path)
selenium.common.exceptions.WebDriverException: Message: Can not connect to the Service chromedriver

Traceback (most recent call last):
  File "/home/ubuntu/trends-script/scraper.py", line 260, in <module>
    main()
  File "/home/ubuntu/trends-script/scraper.py", line 253, in main
    htmlstring = get_html_from_site()
  File "/home/ubuntu/trends-script/scraper.py", line 31, in get_html_from_site
    driver.get(start_url)
  File "/home/ubuntu/.local/lib/python3.8/site-packages/selenium/webdriver/remote/webdriver.py", line 333, in get
    self.execute(Command.GET, {'url': url})
  File "/home/ubuntu/.local/lib/python3.8/site-packages/selenium/webdriver/remote/webdriver.py", line 321, in execute
    self.error_handler.check_response(response)
  File "/home/ubuntu/.local/lib/python3.8/site-packages/selenium/webdriver/remote/errorhandler.py", line 242, in check_response
    raise exception_class(message, screen, stacktrace)
selenium.common.exceptions.TimeoutException: Message: timeout: Timed out receiving message from renderer: 290.005
  (Session info: headless chrome=87.0.4280.88)

Traceback (most recent call last):
  File "/home/ubuntu/trends-script/scraper.py", line 260, in <module>
    main()
  File "/home/ubuntu/trends-script/scraper.py", line 253, in main
    htmlstring = get_html_from_site()
  File "/home/ubuntu/trends-script/scraper.py", line 28, in get_html_from_site
    driver = webdriver.Chrome(options=options)
  File "/home/ubuntu/.local/lib/python3.8/site-packages/selenium/webdriver/chrome/webdriver.py", line 73, in __init__
    self.service.start()
  File "/home/ubuntu/.local/lib/python3.8/site-packages/selenium/webdriver/common/service.py", line 104, in start
    raise WebDriverException("Can not connect to the Service %s" % self.path)
selenium.common.exceptions.WebDriverException: Message: Can not connect to the Service chromedriver

Traceback (most recent call last):
  File "/home/ubuntu/trends-script/scraper.py", line 260, in <module>
    main()
  File "/home/ubuntu/trends-script/scraper.py", line 253, in main
    htmlstring = get_html_from_site()
  File "/home/ubuntu/trends-script/scraper.py", line 28, in get_html_from_site
    driver = webdriver.Chrome(options=options)
  File "/home/ubuntu/.local/lib/python3.8/site-packages/selenium/webdriver/chrome/webdriver.py", line 73, in __init__
    self.service.start()
  File "/home/ubuntu/.local/lib/python3.8/site-packages/selenium/webdriver/common/service.py", line 104, in start
    raise WebDriverException("Can not connect to the Service %s" % self.path)
selenium.common.exceptions.WebDriverException: Message: Can not connect to the Service chromedriver

Traceback (most recent call last):
  File "/home/ubuntu/trends-script/scraper.py", line 260, in <module>
    main()
  File "/home/ubuntu/trends-script/scraper.py", line 253, in main
    htmlstring = get_html_from_site()
  File "/home/ubuntu/trends-script/scraper.py", line 28, in get_html_from_site
    driver = webdriver.Chrome(options=options)
  File "/home/ubuntu/.local/lib/python3.8/site-packages/selenium/webdriver/chrome/webdriver.py", line 73, in __init__
    self.service.start()
  File "/home/ubuntu/.local/lib/python3.8/site-packages/selenium/webdriver/common/service.py", line 104, in start
    raise WebDriverException("Can not connect to the Service %s" % self.path)
selenium.common.exceptions.WebDriverException: Message: Can not connect to the Service chromedriver

Traceback (most recent call last):
  File "/home/ubuntu/trends-script/scraper.py", line 260, in <module>
    main()
  File "/home/ubuntu/trends-script/scraper.py", line 253, in main
    htmlstring = get_html_from_site()
  File "/home/ubuntu/trends-script/scraper.py", line 28, in get_html_from_site
    driver = webdriver.Chrome(options=options)
  File "/home/ubuntu/.local/lib/python3.8/site-packages/selenium/webdriver/chrome/webdriver.py", line 73, in __init__
    self.service.start()
  File "/home/ubuntu/.local/lib/python3.8/site-packages/selenium/webdriver/common/service.py", line 104, in start
    raise WebDriverException("Can not connect to the Service %s" % self.path)
selenium.common.exceptions.WebDriverException: Message: Can not connect to the Service chromedriver

Traceback (most recent call last):
  File "/home/ubuntu/trends-script/scraper.py", line 260, in <module>
    main()
  File "/home/ubuntu/trends-script/scraper.py", line 253, in main
    htmlstring = get_html_from_site()
  File "/home/ubuntu/trends-script/scraper.py", line 31, in get_html_from_site
    driver.get(start_url)
  File "/home/ubuntu/.local/lib/python3.8/site-packages/selenium/webdriver/remote/webdriver.py", line 333, in get
    self.execute(Command.GET, {'url': url})
  File "/home/ubuntu/.local/lib/python3.8/site-packages/selenium/webdriver/remote/webdriver.py", line 321, in execute
    self.error_handler.check_response(response)
  File "/home/ubuntu/.local/lib/python3.8/site-packages/selenium/webdriver/remote/errorhandler.py", line 242, in check_response
    raise exception_class(message, screen, stacktrace)
selenium.common.exceptions.WebDriverException: Message: unknown error: session deleted because of page crash
from unknown error: cannot determine loading status
from tab crashed
  (Session info: headless chrome=87.0.4280.88)

Traceback (most recent call last):
  File "/home/ubuntu/trends-script/scraper.py", line 260, in <module>
    main()
  File "/home/ubuntu/trends-script/scraper.py", line 253, in main
    htmlstring = get_html_from_site()
  File "/home/ubuntu/trends-script/scraper.py", line 28, in get_html_from_site
    driver = webdriver.Chrome(options=options)
  File "/home/ubuntu/.local/lib/python3.8/site-packages/selenium/webdriver/chrome/webdriver.py", line 73, in __init__
    self.service.start()
  File "/home/ubuntu/.local/lib/python3.8/site-packages/selenium/webdriver/common/service.py", line 104, in start
    raise WebDriverException("Can not connect to the Service %s" % self.path)
selenium.common.exceptions.WebDriverException: Message: Can not connect to the Service chromedriver

Traceback (most recent call last):
  File "/home/ubuntu/trends-script/scraper.py", line 260, in <module>
    main()
  File "/home/ubuntu/trends-script/scraper.py", line 253, in main
    htmlstring = get_html_from_site()
  File "/home/ubuntu/trends-script/scraper.py", line 31, in get_html_from_site
    driver.get(start_url)
  File "/home/ubuntu/.local/lib/python3.8/site-packages/selenium/webdriver/remote/webdriver.py", line 333, in get
    self.execute(Command.GET, {'url': url})
  File "/home/ubuntu/.local/lib/python3.8/site-packages/selenium/webdriver/remote/webdriver.py", line 321, in execute
    self.error_handler.check_response(response)
  File "/home/ubuntu/.local/lib/python3.8/site-packages/selenium/webdriver/remote/errorhandler.py", line 242, in check_response
    raise exception_class(message, screen, stacktrace)
selenium.common.exceptions.TimeoutException: Message: timeout: Timed out receiving message from renderer: 280.690
  (Session info: headless chrome=87.0.4280.88)

Traceback (most recent call last):
  File "/home/ubuntu/trends-script/scraper.py", line 260, in <module>
    main()
  File "/home/ubuntu/trends-script/scraper.py", line 253, in main
    htmlstring = get_html_from_site()
  File "/home/ubuntu/trends-script/scraper.py", line 28, in get_html_from_site
    driver = webdriver.Chrome(options=options)
  File "/home/ubuntu/.local/lib/python3.8/site-packages/selenium/webdriver/chrome/webdriver.py", line 73, in __init__
    self.service.start()
  File "/home/ubuntu/.local/lib/python3.8/site-packages/selenium/webdriver/common/service.py", line 104, in start
    raise WebDriverException("Can not connect to the Service %s" % self.path)
selenium.common.exceptions.WebDriverException: Message: Can not connect to the Service chromedriver

Traceback (most recent call last):
  File "/home/ubuntu/trends-script/scraper.py", line 260, in <module>
    main()
  File "/home/ubuntu/trends-script/scraper.py", line 253, in main
    htmlstring = get_html_from_site()
  File "/home/ubuntu/trends-script/scraper.py", line 31, in get_html_from_site
    driver.get(start_url)
  File "/home/ubuntu/.local/lib/python3.8/site-packages/selenium/webdriver/remote/webdriver.py", line 333, in get
    self.execute(Command.GET, {'url': url})
  File "/home/ubuntu/.local/lib/python3.8/site-packages/selenium/webdriver/remote/webdriver.py", line 321, in execute
    self.error_handler.check_response(response)
  File "/home/ubuntu/.local/lib/python3.8/site-packages/selenium/webdriver/remote/errorhandler.py", line 242, in check_response
    raise exception_class(message, screen, stacktrace)
selenium.common.exceptions.TimeoutException: Message: timeout: Timed out receiving message from renderer: 285.664
  (Session info: headless chrome=87.0.4280.88)

Traceback (most recent call last):
  File "/home/ubuntu/trends-script/scraper.py", line 260, in <module>
    main()
  File "/home/ubuntu/trends-script/scraper.py", line 253, in main
    htmlstring = get_html_from_site()
  File "/home/ubuntu/trends-script/scraper.py", line 28, in get_html_from_site
    driver = webdriver.Chrome(options=options)
  File "/home/ubuntu/.local/lib/python3.8/site-packages/selenium/webdriver/chrome/webdriver.py", line 73, in __init__
    self.service.start()
  File "/home/ubuntu/.local/lib/python3.8/site-packages/selenium/webdriver/common/service.py", line 104, in start
    raise WebDriverException("Can not connect to the Service %s" % self.path)
selenium.common.exceptions.WebDriverException: Message: Can not connect to the Service chromedriver

Traceback (most recent call last):
  File "/home/ubuntu/trends-script/scraper.py", line 260, in <module>
    main()
  File "/home/ubuntu/trends-script/scraper.py", line 253, in main
    htmlstring = get_html_from_site()
  File "/home/ubuntu/trends-script/scraper.py", line 31, in get_html_from_site
    driver.get(start_url)
  File "/home/ubuntu/.local/lib/python3.8/site-packages/selenium/webdriver/remote/webdriver.py", line 333, in get
    self.execute(Command.GET, {'url': url})
  File "/home/ubuntu/.local/lib/python3.8/site-packages/selenium/webdriver/remote/webdriver.py", line 321, in execute
    self.error_handler.check_response(response)
  File "/home/ubuntu/.local/lib/python3.8/site-packages/selenium/webdriver/remote/errorhandler.py", line 242, in check_response
    raise exception_class(message, screen, stacktrace)
selenium.common.exceptions.TimeoutException: Message: timeout: Timed out receiving message from renderer: 288.125
  (Session info: headless chrome=87.0.4280.88)

Traceback (most recent call last):
  File "/home/ubuntu/trends-script/scraper.py", line 260, in <module>
    main()
  File "/home/ubuntu/trends-script/scraper.py", line 253, in main
    htmlstring = get_html_from_site()
  File "/home/ubuntu/trends-script/scraper.py", line 28, in get_html_from_site
    driver = webdriver.Chrome(options=options)
  File "/home/ubuntu/.local/lib/python3.8/site-packages/selenium/webdriver/chrome/webdriver.py", line 73, in __init__
    self.service.start()
  File "/home/ubuntu/.local/lib/python3.8/site-packages/selenium/webdriver/common/service.py", line 104, in start
    raise WebDriverException("Can not connect to the Service %s" % self.path)
selenium.common.exceptions.WebDriverException: Message: Can not connect to the Service chromedriver

Traceback (most recent call last):
  File "/home/ubuntu/trends-script/scraper.py", line 260, in <module>
    main()
  File "/home/ubuntu/trends-script/scraper.py", line 253, in main
    htmlstring = get_html_from_site()
  File "/home/ubuntu/trends-script/scraper.py", line 31, in get_html_from_site
    driver.get(start_url)
  File "/home/ubuntu/.local/lib/python3.8/site-packages/selenium/webdriver/remote/webdriver.py", line 333, in get
    self.execute(Command.GET, {'url': url})
  File "/home/ubuntu/.local/lib/python3.8/site-packages/selenium/webdriver/remote/webdriver.py", line 321, in execute
    self.error_handler.check_response(response)
  File "/home/ubuntu/.local/lib/python3.8/site-packages/selenium/webdriver/remote/errorhandler.py", line 242, in check_response
    raise exception_class(message, screen, stacktrace)
selenium.common.exceptions.TimeoutException: Message: timeout: Timed out receiving message from renderer: 290.463
  (Session info: headless chrome=87.0.4280.88)

Traceback (most recent call last):
  File "/home/ubuntu/trends-script/scraper.py", line 260, in <module>
    main()
  File "/home/ubuntu/trends-script/scraper.py", line 253, in main
    htmlstring = get_html_from_site()
  File "/home/ubuntu/trends-script/scraper.py", line 28, in get_html_from_site
    driver = webdriver.Chrome(options=options)
  File "/home/ubuntu/.local/lib/python3.8/site-packages/selenium/webdriver/chrome/webdriver.py", line 73, in __init__
    self.service.start()
  File "/home/ubuntu/.local/lib/python3.8/site-packages/selenium/webdriver/common/service.py", line 104, in start
    raise WebDriverException("Can not connect to the Service %s" % self.path)
selenium.common.exceptions.WebDriverException: Message: Can not connect to the Service chromedriver

Traceback (most recent call last):
  File "/home/ubuntu/trends-script/scraper.py", line 260, in <module>
    main()
  File "/home/ubuntu/trends-script/scraper.py", line 253, in main
    htmlstring = get_html_from_site()
  File "/home/ubuntu/trends-script/scraper.py", line 31, in get_html_from_site
    driver.get(start_url)
  File "/home/ubuntu/.local/lib/python3.8/site-packages/selenium/webdriver/remote/webdriver.py", line 333, in get
    self.execute(Command.GET, {'url': url})
  File "/home/ubuntu/.local/lib/python3.8/site-packages/selenium/webdriver/remote/webdriver.py", line 321, in execute
    self.error_handler.check_response(response)
  File "/home/ubuntu/.local/lib/python3.8/site-packages/selenium/webdriver/remote/errorhandler.py", line 242, in check_response
    raise exception_class(message, screen, stacktrace)
selenium.common.exceptions.TimeoutException: Message: timeout: Timed out receiving message from renderer: 290.220
  (Session info: headless chrome=87.0.4280.88)

Traceback (most recent call last):
  File "/home/ubuntu/trends-script/scraper.py", line 260, in <module>
    main()
  File "/home/ubuntu/trends-script/scraper.py", line 253, in main
    htmlstring = get_html_from_site()
  File "/home/ubuntu/trends-script/scraper.py", line 28, in get_html_from_site
    driver = webdriver.Chrome(options=options)
  File "/home/ubuntu/.local/lib/python3.8/site-packages/selenium/webdriver/chrome/webdriver.py", line 73, in __init__
    self.service.start()
  File "/home/ubuntu/.local/lib/python3.8/site-packages/selenium/webdriver/common/service.py", line 104, in start
    raise WebDriverException("Can not connect to the Service %s" % self.path)
selenium.common.exceptions.WebDriverException: Message: Can not connect to the Service chromedriver

Traceback (most recent call last):
  File "/home/ubuntu/trends-script/scraper.py", line 260, in <module>
    main()
  File "/home/ubuntu/trends-script/scraper.py", line 253, in main
    htmlstring = get_html_from_site()
  File "/home/ubuntu/trends-script/scraper.py", line 31, in get_html_from_site
    driver.get(start_url)
  File "/home/ubuntu/.local/lib/python3.8/site-packages/selenium/webdriver/remote/webdriver.py", line 333, in get
    self.execute(Command.GET, {'url': url})
  File "/home/ubuntu/.local/lib/python3.8/site-packages/selenium/webdriver/remote/webdriver.py", line 321, in execute
    self.error_handler.check_response(response)
  File "/home/ubuntu/.local/lib/python3.8/site-packages/selenium/webdriver/remote/errorhandler.py", line 242, in check_response
    raise exception_class(message, screen, stacktrace)
selenium.common.exceptions.TimeoutException: Message: timeout: Timed out receiving message from renderer: 289.959
  (Session info: headless chrome=87.0.4280.88)

Traceback (most recent call last):
  File "/home/ubuntu/trends-script/scraper.py", line 260, in <module>
    main()
  File "/home/ubuntu/trends-script/scraper.py", line 253, in main
    htmlstring = get_html_from_site()
  File "/home/ubuntu/trends-script/scraper.py", line 28, in get_html_from_site
    driver = webdriver.Chrome(options=options)
  File "/home/ubuntu/.local/lib/python3.8/site-packages/selenium/webdriver/chrome/webdriver.py", line 73, in __init__
    self.service.start()
  File "/home/ubuntu/.local/lib/python3.8/site-packages/selenium/webdriver/common/service.py", line 104, in start
    raise WebDriverException("Can not connect to the Service %s" % self.path)
selenium.common.exceptions.WebDriverException: Message: Can not connect to the Service chromedriver

Traceback (most recent call last):
  File "/home/ubuntu/trends-script/scraper.py", line 260, in <module>
    main()
  File "/home/ubuntu/trends-script/scraper.py", line 253, in main
    htmlstring = get_html_from_site()
  File "/home/ubuntu/trends-script/scraper.py", line 31, in get_html_from_site
    driver.get(start_url)
  File "/home/ubuntu/.local/lib/python3.8/site-packages/selenium/webdriver/remote/webdriver.py", line 333, in get
    self.execute(Command.GET, {'url': url})
  File "/home/ubuntu/.local/lib/python3.8/site-packages/selenium/webdriver/remote/webdriver.py", line 321, in execute
    self.error_handler.check_response(response)
  File "/home/ubuntu/.local/lib/python3.8/site-packages/selenium/webdriver/remote/errorhandler.py", line 242, in check_response
    raise exception_class(message, screen, stacktrace)
selenium.common.exceptions.WebDriverException: Message: unknown error: session deleted because of page crash
from unknown error: cannot determine loading status
from tab crashed
  (Session info: headless chrome=87.0.4280.88)

Traceback (most recent call last):
  File "/home/ubuntu/trends-script/scraper.py", line 260, in <module>
    main()
  File "/home/ubuntu/trends-script/scraper.py", line 253, in main
    htmlstring = get_html_from_site()
  File "/home/ubuntu/trends-script/scraper.py", line 28, in get_html_from_site
    driver = webdriver.Chrome(options=options)
  File "/home/ubuntu/.local/lib/python3.8/site-packages/selenium/webdriver/chrome/webdriver.py", line 73, in __init__
    self.service.start()
  File "/home/ubuntu/.local/lib/python3.8/site-packages/selenium/webdriver/common/service.py", line 104, in start
    raise WebDriverException("Can not connect to the Service %s" % self.path)
selenium.common.exceptions.WebDriverException: Message: Can not connect to the Service chromedriver

Traceback (most recent call last):
  File "/home/ubuntu/trends-script/scraper.py", line 260, in <module>
    main()
  File "/home/ubuntu/trends-script/scraper.py", line 253, in main
    htmlstring = get_html_from_site()
  File "/home/ubuntu/trends-script/scraper.py", line 31, in get_html_from_site
    driver.get(start_url)
  File "/home/ubuntu/.local/lib/python3.8/site-packages/selenium/webdriver/remote/webdriver.py", line 333, in get
    self.execute(Command.GET, {'url': url})
  File "/home/ubuntu/.local/lib/python3.8/site-packages/selenium/webdriver/remote/webdriver.py", line 321, in execute
    self.error_handler.check_response(response)
  File "/home/ubuntu/.local/lib/python3.8/site-packages/selenium/webdriver/remote/errorhandler.py", line 242, in check_response
    raise exception_class(message, screen, stacktrace)
selenium.common.exceptions.TimeoutException: Message: timeout: Timed out receiving message from renderer: 285.681
  (Session info: headless chrome=87.0.4280.88)

Traceback (most recent call last):
  File "/home/ubuntu/trends-script/scraper.py", line 260, in <module>
    main()
  File "/home/ubuntu/trends-script/scraper.py", line 253, in main
    htmlstring = get_html_from_site()
  File "/home/ubuntu/trends-script/scraper.py", line 28, in get_html_from_site
    driver = webdriver.Chrome(options=options)
  File "/home/ubuntu/.local/lib/python3.8/site-packages/selenium/webdriver/chrome/webdriver.py", line 73, in __init__
    self.service.start()
  File "/home/ubuntu/.local/lib/python3.8/site-packages/selenium/webdriver/common/service.py", line 104, in start
    raise WebDriverException("Can not connect to the Service %s" % self.path)
selenium.common.exceptions.WebDriverException: Message: Can not connect to the Service chromedriver

Traceback (most recent call last):
  File "/home/ubuntu/trends-script/scraper.py", line 260, in <module>
    main()
  File "/home/ubuntu/trends-script/scraper.py", line 253, in main
    htmlstring = get_html_from_site()
  File "/home/ubuntu/trends-script/scraper.py", line 31, in get_html_from_site
    driver.get(start_url)
  File "/home/ubuntu/.local/lib/python3.8/site-packages/selenium/webdriver/remote/webdriver.py", line 333, in get
    self.execute(Command.GET, {'url': url})
  File "/home/ubuntu/.local/lib/python3.8/site-packages/selenium/webdriver/remote/webdriver.py", line 321, in execute
    self.error_handler.check_response(response)
  File "/home/ubuntu/.local/lib/python3.8/site-packages/selenium/webdriver/remote/errorhandler.py", line 242, in check_response
    raise exception_class(message, screen, stacktrace)
selenium.common.exceptions.TimeoutException: Message: timeout: Timed out receiving message from renderer: 288.411
  (Session info: headless chrome=87.0.4280.88)

Traceback (most recent call last):
  File "/home/ubuntu/trends-script/scraper.py", line 260, in <module>
    main()
  File "/home/ubuntu/trends-script/scraper.py", line 253, in main
    htmlstring = get_html_from_site()
  File "/home/ubuntu/trends-script/scraper.py", line 28, in get_html_from_site
    driver = webdriver.Chrome(options=options)
  File "/home/ubuntu/.local/lib/python3.8/site-packages/selenium/webdriver/chrome/webdriver.py", line 73, in __init__
    self.service.start()
  File "/home/ubuntu/.local/lib/python3.8/site-packages/selenium/webdriver/common/service.py", line 104, in start
    raise WebDriverException("Can not connect to the Service %s" % self.path)
selenium.common.exceptions.WebDriverException: Message: Can not connect to the Service chromedriver

Traceback (most recent call last):
  File "/home/ubuntu/trends-script/scraper.py", line 260, in <module>
    main()
  File "/home/ubuntu/trends-script/scraper.py", line 253, in main
    htmlstring = get_html_from_site()
  File "/home/ubuntu/trends-script/scraper.py", line 31, in get_html_from_site
    driver.get(start_url)
  File "/home/ubuntu/.local/lib/python3.8/site-packages/selenium/webdriver/remote/webdriver.py", line 333, in get
    self.execute(Command.GET, {'url': url})
  File "/home/ubuntu/.local/lib/python3.8/site-packages/selenium/webdriver/remote/webdriver.py", line 321, in execute
    self.error_handler.check_response(response)
  File "/home/ubuntu/.local/lib/python3.8/site-packages/selenium/webdriver/remote/errorhandler.py", line 242, in check_response
    raise exception_class(message, screen, stacktrace)
selenium.common.exceptions.TimeoutException: Message: timeout: Timed out receiving message from renderer: 287.883
  (Session info: headless chrome=87.0.4280.88)

Traceback (most recent call last):
  File "/home/ubuntu/trends-script/scraper.py", line 260, in <module>
    main()
  File "/home/ubuntu/trends-script/scraper.py", line 253, in main
    htmlstring = get_html_from_site()
  File "/home/ubuntu/trends-script/scraper.py", line 28, in get_html_from_site
    driver = webdriver.Chrome(options=options)
  File "/home/ubuntu/.local/lib/python3.8/site-packages/selenium/webdriver/chrome/webdriver.py", line 73, in __init__
    self.service.start()
  File "/home/ubuntu/.local/lib/python3.8/site-packages/selenium/webdriver/common/service.py", line 104, in start
    raise WebDriverException("Can not connect to the Service %s" % self.path)
selenium.common.exceptions.WebDriverException: Message: Can not connect to the Service chromedriver

Traceback (most recent call last):
  File "/home/ubuntu/trends-script/scraper.py", line 260, in <module>
    main()
  File "/home/ubuntu/trends-script/scraper.py", line 253, in main
    htmlstring = get_html_from_site()
  File "/home/ubuntu/trends-script/scraper.py", line 31, in get_html_from_site
    driver.get(start_url)
  File "/home/ubuntu/.local/lib/python3.8/site-packages/selenium/webdriver/remote/webdriver.py", line 333, in get
    self.execute(Command.GET, {'url': url})
  File "/home/ubuntu/.local/lib/python3.8/site-packages/selenium/webdriver/remote/webdriver.py", line 321, in execute
    self.error_handler.check_response(response)
  File "/home/ubuntu/.local/lib/python3.8/site-packages/selenium/webdriver/remote/errorhandler.py", line 242, in check_response
    raise exception_class(message, screen, stacktrace)
selenium.common.exceptions.TimeoutException: Message: timeout: Timed out receiving message from renderer: 287.855
  (Session info: headless chrome=87.0.4280.88)

Traceback (most recent call last):
  File "/home/ubuntu/trends-script/scraper.py", line 260, in <module>
    main()
  File "/home/ubuntu/trends-script/scraper.py", line 253, in main
    htmlstring = get_html_from_site()
  File "/home/ubuntu/trends-script/scraper.py", line 28, in get_html_from_site
    driver = webdriver.Chrome(options=options)
  File "/home/ubuntu/.local/lib/python3.8/site-packages/selenium/webdriver/chrome/webdriver.py", line 73, in __init__
    self.service.start()
  File "/home/ubuntu/.local/lib/python3.8/site-packages/selenium/webdriver/common/service.py", line 104, in start
    raise WebDriverException("Can not connect to the Service %s" % self.path)
selenium.common.exceptions.WebDriverException: Message: Can not connect to the Service chromedriver

Traceback (most recent call last):
  File "/home/ubuntu/trends-script/scraper.py", line 260, in <module>
    main()
  File "/home/ubuntu/trends-script/scraper.py", line 253, in main
    htmlstring = get_html_from_site()
  File "/home/ubuntu/trends-script/scraper.py", line 31, in get_html_from_site
    driver.get(start_url)
  File "/home/ubuntu/.local/lib/python3.8/site-packages/selenium/webdriver/remote/webdriver.py", line 333, in get
    self.execute(Command.GET, {'url': url})
  File "/home/ubuntu/.local/lib/python3.8/site-packages/selenium/webdriver/remote/webdriver.py", line 321, in execute
    self.error_handler.check_response(response)
  File "/home/ubuntu/.local/lib/python3.8/site-packages/selenium/webdriver/remote/errorhandler.py", line 242, in check_response
    raise exception_class(message, screen, stacktrace)
selenium.common.exceptions.TimeoutException: Message: timeout: Timed out receiving message from renderer: 289.156
  (Session info: headless chrome=87.0.4280.88)

Traceback (most recent call last):
  File "/home/ubuntu/trends-script/scraper.py", line 260, in <module>
    main()
  File "/home/ubuntu/trends-script/scraper.py", line 253, in main
    htmlstring = get_html_from_site()
  File "/home/ubuntu/trends-script/scraper.py", line 28, in get_html_from_site
    driver = webdriver.Chrome(options=options)
  File "/home/ubuntu/.local/lib/python3.8/site-packages/selenium/webdriver/chrome/webdriver.py", line 73, in __init__
    self.service.start()
  File "/home/ubuntu/.local/lib/python3.8/site-packages/selenium/webdriver/common/service.py", line 104, in start
    raise WebDriverException("Can not connect to the Service %s" % self.path)
selenium.common.exceptions.WebDriverException: Message: Can not connect to the Service chromedriver

Traceback (most recent call last):
  File "/home/ubuntu/trends-script/scraper.py", line 260, in <module>
    main()
  File "/home/ubuntu/trends-script/scraper.py", line 253, in main
    htmlstring = get_html_from_site()
  File "/home/ubuntu/trends-script/scraper.py", line 31, in get_html_from_site
    driver.get(start_url)
  File "/home/ubuntu/.local/lib/python3.8/site-packages/selenium/webdriver/remote/webdriver.py", line 333, in get
    self.execute(Command.GET, {'url': url})
  File "/home/ubuntu/.local/lib/python3.8/site-packages/selenium/webdriver/remote/webdriver.py", line 321, in execute
    self.error_handler.check_response(response)
  File "/home/ubuntu/.local/lib/python3.8/site-packages/selenium/webdriver/remote/errorhandler.py", line 242, in check_response
    raise exception_class(message, screen, stacktrace)
selenium.common.exceptions.TimeoutException: Message: timeout: Timed out receiving message from renderer: 287.109
  (Session info: headless chrome=87.0.4280.88)

Traceback (most recent call last):
  File "/home/ubuntu/trends-script/scraper.py", line 260, in <module>
    main()
  File "/home/ubuntu/trends-script/scraper.py", line 253, in main
    htmlstring = get_html_from_site()
  File "/home/ubuntu/trends-script/scraper.py", line 28, in get_html_from_site
    driver = webdriver.Chrome(options=options)
  File "/home/ubuntu/.local/lib/python3.8/site-packages/selenium/webdriver/chrome/webdriver.py", line 73, in __init__
    self.service.start()
  File "/home/ubuntu/.local/lib/python3.8/site-packages/selenium/webdriver/common/service.py", line 104, in start
    raise WebDriverException("Can not connect to the Service %s" % self.path)
selenium.common.exceptions.WebDriverException: Message: Can not connect to the Service chromedriver

Traceback (most recent call last):
  File "/home/ubuntu/trends-script/scraper.py", line 260, in <module>
    main()
  File "/home/ubuntu/trends-script/scraper.py", line 253, in main
    htmlstring = get_html_from_site()
  File "/home/ubuntu/trends-script/scraper.py", line 28, in get_html_from_site
    driver = webdriver.Chrome(options=options)
  File "/home/ubuntu/.local/lib/python3.8/site-packages/selenium/webdriver/chrome/webdriver.py", line 73, in __init__
    self.service.start()
  File "/home/ubuntu/.local/lib/python3.8/site-packages/selenium/webdriver/common/service.py", line 104, in start
    raise WebDriverException("Can not connect to the Service %s" % self.path)
selenium.common.exceptions.WebDriverException: Message: Can not connect to the Service chromedriver

Traceback (most recent call last):
  File "/home/ubuntu/trends-script/scraper.py", line 260, in <module>
    main()
  File "/home/ubuntu/trends-script/scraper.py", line 253, in main
    htmlstring = get_html_from_site()
  File "/home/ubuntu/trends-script/scraper.py", line 31, in get_html_from_site
    driver.get(start_url)
  File "/home/ubuntu/.local/lib/python3.8/site-packages/selenium/webdriver/remote/webdriver.py", line 333, in get
    self.execute(Command.GET, {'url': url})
  File "/home/ubuntu/.local/lib/python3.8/site-packages/selenium/webdriver/remote/webdriver.py", line 321, in execute
    self.error_handler.check_response(response)
  File "/home/ubuntu/.local/lib/python3.8/site-packages/selenium/webdriver/remote/errorhandler.py", line 242, in check_response
    raise exception_class(message, screen, stacktrace)
selenium.common.exceptions.WebDriverException: Message: unknown error: session deleted because of page crash
from unknown error: cannot determine loading status
from tab crashed
  (Session info: headless chrome=87.0.4280.88)

Traceback (most recent call last):
  File "/home/ubuntu/trends-script/scraper.py", line 260, in <module>
    main()
  File "/home/ubuntu/trends-script/scraper.py", line 253, in main
    htmlstring = get_html_from_site()
  File "/home/ubuntu/trends-script/scraper.py", line 28, in get_html_from_site
    driver = webdriver.Chrome(options=options)
  File "/home/ubuntu/.local/lib/python3.8/site-packages/selenium/webdriver/chrome/webdriver.py", line 73, in __init__
    self.service.start()
  File "/home/ubuntu/.local/lib/python3.8/site-packages/selenium/webdriver/common/service.py", line 104, in start
    raise WebDriverException("Can not connect to the Service %s" % self.path)
selenium.common.exceptions.WebDriverException: Message: Can not connect to the Service chromedriver

Traceback (most recent call last):
  File "/home/ubuntu/trends-script/scraper.py", line 260, in <module>
    main()
  File "/home/ubuntu/trends-script/scraper.py", line 253, in main
    htmlstring = get_html_from_site()
  File "/home/ubuntu/trends-script/scraper.py", line 31, in get_html_from_site
    driver.get(start_url)
  File "/home/ubuntu/.local/lib/python3.8/site-packages/selenium/webdriver/remote/webdriver.py", line 333, in get
    self.execute(Command.GET, {'url': url})
  File "/home/ubuntu/.local/lib/python3.8/site-packages/selenium/webdriver/remote/webdriver.py", line 321, in execute
    self.error_handler.check_response(response)
  File "/home/ubuntu/.local/lib/python3.8/site-packages/selenium/webdriver/remote/errorhandler.py", line 242, in check_response
    raise exception_class(message, screen, stacktrace)
selenium.common.exceptions.TimeoutException: Message: timeout: Timed out receiving message from renderer: 287.185
  (Session info: headless chrome=87.0.4280.88)

Traceback (most recent call last):
  File "/home/ubuntu/trends-script/scraper.py", line 260, in <module>
    main()
  File "/home/ubuntu/trends-script/scraper.py", line 253, in main
    htmlstring = get_html_from_site()
  File "/home/ubuntu/trends-script/scraper.py", line 31, in get_html_from_site
    driver.get(start_url)
  File "/home/ubuntu/.local/lib/python3.8/site-packages/selenium/webdriver/remote/webdriver.py", line 333, in get
    self.execute(Command.GET, {'url': url})
  File "/home/ubuntu/.local/lib/python3.8/site-packages/selenium/webdriver/remote/webdriver.py", line 321, in execute
    self.error_handler.check_response(response)
  File "/home/ubuntu/.local/lib/python3.8/site-packages/selenium/webdriver/remote/errorhandler.py", line 242, in check_response
    raise exception_class(message, screen, stacktrace)
selenium.common.exceptions.WebDriverException: Message: unknown error: net::ERR_CONNECTION_CLOSED
  (Session info: headless chrome=87.0.4280.88)

Traceback (most recent call last):
  File "/home/ubuntu/trends-script/scraper.py", line 260, in <module>
    main()
  File "/home/ubuntu/trends-script/scraper.py", line 253, in main
    htmlstring = get_html_from_site()
  File "/home/ubuntu/trends-script/scraper.py", line 28, in get_html_from_site
    driver = webdriver.Chrome(options=options)
  File "/home/ubuntu/.local/lib/python3.8/site-packages/selenium/webdriver/chrome/webdriver.py", line 73, in __init__
    self.service.start()
  File "/home/ubuntu/.local/lib/python3.8/site-packages/selenium/webdriver/common/service.py", line 104, in start
    raise WebDriverException("Can not connect to the Service %s" % self.path)
selenium.common.exceptions.WebDriverException: Message: Can not connect to the Service chromedriver

Traceback (most recent call last):
  File "/home/ubuntu/trends-script/scraper.py", line 260, in <module>
    main()
  File "/home/ubuntu/trends-script/scraper.py", line 253, in main
    htmlstring = get_html_from_site()
  File "/home/ubuntu/trends-script/scraper.py", line 31, in get_html_from_site
    driver.get(start_url)
  File "/home/ubuntu/.local/lib/python3.8/site-packages/selenium/webdriver/remote/webdriver.py", line 333, in get
    self.execute(Command.GET, {'url': url})
  File "/home/ubuntu/.local/lib/python3.8/site-packages/selenium/webdriver/remote/webdriver.py", line 321, in execute
    self.error_handler.check_response(response)
  File "/home/ubuntu/.local/lib/python3.8/site-packages/selenium/webdriver/remote/errorhandler.py", line 242, in check_response
    raise exception_class(message, screen, stacktrace)
selenium.common.exceptions.TimeoutException: Message: timeout: Timed out receiving message from renderer: 288.573
  (Session info: headless chrome=87.0.4280.88)

Traceback (most recent call last):
  File "/home/ubuntu/trends-script/scraper.py", line 260, in <module>
    main()
  File "/home/ubuntu/trends-script/scraper.py", line 253, in main
    htmlstring = get_html_from_site()
  File "/home/ubuntu/trends-script/scraper.py", line 28, in get_html_from_site
    driver = webdriver.Chrome(options=options)
  File "/home/ubuntu/.local/lib/python3.8/site-packages/selenium/webdriver/chrome/webdriver.py", line 73, in __init__
    self.service.start()
  File "/home/ubuntu/.local/lib/python3.8/site-packages/selenium/webdriver/common/service.py", line 104, in start
    raise WebDriverException("Can not connect to the Service %s" % self.path)
selenium.common.exceptions.WebDriverException: Message: Can not connect to the Service chromedriver

Traceback (most recent call last):
  File "/home/ubuntu/trends-script/scraper.py", line 260, in <module>
    main()
  File "/home/ubuntu/trends-script/scraper.py", line 253, in main
    htmlstring = get_html_from_site()
  File "/home/ubuntu/trends-script/scraper.py", line 31, in get_html_from_site
    driver.get(start_url)
  File "/home/ubuntu/.local/lib/python3.8/site-packages/selenium/webdriver/remote/webdriver.py", line 333, in get
    self.execute(Command.GET, {'url': url})
  File "/home/ubuntu/.local/lib/python3.8/site-packages/selenium/webdriver/remote/webdriver.py", line 321, in execute
    self.error_handler.check_response(response)
  File "/home/ubuntu/.local/lib/python3.8/site-packages/selenium/webdriver/remote/errorhandler.py", line 242, in check_response
    raise exception_class(message, screen, stacktrace)
selenium.common.exceptions.TimeoutException: Message: timeout: Timed out receiving message from renderer: 286.204
  (Session info: headless chrome=87.0.4280.88)

