Traceback (most recent call last):
  File "/home/ubuntu/trends-script/scraper.py", line 260, in <module>
    main()
  File "/home/ubuntu/trends-script/scraper.py", line 253, in main
    htmlstring = get_html_from_site()
  File "/home/ubuntu/trends-script/scraper.py", line 28, in get_html_from_site
    driver = webdriver.Chrome(options=options)
  File "/home/ubuntu/.local/lib/python3.8/site-packages/selenium/webdriver/chrome/webdriver.py", line 73, in __init__
    self.service.start()
  File "/home/ubuntu/.local/lib/python3.8/site-packages/selenium/webdriver/common/service.py", line 104, in start
    raise WebDriverException("Can not connect to the Service %s" % self.path)
selenium.common.exceptions.WebDriverException: Message: Can not connect to the Service chromedriver

Traceback (most recent call last):
  File "/home/ubuntu/trends-script/scraper.py", line 260, in <module>
    main()
  File "/home/ubuntu/trends-script/scraper.py", line 253, in main
    htmlstring = get_html_from_site()
  File "/home/ubuntu/trends-script/scraper.py", line 28, in get_html_from_site
    driver = webdriver.Chrome(options=options)
  File "/home/ubuntu/.local/lib/python3.8/site-packages/selenium/webdriver/chrome/webdriver.py", line 73, in __init__
    self.service.start()
  File "/home/ubuntu/.local/lib/python3.8/site-packages/selenium/webdriver/common/service.py", line 104, in start
    raise WebDriverException("Can not connect to the Service %s" % self.path)
selenium.common.exceptions.WebDriverException: Message: Can not connect to the Service chromedriver

Traceback (most recent call last):
  File "/home/ubuntu/trends-script/scraper.py", line 260, in <module>
    main()
  File "/home/ubuntu/trends-script/scraper.py", line 253, in main
    htmlstring = get_html_from_site()
  File "/home/ubuntu/trends-script/scraper.py", line 31, in get_html_from_site
    driver.get(start_url)
  File "/home/ubuntu/.local/lib/python3.8/site-packages/selenium/webdriver/remote/webdriver.py", line 333, in get
    self.execute(Command.GET, {'url': url})
  File "/home/ubuntu/.local/lib/python3.8/site-packages/selenium/webdriver/remote/webdriver.py", line 321, in execute
    self.error_handler.check_response(response)
  File "/home/ubuntu/.local/lib/python3.8/site-packages/selenium/webdriver/remote/errorhandler.py", line 242, in check_response
    raise exception_class(message, screen, stacktrace)
selenium.common.exceptions.TimeoutException: Message: timeout: Timed out receiving message from renderer: 293.165
  (Session info: headless chrome=87.0.4280.88)

Traceback (most recent call last):
  File "/home/ubuntu/trends-script/scraper.py", line 260, in <module>
    main()
  File "/home/ubuntu/trends-script/scraper.py", line 253, in main
    htmlstring = get_html_from_site()
  File "/home/ubuntu/trends-script/scraper.py", line 28, in get_html_from_site
    driver = webdriver.Chrome(options=options)
  File "/home/ubuntu/.local/lib/python3.8/site-packages/selenium/webdriver/chrome/webdriver.py", line 73, in __init__
    self.service.start()
  File "/home/ubuntu/.local/lib/python3.8/site-packages/selenium/webdriver/common/service.py", line 104, in start
    raise WebDriverException("Can not connect to the Service %s" % self.path)
selenium.common.exceptions.WebDriverException: Message: Can not connect to the Service chromedriver

Traceback (most recent call last):
  File "/home/ubuntu/trends-script/scraper.py", line 260, in <module>
    main()
  File "/home/ubuntu/trends-script/scraper.py", line 253, in main
    htmlstring = get_html_from_site()
  File "/home/ubuntu/trends-script/scraper.py", line 31, in get_html_from_site
    driver.get(start_url)
  File "/home/ubuntu/.local/lib/python3.8/site-packages/selenium/webdriver/remote/webdriver.py", line 333, in get
    self.execute(Command.GET, {'url': url})
  File "/home/ubuntu/.local/lib/python3.8/site-packages/selenium/webdriver/remote/webdriver.py", line 321, in execute
    self.error_handler.check_response(response)
  File "/home/ubuntu/.local/lib/python3.8/site-packages/selenium/webdriver/remote/errorhandler.py", line 242, in check_response
    raise exception_class(message, screen, stacktrace)
selenium.common.exceptions.TimeoutException: Message: timeout: Timed out receiving message from renderer: 293.314
  (Session info: headless chrome=87.0.4280.88)

Traceback (most recent call last):
  File "/home/ubuntu/trends-script/scraper.py", line 260, in <module>
    main()
  File "/home/ubuntu/trends-script/scraper.py", line 253, in main
    htmlstring = get_html_from_site()
  File "/home/ubuntu/trends-script/scraper.py", line 28, in get_html_from_site
    driver = webdriver.Chrome(options=options)
  File "/home/ubuntu/.local/lib/python3.8/site-packages/selenium/webdriver/chrome/webdriver.py", line 73, in __init__
    self.service.start()
  File "/home/ubuntu/.local/lib/python3.8/site-packages/selenium/webdriver/common/service.py", line 104, in start
    raise WebDriverException("Can not connect to the Service %s" % self.path)
selenium.common.exceptions.WebDriverException: Message: Can not connect to the Service chromedriver

Traceback (most recent call last):
  File "/home/ubuntu/trends-script/scraper.py", line 260, in <module>
    main()
  File "/home/ubuntu/trends-script/scraper.py", line 253, in main
    htmlstring = get_html_from_site()
  File "/home/ubuntu/trends-script/scraper.py", line 31, in get_html_from_site
    driver.get(start_url)
  File "/home/ubuntu/.local/lib/python3.8/site-packages/selenium/webdriver/remote/webdriver.py", line 333, in get
    self.execute(Command.GET, {'url': url})
  File "/home/ubuntu/.local/lib/python3.8/site-packages/selenium/webdriver/remote/webdriver.py", line 321, in execute
    self.error_handler.check_response(response)
  File "/home/ubuntu/.local/lib/python3.8/site-packages/selenium/webdriver/remote/errorhandler.py", line 242, in check_response
    raise exception_class(message, screen, stacktrace)
selenium.common.exceptions.WebDriverException: Message: unknown error: session deleted because of page crash
from unknown error: cannot determine loading status
from tab crashed
  (Session info: headless chrome=87.0.4280.88)

Traceback (most recent call last):
  File "/home/ubuntu/trends-script/scraper.py", line 260, in <module>
    main()
  File "/home/ubuntu/trends-script/scraper.py", line 253, in main
    htmlstring = get_html_from_site()
  File "/home/ubuntu/trends-script/scraper.py", line 28, in get_html_from_site
    driver = webdriver.Chrome(options=options)
  File "/home/ubuntu/.local/lib/python3.8/site-packages/selenium/webdriver/chrome/webdriver.py", line 73, in __init__
    self.service.start()
  File "/home/ubuntu/.local/lib/python3.8/site-packages/selenium/webdriver/common/service.py", line 104, in start
    raise WebDriverException("Can not connect to the Service %s" % self.path)
selenium.common.exceptions.WebDriverException: Message: Can not connect to the Service chromedriver

Traceback (most recent call last):
  File "/home/ubuntu/trends-script/scraper.py", line 260, in <module>
    main()
  File "/home/ubuntu/trends-script/scraper.py", line 253, in main
    htmlstring = get_html_from_site()
  File "/home/ubuntu/trends-script/scraper.py", line 31, in get_html_from_site
    driver.get(start_url)
  File "/home/ubuntu/.local/lib/python3.8/site-packages/selenium/webdriver/remote/webdriver.py", line 333, in get
    self.execute(Command.GET, {'url': url})
  File "/home/ubuntu/.local/lib/python3.8/site-packages/selenium/webdriver/remote/webdriver.py", line 321, in execute
    self.error_handler.check_response(response)
  File "/home/ubuntu/.local/lib/python3.8/site-packages/selenium/webdriver/remote/errorhandler.py", line 242, in check_response
    raise exception_class(message, screen, stacktrace)
selenium.common.exceptions.TimeoutException: Message: timeout: Timed out receiving message from renderer: 293.841
  (Session info: headless chrome=87.0.4280.88)

