Traceback (most recent call last):
  File "/home/ubuntu/trends-script/scraper.py", line 260, in <module>
    main()
  File "/home/ubuntu/trends-script/scraper.py", line 253, in main
    htmlstring = get_html_from_site()
  File "/home/ubuntu/trends-script/scraper.py", line 28, in get_html_from_site
    driver = webdriver.Chrome(options=options)
  File "/home/ubuntu/.local/lib/python3.8/site-packages/selenium/webdriver/chrome/webdriver.py", line 73, in __init__
    self.service.start()
  File "/home/ubuntu/.local/lib/python3.8/site-packages/selenium/webdriver/common/service.py", line 104, in start
    raise WebDriverException("Can not connect to the Service %s" % self.path)
selenium.common.exceptions.WebDriverException: Message: Can not connect to the Service chromedriver

Traceback (most recent call last):
  File "/home/ubuntu/trends-script/scraper.py", line 260, in <module>
    main()
  File "/home/ubuntu/trends-script/scraper.py", line 253, in main
    htmlstring = get_html_from_site()
  File "/home/ubuntu/trends-script/scraper.py", line 31, in get_html_from_site
    driver.get(start_url)
  File "/home/ubuntu/.local/lib/python3.8/site-packages/selenium/webdriver/remote/webdriver.py", line 333, in get
    self.execute(Command.GET, {'url': url})
  File "/home/ubuntu/.local/lib/python3.8/site-packages/selenium/webdriver/remote/webdriver.py", line 321, in execute
    self.error_handler.check_response(response)
  File "/home/ubuntu/.local/lib/python3.8/site-packages/selenium/webdriver/remote/errorhandler.py", line 242, in check_response
    raise exception_class(message, screen, stacktrace)
selenium.common.exceptions.TimeoutException: Message: timeout: Timed out receiving message from renderer: 292.879
  (Session info: headless chrome=87.0.4280.88)

Traceback (most recent call last):
  File "/home/ubuntu/trends-script/scraper.py", line 260, in <module>
    main()
  File "/home/ubuntu/trends-script/scraper.py", line 253, in main
    htmlstring = get_html_from_site()
  File "/home/ubuntu/trends-script/scraper.py", line 28, in get_html_from_site
    driver = webdriver.Chrome(options=options)
  File "/home/ubuntu/.local/lib/python3.8/site-packages/selenium/webdriver/chrome/webdriver.py", line 73, in __init__
    self.service.start()
  File "/home/ubuntu/.local/lib/python3.8/site-packages/selenium/webdriver/common/service.py", line 104, in start
    raise WebDriverException("Can not connect to the Service %s" % self.path)
selenium.common.exceptions.WebDriverException: Message: Can not connect to the Service chromedriver

Traceback (most recent call last):
  File "/home/ubuntu/trends-script/scraper.py", line 260, in <module>
    main()
  File "/home/ubuntu/trends-script/scraper.py", line 253, in main
    htmlstring = get_html_from_site()
  File "/home/ubuntu/trends-script/scraper.py", line 31, in get_html_from_site
    driver.get(start_url)
  File "/home/ubuntu/.local/lib/python3.8/site-packages/selenium/webdriver/remote/webdriver.py", line 333, in get
    self.execute(Command.GET, {'url': url})
  File "/home/ubuntu/.local/lib/python3.8/site-packages/selenium/webdriver/remote/webdriver.py", line 321, in execute
    self.error_handler.check_response(response)
  File "/home/ubuntu/.local/lib/python3.8/site-packages/selenium/webdriver/remote/errorhandler.py", line 242, in check_response
    raise exception_class(message, screen, stacktrace)
selenium.common.exceptions.TimeoutException: Message: timeout: Timed out receiving message from renderer: 293.595
  (Session info: headless chrome=87.0.4280.88)

Traceback (most recent call last):
  File "/home/ubuntu/trends-script/scraper.py", line 260, in <module>
    main()
  File "/home/ubuntu/trends-script/scraper.py", line 253, in main
    htmlstring = get_html_from_site()
  File "/home/ubuntu/trends-script/scraper.py", line 28, in get_html_from_site
    driver = webdriver.Chrome(options=options)
  File "/home/ubuntu/.local/lib/python3.8/site-packages/selenium/webdriver/chrome/webdriver.py", line 73, in __init__
    self.service.start()
  File "/home/ubuntu/.local/lib/python3.8/site-packages/selenium/webdriver/common/service.py", line 104, in start
    raise WebDriverException("Can not connect to the Service %s" % self.path)
selenium.common.exceptions.WebDriverException: Message: Can not connect to the Service chromedriver

Traceback (most recent call last):
  File "/home/ubuntu/trends-script/scraper.py", line 260, in <module>
    main()
  File "/home/ubuntu/trends-script/scraper.py", line 253, in main
    htmlstring = get_html_from_site()
  File "/home/ubuntu/trends-script/scraper.py", line 31, in get_html_from_site
    driver.get(start_url)
  File "/home/ubuntu/.local/lib/python3.8/site-packages/selenium/webdriver/remote/webdriver.py", line 333, in get
    self.execute(Command.GET, {'url': url})
  File "/home/ubuntu/.local/lib/python3.8/site-packages/selenium/webdriver/remote/webdriver.py", line 321, in execute
    self.error_handler.check_response(response)
  File "/home/ubuntu/.local/lib/python3.8/site-packages/selenium/webdriver/remote/errorhandler.py", line 242, in check_response
    raise exception_class(message, screen, stacktrace)
selenium.common.exceptions.TimeoutException: Message: timeout: Timed out receiving message from renderer: 290.651
  (Session info: headless chrome=87.0.4280.88)

Traceback (most recent call last):
  File "/home/ubuntu/trends-script/scraper.py", line 260, in <module>
    main()
  File "/home/ubuntu/trends-script/scraper.py", line 253, in main
    htmlstring = get_html_from_site()
  File "/home/ubuntu/trends-script/scraper.py", line 28, in get_html_from_site
    driver = webdriver.Chrome(options=options)
  File "/home/ubuntu/.local/lib/python3.8/site-packages/selenium/webdriver/chrome/webdriver.py", line 73, in __init__
    self.service.start()
  File "/home/ubuntu/.local/lib/python3.8/site-packages/selenium/webdriver/common/service.py", line 104, in start
    raise WebDriverException("Can not connect to the Service %s" % self.path)
selenium.common.exceptions.WebDriverException: Message: Can not connect to the Service chromedriver

Traceback (most recent call last):
  File "/home/ubuntu/trends-script/scraper.py", line 260, in <module>
    main()
  File "/home/ubuntu/trends-script/scraper.py", line 253, in main
    htmlstring = get_html_from_site()
  File "/home/ubuntu/trends-script/scraper.py", line 31, in get_html_from_site
    driver.get(start_url)
  File "/home/ubuntu/.local/lib/python3.8/site-packages/selenium/webdriver/remote/webdriver.py", line 333, in get
    self.execute(Command.GET, {'url': url})
  File "/home/ubuntu/.local/lib/python3.8/site-packages/selenium/webdriver/remote/webdriver.py", line 321, in execute
    self.error_handler.check_response(response)
  File "/home/ubuntu/.local/lib/python3.8/site-packages/selenium/webdriver/remote/errorhandler.py", line 242, in check_response
    raise exception_class(message, screen, stacktrace)
selenium.common.exceptions.TimeoutException: Message: timeout: Timed out receiving message from renderer: 294.023
  (Session info: headless chrome=87.0.4280.88)

Traceback (most recent call last):
  File "/home/ubuntu/trends-script/scraper.py", line 260, in <module>
    main()
  File "/home/ubuntu/trends-script/scraper.py", line 253, in main
    htmlstring = get_html_from_site()
  File "/home/ubuntu/trends-script/scraper.py", line 28, in get_html_from_site
    driver = webdriver.Chrome(options=options)
  File "/home/ubuntu/.local/lib/python3.8/site-packages/selenium/webdriver/chrome/webdriver.py", line 73, in __init__
    self.service.start()
  File "/home/ubuntu/.local/lib/python3.8/site-packages/selenium/webdriver/common/service.py", line 104, in start
    raise WebDriverException("Can not connect to the Service %s" % self.path)
selenium.common.exceptions.WebDriverException: Message: Can not connect to the Service chromedriver

Traceback (most recent call last):
  File "/home/ubuntu/trends-script/scraper.py", line 260, in <module>
    main()
  File "/home/ubuntu/trends-script/scraper.py", line 253, in main
    htmlstring = get_html_from_site()
  File "/home/ubuntu/trends-script/scraper.py", line 28, in get_html_from_site
    driver = webdriver.Chrome(options=options)
  File "/home/ubuntu/.local/lib/python3.8/site-packages/selenium/webdriver/chrome/webdriver.py", line 73, in __init__
    self.service.start()
  File "/home/ubuntu/.local/lib/python3.8/site-packages/selenium/webdriver/common/service.py", line 104, in start
    raise WebDriverException("Can not connect to the Service %s" % self.path)
selenium.common.exceptions.WebDriverException: Message: Can not connect to the Service chromedriver

Traceback (most recent call last):
  File "/home/ubuntu/trends-script/scraper.py", line 260, in <module>
    main()
  File "/home/ubuntu/trends-script/scraper.py", line 253, in main
    htmlstring = get_html_from_site()
  File "/home/ubuntu/trends-script/scraper.py", line 31, in get_html_from_site
    driver.get(start_url)
  File "/home/ubuntu/.local/lib/python3.8/site-packages/selenium/webdriver/remote/webdriver.py", line 333, in get
    self.execute(Command.GET, {'url': url})
  File "/home/ubuntu/.local/lib/python3.8/site-packages/selenium/webdriver/remote/webdriver.py", line 321, in execute
    self.error_handler.check_response(response)
  File "/home/ubuntu/.local/lib/python3.8/site-packages/selenium/webdriver/remote/errorhandler.py", line 242, in check_response
    raise exception_class(message, screen, stacktrace)
selenium.common.exceptions.TimeoutException: Message: timeout: Timed out receiving message from renderer: 293.170
  (Session info: headless chrome=87.0.4280.88)

Traceback (most recent call last):
  File "/home/ubuntu/trends-script/scraper.py", line 260, in <module>
    main()
  File "/home/ubuntu/trends-script/scraper.py", line 253, in main
    htmlstring = get_html_from_site()
  File "/home/ubuntu/trends-script/scraper.py", line 28, in get_html_from_site
    driver = webdriver.Chrome(options=options)
  File "/home/ubuntu/.local/lib/python3.8/site-packages/selenium/webdriver/chrome/webdriver.py", line 73, in __init__
    self.service.start()
  File "/home/ubuntu/.local/lib/python3.8/site-packages/selenium/webdriver/common/service.py", line 104, in start
    raise WebDriverException("Can not connect to the Service %s" % self.path)
selenium.common.exceptions.WebDriverException: Message: Can not connect to the Service chromedriver

Traceback (most recent call last):
  File "/home/ubuntu/trends-script/scraper.py", line 260, in <module>
    main()
  File "/home/ubuntu/trends-script/scraper.py", line 253, in main
    htmlstring = get_html_from_site()
  File "/home/ubuntu/trends-script/scraper.py", line 31, in get_html_from_site
    driver.get(start_url)
  File "/home/ubuntu/.local/lib/python3.8/site-packages/selenium/webdriver/remote/webdriver.py", line 333, in get
    self.execute(Command.GET, {'url': url})
  File "/home/ubuntu/.local/lib/python3.8/site-packages/selenium/webdriver/remote/webdriver.py", line 321, in execute
    self.error_handler.check_response(response)
  File "/home/ubuntu/.local/lib/python3.8/site-packages/selenium/webdriver/remote/errorhandler.py", line 242, in check_response
    raise exception_class(message, screen, stacktrace)
selenium.common.exceptions.TimeoutException: Message: timeout: Timed out receiving message from renderer: 294.841
  (Session info: headless chrome=87.0.4280.88)

Traceback (most recent call last):
  File "/home/ubuntu/trends-script/scraper.py", line 260, in <module>
    main()
  File "/home/ubuntu/trends-script/scraper.py", line 253, in main
    htmlstring = get_html_from_site()
  File "/home/ubuntu/trends-script/scraper.py", line 28, in get_html_from_site
    driver = webdriver.Chrome(options=options)
  File "/home/ubuntu/.local/lib/python3.8/site-packages/selenium/webdriver/chrome/webdriver.py", line 73, in __init__
    self.service.start()
  File "/home/ubuntu/.local/lib/python3.8/site-packages/selenium/webdriver/common/service.py", line 104, in start
    raise WebDriverException("Can not connect to the Service %s" % self.path)
selenium.common.exceptions.WebDriverException: Message: Can not connect to the Service chromedriver

Traceback (most recent call last):
  File "/home/ubuntu/trends-script/scraper.py", line 260, in <module>
    main()
  File "/home/ubuntu/trends-script/scraper.py", line 253, in main
    htmlstring = get_html_from_site()
  File "/home/ubuntu/trends-script/scraper.py", line 31, in get_html_from_site
    driver.get(start_url)
  File "/home/ubuntu/.local/lib/python3.8/site-packages/selenium/webdriver/remote/webdriver.py", line 333, in get
    self.execute(Command.GET, {'url': url})
  File "/home/ubuntu/.local/lib/python3.8/site-packages/selenium/webdriver/remote/webdriver.py", line 321, in execute
    self.error_handler.check_response(response)
  File "/home/ubuntu/.local/lib/python3.8/site-packages/selenium/webdriver/remote/errorhandler.py", line 242, in check_response
    raise exception_class(message, screen, stacktrace)
selenium.common.exceptions.TimeoutException: Message: timeout: Timed out receiving message from renderer: 293.211
  (Session info: headless chrome=87.0.4280.88)

Traceback (most recent call last):
  File "/home/ubuntu/trends-script/scraper.py", line 260, in <module>
    main()
  File "/home/ubuntu/trends-script/scraper.py", line 253, in main
    htmlstring = get_html_from_site()
  File "/home/ubuntu/trends-script/scraper.py", line 28, in get_html_from_site
    driver = webdriver.Chrome(options=options)
  File "/home/ubuntu/.local/lib/python3.8/site-packages/selenium/webdriver/chrome/webdriver.py", line 73, in __init__
    self.service.start()
  File "/home/ubuntu/.local/lib/python3.8/site-packages/selenium/webdriver/common/service.py", line 104, in start
    raise WebDriverException("Can not connect to the Service %s" % self.path)
selenium.common.exceptions.WebDriverException: Message: Can not connect to the Service chromedriver

Traceback (most recent call last):
  File "/home/ubuntu/trends-script/scraper.py", line 260, in <module>
    main()
  File "/home/ubuntu/trends-script/scraper.py", line 253, in main
    htmlstring = get_html_from_site()
  File "/home/ubuntu/trends-script/scraper.py", line 31, in get_html_from_site
    driver.get(start_url)
  File "/home/ubuntu/.local/lib/python3.8/site-packages/selenium/webdriver/remote/webdriver.py", line 333, in get
    self.execute(Command.GET, {'url': url})
  File "/home/ubuntu/.local/lib/python3.8/site-packages/selenium/webdriver/remote/webdriver.py", line 321, in execute
    self.error_handler.check_response(response)
  File "/home/ubuntu/.local/lib/python3.8/site-packages/selenium/webdriver/remote/errorhandler.py", line 242, in check_response
    raise exception_class(message, screen, stacktrace)
selenium.common.exceptions.TimeoutException: Message: timeout: Timed out receiving message from renderer: 293.728
  (Session info: headless chrome=87.0.4280.88)

Traceback (most recent call last):
  File "/home/ubuntu/trends-script/scraper.py", line 260, in <module>
    main()
  File "/home/ubuntu/trends-script/scraper.py", line 253, in main
    htmlstring = get_html_from_site()
  File "/home/ubuntu/trends-script/scraper.py", line 28, in get_html_from_site
    driver = webdriver.Chrome(options=options)
  File "/home/ubuntu/.local/lib/python3.8/site-packages/selenium/webdriver/chrome/webdriver.py", line 73, in __init__
    self.service.start()
  File "/home/ubuntu/.local/lib/python3.8/site-packages/selenium/webdriver/common/service.py", line 104, in start
    raise WebDriverException("Can not connect to the Service %s" % self.path)
selenium.common.exceptions.WebDriverException: Message: Can not connect to the Service chromedriver

Traceback (most recent call last):
  File "/home/ubuntu/trends-script/scraper.py", line 260, in <module>
    main()
  File "/home/ubuntu/trends-script/scraper.py", line 253, in main
    htmlstring = get_html_from_site()
  File "/home/ubuntu/trends-script/scraper.py", line 31, in get_html_from_site
    driver.get(start_url)
  File "/home/ubuntu/.local/lib/python3.8/site-packages/selenium/webdriver/remote/webdriver.py", line 333, in get
    self.execute(Command.GET, {'url': url})
  File "/home/ubuntu/.local/lib/python3.8/site-packages/selenium/webdriver/remote/webdriver.py", line 321, in execute
    self.error_handler.check_response(response)
  File "/home/ubuntu/.local/lib/python3.8/site-packages/selenium/webdriver/remote/errorhandler.py", line 242, in check_response
    raise exception_class(message, screen, stacktrace)
selenium.common.exceptions.TimeoutException: Message: timeout: Timed out receiving message from renderer: 294.352
  (Session info: headless chrome=87.0.4280.88)

Traceback (most recent call last):
  File "/home/ubuntu/trends-script/scraper.py", line 260, in <module>
    main()
  File "/home/ubuntu/trends-script/scraper.py", line 253, in main
    htmlstring = get_html_from_site()
  File "/home/ubuntu/trends-script/scraper.py", line 28, in get_html_from_site
    driver = webdriver.Chrome(options=options)
  File "/home/ubuntu/.local/lib/python3.8/site-packages/selenium/webdriver/chrome/webdriver.py", line 73, in __init__
    self.service.start()
  File "/home/ubuntu/.local/lib/python3.8/site-packages/selenium/webdriver/common/service.py", line 104, in start
    raise WebDriverException("Can not connect to the Service %s" % self.path)
selenium.common.exceptions.WebDriverException: Message: Can not connect to the Service chromedriver

Traceback (most recent call last):
  File "/home/ubuntu/trends-script/scraper.py", line 260, in <module>
    main()
  File "/home/ubuntu/trends-script/scraper.py", line 253, in main
    htmlstring = get_html_from_site()
  File "/home/ubuntu/trends-script/scraper.py", line 31, in get_html_from_site
    driver.get(start_url)
  File "/home/ubuntu/.local/lib/python3.8/site-packages/selenium/webdriver/remote/webdriver.py", line 333, in get
    self.execute(Command.GET, {'url': url})
  File "/home/ubuntu/.local/lib/python3.8/site-packages/selenium/webdriver/remote/webdriver.py", line 321, in execute
    self.error_handler.check_response(response)
  File "/home/ubuntu/.local/lib/python3.8/site-packages/selenium/webdriver/remote/errorhandler.py", line 242, in check_response
    raise exception_class(message, screen, stacktrace)
selenium.common.exceptions.TimeoutException: Message: timeout: Timed out receiving message from renderer: 292.654
  (Session info: headless chrome=87.0.4280.88)

Traceback (most recent call last):
  File "/home/ubuntu/trends-script/scraper.py", line 260, in <module>
    main()
  File "/home/ubuntu/trends-script/scraper.py", line 253, in main
    htmlstring = get_html_from_site()
  File "/home/ubuntu/trends-script/scraper.py", line 28, in get_html_from_site
    driver = webdriver.Chrome(options=options)
  File "/home/ubuntu/.local/lib/python3.8/site-packages/selenium/webdriver/chrome/webdriver.py", line 73, in __init__
    self.service.start()
  File "/home/ubuntu/.local/lib/python3.8/site-packages/selenium/webdriver/common/service.py", line 104, in start
    raise WebDriverException("Can not connect to the Service %s" % self.path)
selenium.common.exceptions.WebDriverException: Message: Can not connect to the Service chromedriver

Traceback (most recent call last):
  File "/home/ubuntu/trends-script/scraper.py", line 260, in <module>
    main()
  File "/home/ubuntu/trends-script/scraper.py", line 253, in main
    htmlstring = get_html_from_site()
  File "/home/ubuntu/trends-script/scraper.py", line 31, in get_html_from_site
    driver.get(start_url)
  File "/home/ubuntu/.local/lib/python3.8/site-packages/selenium/webdriver/remote/webdriver.py", line 333, in get
    self.execute(Command.GET, {'url': url})
  File "/home/ubuntu/.local/lib/python3.8/site-packages/selenium/webdriver/remote/webdriver.py", line 321, in execute
    self.error_handler.check_response(response)
  File "/home/ubuntu/.local/lib/python3.8/site-packages/selenium/webdriver/remote/errorhandler.py", line 242, in check_response
    raise exception_class(message, screen, stacktrace)
selenium.common.exceptions.TimeoutException: Message: timeout: Timed out receiving message from renderer: 293.157
  (Session info: headless chrome=87.0.4280.88)

Traceback (most recent call last):
  File "/home/ubuntu/trends-script/scraper.py", line 260, in <module>
    main()
  File "/home/ubuntu/trends-script/scraper.py", line 253, in main
    htmlstring = get_html_from_site()
  File "/home/ubuntu/trends-script/scraper.py", line 28, in get_html_from_site
    driver = webdriver.Chrome(options=options)
  File "/home/ubuntu/.local/lib/python3.8/site-packages/selenium/webdriver/chrome/webdriver.py", line 73, in __init__
    self.service.start()
  File "/home/ubuntu/.local/lib/python3.8/site-packages/selenium/webdriver/common/service.py", line 104, in start
    raise WebDriverException("Can not connect to the Service %s" % self.path)
selenium.common.exceptions.WebDriverException: Message: Can not connect to the Service chromedriver

Traceback (most recent call last):
  File "/home/ubuntu/trends-script/scraper.py", line 260, in <module>
    main()
  File "/home/ubuntu/trends-script/scraper.py", line 253, in main
    htmlstring = get_html_from_site()
  File "/home/ubuntu/trends-script/scraper.py", line 31, in get_html_from_site
    driver.get(start_url)
  File "/home/ubuntu/.local/lib/python3.8/site-packages/selenium/webdriver/remote/webdriver.py", line 333, in get
    self.execute(Command.GET, {'url': url})
  File "/home/ubuntu/.local/lib/python3.8/site-packages/selenium/webdriver/remote/webdriver.py", line 321, in execute
    self.error_handler.check_response(response)
  File "/home/ubuntu/.local/lib/python3.8/site-packages/selenium/webdriver/remote/errorhandler.py", line 242, in check_response
    raise exception_class(message, screen, stacktrace)
selenium.common.exceptions.TimeoutException: Message: timeout: Timed out receiving message from renderer: 293.620
  (Session info: headless chrome=87.0.4280.88)

Traceback (most recent call last):
  File "/home/ubuntu/trends-script/scraper.py", line 260, in <module>
    main()
  File "/home/ubuntu/trends-script/scraper.py", line 253, in main
    htmlstring = get_html_from_site()
  File "/home/ubuntu/trends-script/scraper.py", line 28, in get_html_from_site
    driver = webdriver.Chrome(options=options)
  File "/home/ubuntu/.local/lib/python3.8/site-packages/selenium/webdriver/chrome/webdriver.py", line 73, in __init__
    self.service.start()
  File "/home/ubuntu/.local/lib/python3.8/site-packages/selenium/webdriver/common/service.py", line 104, in start
    raise WebDriverException("Can not connect to the Service %s" % self.path)
selenium.common.exceptions.WebDriverException: Message: Can not connect to the Service chromedriver

Traceback (most recent call last):
  File "/home/ubuntu/trends-script/scraper.py", line 260, in <module>
    main()
  File "/home/ubuntu/trends-script/scraper.py", line 253, in main
    htmlstring = get_html_from_site()
  File "/home/ubuntu/trends-script/scraper.py", line 31, in get_html_from_site
    driver.get(start_url)
  File "/home/ubuntu/.local/lib/python3.8/site-packages/selenium/webdriver/remote/webdriver.py", line 333, in get
    self.execute(Command.GET, {'url': url})
  File "/home/ubuntu/.local/lib/python3.8/site-packages/selenium/webdriver/remote/webdriver.py", line 321, in execute
    self.error_handler.check_response(response)
  File "/home/ubuntu/.local/lib/python3.8/site-packages/selenium/webdriver/remote/errorhandler.py", line 242, in check_response
    raise exception_class(message, screen, stacktrace)
selenium.common.exceptions.TimeoutException: Message: timeout: Timed out receiving message from renderer: 293.772
  (Session info: headless chrome=87.0.4280.88)

Traceback (most recent call last):
  File "/home/ubuntu/trends-script/scraper.py", line 260, in <module>
    main()
  File "/home/ubuntu/trends-script/scraper.py", line 253, in main
    htmlstring = get_html_from_site()
  File "/home/ubuntu/trends-script/scraper.py", line 28, in get_html_from_site
    driver = webdriver.Chrome(options=options)
  File "/home/ubuntu/.local/lib/python3.8/site-packages/selenium/webdriver/chrome/webdriver.py", line 73, in __init__
    self.service.start()
  File "/home/ubuntu/.local/lib/python3.8/site-packages/selenium/webdriver/common/service.py", line 104, in start
    raise WebDriverException("Can not connect to the Service %s" % self.path)
selenium.common.exceptions.WebDriverException: Message: Can not connect to the Service chromedriver

Traceback (most recent call last):
  File "/home/ubuntu/trends-script/scraper.py", line 260, in <module>
    main()
  File "/home/ubuntu/trends-script/scraper.py", line 253, in main
    htmlstring = get_html_from_site()
  File "/home/ubuntu/trends-script/scraper.py", line 31, in get_html_from_site
    driver.get(start_url)
  File "/home/ubuntu/.local/lib/python3.8/site-packages/selenium/webdriver/remote/webdriver.py", line 333, in get
    self.execute(Command.GET, {'url': url})
  File "/home/ubuntu/.local/lib/python3.8/site-packages/selenium/webdriver/remote/webdriver.py", line 321, in execute
    self.error_handler.check_response(response)
  File "/home/ubuntu/.local/lib/python3.8/site-packages/selenium/webdriver/remote/errorhandler.py", line 242, in check_response
    raise exception_class(message, screen, stacktrace)
selenium.common.exceptions.TimeoutException: Message: timeout: Timed out receiving message from renderer: 294.466
  (Session info: headless chrome=87.0.4280.88)

Traceback (most recent call last):
  File "/home/ubuntu/trends-script/scraper.py", line 260, in <module>
    main()
  File "/home/ubuntu/trends-script/scraper.py", line 253, in main
    htmlstring = get_html_from_site()
  File "/home/ubuntu/trends-script/scraper.py", line 28, in get_html_from_site
    driver = webdriver.Chrome(options=options)
  File "/home/ubuntu/.local/lib/python3.8/site-packages/selenium/webdriver/chrome/webdriver.py", line 73, in __init__
    self.service.start()
  File "/home/ubuntu/.local/lib/python3.8/site-packages/selenium/webdriver/common/service.py", line 104, in start
    raise WebDriverException("Can not connect to the Service %s" % self.path)
selenium.common.exceptions.WebDriverException: Message: Can not connect to the Service chromedriver

Traceback (most recent call last):
  File "/home/ubuntu/trends-script/scraper.py", line 260, in <module>
    main()
  File "/home/ubuntu/trends-script/scraper.py", line 253, in main
    htmlstring = get_html_from_site()
  File "/home/ubuntu/trends-script/scraper.py", line 31, in get_html_from_site
    driver.get(start_url)
  File "/home/ubuntu/.local/lib/python3.8/site-packages/selenium/webdriver/remote/webdriver.py", line 333, in get
    self.execute(Command.GET, {'url': url})
  File "/home/ubuntu/.local/lib/python3.8/site-packages/selenium/webdriver/remote/webdriver.py", line 321, in execute
    self.error_handler.check_response(response)
  File "/home/ubuntu/.local/lib/python3.8/site-packages/selenium/webdriver/remote/errorhandler.py", line 242, in check_response
    raise exception_class(message, screen, stacktrace)
selenium.common.exceptions.TimeoutException: Message: timeout: Timed out receiving message from renderer: 294.156
  (Session info: headless chrome=87.0.4280.88)

Traceback (most recent call last):
  File "/home/ubuntu/trends-script/scraper.py", line 260, in <module>
    main()
  File "/home/ubuntu/trends-script/scraper.py", line 253, in main
    htmlstring = get_html_from_site()
  File "/home/ubuntu/trends-script/scraper.py", line 28, in get_html_from_site
    driver = webdriver.Chrome(options=options)
  File "/home/ubuntu/.local/lib/python3.8/site-packages/selenium/webdriver/chrome/webdriver.py", line 73, in __init__
    self.service.start()
  File "/home/ubuntu/.local/lib/python3.8/site-packages/selenium/webdriver/common/service.py", line 104, in start
    raise WebDriverException("Can not connect to the Service %s" % self.path)
selenium.common.exceptions.WebDriverException: Message: Can not connect to the Service chromedriver

Traceback (most recent call last):
  File "/home/ubuntu/trends-script/scraper.py", line 260, in <module>
    main()
  File "/home/ubuntu/trends-script/scraper.py", line 253, in main
    htmlstring = get_html_from_site()
  File "/home/ubuntu/trends-script/scraper.py", line 31, in get_html_from_site
    driver.get(start_url)
  File "/home/ubuntu/.local/lib/python3.8/site-packages/selenium/webdriver/remote/webdriver.py", line 333, in get
    self.execute(Command.GET, {'url': url})
  File "/home/ubuntu/.local/lib/python3.8/site-packages/selenium/webdriver/remote/webdriver.py", line 321, in execute
    self.error_handler.check_response(response)
  File "/home/ubuntu/.local/lib/python3.8/site-packages/selenium/webdriver/remote/errorhandler.py", line 242, in check_response
    raise exception_class(message, screen, stacktrace)
selenium.common.exceptions.TimeoutException: Message: timeout: Timed out receiving message from renderer: 293.727
  (Session info: headless chrome=87.0.4280.88)

Traceback (most recent call last):
  File "/home/ubuntu/trends-script/scraper.py", line 260, in <module>
    main()
  File "/home/ubuntu/trends-script/scraper.py", line 253, in main
    htmlstring = get_html_from_site()
  File "/home/ubuntu/trends-script/scraper.py", line 28, in get_html_from_site
    driver = webdriver.Chrome(options=options)
  File "/home/ubuntu/.local/lib/python3.8/site-packages/selenium/webdriver/chrome/webdriver.py", line 73, in __init__
    self.service.start()
  File "/home/ubuntu/.local/lib/python3.8/site-packages/selenium/webdriver/common/service.py", line 104, in start
    raise WebDriverException("Can not connect to the Service %s" % self.path)
selenium.common.exceptions.WebDriverException: Message: Can not connect to the Service chromedriver

Traceback (most recent call last):
  File "/home/ubuntu/trends-script/scraper.py", line 260, in <module>
    main()
  File "/home/ubuntu/trends-script/scraper.py", line 253, in main
    htmlstring = get_html_from_site()
  File "/home/ubuntu/trends-script/scraper.py", line 31, in get_html_from_site
    driver.get(start_url)
  File "/home/ubuntu/.local/lib/python3.8/site-packages/selenium/webdriver/remote/webdriver.py", line 333, in get
    self.execute(Command.GET, {'url': url})
  File "/home/ubuntu/.local/lib/python3.8/site-packages/selenium/webdriver/remote/webdriver.py", line 321, in execute
    self.error_handler.check_response(response)
  File "/home/ubuntu/.local/lib/python3.8/site-packages/selenium/webdriver/remote/errorhandler.py", line 242, in check_response
    raise exception_class(message, screen, stacktrace)
selenium.common.exceptions.TimeoutException: Message: timeout: Timed out receiving message from renderer: 292.856
  (Session info: headless chrome=87.0.4280.88)

Traceback (most recent call last):
  File "/home/ubuntu/trends-script/scraper.py", line 260, in <module>
    main()
  File "/home/ubuntu/trends-script/scraper.py", line 253, in main
    htmlstring = get_html_from_site()
  File "/home/ubuntu/trends-script/scraper.py", line 28, in get_html_from_site
    driver = webdriver.Chrome(options=options)
  File "/home/ubuntu/.local/lib/python3.8/site-packages/selenium/webdriver/chrome/webdriver.py", line 73, in __init__
    self.service.start()
  File "/home/ubuntu/.local/lib/python3.8/site-packages/selenium/webdriver/common/service.py", line 104, in start
    raise WebDriverException("Can not connect to the Service %s" % self.path)
selenium.common.exceptions.WebDriverException: Message: Can not connect to the Service chromedriver

Traceback (most recent call last):
  File "/home/ubuntu/trends-script/scraper.py", line 260, in <module>
    main()
  File "/home/ubuntu/trends-script/scraper.py", line 253, in main
    htmlstring = get_html_from_site()
  File "/home/ubuntu/trends-script/scraper.py", line 31, in get_html_from_site
    driver.get(start_url)
  File "/home/ubuntu/.local/lib/python3.8/site-packages/selenium/webdriver/remote/webdriver.py", line 333, in get
    self.execute(Command.GET, {'url': url})
  File "/home/ubuntu/.local/lib/python3.8/site-packages/selenium/webdriver/remote/webdriver.py", line 321, in execute
    self.error_handler.check_response(response)
  File "/home/ubuntu/.local/lib/python3.8/site-packages/selenium/webdriver/remote/errorhandler.py", line 242, in check_response
    raise exception_class(message, screen, stacktrace)
selenium.common.exceptions.TimeoutException: Message: timeout: Timed out receiving message from renderer: 292.269
  (Session info: headless chrome=87.0.4280.88)

Traceback (most recent call last):
  File "/home/ubuntu/trends-script/scraper.py", line 260, in <module>
    main()
  File "/home/ubuntu/trends-script/scraper.py", line 253, in main
    htmlstring = get_html_from_site()
  File "/home/ubuntu/trends-script/scraper.py", line 28, in get_html_from_site
    driver = webdriver.Chrome(options=options)
  File "/home/ubuntu/.local/lib/python3.8/site-packages/selenium/webdriver/chrome/webdriver.py", line 73, in __init__
    self.service.start()
  File "/home/ubuntu/.local/lib/python3.8/site-packages/selenium/webdriver/common/service.py", line 104, in start
    raise WebDriverException("Can not connect to the Service %s" % self.path)
selenium.common.exceptions.WebDriverException: Message: Can not connect to the Service chromedriver

Traceback (most recent call last):
  File "/home/ubuntu/trends-script/scraper.py", line 260, in <module>
    main()
  File "/home/ubuntu/trends-script/scraper.py", line 253, in main
    htmlstring = get_html_from_site()
  File "/home/ubuntu/trends-script/scraper.py", line 31, in get_html_from_site
    driver.get(start_url)
  File "/home/ubuntu/.local/lib/python3.8/site-packages/selenium/webdriver/remote/webdriver.py", line 333, in get
    self.execute(Command.GET, {'url': url})
  File "/home/ubuntu/.local/lib/python3.8/site-packages/selenium/webdriver/remote/webdriver.py", line 321, in execute
    self.error_handler.check_response(response)
  File "/home/ubuntu/.local/lib/python3.8/site-packages/selenium/webdriver/remote/errorhandler.py", line 242, in check_response
    raise exception_class(message, screen, stacktrace)
selenium.common.exceptions.TimeoutException: Message: timeout: Timed out receiving message from renderer: 294.159
  (Session info: headless chrome=87.0.4280.88)

Traceback (most recent call last):
  File "/home/ubuntu/trends-script/scraper.py", line 260, in <module>
    main()
  File "/home/ubuntu/trends-script/scraper.py", line 253, in main
    htmlstring = get_html_from_site()
  File "/home/ubuntu/trends-script/scraper.py", line 28, in get_html_from_site
    driver = webdriver.Chrome(options=options)
  File "/home/ubuntu/.local/lib/python3.8/site-packages/selenium/webdriver/chrome/webdriver.py", line 73, in __init__
    self.service.start()
  File "/home/ubuntu/.local/lib/python3.8/site-packages/selenium/webdriver/common/service.py", line 104, in start
    raise WebDriverException("Can not connect to the Service %s" % self.path)
selenium.common.exceptions.WebDriverException: Message: Can not connect to the Service chromedriver

Traceback (most recent call last):
  File "/home/ubuntu/trends-script/scraper.py", line 260, in <module>
    main()
  File "/home/ubuntu/trends-script/scraper.py", line 253, in main
    htmlstring = get_html_from_site()
  File "/home/ubuntu/trends-script/scraper.py", line 31, in get_html_from_site
    driver.get(start_url)
  File "/home/ubuntu/.local/lib/python3.8/site-packages/selenium/webdriver/remote/webdriver.py", line 333, in get
    self.execute(Command.GET, {'url': url})
  File "/home/ubuntu/.local/lib/python3.8/site-packages/selenium/webdriver/remote/webdriver.py", line 321, in execute
    self.error_handler.check_response(response)
  File "/home/ubuntu/.local/lib/python3.8/site-packages/selenium/webdriver/remote/errorhandler.py", line 242, in check_response
    raise exception_class(message, screen, stacktrace)
selenium.common.exceptions.TimeoutException: Message: timeout: Timed out receiving message from renderer: 291.939
  (Session info: headless chrome=87.0.4280.88)

Traceback (most recent call last):
  File "/home/ubuntu/trends-script/scraper.py", line 260, in <module>
    main()
  File "/home/ubuntu/trends-script/scraper.py", line 253, in main
    htmlstring = get_html_from_site()
  File "/home/ubuntu/trends-script/scraper.py", line 28, in get_html_from_site
    driver = webdriver.Chrome(options=options)
  File "/home/ubuntu/.local/lib/python3.8/site-packages/selenium/webdriver/chrome/webdriver.py", line 73, in __init__
    self.service.start()
  File "/home/ubuntu/.local/lib/python3.8/site-packages/selenium/webdriver/common/service.py", line 104, in start
    raise WebDriverException("Can not connect to the Service %s" % self.path)
selenium.common.exceptions.WebDriverException: Message: Can not connect to the Service chromedriver

Traceback (most recent call last):
  File "/home/ubuntu/trends-script/scraper.py", line 260, in <module>
    main()
  File "/home/ubuntu/trends-script/scraper.py", line 253, in main
    htmlstring = get_html_from_site()
  File "/home/ubuntu/trends-script/scraper.py", line 31, in get_html_from_site
    driver.get(start_url)
  File "/home/ubuntu/.local/lib/python3.8/site-packages/selenium/webdriver/remote/webdriver.py", line 333, in get
    self.execute(Command.GET, {'url': url})
  File "/home/ubuntu/.local/lib/python3.8/site-packages/selenium/webdriver/remote/webdriver.py", line 321, in execute
    self.error_handler.check_response(response)
  File "/home/ubuntu/.local/lib/python3.8/site-packages/selenium/webdriver/remote/errorhandler.py", line 242, in check_response
    raise exception_class(message, screen, stacktrace)
selenium.common.exceptions.TimeoutException: Message: timeout: Timed out receiving message from renderer: 293.779
  (Session info: headless chrome=87.0.4280.88)

Traceback (most recent call last):
  File "/home/ubuntu/trends-script/scraper.py", line 260, in <module>
    main()
  File "/home/ubuntu/trends-script/scraper.py", line 253, in main
    htmlstring = get_html_from_site()
  File "/home/ubuntu/trends-script/scraper.py", line 28, in get_html_from_site
    driver = webdriver.Chrome(options=options)
  File "/home/ubuntu/.local/lib/python3.8/site-packages/selenium/webdriver/chrome/webdriver.py", line 73, in __init__
    self.service.start()
  File "/home/ubuntu/.local/lib/python3.8/site-packages/selenium/webdriver/common/service.py", line 104, in start
    raise WebDriverException("Can not connect to the Service %s" % self.path)
selenium.common.exceptions.WebDriverException: Message: Can not connect to the Service chromedriver

Traceback (most recent call last):
  File "/home/ubuntu/trends-script/scraper.py", line 260, in <module>
    main()
  File "/home/ubuntu/trends-script/scraper.py", line 253, in main
    htmlstring = get_html_from_site()
  File "/home/ubuntu/trends-script/scraper.py", line 31, in get_html_from_site
    driver.get(start_url)
  File "/home/ubuntu/.local/lib/python3.8/site-packages/selenium/webdriver/remote/webdriver.py", line 333, in get
    self.execute(Command.GET, {'url': url})
  File "/home/ubuntu/.local/lib/python3.8/site-packages/selenium/webdriver/remote/webdriver.py", line 321, in execute
    self.error_handler.check_response(response)
  File "/home/ubuntu/.local/lib/python3.8/site-packages/selenium/webdriver/remote/errorhandler.py", line 242, in check_response
    raise exception_class(message, screen, stacktrace)
selenium.common.exceptions.TimeoutException: Message: timeout: Timed out receiving message from renderer: 293.146
  (Session info: headless chrome=87.0.4280.88)

Traceback (most recent call last):
  File "/home/ubuntu/trends-script/scraper.py", line 260, in <module>
    main()
  File "/home/ubuntu/trends-script/scraper.py", line 253, in main
    htmlstring = get_html_from_site()
  File "/home/ubuntu/trends-script/scraper.py", line 28, in get_html_from_site
    driver = webdriver.Chrome(options=options)
  File "/home/ubuntu/.local/lib/python3.8/site-packages/selenium/webdriver/chrome/webdriver.py", line 73, in __init__
    self.service.start()
  File "/home/ubuntu/.local/lib/python3.8/site-packages/selenium/webdriver/common/service.py", line 104, in start
    raise WebDriverException("Can not connect to the Service %s" % self.path)
selenium.common.exceptions.WebDriverException: Message: Can not connect to the Service chromedriver

Traceback (most recent call last):
  File "/home/ubuntu/trends-script/scraper.py", line 260, in <module>
    main()
  File "/home/ubuntu/trends-script/scraper.py", line 253, in main
    htmlstring = get_html_from_site()
  File "/home/ubuntu/trends-script/scraper.py", line 31, in get_html_from_site
    driver.get(start_url)
  File "/home/ubuntu/.local/lib/python3.8/site-packages/selenium/webdriver/remote/webdriver.py", line 333, in get
    self.execute(Command.GET, {'url': url})
  File "/home/ubuntu/.local/lib/python3.8/site-packages/selenium/webdriver/remote/webdriver.py", line 321, in execute
    self.error_handler.check_response(response)
  File "/home/ubuntu/.local/lib/python3.8/site-packages/selenium/webdriver/remote/errorhandler.py", line 242, in check_response
    raise exception_class(message, screen, stacktrace)
selenium.common.exceptions.TimeoutException: Message: timeout: Timed out receiving message from renderer: 292.576
  (Session info: headless chrome=87.0.4280.88)

Traceback (most recent call last):
  File "/home/ubuntu/trends-script/scraper.py", line 260, in <module>
    main()
  File "/home/ubuntu/trends-script/scraper.py", line 253, in main
    htmlstring = get_html_from_site()
  File "/home/ubuntu/trends-script/scraper.py", line 28, in get_html_from_site
    driver = webdriver.Chrome(options=options)
  File "/home/ubuntu/.local/lib/python3.8/site-packages/selenium/webdriver/chrome/webdriver.py", line 73, in __init__
    self.service.start()
  File "/home/ubuntu/.local/lib/python3.8/site-packages/selenium/webdriver/common/service.py", line 104, in start
    raise WebDriverException("Can not connect to the Service %s" % self.path)
selenium.common.exceptions.WebDriverException: Message: Can not connect to the Service chromedriver

Traceback (most recent call last):
  File "/home/ubuntu/trends-script/scraper.py", line 260, in <module>
    main()
  File "/home/ubuntu/trends-script/scraper.py", line 253, in main
    htmlstring = get_html_from_site()
  File "/home/ubuntu/trends-script/scraper.py", line 31, in get_html_from_site
    driver.get(start_url)
  File "/home/ubuntu/.local/lib/python3.8/site-packages/selenium/webdriver/remote/webdriver.py", line 333, in get
    self.execute(Command.GET, {'url': url})
  File "/home/ubuntu/.local/lib/python3.8/site-packages/selenium/webdriver/remote/webdriver.py", line 321, in execute
    self.error_handler.check_response(response)
  File "/home/ubuntu/.local/lib/python3.8/site-packages/selenium/webdriver/remote/errorhandler.py", line 242, in check_response
    raise exception_class(message, screen, stacktrace)
selenium.common.exceptions.TimeoutException: Message: timeout: Timed out receiving message from renderer: 293.678
  (Session info: headless chrome=87.0.4280.88)

Traceback (most recent call last):
  File "/home/ubuntu/trends-script/scraper.py", line 260, in <module>
    main()
  File "/home/ubuntu/trends-script/scraper.py", line 253, in main
    htmlstring = get_html_from_site()
  File "/home/ubuntu/trends-script/scraper.py", line 28, in get_html_from_site
    driver = webdriver.Chrome(options=options)
  File "/home/ubuntu/.local/lib/python3.8/site-packages/selenium/webdriver/chrome/webdriver.py", line 73, in __init__
    self.service.start()
  File "/home/ubuntu/.local/lib/python3.8/site-packages/selenium/webdriver/common/service.py", line 104, in start
    raise WebDriverException("Can not connect to the Service %s" % self.path)
selenium.common.exceptions.WebDriverException: Message: Can not connect to the Service chromedriver

Traceback (most recent call last):
  File "/home/ubuntu/trends-script/scraper.py", line 260, in <module>
    main()
  File "/home/ubuntu/trends-script/scraper.py", line 253, in main
    htmlstring = get_html_from_site()
  File "/home/ubuntu/trends-script/scraper.py", line 31, in get_html_from_site
    driver.get(start_url)
  File "/home/ubuntu/.local/lib/python3.8/site-packages/selenium/webdriver/remote/webdriver.py", line 333, in get
    self.execute(Command.GET, {'url': url})
  File "/home/ubuntu/.local/lib/python3.8/site-packages/selenium/webdriver/remote/webdriver.py", line 321, in execute
    self.error_handler.check_response(response)
  File "/home/ubuntu/.local/lib/python3.8/site-packages/selenium/webdriver/remote/errorhandler.py", line 242, in check_response
    raise exception_class(message, screen, stacktrace)
selenium.common.exceptions.TimeoutException: Message: timeout: Timed out receiving message from renderer: 292.381
  (Session info: headless chrome=87.0.4280.88)

