Traceback (most recent call last):
  File "/home/ubuntu/trends-script/scraper.py", line 260, in <module>
    main()
  File "/home/ubuntu/trends-script/scraper.py", line 253, in main
    htmlstring = get_html_from_site()
  File "/home/ubuntu/trends-script/scraper.py", line 28, in get_html_from_site
    driver = webdriver.Chrome(options=options)
  File "/home/ubuntu/.local/lib/python3.8/site-packages/selenium/webdriver/chrome/webdriver.py", line 73, in __init__
    self.service.start()
  File "/home/ubuntu/.local/lib/python3.8/site-packages/selenium/webdriver/common/service.py", line 104, in start
    raise WebDriverException("Can not connect to the Service %s" % self.path)
selenium.common.exceptions.WebDriverException: Message: Can not connect to the Service chromedriver

Traceback (most recent call last):
  File "/home/ubuntu/trends-script/scraper.py", line 260, in <module>
    main()
  File "/home/ubuntu/trends-script/scraper.py", line 253, in main
    htmlstring = get_html_from_site()
  File "/home/ubuntu/trends-script/scraper.py", line 31, in get_html_from_site
    driver.get(start_url)
  File "/home/ubuntu/.local/lib/python3.8/site-packages/selenium/webdriver/remote/webdriver.py", line 333, in get
    self.execute(Command.GET, {'url': url})
  File "/home/ubuntu/.local/lib/python3.8/site-packages/selenium/webdriver/remote/webdriver.py", line 321, in execute
    self.error_handler.check_response(response)
  File "/home/ubuntu/.local/lib/python3.8/site-packages/selenium/webdriver/remote/errorhandler.py", line 242, in check_response
    raise exception_class(message, screen, stacktrace)
selenium.common.exceptions.TimeoutException: Message: timeout: Timed out receiving message from renderer: 287.364
  (Session info: headless chrome=87.0.4280.88)

Traceback (most recent call last):
  File "/home/ubuntu/trends-script/scraper.py", line 260, in <module>
    main()
  File "/home/ubuntu/trends-script/scraper.py", line 253, in main
    htmlstring = get_html_from_site()
  File "/home/ubuntu/trends-script/scraper.py", line 28, in get_html_from_site
    driver = webdriver.Chrome(options=options)
  File "/home/ubuntu/.local/lib/python3.8/site-packages/selenium/webdriver/chrome/webdriver.py", line 73, in __init__
    self.service.start()
  File "/home/ubuntu/.local/lib/python3.8/site-packages/selenium/webdriver/common/service.py", line 104, in start
    raise WebDriverException("Can not connect to the Service %s" % self.path)
selenium.common.exceptions.WebDriverException: Message: Can not connect to the Service chromedriver

Traceback (most recent call last):
  File "/home/ubuntu/trends-script/scraper.py", line 260, in <module>
    main()
  File "/home/ubuntu/trends-script/scraper.py", line 253, in main
    htmlstring = get_html_from_site()
  File "/home/ubuntu/trends-script/scraper.py", line 31, in get_html_from_site
    driver.get(start_url)
  File "/home/ubuntu/.local/lib/python3.8/site-packages/selenium/webdriver/remote/webdriver.py", line 333, in get
    self.execute(Command.GET, {'url': url})
  File "/home/ubuntu/.local/lib/python3.8/site-packages/selenium/webdriver/remote/webdriver.py", line 321, in execute
    self.error_handler.check_response(response)
  File "/home/ubuntu/.local/lib/python3.8/site-packages/selenium/webdriver/remote/errorhandler.py", line 242, in check_response
    raise exception_class(message, screen, stacktrace)
selenium.common.exceptions.TimeoutException: Message: timeout: Timed out receiving message from renderer: 286.459
  (Session info: headless chrome=87.0.4280.88)

Traceback (most recent call last):
  File "/home/ubuntu/trends-script/scraper.py", line 260, in <module>
    main()
  File "/home/ubuntu/trends-script/scraper.py", line 253, in main
    htmlstring = get_html_from_site()
  File "/home/ubuntu/trends-script/scraper.py", line 28, in get_html_from_site
    driver = webdriver.Chrome(options=options)
  File "/home/ubuntu/.local/lib/python3.8/site-packages/selenium/webdriver/chrome/webdriver.py", line 73, in __init__
    self.service.start()
  File "/home/ubuntu/.local/lib/python3.8/site-packages/selenium/webdriver/common/service.py", line 104, in start
    raise WebDriverException("Can not connect to the Service %s" % self.path)
selenium.common.exceptions.WebDriverException: Message: Can not connect to the Service chromedriver

Traceback (most recent call last):
  File "/home/ubuntu/trends-script/scraper.py", line 260, in <module>
    main()
  File "/home/ubuntu/trends-script/scraper.py", line 253, in main
    htmlstring = get_html_from_site()
  File "/home/ubuntu/trends-script/scraper.py", line 31, in get_html_from_site
    driver.get(start_url)
  File "/home/ubuntu/.local/lib/python3.8/site-packages/selenium/webdriver/remote/webdriver.py", line 333, in get
    self.execute(Command.GET, {'url': url})
  File "/home/ubuntu/.local/lib/python3.8/site-packages/selenium/webdriver/remote/webdriver.py", line 321, in execute
    self.error_handler.check_response(response)
  File "/home/ubuntu/.local/lib/python3.8/site-packages/selenium/webdriver/remote/errorhandler.py", line 242, in check_response
    raise exception_class(message, screen, stacktrace)
selenium.common.exceptions.TimeoutException: Message: timeout: Timed out receiving message from renderer: 287.254
  (Session info: headless chrome=87.0.4280.88)

Traceback (most recent call last):
  File "/home/ubuntu/trends-script/scraper.py", line 260, in <module>
    main()
  File "/home/ubuntu/trends-script/scraper.py", line 253, in main
    htmlstring = get_html_from_site()
  File "/home/ubuntu/trends-script/scraper.py", line 28, in get_html_from_site
    driver = webdriver.Chrome(options=options)
  File "/home/ubuntu/.local/lib/python3.8/site-packages/selenium/webdriver/chrome/webdriver.py", line 73, in __init__
    self.service.start()
  File "/home/ubuntu/.local/lib/python3.8/site-packages/selenium/webdriver/common/service.py", line 104, in start
    raise WebDriverException("Can not connect to the Service %s" % self.path)
selenium.common.exceptions.WebDriverException: Message: Can not connect to the Service chromedriver

Traceback (most recent call last):
  File "/home/ubuntu/trends-script/scraper.py", line 260, in <module>
    main()
  File "/home/ubuntu/trends-script/scraper.py", line 253, in main
    htmlstring = get_html_from_site()
  File "/home/ubuntu/trends-script/scraper.py", line 31, in get_html_from_site
    driver.get(start_url)
  File "/home/ubuntu/.local/lib/python3.8/site-packages/selenium/webdriver/remote/webdriver.py", line 333, in get
    self.execute(Command.GET, {'url': url})
  File "/home/ubuntu/.local/lib/python3.8/site-packages/selenium/webdriver/remote/webdriver.py", line 321, in execute
    self.error_handler.check_response(response)
  File "/home/ubuntu/.local/lib/python3.8/site-packages/selenium/webdriver/remote/errorhandler.py", line 242, in check_response
    raise exception_class(message, screen, stacktrace)
selenium.common.exceptions.TimeoutException: Message: timeout: Timed out receiving message from renderer: 288.518
  (Session info: headless chrome=87.0.4280.88)

Traceback (most recent call last):
  File "/home/ubuntu/trends-script/scraper.py", line 260, in <module>
    main()
  File "/home/ubuntu/trends-script/scraper.py", line 253, in main
    htmlstring = get_html_from_site()
  File "/home/ubuntu/trends-script/scraper.py", line 28, in get_html_from_site
    driver = webdriver.Chrome(options=options)
  File "/home/ubuntu/.local/lib/python3.8/site-packages/selenium/webdriver/chrome/webdriver.py", line 73, in __init__
    self.service.start()
  File "/home/ubuntu/.local/lib/python3.8/site-packages/selenium/webdriver/common/service.py", line 104, in start
    raise WebDriverException("Can not connect to the Service %s" % self.path)
selenium.common.exceptions.WebDriverException: Message: Can not connect to the Service chromedriver

Traceback (most recent call last):
  File "/home/ubuntu/trends-script/scraper.py", line 260, in <module>
    main()
  File "/home/ubuntu/trends-script/scraper.py", line 253, in main
    htmlstring = get_html_from_site()
  File "/home/ubuntu/trends-script/scraper.py", line 31, in get_html_from_site
    driver.get(start_url)
  File "/home/ubuntu/.local/lib/python3.8/site-packages/selenium/webdriver/remote/webdriver.py", line 333, in get
    self.execute(Command.GET, {'url': url})
  File "/home/ubuntu/.local/lib/python3.8/site-packages/selenium/webdriver/remote/webdriver.py", line 321, in execute
    self.error_handler.check_response(response)
  File "/home/ubuntu/.local/lib/python3.8/site-packages/selenium/webdriver/remote/errorhandler.py", line 242, in check_response
    raise exception_class(message, screen, stacktrace)
selenium.common.exceptions.TimeoutException: Message: timeout: Timed out receiving message from renderer: 287.060
  (Session info: headless chrome=87.0.4280.88)

Traceback (most recent call last):
  File "/home/ubuntu/trends-script/scraper.py", line 260, in <module>
    main()
  File "/home/ubuntu/trends-script/scraper.py", line 253, in main
    htmlstring = get_html_from_site()
  File "/home/ubuntu/trends-script/scraper.py", line 28, in get_html_from_site
    driver = webdriver.Chrome(options=options)
  File "/home/ubuntu/.local/lib/python3.8/site-packages/selenium/webdriver/chrome/webdriver.py", line 73, in __init__
    self.service.start()
  File "/home/ubuntu/.local/lib/python3.8/site-packages/selenium/webdriver/common/service.py", line 104, in start
    raise WebDriverException("Can not connect to the Service %s" % self.path)
selenium.common.exceptions.WebDriverException: Message: Can not connect to the Service chromedriver

Traceback (most recent call last):
  File "/home/ubuntu/trends-script/scraper.py", line 260, in <module>
    main()
  File "/home/ubuntu/trends-script/scraper.py", line 253, in main
    htmlstring = get_html_from_site()
  File "/home/ubuntu/trends-script/scraper.py", line 31, in get_html_from_site
    driver.get(start_url)
  File "/home/ubuntu/.local/lib/python3.8/site-packages/selenium/webdriver/remote/webdriver.py", line 333, in get
    self.execute(Command.GET, {'url': url})
  File "/home/ubuntu/.local/lib/python3.8/site-packages/selenium/webdriver/remote/webdriver.py", line 321, in execute
    self.error_handler.check_response(response)
  File "/home/ubuntu/.local/lib/python3.8/site-packages/selenium/webdriver/remote/errorhandler.py", line 242, in check_response
    raise exception_class(message, screen, stacktrace)
selenium.common.exceptions.TimeoutException: Message: timeout: Timed out receiving message from renderer: 287.031
  (Session info: headless chrome=87.0.4280.88)

Traceback (most recent call last):
  File "/home/ubuntu/trends-script/scraper.py", line 260, in <module>
    main()
  File "/home/ubuntu/trends-script/scraper.py", line 253, in main
    htmlstring = get_html_from_site()
  File "/home/ubuntu/trends-script/scraper.py", line 28, in get_html_from_site
    driver = webdriver.Chrome(options=options)
  File "/home/ubuntu/.local/lib/python3.8/site-packages/selenium/webdriver/chrome/webdriver.py", line 73, in __init__
    self.service.start()
  File "/home/ubuntu/.local/lib/python3.8/site-packages/selenium/webdriver/common/service.py", line 104, in start
    raise WebDriverException("Can not connect to the Service %s" % self.path)
selenium.common.exceptions.WebDriverException: Message: Can not connect to the Service chromedriver

Traceback (most recent call last):
  File "/home/ubuntu/trends-script/scraper.py", line 260, in <module>
    main()
  File "/home/ubuntu/trends-script/scraper.py", line 253, in main
    htmlstring = get_html_from_site()
  File "/home/ubuntu/trends-script/scraper.py", line 31, in get_html_from_site
    driver.get(start_url)
  File "/home/ubuntu/.local/lib/python3.8/site-packages/selenium/webdriver/remote/webdriver.py", line 333, in get
    self.execute(Command.GET, {'url': url})
  File "/home/ubuntu/.local/lib/python3.8/site-packages/selenium/webdriver/remote/webdriver.py", line 321, in execute
    self.error_handler.check_response(response)
  File "/home/ubuntu/.local/lib/python3.8/site-packages/selenium/webdriver/remote/errorhandler.py", line 242, in check_response
    raise exception_class(message, screen, stacktrace)
selenium.common.exceptions.TimeoutException: Message: timeout: Timed out receiving message from renderer: 277.026
  (Session info: headless chrome=87.0.4280.88)

Traceback (most recent call last):
  File "/home/ubuntu/trends-script/scraper.py", line 260, in <module>
    main()
  File "/home/ubuntu/trends-script/scraper.py", line 253, in main
    htmlstring = get_html_from_site()
  File "/home/ubuntu/trends-script/scraper.py", line 28, in get_html_from_site
    driver = webdriver.Chrome(options=options)
  File "/home/ubuntu/.local/lib/python3.8/site-packages/selenium/webdriver/chrome/webdriver.py", line 73, in __init__
    self.service.start()
  File "/home/ubuntu/.local/lib/python3.8/site-packages/selenium/webdriver/common/service.py", line 104, in start
    raise WebDriverException("Can not connect to the Service %s" % self.path)
selenium.common.exceptions.WebDriverException: Message: Can not connect to the Service chromedriver

Traceback (most recent call last):
  File "/home/ubuntu/trends-script/scraper.py", line 260, in <module>
    main()
  File "/home/ubuntu/trends-script/scraper.py", line 253, in main
    htmlstring = get_html_from_site()
  File "/home/ubuntu/trends-script/scraper.py", line 31, in get_html_from_site
    driver.get(start_url)
  File "/home/ubuntu/.local/lib/python3.8/site-packages/selenium/webdriver/remote/webdriver.py", line 333, in get
    self.execute(Command.GET, {'url': url})
  File "/home/ubuntu/.local/lib/python3.8/site-packages/selenium/webdriver/remote/webdriver.py", line 321, in execute
    self.error_handler.check_response(response)
  File "/home/ubuntu/.local/lib/python3.8/site-packages/selenium/webdriver/remote/errorhandler.py", line 242, in check_response
    raise exception_class(message, screen, stacktrace)
selenium.common.exceptions.TimeoutException: Message: timeout: Timed out receiving message from renderer: 284.117
  (Session info: headless chrome=87.0.4280.88)

Traceback (most recent call last):
  File "/home/ubuntu/trends-script/scraper.py", line 260, in <module>
    main()
  File "/home/ubuntu/trends-script/scraper.py", line 253, in main
    htmlstring = get_html_from_site()
  File "/home/ubuntu/trends-script/scraper.py", line 28, in get_html_from_site
    driver = webdriver.Chrome(options=options)
  File "/home/ubuntu/.local/lib/python3.8/site-packages/selenium/webdriver/chrome/webdriver.py", line 73, in __init__
    self.service.start()
  File "/home/ubuntu/.local/lib/python3.8/site-packages/selenium/webdriver/common/service.py", line 104, in start
    raise WebDriverException("Can not connect to the Service %s" % self.path)
selenium.common.exceptions.WebDriverException: Message: Can not connect to the Service chromedriver

Traceback (most recent call last):
  File "/home/ubuntu/trends-script/scraper.py", line 260, in <module>
    main()
  File "/home/ubuntu/trends-script/scraper.py", line 253, in main
    htmlstring = get_html_from_site()
  File "/home/ubuntu/trends-script/scraper.py", line 31, in get_html_from_site
    driver.get(start_url)
  File "/home/ubuntu/.local/lib/python3.8/site-packages/selenium/webdriver/remote/webdriver.py", line 333, in get
    self.execute(Command.GET, {'url': url})
  File "/home/ubuntu/.local/lib/python3.8/site-packages/selenium/webdriver/remote/webdriver.py", line 321, in execute
    self.error_handler.check_response(response)
  File "/home/ubuntu/.local/lib/python3.8/site-packages/selenium/webdriver/remote/errorhandler.py", line 242, in check_response
    raise exception_class(message, screen, stacktrace)
selenium.common.exceptions.TimeoutException: Message: timeout: Timed out receiving message from renderer: 286.752
  (Session info: headless chrome=87.0.4280.88)

Traceback (most recent call last):
  File "/home/ubuntu/trends-script/scraper.py", line 260, in <module>
    main()
  File "/home/ubuntu/trends-script/scraper.py", line 253, in main
    htmlstring = get_html_from_site()
  File "/home/ubuntu/trends-script/scraper.py", line 28, in get_html_from_site
    driver = webdriver.Chrome(options=options)
  File "/home/ubuntu/.local/lib/python3.8/site-packages/selenium/webdriver/chrome/webdriver.py", line 73, in __init__
    self.service.start()
  File "/home/ubuntu/.local/lib/python3.8/site-packages/selenium/webdriver/common/service.py", line 104, in start
    raise WebDriverException("Can not connect to the Service %s" % self.path)
selenium.common.exceptions.WebDriverException: Message: Can not connect to the Service chromedriver

Traceback (most recent call last):
  File "/home/ubuntu/trends-script/scraper.py", line 260, in <module>
    main()
  File "/home/ubuntu/trends-script/scraper.py", line 253, in main
    htmlstring = get_html_from_site()
  File "/home/ubuntu/trends-script/scraper.py", line 31, in get_html_from_site
    driver.get(start_url)
  File "/home/ubuntu/.local/lib/python3.8/site-packages/selenium/webdriver/remote/webdriver.py", line 333, in get
    self.execute(Command.GET, {'url': url})
  File "/home/ubuntu/.local/lib/python3.8/site-packages/selenium/webdriver/remote/webdriver.py", line 321, in execute
    self.error_handler.check_response(response)
  File "/home/ubuntu/.local/lib/python3.8/site-packages/selenium/webdriver/remote/errorhandler.py", line 242, in check_response
    raise exception_class(message, screen, stacktrace)
selenium.common.exceptions.TimeoutException: Message: timeout: Timed out receiving message from renderer: 287.137
  (Session info: headless chrome=87.0.4280.88)

Traceback (most recent call last):
  File "/home/ubuntu/trends-script/scraper.py", line 260, in <module>
    main()
  File "/home/ubuntu/trends-script/scraper.py", line 253, in main
    htmlstring = get_html_from_site()
  File "/home/ubuntu/trends-script/scraper.py", line 28, in get_html_from_site
    driver = webdriver.Chrome(options=options)
  File "/home/ubuntu/.local/lib/python3.8/site-packages/selenium/webdriver/chrome/webdriver.py", line 73, in __init__
    self.service.start()
  File "/home/ubuntu/.local/lib/python3.8/site-packages/selenium/webdriver/common/service.py", line 104, in start
    raise WebDriverException("Can not connect to the Service %s" % self.path)
selenium.common.exceptions.WebDriverException: Message: Can not connect to the Service chromedriver

Traceback (most recent call last):
  File "/home/ubuntu/trends-script/scraper.py", line 260, in <module>
    main()
  File "/home/ubuntu/trends-script/scraper.py", line 253, in main
    htmlstring = get_html_from_site()
  File "/home/ubuntu/trends-script/scraper.py", line 31, in get_html_from_site
    driver.get(start_url)
  File "/home/ubuntu/.local/lib/python3.8/site-packages/selenium/webdriver/remote/webdriver.py", line 333, in get
    self.execute(Command.GET, {'url': url})
  File "/home/ubuntu/.local/lib/python3.8/site-packages/selenium/webdriver/remote/webdriver.py", line 321, in execute
    self.error_handler.check_response(response)
  File "/home/ubuntu/.local/lib/python3.8/site-packages/selenium/webdriver/remote/errorhandler.py", line 242, in check_response
    raise exception_class(message, screen, stacktrace)
selenium.common.exceptions.TimeoutException: Message: timeout: Timed out receiving message from renderer: 287.672
  (Session info: headless chrome=87.0.4280.88)

Traceback (most recent call last):
  File "/home/ubuntu/trends-script/scraper.py", line 260, in <module>
    main()
  File "/home/ubuntu/trends-script/scraper.py", line 253, in main
    htmlstring = get_html_from_site()
  File "/home/ubuntu/trends-script/scraper.py", line 28, in get_html_from_site
    driver = webdriver.Chrome(options=options)
  File "/home/ubuntu/.local/lib/python3.8/site-packages/selenium/webdriver/chrome/webdriver.py", line 73, in __init__
    self.service.start()
  File "/home/ubuntu/.local/lib/python3.8/site-packages/selenium/webdriver/common/service.py", line 104, in start
    raise WebDriverException("Can not connect to the Service %s" % self.path)
selenium.common.exceptions.WebDriverException: Message: Can not connect to the Service chromedriver

Traceback (most recent call last):
  File "/home/ubuntu/trends-script/scraper.py", line 260, in <module>
    main()
  File "/home/ubuntu/trends-script/scraper.py", line 253, in main
    htmlstring = get_html_from_site()
  File "/home/ubuntu/trends-script/scraper.py", line 31, in get_html_from_site
    driver.get(start_url)
  File "/home/ubuntu/.local/lib/python3.8/site-packages/selenium/webdriver/remote/webdriver.py", line 333, in get
    self.execute(Command.GET, {'url': url})
  File "/home/ubuntu/.local/lib/python3.8/site-packages/selenium/webdriver/remote/webdriver.py", line 321, in execute
    self.error_handler.check_response(response)
  File "/home/ubuntu/.local/lib/python3.8/site-packages/selenium/webdriver/remote/errorhandler.py", line 242, in check_response
    raise exception_class(message, screen, stacktrace)
selenium.common.exceptions.TimeoutException: Message: timeout: Timed out receiving message from renderer: 287.305
  (Session info: headless chrome=87.0.4280.88)

Traceback (most recent call last):
  File "/home/ubuntu/trends-script/scraper.py", line 260, in <module>
    main()
  File "/home/ubuntu/trends-script/scraper.py", line 253, in main
    htmlstring = get_html_from_site()
  File "/home/ubuntu/trends-script/scraper.py", line 28, in get_html_from_site
    driver = webdriver.Chrome(options=options)
  File "/home/ubuntu/.local/lib/python3.8/site-packages/selenium/webdriver/chrome/webdriver.py", line 73, in __init__
    self.service.start()
  File "/home/ubuntu/.local/lib/python3.8/site-packages/selenium/webdriver/common/service.py", line 104, in start
    raise WebDriverException("Can not connect to the Service %s" % self.path)
selenium.common.exceptions.WebDriverException: Message: Can not connect to the Service chromedriver

Traceback (most recent call last):
  File "/home/ubuntu/trends-script/scraper.py", line 260, in <module>
    main()
  File "/home/ubuntu/trends-script/scraper.py", line 253, in main
    htmlstring = get_html_from_site()
  File "/home/ubuntu/trends-script/scraper.py", line 31, in get_html_from_site
    driver.get(start_url)
  File "/home/ubuntu/.local/lib/python3.8/site-packages/selenium/webdriver/remote/webdriver.py", line 333, in get
    self.execute(Command.GET, {'url': url})
  File "/home/ubuntu/.local/lib/python3.8/site-packages/selenium/webdriver/remote/webdriver.py", line 321, in execute
    self.error_handler.check_response(response)
  File "/home/ubuntu/.local/lib/python3.8/site-packages/selenium/webdriver/remote/errorhandler.py", line 242, in check_response
    raise exception_class(message, screen, stacktrace)
selenium.common.exceptions.TimeoutException: Message: timeout: Timed out receiving message from renderer: 287.213
  (Session info: headless chrome=87.0.4280.88)

Traceback (most recent call last):
  File "/home/ubuntu/trends-script/scraper.py", line 260, in <module>
    main()
  File "/home/ubuntu/trends-script/scraper.py", line 253, in main
    htmlstring = get_html_from_site()
  File "/home/ubuntu/trends-script/scraper.py", line 28, in get_html_from_site
    driver = webdriver.Chrome(options=options)
  File "/home/ubuntu/.local/lib/python3.8/site-packages/selenium/webdriver/chrome/webdriver.py", line 73, in __init__
    self.service.start()
  File "/home/ubuntu/.local/lib/python3.8/site-packages/selenium/webdriver/common/service.py", line 104, in start
    raise WebDriverException("Can not connect to the Service %s" % self.path)
selenium.common.exceptions.WebDriverException: Message: Can not connect to the Service chromedriver

Traceback (most recent call last):
  File "/home/ubuntu/trends-script/scraper.py", line 260, in <module>
    main()
  File "/home/ubuntu/trends-script/scraper.py", line 253, in main
    htmlstring = get_html_from_site()
  File "/home/ubuntu/trends-script/scraper.py", line 31, in get_html_from_site
    driver.get(start_url)
  File "/home/ubuntu/.local/lib/python3.8/site-packages/selenium/webdriver/remote/webdriver.py", line 333, in get
    self.execute(Command.GET, {'url': url})
  File "/home/ubuntu/.local/lib/python3.8/site-packages/selenium/webdriver/remote/webdriver.py", line 321, in execute
    self.error_handler.check_response(response)
  File "/home/ubuntu/.local/lib/python3.8/site-packages/selenium/webdriver/remote/errorhandler.py", line 242, in check_response
    raise exception_class(message, screen, stacktrace)
selenium.common.exceptions.TimeoutException: Message: timeout: Timed out receiving message from renderer: 284.578
  (Session info: headless chrome=87.0.4280.88)

Traceback (most recent call last):
  File "/home/ubuntu/trends-script/scraper.py", line 260, in <module>
    main()
  File "/home/ubuntu/trends-script/scraper.py", line 253, in main
    htmlstring = get_html_from_site()
  File "/home/ubuntu/trends-script/scraper.py", line 31, in get_html_from_site
    driver.get(start_url)
  File "/home/ubuntu/.local/lib/python3.8/site-packages/selenium/webdriver/remote/webdriver.py", line 333, in get
    self.execute(Command.GET, {'url': url})
  File "/home/ubuntu/.local/lib/python3.8/site-packages/selenium/webdriver/remote/webdriver.py", line 321, in execute
    self.error_handler.check_response(response)
  File "/home/ubuntu/.local/lib/python3.8/site-packages/selenium/webdriver/remote/errorhandler.py", line 242, in check_response
    raise exception_class(message, screen, stacktrace)
selenium.common.exceptions.WebDriverException: Message: unknown error: net::ERR_CONNECTION_CLOSED
  (Session info: headless chrome=87.0.4280.88)

Traceback (most recent call last):
  File "/home/ubuntu/trends-script/scraper.py", line 260, in <module>
    main()
  File "/home/ubuntu/trends-script/scraper.py", line 253, in main
    htmlstring = get_html_from_site()
  File "/home/ubuntu/trends-script/scraper.py", line 28, in get_html_from_site
    driver = webdriver.Chrome(options=options)
  File "/home/ubuntu/.local/lib/python3.8/site-packages/selenium/webdriver/chrome/webdriver.py", line 73, in __init__
    self.service.start()
  File "/home/ubuntu/.local/lib/python3.8/site-packages/selenium/webdriver/common/service.py", line 104, in start
    raise WebDriverException("Can not connect to the Service %s" % self.path)
selenium.common.exceptions.WebDriverException: Message: Can not connect to the Service chromedriver

Traceback (most recent call last):
  File "/home/ubuntu/trends-script/scraper.py", line 260, in <module>
    main()
  File "/home/ubuntu/trends-script/scraper.py", line 253, in main
    htmlstring = get_html_from_site()
  File "/home/ubuntu/trends-script/scraper.py", line 31, in get_html_from_site
    driver.get(start_url)
  File "/home/ubuntu/.local/lib/python3.8/site-packages/selenium/webdriver/remote/webdriver.py", line 333, in get
    self.execute(Command.GET, {'url': url})
  File "/home/ubuntu/.local/lib/python3.8/site-packages/selenium/webdriver/remote/webdriver.py", line 321, in execute
    self.error_handler.check_response(response)
  File "/home/ubuntu/.local/lib/python3.8/site-packages/selenium/webdriver/remote/errorhandler.py", line 242, in check_response
    raise exception_class(message, screen, stacktrace)
selenium.common.exceptions.TimeoutException: Message: timeout: Timed out receiving message from renderer: 285.603
  (Session info: headless chrome=87.0.4280.88)

Traceback (most recent call last):
  File "/home/ubuntu/trends-script/scraper.py", line 260, in <module>
    main()
  File "/home/ubuntu/trends-script/scraper.py", line 253, in main
    htmlstring = get_html_from_site()
  File "/home/ubuntu/trends-script/scraper.py", line 28, in get_html_from_site
    driver = webdriver.Chrome(options=options)
  File "/home/ubuntu/.local/lib/python3.8/site-packages/selenium/webdriver/chrome/webdriver.py", line 73, in __init__
    self.service.start()
  File "/home/ubuntu/.local/lib/python3.8/site-packages/selenium/webdriver/common/service.py", line 104, in start
    raise WebDriverException("Can not connect to the Service %s" % self.path)
selenium.common.exceptions.WebDriverException: Message: Can not connect to the Service chromedriver

Traceback (most recent call last):
  File "/home/ubuntu/trends-script/scraper.py", line 260, in <module>
    main()
  File "/home/ubuntu/trends-script/scraper.py", line 253, in main
    htmlstring = get_html_from_site()
  File "/home/ubuntu/trends-script/scraper.py", line 31, in get_html_from_site
    driver.get(start_url)
  File "/home/ubuntu/.local/lib/python3.8/site-packages/selenium/webdriver/remote/webdriver.py", line 333, in get
    self.execute(Command.GET, {'url': url})
  File "/home/ubuntu/.local/lib/python3.8/site-packages/selenium/webdriver/remote/webdriver.py", line 321, in execute
    self.error_handler.check_response(response)
  File "/home/ubuntu/.local/lib/python3.8/site-packages/selenium/webdriver/remote/errorhandler.py", line 242, in check_response
    raise exception_class(message, screen, stacktrace)
selenium.common.exceptions.TimeoutException: Message: timeout: Timed out receiving message from renderer: 287.979
  (Session info: headless chrome=87.0.4280.88)

Traceback (most recent call last):
  File "/home/ubuntu/trends-script/scraper.py", line 260, in <module>
    main()
  File "/home/ubuntu/trends-script/scraper.py", line 253, in main
    htmlstring = get_html_from_site()
  File "/home/ubuntu/trends-script/scraper.py", line 28, in get_html_from_site
    driver = webdriver.Chrome(options=options)
  File "/home/ubuntu/.local/lib/python3.8/site-packages/selenium/webdriver/chrome/webdriver.py", line 73, in __init__
    self.service.start()
  File "/home/ubuntu/.local/lib/python3.8/site-packages/selenium/webdriver/common/service.py", line 104, in start
    raise WebDriverException("Can not connect to the Service %s" % self.path)
selenium.common.exceptions.WebDriverException: Message: Can not connect to the Service chromedriver

Traceback (most recent call last):
  File "/home/ubuntu/trends-script/scraper.py", line 260, in <module>
    main()
  File "/home/ubuntu/trends-script/scraper.py", line 253, in main
    htmlstring = get_html_from_site()
  File "/home/ubuntu/trends-script/scraper.py", line 31, in get_html_from_site
    driver.get(start_url)
  File "/home/ubuntu/.local/lib/python3.8/site-packages/selenium/webdriver/remote/webdriver.py", line 333, in get
    self.execute(Command.GET, {'url': url})
  File "/home/ubuntu/.local/lib/python3.8/site-packages/selenium/webdriver/remote/webdriver.py", line 321, in execute
    self.error_handler.check_response(response)
  File "/home/ubuntu/.local/lib/python3.8/site-packages/selenium/webdriver/remote/errorhandler.py", line 242, in check_response
    raise exception_class(message, screen, stacktrace)
selenium.common.exceptions.WebDriverException: Message: unknown error: session deleted because of page crash
from unknown error: cannot determine loading status
from tab crashed
  (Session info: headless chrome=87.0.4280.88)

Traceback (most recent call last):
  File "/home/ubuntu/trends-script/scraper.py", line 260, in <module>
    main()
  File "/home/ubuntu/trends-script/scraper.py", line 253, in main
    htmlstring = get_html_from_site()
  File "/home/ubuntu/trends-script/scraper.py", line 28, in get_html_from_site
    driver = webdriver.Chrome(options=options)
  File "/home/ubuntu/.local/lib/python3.8/site-packages/selenium/webdriver/chrome/webdriver.py", line 73, in __init__
    self.service.start()
  File "/home/ubuntu/.local/lib/python3.8/site-packages/selenium/webdriver/common/service.py", line 104, in start
    raise WebDriverException("Can not connect to the Service %s" % self.path)
selenium.common.exceptions.WebDriverException: Message: Can not connect to the Service chromedriver

Traceback (most recent call last):
  File "/home/ubuntu/trends-script/scraper.py", line 260, in <module>
    main()
  File "/home/ubuntu/trends-script/scraper.py", line 253, in main
    htmlstring = get_html_from_site()
  File "/home/ubuntu/trends-script/scraper.py", line 31, in get_html_from_site
    driver.get(start_url)
  File "/home/ubuntu/.local/lib/python3.8/site-packages/selenium/webdriver/remote/webdriver.py", line 333, in get
    self.execute(Command.GET, {'url': url})
  File "/home/ubuntu/.local/lib/python3.8/site-packages/selenium/webdriver/remote/webdriver.py", line 321, in execute
    self.error_handler.check_response(response)
  File "/home/ubuntu/.local/lib/python3.8/site-packages/selenium/webdriver/remote/errorhandler.py", line 242, in check_response
    raise exception_class(message, screen, stacktrace)
selenium.common.exceptions.WebDriverException: Message: unknown error: session deleted because of page crash
from unknown error: cannot determine loading status
from tab crashed
  (Session info: headless chrome=87.0.4280.88)

Traceback (most recent call last):
  File "/home/ubuntu/trends-script/scraper.py", line 260, in <module>
    main()
  File "/home/ubuntu/trends-script/scraper.py", line 253, in main
    htmlstring = get_html_from_site()
  File "/home/ubuntu/trends-script/scraper.py", line 28, in get_html_from_site
    driver = webdriver.Chrome(options=options)
  File "/home/ubuntu/.local/lib/python3.8/site-packages/selenium/webdriver/chrome/webdriver.py", line 76, in __init__
    RemoteWebDriver.__init__(
  File "/home/ubuntu/.local/lib/python3.8/site-packages/selenium/webdriver/remote/webdriver.py", line 157, in __init__
    self.start_session(capabilities, browser_profile)
  File "/home/ubuntu/.local/lib/python3.8/site-packages/selenium/webdriver/remote/webdriver.py", line 252, in start_session
    response = self.execute(Command.NEW_SESSION, parameters)
  File "/home/ubuntu/.local/lib/python3.8/site-packages/selenium/webdriver/remote/webdriver.py", line 321, in execute
    self.error_handler.check_response(response)
  File "/home/ubuntu/.local/lib/python3.8/site-packages/selenium/webdriver/remote/errorhandler.py", line 242, in check_response
    raise exception_class(message, screen, stacktrace)
selenium.common.exceptions.WebDriverException: Message: unknown error: DevToolsActivePort file doesn't exist

Traceback (most recent call last):
  File "/home/ubuntu/trends-script/scraper.py", line 260, in <module>
    main()
  File "/home/ubuntu/trends-script/scraper.py", line 253, in main
    htmlstring = get_html_from_site()
  File "/home/ubuntu/trends-script/scraper.py", line 31, in get_html_from_site
    driver.get(start_url)
  File "/home/ubuntu/.local/lib/python3.8/site-packages/selenium/webdriver/remote/webdriver.py", line 333, in get
    self.execute(Command.GET, {'url': url})
  File "/home/ubuntu/.local/lib/python3.8/site-packages/selenium/webdriver/remote/webdriver.py", line 321, in execute
    self.error_handler.check_response(response)
  File "/home/ubuntu/.local/lib/python3.8/site-packages/selenium/webdriver/remote/errorhandler.py", line 242, in check_response
    raise exception_class(message, screen, stacktrace)
selenium.common.exceptions.TimeoutException: Message: timeout: Timed out receiving message from renderer: 254.147
  (Session info: headless chrome=87.0.4280.88)

Traceback (most recent call last):
  File "/home/ubuntu/trends-script/scraper.py", line 260, in <module>
    main()
  File "/home/ubuntu/trends-script/scraper.py", line 253, in main
    htmlstring = get_html_from_site()
  File "/home/ubuntu/trends-script/scraper.py", line 28, in get_html_from_site
    driver = webdriver.Chrome(options=options)
  File "/home/ubuntu/.local/lib/python3.8/site-packages/selenium/webdriver/chrome/webdriver.py", line 73, in __init__
    self.service.start()
  File "/home/ubuntu/.local/lib/python3.8/site-packages/selenium/webdriver/common/service.py", line 104, in start
    raise WebDriverException("Can not connect to the Service %s" % self.path)
selenium.common.exceptions.WebDriverException: Message: Can not connect to the Service chromedriver

Traceback (most recent call last):
  File "/home/ubuntu/trends-script/scraper.py", line 260, in <module>
    main()
  File "/home/ubuntu/trends-script/scraper.py", line 253, in main
    htmlstring = get_html_from_site()
  File "/home/ubuntu/trends-script/scraper.py", line 31, in get_html_from_site
    driver.get(start_url)
  File "/home/ubuntu/.local/lib/python3.8/site-packages/selenium/webdriver/remote/webdriver.py", line 333, in get
    self.execute(Command.GET, {'url': url})
  File "/home/ubuntu/.local/lib/python3.8/site-packages/selenium/webdriver/remote/webdriver.py", line 321, in execute
    self.error_handler.check_response(response)
  File "/home/ubuntu/.local/lib/python3.8/site-packages/selenium/webdriver/remote/errorhandler.py", line 242, in check_response
    raise exception_class(message, screen, stacktrace)
selenium.common.exceptions.TimeoutException: Message: timeout: Timed out receiving message from renderer: 292.048
  (Session info: headless chrome=87.0.4280.88)

Traceback (most recent call last):
  File "/home/ubuntu/trends-script/scraper.py", line 260, in <module>
    main()
  File "/home/ubuntu/trends-script/scraper.py", line 253, in main
    htmlstring = get_html_from_site()
  File "/home/ubuntu/trends-script/scraper.py", line 28, in get_html_from_site
    driver = webdriver.Chrome(options=options)
  File "/home/ubuntu/.local/lib/python3.8/site-packages/selenium/webdriver/chrome/webdriver.py", line 73, in __init__
    self.service.start()
  File "/home/ubuntu/.local/lib/python3.8/site-packages/selenium/webdriver/common/service.py", line 104, in start
    raise WebDriverException("Can not connect to the Service %s" % self.path)
selenium.common.exceptions.WebDriverException: Message: Can not connect to the Service chromedriver

Traceback (most recent call last):
  File "/home/ubuntu/trends-script/scraper.py", line 260, in <module>
    main()
  File "/home/ubuntu/trends-script/scraper.py", line 253, in main
    htmlstring = get_html_from_site()
  File "/home/ubuntu/trends-script/scraper.py", line 31, in get_html_from_site
    driver.get(start_url)
  File "/home/ubuntu/.local/lib/python3.8/site-packages/selenium/webdriver/remote/webdriver.py", line 333, in get
    self.execute(Command.GET, {'url': url})
  File "/home/ubuntu/.local/lib/python3.8/site-packages/selenium/webdriver/remote/webdriver.py", line 321, in execute
    self.error_handler.check_response(response)
  File "/home/ubuntu/.local/lib/python3.8/site-packages/selenium/webdriver/remote/errorhandler.py", line 242, in check_response
    raise exception_class(message, screen, stacktrace)
selenium.common.exceptions.TimeoutException: Message: timeout: Timed out receiving message from renderer: 285.875
  (Session info: headless chrome=87.0.4280.88)

Traceback (most recent call last):
  File "/home/ubuntu/trends-script/scraper.py", line 260, in <module>
    main()
  File "/home/ubuntu/trends-script/scraper.py", line 253, in main
    htmlstring = get_html_from_site()
  File "/home/ubuntu/trends-script/scraper.py", line 28, in get_html_from_site
    driver = webdriver.Chrome(options=options)
  File "/home/ubuntu/.local/lib/python3.8/site-packages/selenium/webdriver/chrome/webdriver.py", line 73, in __init__
    self.service.start()
  File "/home/ubuntu/.local/lib/python3.8/site-packages/selenium/webdriver/common/service.py", line 104, in start
    raise WebDriverException("Can not connect to the Service %s" % self.path)
selenium.common.exceptions.WebDriverException: Message: Can not connect to the Service chromedriver

Traceback (most recent call last):
  File "/home/ubuntu/trends-script/scraper.py", line 260, in <module>
    main()
  File "/home/ubuntu/trends-script/scraper.py", line 253, in main
    htmlstring = get_html_from_site()
  File "/home/ubuntu/trends-script/scraper.py", line 31, in get_html_from_site
    driver.get(start_url)
  File "/home/ubuntu/.local/lib/python3.8/site-packages/selenium/webdriver/remote/webdriver.py", line 333, in get
    self.execute(Command.GET, {'url': url})
  File "/home/ubuntu/.local/lib/python3.8/site-packages/selenium/webdriver/remote/webdriver.py", line 321, in execute
    self.error_handler.check_response(response)
  File "/home/ubuntu/.local/lib/python3.8/site-packages/selenium/webdriver/remote/errorhandler.py", line 242, in check_response
    raise exception_class(message, screen, stacktrace)
selenium.common.exceptions.TimeoutException: Message: timeout: Timed out receiving message from renderer: 287.761
  (Session info: headless chrome=87.0.4280.88)

Traceback (most recent call last):
  File "/home/ubuntu/trends-script/scraper.py", line 260, in <module>
    main()
  File "/home/ubuntu/trends-script/scraper.py", line 253, in main
    htmlstring = get_html_from_site()
  File "/home/ubuntu/trends-script/scraper.py", line 28, in get_html_from_site
    driver = webdriver.Chrome(options=options)
  File "/home/ubuntu/.local/lib/python3.8/site-packages/selenium/webdriver/chrome/webdriver.py", line 73, in __init__
    self.service.start()
  File "/home/ubuntu/.local/lib/python3.8/site-packages/selenium/webdriver/common/service.py", line 104, in start
    raise WebDriverException("Can not connect to the Service %s" % self.path)
selenium.common.exceptions.WebDriverException: Message: Can not connect to the Service chromedriver

Traceback (most recent call last):
  File "/home/ubuntu/trends-script/scraper.py", line 260, in <module>
    main()
  File "/home/ubuntu/trends-script/scraper.py", line 253, in main
    htmlstring = get_html_from_site()
  File "/home/ubuntu/trends-script/scraper.py", line 28, in get_html_from_site
    driver = webdriver.Chrome(options=options)
  File "/home/ubuntu/.local/lib/python3.8/site-packages/selenium/webdriver/chrome/webdriver.py", line 73, in __init__
    self.service.start()
  File "/home/ubuntu/.local/lib/python3.8/site-packages/selenium/webdriver/common/service.py", line 104, in start
    raise WebDriverException("Can not connect to the Service %s" % self.path)
selenium.common.exceptions.WebDriverException: Message: Can not connect to the Service chromedriver

Traceback (most recent call last):
  File "/home/ubuntu/trends-script/scraper.py", line 260, in <module>
    main()
  File "/home/ubuntu/trends-script/scraper.py", line 253, in main
    htmlstring = get_html_from_site()
  File "/home/ubuntu/trends-script/scraper.py", line 31, in get_html_from_site
    driver.get(start_url)
  File "/home/ubuntu/.local/lib/python3.8/site-packages/selenium/webdriver/remote/webdriver.py", line 333, in get
    self.execute(Command.GET, {'url': url})
  File "/home/ubuntu/.local/lib/python3.8/site-packages/selenium/webdriver/remote/webdriver.py", line 321, in execute
    self.error_handler.check_response(response)
  File "/home/ubuntu/.local/lib/python3.8/site-packages/selenium/webdriver/remote/errorhandler.py", line 242, in check_response
    raise exception_class(message, screen, stacktrace)
selenium.common.exceptions.WebDriverException: Message: unknown error: session deleted because of page crash
from unknown error: cannot determine loading status
from tab crashed
  (Session info: headless chrome=87.0.4280.88)

Traceback (most recent call last):
  File "/home/ubuntu/trends-script/scraper.py", line 260, in <module>
    main()
  File "/home/ubuntu/trends-script/scraper.py", line 253, in main
    htmlstring = get_html_from_site()
  File "/home/ubuntu/trends-script/scraper.py", line 28, in get_html_from_site
    driver = webdriver.Chrome(options=options)
  File "/home/ubuntu/.local/lib/python3.8/site-packages/selenium/webdriver/chrome/webdriver.py", line 73, in __init__
    self.service.start()
  File "/home/ubuntu/.local/lib/python3.8/site-packages/selenium/webdriver/common/service.py", line 104, in start
    raise WebDriverException("Can not connect to the Service %s" % self.path)
selenium.common.exceptions.WebDriverException: Message: Can not connect to the Service chromedriver

Traceback (most recent call last):
  File "/home/ubuntu/trends-script/scraper.py", line 260, in <module>
    main()
  File "/home/ubuntu/trends-script/scraper.py", line 253, in main
    htmlstring = get_html_from_site()
  File "/home/ubuntu/trends-script/scraper.py", line 31, in get_html_from_site
    driver.get(start_url)
  File "/home/ubuntu/.local/lib/python3.8/site-packages/selenium/webdriver/remote/webdriver.py", line 333, in get
    self.execute(Command.GET, {'url': url})
  File "/home/ubuntu/.local/lib/python3.8/site-packages/selenium/webdriver/remote/webdriver.py", line 321, in execute
    self.error_handler.check_response(response)
  File "/home/ubuntu/.local/lib/python3.8/site-packages/selenium/webdriver/remote/errorhandler.py", line 242, in check_response
    raise exception_class(message, screen, stacktrace)
selenium.common.exceptions.TimeoutException: Message: timeout: Timed out receiving message from renderer: 284.786
  (Session info: headless chrome=87.0.4280.88)

Traceback (most recent call last):
  File "/home/ubuntu/trends-script/scraper.py", line 260, in <module>
    main()
  File "/home/ubuntu/trends-script/scraper.py", line 253, in main
    htmlstring = get_html_from_site()
  File "/home/ubuntu/trends-script/scraper.py", line 28, in get_html_from_site
    driver = webdriver.Chrome(options=options)
  File "/home/ubuntu/.local/lib/python3.8/site-packages/selenium/webdriver/chrome/webdriver.py", line 73, in __init__
    self.service.start()
  File "/home/ubuntu/.local/lib/python3.8/site-packages/selenium/webdriver/common/service.py", line 104, in start
    raise WebDriverException("Can not connect to the Service %s" % self.path)
selenium.common.exceptions.WebDriverException: Message: Can not connect to the Service chromedriver

Traceback (most recent call last):
  File "/home/ubuntu/trends-script/scraper.py", line 260, in <module>
    main()
  File "/home/ubuntu/trends-script/scraper.py", line 253, in main
    htmlstring = get_html_from_site()
  File "/home/ubuntu/trends-script/scraper.py", line 31, in get_html_from_site
    driver.get(start_url)
  File "/home/ubuntu/.local/lib/python3.8/site-packages/selenium/webdriver/remote/webdriver.py", line 333, in get
    self.execute(Command.GET, {'url': url})
  File "/home/ubuntu/.local/lib/python3.8/site-packages/selenium/webdriver/remote/webdriver.py", line 321, in execute
    self.error_handler.check_response(response)
  File "/home/ubuntu/.local/lib/python3.8/site-packages/selenium/webdriver/remote/errorhandler.py", line 242, in check_response
    raise exception_class(message, screen, stacktrace)
selenium.common.exceptions.TimeoutException: Message: timeout: Timed out receiving message from renderer: 284.380
  (Session info: headless chrome=87.0.4280.88)

Traceback (most recent call last):
  File "/home/ubuntu/trends-script/scraper.py", line 260, in <module>
    main()
  File "/home/ubuntu/trends-script/scraper.py", line 253, in main
    htmlstring = get_html_from_site()
  File "/home/ubuntu/trends-script/scraper.py", line 28, in get_html_from_site
    driver = webdriver.Chrome(options=options)
  File "/home/ubuntu/.local/lib/python3.8/site-packages/selenium/webdriver/chrome/webdriver.py", line 73, in __init__
    self.service.start()
  File "/home/ubuntu/.local/lib/python3.8/site-packages/selenium/webdriver/common/service.py", line 104, in start
    raise WebDriverException("Can not connect to the Service %s" % self.path)
selenium.common.exceptions.WebDriverException: Message: Can not connect to the Service chromedriver

Traceback (most recent call last):
  File "/home/ubuntu/trends-script/scraper.py", line 260, in <module>
    main()
  File "/home/ubuntu/trends-script/scraper.py", line 253, in main
    htmlstring = get_html_from_site()
  File "/home/ubuntu/trends-script/scraper.py", line 31, in get_html_from_site
    driver.get(start_url)
  File "/home/ubuntu/.local/lib/python3.8/site-packages/selenium/webdriver/remote/webdriver.py", line 333, in get
    self.execute(Command.GET, {'url': url})
  File "/home/ubuntu/.local/lib/python3.8/site-packages/selenium/webdriver/remote/webdriver.py", line 321, in execute
    self.error_handler.check_response(response)
  File "/home/ubuntu/.local/lib/python3.8/site-packages/selenium/webdriver/remote/errorhandler.py", line 242, in check_response
    raise exception_class(message, screen, stacktrace)
selenium.common.exceptions.TimeoutException: Message: timeout: Timed out receiving message from renderer: 282.982
  (Session info: headless chrome=87.0.4280.88)

Traceback (most recent call last):
  File "/home/ubuntu/trends-script/scraper.py", line 260, in <module>
    main()
  File "/home/ubuntu/trends-script/scraper.py", line 253, in main
    htmlstring = get_html_from_site()
  File "/home/ubuntu/trends-script/scraper.py", line 28, in get_html_from_site
    driver = webdriver.Chrome(options=options)
  File "/home/ubuntu/.local/lib/python3.8/site-packages/selenium/webdriver/chrome/webdriver.py", line 73, in __init__
    self.service.start()
  File "/home/ubuntu/.local/lib/python3.8/site-packages/selenium/webdriver/common/service.py", line 104, in start
    raise WebDriverException("Can not connect to the Service %s" % self.path)
selenium.common.exceptions.WebDriverException: Message: Can not connect to the Service chromedriver

Traceback (most recent call last):
  File "/home/ubuntu/trends-script/scraper.py", line 260, in <module>
    main()
  File "/home/ubuntu/trends-script/scraper.py", line 253, in main
    htmlstring = get_html_from_site()
  File "/home/ubuntu/trends-script/scraper.py", line 31, in get_html_from_site
    driver.get(start_url)
  File "/home/ubuntu/.local/lib/python3.8/site-packages/selenium/webdriver/remote/webdriver.py", line 333, in get
    self.execute(Command.GET, {'url': url})
  File "/home/ubuntu/.local/lib/python3.8/site-packages/selenium/webdriver/remote/webdriver.py", line 321, in execute
    self.error_handler.check_response(response)
  File "/home/ubuntu/.local/lib/python3.8/site-packages/selenium/webdriver/remote/errorhandler.py", line 242, in check_response
    raise exception_class(message, screen, stacktrace)
selenium.common.exceptions.TimeoutException: Message: timeout: Timed out receiving message from renderer: 278.870
  (Session info: headless chrome=87.0.4280.88)

Traceback (most recent call last):
  File "/home/ubuntu/trends-script/scraper.py", line 260, in <module>
    main()
  File "/home/ubuntu/trends-script/scraper.py", line 253, in main
    htmlstring = get_html_from_site()
  File "/home/ubuntu/trends-script/scraper.py", line 28, in get_html_from_site
    driver = webdriver.Chrome(options=options)
  File "/home/ubuntu/.local/lib/python3.8/site-packages/selenium/webdriver/chrome/webdriver.py", line 73, in __init__
    self.service.start()
  File "/home/ubuntu/.local/lib/python3.8/site-packages/selenium/webdriver/common/service.py", line 104, in start
    raise WebDriverException("Can not connect to the Service %s" % self.path)
selenium.common.exceptions.WebDriverException: Message: Can not connect to the Service chromedriver

Traceback (most recent call last):
  File "/home/ubuntu/trends-script/scraper.py", line 260, in <module>
    main()
  File "/home/ubuntu/trends-script/scraper.py", line 253, in main
    htmlstring = get_html_from_site()
  File "/home/ubuntu/trends-script/scraper.py", line 31, in get_html_from_site
    driver.get(start_url)
  File "/home/ubuntu/.local/lib/python3.8/site-packages/selenium/webdriver/remote/webdriver.py", line 333, in get
    self.execute(Command.GET, {'url': url})
  File "/home/ubuntu/.local/lib/python3.8/site-packages/selenium/webdriver/remote/webdriver.py", line 321, in execute
    self.error_handler.check_response(response)
  File "/home/ubuntu/.local/lib/python3.8/site-packages/selenium/webdriver/remote/errorhandler.py", line 242, in check_response
    raise exception_class(message, screen, stacktrace)
selenium.common.exceptions.TimeoutException: Message: timeout: Timed out receiving message from renderer: 284.463
  (Session info: headless chrome=87.0.4280.88)

Traceback (most recent call last):
  File "/home/ubuntu/trends-script/scraper.py", line 260, in <module>
    main()
  File "/home/ubuntu/trends-script/scraper.py", line 253, in main
    htmlstring = get_html_from_site()
  File "/home/ubuntu/trends-script/scraper.py", line 28, in get_html_from_site
    driver = webdriver.Chrome(options=options)
  File "/home/ubuntu/.local/lib/python3.8/site-packages/selenium/webdriver/chrome/webdriver.py", line 73, in __init__
    self.service.start()
  File "/home/ubuntu/.local/lib/python3.8/site-packages/selenium/webdriver/common/service.py", line 104, in start
    raise WebDriverException("Can not connect to the Service %s" % self.path)
selenium.common.exceptions.WebDriverException: Message: Can not connect to the Service chromedriver

Traceback (most recent call last):
  File "/home/ubuntu/trends-script/scraper.py", line 260, in <module>
    main()
  File "/home/ubuntu/trends-script/scraper.py", line 253, in main
    htmlstring = get_html_from_site()
  File "/home/ubuntu/trends-script/scraper.py", line 31, in get_html_from_site
    driver.get(start_url)
  File "/home/ubuntu/.local/lib/python3.8/site-packages/selenium/webdriver/remote/webdriver.py", line 333, in get
    self.execute(Command.GET, {'url': url})
  File "/home/ubuntu/.local/lib/python3.8/site-packages/selenium/webdriver/remote/webdriver.py", line 321, in execute
    self.error_handler.check_response(response)
  File "/home/ubuntu/.local/lib/python3.8/site-packages/selenium/webdriver/remote/errorhandler.py", line 242, in check_response
    raise exception_class(message, screen, stacktrace)
selenium.common.exceptions.TimeoutException: Message: timeout: Timed out receiving message from renderer: 283.293
  (Session info: headless chrome=87.0.4280.88)

Traceback (most recent call last):
  File "/home/ubuntu/trends-script/scraper.py", line 260, in <module>
    main()
  File "/home/ubuntu/trends-script/scraper.py", line 253, in main
    htmlstring = get_html_from_site()
  File "/home/ubuntu/trends-script/scraper.py", line 28, in get_html_from_site
    driver = webdriver.Chrome(options=options)
  File "/home/ubuntu/.local/lib/python3.8/site-packages/selenium/webdriver/chrome/webdriver.py", line 73, in __init__
    self.service.start()
  File "/home/ubuntu/.local/lib/python3.8/site-packages/selenium/webdriver/common/service.py", line 104, in start
    raise WebDriverException("Can not connect to the Service %s" % self.path)
selenium.common.exceptions.WebDriverException: Message: Can not connect to the Service chromedriver

Traceback (most recent call last):
  File "/home/ubuntu/trends-script/scraper.py", line 260, in <module>
    main()
  File "/home/ubuntu/trends-script/scraper.py", line 253, in main
    htmlstring = get_html_from_site()
  File "/home/ubuntu/trends-script/scraper.py", line 28, in get_html_from_site
    driver = webdriver.Chrome(options=options)
  File "/home/ubuntu/.local/lib/python3.8/site-packages/selenium/webdriver/chrome/webdriver.py", line 73, in __init__
    self.service.start()
  File "/home/ubuntu/.local/lib/python3.8/site-packages/selenium/webdriver/common/service.py", line 104, in start
    raise WebDriverException("Can not connect to the Service %s" % self.path)
selenium.common.exceptions.WebDriverException: Message: Can not connect to the Service chromedriver

Traceback (most recent call last):
  File "/home/ubuntu/trends-script/scraper.py", line 260, in <module>
    main()
  File "/home/ubuntu/trends-script/scraper.py", line 253, in main
    htmlstring = get_html_from_site()
  File "/home/ubuntu/trends-script/scraper.py", line 31, in get_html_from_site
    driver.get(start_url)
  File "/home/ubuntu/.local/lib/python3.8/site-packages/selenium/webdriver/remote/webdriver.py", line 333, in get
    self.execute(Command.GET, {'url': url})
  File "/home/ubuntu/.local/lib/python3.8/site-packages/selenium/webdriver/remote/webdriver.py", line 321, in execute
    self.error_handler.check_response(response)
  File "/home/ubuntu/.local/lib/python3.8/site-packages/selenium/webdriver/remote/errorhandler.py", line 242, in check_response
    raise exception_class(message, screen, stacktrace)
selenium.common.exceptions.TimeoutException: Message: timeout: Timed out receiving message from renderer: 290.291
  (Session info: headless chrome=87.0.4280.88)

Traceback (most recent call last):
  File "/home/ubuntu/trends-script/scraper.py", line 260, in <module>
    main()
  File "/home/ubuntu/trends-script/scraper.py", line 253, in main
    htmlstring = get_html_from_site()
  File "/home/ubuntu/trends-script/scraper.py", line 28, in get_html_from_site
    driver = webdriver.Chrome(options=options)
  File "/home/ubuntu/.local/lib/python3.8/site-packages/selenium/webdriver/chrome/webdriver.py", line 73, in __init__
    self.service.start()
  File "/home/ubuntu/.local/lib/python3.8/site-packages/selenium/webdriver/common/service.py", line 104, in start
    raise WebDriverException("Can not connect to the Service %s" % self.path)
selenium.common.exceptions.WebDriverException: Message: Can not connect to the Service chromedriver

Traceback (most recent call last):
  File "/home/ubuntu/trends-script/scraper.py", line 260, in <module>
    main()
  File "/home/ubuntu/trends-script/scraper.py", line 253, in main
    htmlstring = get_html_from_site()
  File "/home/ubuntu/trends-script/scraper.py", line 31, in get_html_from_site
    driver.get(start_url)
  File "/home/ubuntu/.local/lib/python3.8/site-packages/selenium/webdriver/remote/webdriver.py", line 333, in get
    self.execute(Command.GET, {'url': url})
  File "/home/ubuntu/.local/lib/python3.8/site-packages/selenium/webdriver/remote/webdriver.py", line 321, in execute
    self.error_handler.check_response(response)
  File "/home/ubuntu/.local/lib/python3.8/site-packages/selenium/webdriver/remote/errorhandler.py", line 242, in check_response
    raise exception_class(message, screen, stacktrace)
selenium.common.exceptions.TimeoutException: Message: timeout: Timed out receiving message from renderer: 294.259
  (Session info: headless chrome=87.0.4280.88)

Traceback (most recent call last):
  File "/home/ubuntu/trends-script/scraper.py", line 260, in <module>
    main()
  File "/home/ubuntu/trends-script/scraper.py", line 253, in main
    htmlstring = get_html_from_site()
  File "/home/ubuntu/trends-script/scraper.py", line 28, in get_html_from_site
    driver = webdriver.Chrome(options=options)
  File "/home/ubuntu/.local/lib/python3.8/site-packages/selenium/webdriver/chrome/webdriver.py", line 73, in __init__
    self.service.start()
  File "/home/ubuntu/.local/lib/python3.8/site-packages/selenium/webdriver/common/service.py", line 104, in start
    raise WebDriverException("Can not connect to the Service %s" % self.path)
selenium.common.exceptions.WebDriverException: Message: Can not connect to the Service chromedriver

Traceback (most recent call last):
  File "/home/ubuntu/trends-script/scraper.py", line 260, in <module>
    main()
  File "/home/ubuntu/trends-script/scraper.py", line 253, in main
    htmlstring = get_html_from_site()
  File "/home/ubuntu/trends-script/scraper.py", line 31, in get_html_from_site
    driver.get(start_url)
  File "/home/ubuntu/.local/lib/python3.8/site-packages/selenium/webdriver/remote/webdriver.py", line 333, in get
    self.execute(Command.GET, {'url': url})
  File "/home/ubuntu/.local/lib/python3.8/site-packages/selenium/webdriver/remote/webdriver.py", line 321, in execute
    self.error_handler.check_response(response)
  File "/home/ubuntu/.local/lib/python3.8/site-packages/selenium/webdriver/remote/errorhandler.py", line 242, in check_response
    raise exception_class(message, screen, stacktrace)
selenium.common.exceptions.TimeoutException: Message: timeout: Timed out receiving message from renderer: 293.985
  (Session info: headless chrome=87.0.4280.88)

Traceback (most recent call last):
  File "/home/ubuntu/trends-script/scraper.py", line 260, in <module>
    main()
  File "/home/ubuntu/trends-script/scraper.py", line 253, in main
    htmlstring = get_html_from_site()
  File "/home/ubuntu/trends-script/scraper.py", line 28, in get_html_from_site
    driver = webdriver.Chrome(options=options)
  File "/home/ubuntu/.local/lib/python3.8/site-packages/selenium/webdriver/chrome/webdriver.py", line 73, in __init__
    self.service.start()
  File "/home/ubuntu/.local/lib/python3.8/site-packages/selenium/webdriver/common/service.py", line 104, in start
    raise WebDriverException("Can not connect to the Service %s" % self.path)
selenium.common.exceptions.WebDriverException: Message: Can not connect to the Service chromedriver

Traceback (most recent call last):
  File "/home/ubuntu/trends-script/scraper.py", line 260, in <module>
    main()
  File "/home/ubuntu/trends-script/scraper.py", line 253, in main
    htmlstring = get_html_from_site()
  File "/home/ubuntu/trends-script/scraper.py", line 31, in get_html_from_site
    driver.get(start_url)
  File "/home/ubuntu/.local/lib/python3.8/site-packages/selenium/webdriver/remote/webdriver.py", line 333, in get
    self.execute(Command.GET, {'url': url})
  File "/home/ubuntu/.local/lib/python3.8/site-packages/selenium/webdriver/remote/webdriver.py", line 321, in execute
    self.error_handler.check_response(response)
  File "/home/ubuntu/.local/lib/python3.8/site-packages/selenium/webdriver/remote/errorhandler.py", line 242, in check_response
    raise exception_class(message, screen, stacktrace)
selenium.common.exceptions.TimeoutException: Message: timeout: Timed out receiving message from renderer: 291.511
  (Session info: headless chrome=87.0.4280.88)

Traceback (most recent call last):
  File "/home/ubuntu/trends-script/scraper.py", line 260, in <module>
    main()
  File "/home/ubuntu/trends-script/scraper.py", line 253, in main
    htmlstring = get_html_from_site()
  File "/home/ubuntu/trends-script/scraper.py", line 28, in get_html_from_site
    driver = webdriver.Chrome(options=options)
  File "/home/ubuntu/.local/lib/python3.8/site-packages/selenium/webdriver/chrome/webdriver.py", line 73, in __init__
    self.service.start()
  File "/home/ubuntu/.local/lib/python3.8/site-packages/selenium/webdriver/common/service.py", line 104, in start
    raise WebDriverException("Can not connect to the Service %s" % self.path)
selenium.common.exceptions.WebDriverException: Message: Can not connect to the Service chromedriver

Traceback (most recent call last):
  File "/home/ubuntu/trends-script/scraper.py", line 260, in <module>
    main()
  File "/home/ubuntu/trends-script/scraper.py", line 253, in main
    htmlstring = get_html_from_site()
  File "/home/ubuntu/trends-script/scraper.py", line 31, in get_html_from_site
    driver.get(start_url)
  File "/home/ubuntu/.local/lib/python3.8/site-packages/selenium/webdriver/remote/webdriver.py", line 333, in get
    self.execute(Command.GET, {'url': url})
  File "/home/ubuntu/.local/lib/python3.8/site-packages/selenium/webdriver/remote/webdriver.py", line 321, in execute
    self.error_handler.check_response(response)
  File "/home/ubuntu/.local/lib/python3.8/site-packages/selenium/webdriver/remote/errorhandler.py", line 242, in check_response
    raise exception_class(message, screen, stacktrace)
selenium.common.exceptions.TimeoutException: Message: timeout: Timed out receiving message from renderer: 292.634
  (Session info: headless chrome=87.0.4280.88)

Traceback (most recent call last):
  File "/home/ubuntu/trends-script/scraper.py", line 260, in <module>
    main()
  File "/home/ubuntu/trends-script/scraper.py", line 253, in main
    htmlstring = get_html_from_site()
  File "/home/ubuntu/trends-script/scraper.py", line 28, in get_html_from_site
    driver = webdriver.Chrome(options=options)
  File "/home/ubuntu/.local/lib/python3.8/site-packages/selenium/webdriver/chrome/webdriver.py", line 73, in __init__
    self.service.start()
  File "/home/ubuntu/.local/lib/python3.8/site-packages/selenium/webdriver/common/service.py", line 104, in start
    raise WebDriverException("Can not connect to the Service %s" % self.path)
selenium.common.exceptions.WebDriverException: Message: Can not connect to the Service chromedriver

Traceback (most recent call last):
  File "/home/ubuntu/trends-script/scraper.py", line 260, in <module>
    main()
  File "/home/ubuntu/trends-script/scraper.py", line 253, in main
    htmlstring = get_html_from_site()
  File "/home/ubuntu/trends-script/scraper.py", line 31, in get_html_from_site
    driver.get(start_url)
  File "/home/ubuntu/.local/lib/python3.8/site-packages/selenium/webdriver/remote/webdriver.py", line 333, in get
    self.execute(Command.GET, {'url': url})
  File "/home/ubuntu/.local/lib/python3.8/site-packages/selenium/webdriver/remote/webdriver.py", line 321, in execute
    self.error_handler.check_response(response)
  File "/home/ubuntu/.local/lib/python3.8/site-packages/selenium/webdriver/remote/errorhandler.py", line 242, in check_response
    raise exception_class(message, screen, stacktrace)
selenium.common.exceptions.TimeoutException: Message: timeout: Timed out receiving message from renderer: 291.383
  (Session info: headless chrome=87.0.4280.88)

Traceback (most recent call last):
  File "/home/ubuntu/trends-script/scraper.py", line 260, in <module>
    main()
  File "/home/ubuntu/trends-script/scraper.py", line 253, in main
    htmlstring = get_html_from_site()
  File "/home/ubuntu/trends-script/scraper.py", line 28, in get_html_from_site
    driver = webdriver.Chrome(options=options)
  File "/home/ubuntu/.local/lib/python3.8/site-packages/selenium/webdriver/chrome/webdriver.py", line 73, in __init__
    self.service.start()
  File "/home/ubuntu/.local/lib/python3.8/site-packages/selenium/webdriver/common/service.py", line 104, in start
    raise WebDriverException("Can not connect to the Service %s" % self.path)
selenium.common.exceptions.WebDriverException: Message: Can not connect to the Service chromedriver

Traceback (most recent call last):
  File "/home/ubuntu/trends-script/scraper.py", line 260, in <module>
    main()
  File "/home/ubuntu/trends-script/scraper.py", line 253, in main
    htmlstring = get_html_from_site()
  File "/home/ubuntu/trends-script/scraper.py", line 31, in get_html_from_site
    driver.get(start_url)
  File "/home/ubuntu/.local/lib/python3.8/site-packages/selenium/webdriver/remote/webdriver.py", line 333, in get
    self.execute(Command.GET, {'url': url})
  File "/home/ubuntu/.local/lib/python3.8/site-packages/selenium/webdriver/remote/webdriver.py", line 321, in execute
    self.error_handler.check_response(response)
  File "/home/ubuntu/.local/lib/python3.8/site-packages/selenium/webdriver/remote/errorhandler.py", line 242, in check_response
    raise exception_class(message, screen, stacktrace)
selenium.common.exceptions.TimeoutException: Message: timeout: Timed out receiving message from renderer: 289.619
  (Session info: headless chrome=87.0.4280.88)

Traceback (most recent call last):
  File "/home/ubuntu/trends-script/scraper.py", line 260, in <module>
    main()
  File "/home/ubuntu/trends-script/scraper.py", line 253, in main
    htmlstring = get_html_from_site()
  File "/home/ubuntu/trends-script/scraper.py", line 28, in get_html_from_site
    driver = webdriver.Chrome(options=options)
  File "/home/ubuntu/.local/lib/python3.8/site-packages/selenium/webdriver/chrome/webdriver.py", line 73, in __init__
    self.service.start()
  File "/home/ubuntu/.local/lib/python3.8/site-packages/selenium/webdriver/common/service.py", line 104, in start
    raise WebDriverException("Can not connect to the Service %s" % self.path)
selenium.common.exceptions.WebDriverException: Message: Can not connect to the Service chromedriver

Traceback (most recent call last):
  File "/home/ubuntu/trends-script/scraper.py", line 260, in <module>
    main()
  File "/home/ubuntu/trends-script/scraper.py", line 253, in main
    htmlstring = get_html_from_site()
  File "/home/ubuntu/trends-script/scraper.py", line 31, in get_html_from_site
    driver.get(start_url)
  File "/home/ubuntu/.local/lib/python3.8/site-packages/selenium/webdriver/remote/webdriver.py", line 333, in get
    self.execute(Command.GET, {'url': url})
  File "/home/ubuntu/.local/lib/python3.8/site-packages/selenium/webdriver/remote/webdriver.py", line 321, in execute
    self.error_handler.check_response(response)
  File "/home/ubuntu/.local/lib/python3.8/site-packages/selenium/webdriver/remote/errorhandler.py", line 242, in check_response
    raise exception_class(message, screen, stacktrace)
selenium.common.exceptions.TimeoutException: Message: timeout: Timed out receiving message from renderer: 288.531
  (Session info: headless chrome=87.0.4280.88)

Traceback (most recent call last):
  File "/home/ubuntu/trends-script/scraper.py", line 260, in <module>
    main()
  File "/home/ubuntu/trends-script/scraper.py", line 253, in main
    htmlstring = get_html_from_site()
  File "/home/ubuntu/trends-script/scraper.py", line 28, in get_html_from_site
    driver = webdriver.Chrome(options=options)
  File "/home/ubuntu/.local/lib/python3.8/site-packages/selenium/webdriver/chrome/webdriver.py", line 73, in __init__
    self.service.start()
  File "/home/ubuntu/.local/lib/python3.8/site-packages/selenium/webdriver/common/service.py", line 104, in start
    raise WebDriverException("Can not connect to the Service %s" % self.path)
selenium.common.exceptions.WebDriverException: Message: Can not connect to the Service chromedriver

Traceback (most recent call last):
  File "/home/ubuntu/trends-script/scraper.py", line 260, in <module>
    main()
  File "/home/ubuntu/trends-script/scraper.py", line 253, in main
    htmlstring = get_html_from_site()
  File "/home/ubuntu/trends-script/scraper.py", line 31, in get_html_from_site
    driver.get(start_url)
  File "/home/ubuntu/.local/lib/python3.8/site-packages/selenium/webdriver/remote/webdriver.py", line 333, in get
    self.execute(Command.GET, {'url': url})
  File "/home/ubuntu/.local/lib/python3.8/site-packages/selenium/webdriver/remote/webdriver.py", line 321, in execute
    self.error_handler.check_response(response)
  File "/home/ubuntu/.local/lib/python3.8/site-packages/selenium/webdriver/remote/errorhandler.py", line 242, in check_response
    raise exception_class(message, screen, stacktrace)
selenium.common.exceptions.WebDriverException: Message: unknown error: session deleted because of page crash
from unknown error: cannot determine loading status
from tab crashed
  (Session info: headless chrome=87.0.4280.88)

Traceback (most recent call last):
  File "/home/ubuntu/trends-script/scraper.py", line 260, in <module>
    main()
  File "/home/ubuntu/trends-script/scraper.py", line 253, in main
    htmlstring = get_html_from_site()
  File "/home/ubuntu/trends-script/scraper.py", line 28, in get_html_from_site
    driver = webdriver.Chrome(options=options)
  File "/home/ubuntu/.local/lib/python3.8/site-packages/selenium/webdriver/chrome/webdriver.py", line 73, in __init__
    self.service.start()
  File "/home/ubuntu/.local/lib/python3.8/site-packages/selenium/webdriver/common/service.py", line 104, in start
    raise WebDriverException("Can not connect to the Service %s" % self.path)
selenium.common.exceptions.WebDriverException: Message: Can not connect to the Service chromedriver

Traceback (most recent call last):
  File "/home/ubuntu/trends-script/scraper.py", line 260, in <module>
    main()
  File "/home/ubuntu/trends-script/scraper.py", line 253, in main
    htmlstring = get_html_from_site()
  File "/home/ubuntu/trends-script/scraper.py", line 31, in get_html_from_site
    driver.get(start_url)
  File "/home/ubuntu/.local/lib/python3.8/site-packages/selenium/webdriver/remote/webdriver.py", line 333, in get
    self.execute(Command.GET, {'url': url})
  File "/home/ubuntu/.local/lib/python3.8/site-packages/selenium/webdriver/remote/webdriver.py", line 321, in execute
    self.error_handler.check_response(response)
  File "/home/ubuntu/.local/lib/python3.8/site-packages/selenium/webdriver/remote/errorhandler.py", line 242, in check_response
    raise exception_class(message, screen, stacktrace)
selenium.common.exceptions.TimeoutException: Message: timeout: Timed out receiving message from renderer: 290.020
  (Session info: headless chrome=87.0.4280.88)

Traceback (most recent call last):
  File "/home/ubuntu/trends-script/scraper.py", line 260, in <module>
    main()
  File "/home/ubuntu/trends-script/scraper.py", line 253, in main
    htmlstring = get_html_from_site()
  File "/home/ubuntu/trends-script/scraper.py", line 28, in get_html_from_site
    driver = webdriver.Chrome(options=options)
  File "/home/ubuntu/.local/lib/python3.8/site-packages/selenium/webdriver/chrome/webdriver.py", line 73, in __init__
    self.service.start()
  File "/home/ubuntu/.local/lib/python3.8/site-packages/selenium/webdriver/common/service.py", line 104, in start
    raise WebDriverException("Can not connect to the Service %s" % self.path)
selenium.common.exceptions.WebDriverException: Message: Can not connect to the Service chromedriver

Traceback (most recent call last):
  File "/home/ubuntu/trends-script/scraper.py", line 260, in <module>
    main()
  File "/home/ubuntu/trends-script/scraper.py", line 253, in main
    htmlstring = get_html_from_site()
  File "/home/ubuntu/trends-script/scraper.py", line 31, in get_html_from_site
    driver.get(start_url)
  File "/home/ubuntu/.local/lib/python3.8/site-packages/selenium/webdriver/remote/webdriver.py", line 333, in get
    self.execute(Command.GET, {'url': url})
  File "/home/ubuntu/.local/lib/python3.8/site-packages/selenium/webdriver/remote/webdriver.py", line 321, in execute
    self.error_handler.check_response(response)
  File "/home/ubuntu/.local/lib/python3.8/site-packages/selenium/webdriver/remote/errorhandler.py", line 242, in check_response
    raise exception_class(message, screen, stacktrace)
selenium.common.exceptions.TimeoutException: Message: timeout: Timed out receiving message from renderer: 290.410
  (Session info: headless chrome=87.0.4280.88)

Traceback (most recent call last):
  File "/home/ubuntu/trends-script/scraper.py", line 260, in <module>
    main()
  File "/home/ubuntu/trends-script/scraper.py", line 253, in main
    htmlstring = get_html_from_site()
  File "/home/ubuntu/trends-script/scraper.py", line 28, in get_html_from_site
    driver = webdriver.Chrome(options=options)
  File "/home/ubuntu/.local/lib/python3.8/site-packages/selenium/webdriver/chrome/webdriver.py", line 73, in __init__
    self.service.start()
  File "/home/ubuntu/.local/lib/python3.8/site-packages/selenium/webdriver/common/service.py", line 104, in start
    raise WebDriverException("Can not connect to the Service %s" % self.path)
selenium.common.exceptions.WebDriverException: Message: Can not connect to the Service chromedriver

Traceback (most recent call last):
  File "/home/ubuntu/trends-script/scraper.py", line 260, in <module>
    main()
  File "/home/ubuntu/trends-script/scraper.py", line 253, in main
    htmlstring = get_html_from_site()
  File "/home/ubuntu/trends-script/scraper.py", line 31, in get_html_from_site
    driver.get(start_url)
  File "/home/ubuntu/.local/lib/python3.8/site-packages/selenium/webdriver/remote/webdriver.py", line 333, in get
    self.execute(Command.GET, {'url': url})
  File "/home/ubuntu/.local/lib/python3.8/site-packages/selenium/webdriver/remote/webdriver.py", line 321, in execute
    self.error_handler.check_response(response)
  File "/home/ubuntu/.local/lib/python3.8/site-packages/selenium/webdriver/remote/errorhandler.py", line 242, in check_response
    raise exception_class(message, screen, stacktrace)
selenium.common.exceptions.TimeoutException: Message: timeout: Timed out receiving message from renderer: 295.656
  (Session info: headless chrome=87.0.4280.88)

Traceback (most recent call last):
  File "/home/ubuntu/trends-script/scraper.py", line 260, in <module>
    main()
  File "/home/ubuntu/trends-script/scraper.py", line 253, in main
    htmlstring = get_html_from_site()
  File "/home/ubuntu/trends-script/scraper.py", line 28, in get_html_from_site
    driver = webdriver.Chrome(options=options)
  File "/home/ubuntu/.local/lib/python3.8/site-packages/selenium/webdriver/chrome/webdriver.py", line 73, in __init__
    self.service.start()
  File "/home/ubuntu/.local/lib/python3.8/site-packages/selenium/webdriver/common/service.py", line 104, in start
    raise WebDriverException("Can not connect to the Service %s" % self.path)
selenium.common.exceptions.WebDriverException: Message: Can not connect to the Service chromedriver

Traceback (most recent call last):
  File "/home/ubuntu/trends-script/scraper.py", line 260, in <module>
    main()
  File "/home/ubuntu/trends-script/scraper.py", line 253, in main
    htmlstring = get_html_from_site()
  File "/home/ubuntu/trends-script/scraper.py", line 31, in get_html_from_site
    driver.get(start_url)
  File "/home/ubuntu/.local/lib/python3.8/site-packages/selenium/webdriver/remote/webdriver.py", line 333, in get
    self.execute(Command.GET, {'url': url})
  File "/home/ubuntu/.local/lib/python3.8/site-packages/selenium/webdriver/remote/webdriver.py", line 321, in execute
    self.error_handler.check_response(response)
  File "/home/ubuntu/.local/lib/python3.8/site-packages/selenium/webdriver/remote/errorhandler.py", line 242, in check_response
    raise exception_class(message, screen, stacktrace)
selenium.common.exceptions.TimeoutException: Message: timeout: Timed out receiving message from renderer: 294.776
  (Session info: headless chrome=87.0.4280.88)

Traceback (most recent call last):
  File "/home/ubuntu/trends-script/scraper.py", line 260, in <module>
    main()
  File "/home/ubuntu/trends-script/scraper.py", line 253, in main
    htmlstring = get_html_from_site()
  File "/home/ubuntu/trends-script/scraper.py", line 28, in get_html_from_site
    driver = webdriver.Chrome(options=options)
  File "/home/ubuntu/.local/lib/python3.8/site-packages/selenium/webdriver/chrome/webdriver.py", line 73, in __init__
    self.service.start()
  File "/home/ubuntu/.local/lib/python3.8/site-packages/selenium/webdriver/common/service.py", line 104, in start
    raise WebDriverException("Can not connect to the Service %s" % self.path)
selenium.common.exceptions.WebDriverException: Message: Can not connect to the Service chromedriver

Traceback (most recent call last):
  File "/home/ubuntu/trends-script/scraper.py", line 260, in <module>
    main()
  File "/home/ubuntu/trends-script/scraper.py", line 253, in main
    htmlstring = get_html_from_site()
  File "/home/ubuntu/trends-script/scraper.py", line 31, in get_html_from_site
    driver.get(start_url)
  File "/home/ubuntu/.local/lib/python3.8/site-packages/selenium/webdriver/remote/webdriver.py", line 333, in get
    self.execute(Command.GET, {'url': url})
  File "/home/ubuntu/.local/lib/python3.8/site-packages/selenium/webdriver/remote/webdriver.py", line 321, in execute
    self.error_handler.check_response(response)
  File "/home/ubuntu/.local/lib/python3.8/site-packages/selenium/webdriver/remote/errorhandler.py", line 242, in check_response
    raise exception_class(message, screen, stacktrace)
selenium.common.exceptions.TimeoutException: Message: timeout: Timed out receiving message from renderer: 291.751
  (Session info: headless chrome=87.0.4280.88)

Traceback (most recent call last):
  File "/home/ubuntu/trends-script/scraper.py", line 260, in <module>
    main()
  File "/home/ubuntu/trends-script/scraper.py", line 253, in main
    htmlstring = get_html_from_site()
  File "/home/ubuntu/trends-script/scraper.py", line 28, in get_html_from_site
    driver = webdriver.Chrome(options=options)
  File "/home/ubuntu/.local/lib/python3.8/site-packages/selenium/webdriver/chrome/webdriver.py", line 73, in __init__
    self.service.start()
  File "/home/ubuntu/.local/lib/python3.8/site-packages/selenium/webdriver/common/service.py", line 104, in start
    raise WebDriverException("Can not connect to the Service %s" % self.path)
selenium.common.exceptions.WebDriverException: Message: Can not connect to the Service chromedriver

Traceback (most recent call last):
  File "/home/ubuntu/trends-script/scraper.py", line 260, in <module>
    main()
  File "/home/ubuntu/trends-script/scraper.py", line 253, in main
    htmlstring = get_html_from_site()
  File "/home/ubuntu/trends-script/scraper.py", line 31, in get_html_from_site
    driver.get(start_url)
  File "/home/ubuntu/.local/lib/python3.8/site-packages/selenium/webdriver/remote/webdriver.py", line 333, in get
    self.execute(Command.GET, {'url': url})
  File "/home/ubuntu/.local/lib/python3.8/site-packages/selenium/webdriver/remote/webdriver.py", line 321, in execute
    self.error_handler.check_response(response)
  File "/home/ubuntu/.local/lib/python3.8/site-packages/selenium/webdriver/remote/errorhandler.py", line 242, in check_response
    raise exception_class(message, screen, stacktrace)
selenium.common.exceptions.TimeoutException: Message: timeout: Timed out receiving message from renderer: 291.927
  (Session info: headless chrome=87.0.4280.88)

Traceback (most recent call last):
  File "/home/ubuntu/trends-script/scraper.py", line 260, in <module>
    main()
  File "/home/ubuntu/trends-script/scraper.py", line 253, in main
    htmlstring = get_html_from_site()
  File "/home/ubuntu/trends-script/scraper.py", line 28, in get_html_from_site
    driver = webdriver.Chrome(options=options)
  File "/home/ubuntu/.local/lib/python3.8/site-packages/selenium/webdriver/chrome/webdriver.py", line 73, in __init__
    self.service.start()
  File "/home/ubuntu/.local/lib/python3.8/site-packages/selenium/webdriver/common/service.py", line 104, in start
    raise WebDriverException("Can not connect to the Service %s" % self.path)
selenium.common.exceptions.WebDriverException: Message: Can not connect to the Service chromedriver

Traceback (most recent call last):
  File "/home/ubuntu/trends-script/scraper.py", line 260, in <module>
    main()
  File "/home/ubuntu/trends-script/scraper.py", line 253, in main
    htmlstring = get_html_from_site()
  File "/home/ubuntu/trends-script/scraper.py", line 31, in get_html_from_site
    driver.get(start_url)
  File "/home/ubuntu/.local/lib/python3.8/site-packages/selenium/webdriver/remote/webdriver.py", line 333, in get
    self.execute(Command.GET, {'url': url})
  File "/home/ubuntu/.local/lib/python3.8/site-packages/selenium/webdriver/remote/webdriver.py", line 321, in execute
    self.error_handler.check_response(response)
  File "/home/ubuntu/.local/lib/python3.8/site-packages/selenium/webdriver/remote/errorhandler.py", line 242, in check_response
    raise exception_class(message, screen, stacktrace)
selenium.common.exceptions.TimeoutException: Message: timeout: Timed out receiving message from renderer: 292.860
  (Session info: headless chrome=87.0.4280.88)

Traceback (most recent call last):
  File "/home/ubuntu/trends-script/scraper.py", line 260, in <module>
    main()
  File "/home/ubuntu/trends-script/scraper.py", line 253, in main
    htmlstring = get_html_from_site()
  File "/home/ubuntu/trends-script/scraper.py", line 28, in get_html_from_site
    driver = webdriver.Chrome(options=options)
  File "/home/ubuntu/.local/lib/python3.8/site-packages/selenium/webdriver/chrome/webdriver.py", line 73, in __init__
    self.service.start()
  File "/home/ubuntu/.local/lib/python3.8/site-packages/selenium/webdriver/common/service.py", line 104, in start
    raise WebDriverException("Can not connect to the Service %s" % self.path)
selenium.common.exceptions.WebDriverException: Message: Can not connect to the Service chromedriver

Traceback (most recent call last):
  File "/home/ubuntu/trends-script/scraper.py", line 260, in <module>
    main()
  File "/home/ubuntu/trends-script/scraper.py", line 253, in main
    htmlstring = get_html_from_site()
  File "/home/ubuntu/trends-script/scraper.py", line 31, in get_html_from_site
    driver.get(start_url)
  File "/home/ubuntu/.local/lib/python3.8/site-packages/selenium/webdriver/remote/webdriver.py", line 333, in get
    self.execute(Command.GET, {'url': url})
  File "/home/ubuntu/.local/lib/python3.8/site-packages/selenium/webdriver/remote/webdriver.py", line 321, in execute
    self.error_handler.check_response(response)
  File "/home/ubuntu/.local/lib/python3.8/site-packages/selenium/webdriver/remote/errorhandler.py", line 242, in check_response
    raise exception_class(message, screen, stacktrace)
selenium.common.exceptions.TimeoutException: Message: timeout: Timed out receiving message from renderer: 292.595
  (Session info: headless chrome=87.0.4280.88)

Traceback (most recent call last):
  File "/home/ubuntu/trends-script/scraper.py", line 260, in <module>
    main()
  File "/home/ubuntu/trends-script/scraper.py", line 253, in main
    htmlstring = get_html_from_site()
  File "/home/ubuntu/trends-script/scraper.py", line 28, in get_html_from_site
    driver = webdriver.Chrome(options=options)
  File "/home/ubuntu/.local/lib/python3.8/site-packages/selenium/webdriver/chrome/webdriver.py", line 73, in __init__
    self.service.start()
  File "/home/ubuntu/.local/lib/python3.8/site-packages/selenium/webdriver/common/service.py", line 104, in start
    raise WebDriverException("Can not connect to the Service %s" % self.path)
selenium.common.exceptions.WebDriverException: Message: Can not connect to the Service chromedriver

Traceback (most recent call last):
  File "/home/ubuntu/trends-script/scraper.py", line 260, in <module>
    main()
  File "/home/ubuntu/trends-script/scraper.py", line 253, in main
    htmlstring = get_html_from_site()
  File "/home/ubuntu/trends-script/scraper.py", line 31, in get_html_from_site
    driver.get(start_url)
  File "/home/ubuntu/.local/lib/python3.8/site-packages/selenium/webdriver/remote/webdriver.py", line 333, in get
    self.execute(Command.GET, {'url': url})
  File "/home/ubuntu/.local/lib/python3.8/site-packages/selenium/webdriver/remote/webdriver.py", line 321, in execute
    self.error_handler.check_response(response)
  File "/home/ubuntu/.local/lib/python3.8/site-packages/selenium/webdriver/remote/errorhandler.py", line 242, in check_response
    raise exception_class(message, screen, stacktrace)
selenium.common.exceptions.TimeoutException: Message: timeout: Timed out receiving message from renderer: 294.941
  (Session info: headless chrome=87.0.4280.88)

Traceback (most recent call last):
  File "/home/ubuntu/trends-script/scraper.py", line 260, in <module>
    main()
  File "/home/ubuntu/trends-script/scraper.py", line 253, in main
    htmlstring = get_html_from_site()
  File "/home/ubuntu/trends-script/scraper.py", line 28, in get_html_from_site
    driver = webdriver.Chrome(options=options)
  File "/home/ubuntu/.local/lib/python3.8/site-packages/selenium/webdriver/chrome/webdriver.py", line 73, in __init__
    self.service.start()
  File "/home/ubuntu/.local/lib/python3.8/site-packages/selenium/webdriver/common/service.py", line 104, in start
    raise WebDriverException("Can not connect to the Service %s" % self.path)
selenium.common.exceptions.WebDriverException: Message: Can not connect to the Service chromedriver

Traceback (most recent call last):
  File "/home/ubuntu/trends-script/scraper.py", line 260, in <module>
    main()
  File "/home/ubuntu/trends-script/scraper.py", line 253, in main
    htmlstring = get_html_from_site()
  File "/home/ubuntu/trends-script/scraper.py", line 31, in get_html_from_site
    driver.get(start_url)
  File "/home/ubuntu/.local/lib/python3.8/site-packages/selenium/webdriver/remote/webdriver.py", line 333, in get
    self.execute(Command.GET, {'url': url})
  File "/home/ubuntu/.local/lib/python3.8/site-packages/selenium/webdriver/remote/webdriver.py", line 321, in execute
    self.error_handler.check_response(response)
  File "/home/ubuntu/.local/lib/python3.8/site-packages/selenium/webdriver/remote/errorhandler.py", line 242, in check_response
    raise exception_class(message, screen, stacktrace)
selenium.common.exceptions.TimeoutException: Message: timeout: Timed out receiving message from renderer: 294.428
  (Session info: headless chrome=87.0.4280.88)

Traceback (most recent call last):
  File "/home/ubuntu/trends-script/scraper.py", line 260, in <module>
    main()
  File "/home/ubuntu/trends-script/scraper.py", line 253, in main
    htmlstring = get_html_from_site()
  File "/home/ubuntu/trends-script/scraper.py", line 28, in get_html_from_site
    driver = webdriver.Chrome(options=options)
  File "/home/ubuntu/.local/lib/python3.8/site-packages/selenium/webdriver/chrome/webdriver.py", line 73, in __init__
    self.service.start()
  File "/home/ubuntu/.local/lib/python3.8/site-packages/selenium/webdriver/common/service.py", line 104, in start
    raise WebDriverException("Can not connect to the Service %s" % self.path)
selenium.common.exceptions.WebDriverException: Message: Can not connect to the Service chromedriver

Traceback (most recent call last):
  File "/home/ubuntu/trends-script/scraper.py", line 260, in <module>
    main()
  File "/home/ubuntu/trends-script/scraper.py", line 253, in main
    htmlstring = get_html_from_site()
  File "/home/ubuntu/trends-script/scraper.py", line 31, in get_html_from_site
    driver.get(start_url)
  File "/home/ubuntu/.local/lib/python3.8/site-packages/selenium/webdriver/remote/webdriver.py", line 333, in get
    self.execute(Command.GET, {'url': url})
  File "/home/ubuntu/.local/lib/python3.8/site-packages/selenium/webdriver/remote/webdriver.py", line 321, in execute
    self.error_handler.check_response(response)
  File "/home/ubuntu/.local/lib/python3.8/site-packages/selenium/webdriver/remote/errorhandler.py", line 242, in check_response
    raise exception_class(message, screen, stacktrace)
selenium.common.exceptions.TimeoutException: Message: timeout: Timed out receiving message from renderer: 293.910
  (Session info: headless chrome=87.0.4280.88)

Traceback (most recent call last):
  File "/home/ubuntu/trends-script/scraper.py", line 260, in <module>
    main()
  File "/home/ubuntu/trends-script/scraper.py", line 253, in main
    htmlstring = get_html_from_site()
  File "/home/ubuntu/trends-script/scraper.py", line 28, in get_html_from_site
    driver = webdriver.Chrome(options=options)
  File "/home/ubuntu/.local/lib/python3.8/site-packages/selenium/webdriver/chrome/webdriver.py", line 73, in __init__
    self.service.start()
  File "/home/ubuntu/.local/lib/python3.8/site-packages/selenium/webdriver/common/service.py", line 104, in start
    raise WebDriverException("Can not connect to the Service %s" % self.path)
selenium.common.exceptions.WebDriverException: Message: Can not connect to the Service chromedriver

Traceback (most recent call last):
  File "/home/ubuntu/trends-script/scraper.py", line 260, in <module>
    main()
  File "/home/ubuntu/trends-script/scraper.py", line 253, in main
    htmlstring = get_html_from_site()
  File "/home/ubuntu/trends-script/scraper.py", line 31, in get_html_from_site
    driver.get(start_url)
  File "/home/ubuntu/.local/lib/python3.8/site-packages/selenium/webdriver/remote/webdriver.py", line 333, in get
    self.execute(Command.GET, {'url': url})
  File "/home/ubuntu/.local/lib/python3.8/site-packages/selenium/webdriver/remote/webdriver.py", line 321, in execute
    self.error_handler.check_response(response)
  File "/home/ubuntu/.local/lib/python3.8/site-packages/selenium/webdriver/remote/errorhandler.py", line 242, in check_response
    raise exception_class(message, screen, stacktrace)
selenium.common.exceptions.TimeoutException: Message: timeout: Timed out receiving message from renderer: 294.027
  (Session info: headless chrome=87.0.4280.88)

Traceback (most recent call last):
  File "/home/ubuntu/trends-script/scraper.py", line 260, in <module>
    main()
  File "/home/ubuntu/trends-script/scraper.py", line 253, in main
    htmlstring = get_html_from_site()
  File "/home/ubuntu/trends-script/scraper.py", line 28, in get_html_from_site
    driver = webdriver.Chrome(options=options)
  File "/home/ubuntu/.local/lib/python3.8/site-packages/selenium/webdriver/chrome/webdriver.py", line 73, in __init__
    self.service.start()
  File "/home/ubuntu/.local/lib/python3.8/site-packages/selenium/webdriver/common/service.py", line 104, in start
    raise WebDriverException("Can not connect to the Service %s" % self.path)
selenium.common.exceptions.WebDriverException: Message: Can not connect to the Service chromedriver

Traceback (most recent call last):
  File "/home/ubuntu/trends-script/scraper.py", line 260, in <module>
    main()
  File "/home/ubuntu/trends-script/scraper.py", line 253, in main
    htmlstring = get_html_from_site()
  File "/home/ubuntu/trends-script/scraper.py", line 31, in get_html_from_site
    driver.get(start_url)
  File "/home/ubuntu/.local/lib/python3.8/site-packages/selenium/webdriver/remote/webdriver.py", line 333, in get
    self.execute(Command.GET, {'url': url})
  File "/home/ubuntu/.local/lib/python3.8/site-packages/selenium/webdriver/remote/webdriver.py", line 321, in execute
    self.error_handler.check_response(response)
  File "/home/ubuntu/.local/lib/python3.8/site-packages/selenium/webdriver/remote/errorhandler.py", line 242, in check_response
    raise exception_class(message, screen, stacktrace)
selenium.common.exceptions.TimeoutException: Message: timeout: Timed out receiving message from renderer: 293.997
  (Session info: headless chrome=87.0.4280.88)

Traceback (most recent call last):
  File "/home/ubuntu/trends-script/scraper.py", line 260, in <module>
    main()
  File "/home/ubuntu/trends-script/scraper.py", line 253, in main
    htmlstring = get_html_from_site()
  File "/home/ubuntu/trends-script/scraper.py", line 28, in get_html_from_site
    driver = webdriver.Chrome(options=options)
  File "/home/ubuntu/.local/lib/python3.8/site-packages/selenium/webdriver/chrome/webdriver.py", line 73, in __init__
    self.service.start()
  File "/home/ubuntu/.local/lib/python3.8/site-packages/selenium/webdriver/common/service.py", line 104, in start
    raise WebDriverException("Can not connect to the Service %s" % self.path)
selenium.common.exceptions.WebDriverException: Message: Can not connect to the Service chromedriver

Traceback (most recent call last):
  File "/home/ubuntu/trends-script/scraper.py", line 260, in <module>
    main()
  File "/home/ubuntu/trends-script/scraper.py", line 253, in main
    htmlstring = get_html_from_site()
  File "/home/ubuntu/trends-script/scraper.py", line 31, in get_html_from_site
    driver.get(start_url)
  File "/home/ubuntu/.local/lib/python3.8/site-packages/selenium/webdriver/remote/webdriver.py", line 333, in get
    self.execute(Command.GET, {'url': url})
  File "/home/ubuntu/.local/lib/python3.8/site-packages/selenium/webdriver/remote/webdriver.py", line 321, in execute
    self.error_handler.check_response(response)
  File "/home/ubuntu/.local/lib/python3.8/site-packages/selenium/webdriver/remote/errorhandler.py", line 242, in check_response
    raise exception_class(message, screen, stacktrace)
selenium.common.exceptions.TimeoutException: Message: timeout: Timed out receiving message from renderer: 293.621
  (Session info: headless chrome=87.0.4280.88)

Traceback (most recent call last):
  File "/home/ubuntu/trends-script/scraper.py", line 260, in <module>
    main()
  File "/home/ubuntu/trends-script/scraper.py", line 253, in main
    htmlstring = get_html_from_site()
  File "/home/ubuntu/trends-script/scraper.py", line 28, in get_html_from_site
    driver = webdriver.Chrome(options=options)
  File "/home/ubuntu/.local/lib/python3.8/site-packages/selenium/webdriver/chrome/webdriver.py", line 73, in __init__
    self.service.start()
  File "/home/ubuntu/.local/lib/python3.8/site-packages/selenium/webdriver/common/service.py", line 104, in start
    raise WebDriverException("Can not connect to the Service %s" % self.path)
selenium.common.exceptions.WebDriverException: Message: Can not connect to the Service chromedriver

Traceback (most recent call last):
  File "/home/ubuntu/trends-script/scraper.py", line 260, in <module>
    main()
  File "/home/ubuntu/trends-script/scraper.py", line 253, in main
    htmlstring = get_html_from_site()
  File "/home/ubuntu/trends-script/scraper.py", line 31, in get_html_from_site
    driver.get(start_url)
  File "/home/ubuntu/.local/lib/python3.8/site-packages/selenium/webdriver/remote/webdriver.py", line 333, in get
    self.execute(Command.GET, {'url': url})
  File "/home/ubuntu/.local/lib/python3.8/site-packages/selenium/webdriver/remote/webdriver.py", line 321, in execute
    self.error_handler.check_response(response)
  File "/home/ubuntu/.local/lib/python3.8/site-packages/selenium/webdriver/remote/errorhandler.py", line 242, in check_response
    raise exception_class(message, screen, stacktrace)
selenium.common.exceptions.TimeoutException: Message: timeout: Timed out receiving message from renderer: 293.300
  (Session info: headless chrome=87.0.4280.88)

Traceback (most recent call last):
  File "/home/ubuntu/trends-script/scraper.py", line 260, in <module>
    main()
  File "/home/ubuntu/trends-script/scraper.py", line 253, in main
    htmlstring = get_html_from_site()
  File "/home/ubuntu/trends-script/scraper.py", line 28, in get_html_from_site
    driver = webdriver.Chrome(options=options)
  File "/home/ubuntu/.local/lib/python3.8/site-packages/selenium/webdriver/chrome/webdriver.py", line 73, in __init__
    self.service.start()
  File "/home/ubuntu/.local/lib/python3.8/site-packages/selenium/webdriver/common/service.py", line 104, in start
    raise WebDriverException("Can not connect to the Service %s" % self.path)
selenium.common.exceptions.WebDriverException: Message: Can not connect to the Service chromedriver

Traceback (most recent call last):
  File "/home/ubuntu/trends-script/scraper.py", line 260, in <module>
    main()
  File "/home/ubuntu/trends-script/scraper.py", line 253, in main
    htmlstring = get_html_from_site()
  File "/home/ubuntu/trends-script/scraper.py", line 31, in get_html_from_site
    driver.get(start_url)
  File "/home/ubuntu/.local/lib/python3.8/site-packages/selenium/webdriver/remote/webdriver.py", line 333, in get
    self.execute(Command.GET, {'url': url})
  File "/home/ubuntu/.local/lib/python3.8/site-packages/selenium/webdriver/remote/webdriver.py", line 321, in execute
    self.error_handler.check_response(response)
  File "/home/ubuntu/.local/lib/python3.8/site-packages/selenium/webdriver/remote/errorhandler.py", line 242, in check_response
    raise exception_class(message, screen, stacktrace)
selenium.common.exceptions.TimeoutException: Message: timeout: Timed out receiving message from renderer: 293.542
  (Session info: headless chrome=87.0.4280.88)

Traceback (most recent call last):
  File "/home/ubuntu/trends-script/scraper.py", line 260, in <module>
    main()
  File "/home/ubuntu/trends-script/scraper.py", line 253, in main
    htmlstring = get_html_from_site()
  File "/home/ubuntu/trends-script/scraper.py", line 28, in get_html_from_site
    driver = webdriver.Chrome(options=options)
  File "/home/ubuntu/.local/lib/python3.8/site-packages/selenium/webdriver/chrome/webdriver.py", line 73, in __init__
    self.service.start()
  File "/home/ubuntu/.local/lib/python3.8/site-packages/selenium/webdriver/common/service.py", line 104, in start
    raise WebDriverException("Can not connect to the Service %s" % self.path)
selenium.common.exceptions.WebDriverException: Message: Can not connect to the Service chromedriver

Traceback (most recent call last):
  File "/home/ubuntu/trends-script/scraper.py", line 260, in <module>
    main()
  File "/home/ubuntu/trends-script/scraper.py", line 253, in main
    htmlstring = get_html_from_site()
  File "/home/ubuntu/trends-script/scraper.py", line 31, in get_html_from_site
    driver.get(start_url)
  File "/home/ubuntu/.local/lib/python3.8/site-packages/selenium/webdriver/remote/webdriver.py", line 333, in get
    self.execute(Command.GET, {'url': url})
  File "/home/ubuntu/.local/lib/python3.8/site-packages/selenium/webdriver/remote/webdriver.py", line 321, in execute
    self.error_handler.check_response(response)
  File "/home/ubuntu/.local/lib/python3.8/site-packages/selenium/webdriver/remote/errorhandler.py", line 242, in check_response
    raise exception_class(message, screen, stacktrace)
selenium.common.exceptions.TimeoutException: Message: timeout: Timed out receiving message from renderer: 292.339
  (Session info: headless chrome=87.0.4280.88)

Traceback (most recent call last):
  File "/home/ubuntu/trends-script/scraper.py", line 260, in <module>
    main()
  File "/home/ubuntu/trends-script/scraper.py", line 253, in main
    htmlstring = get_html_from_site()
  File "/home/ubuntu/trends-script/scraper.py", line 28, in get_html_from_site
    driver = webdriver.Chrome(options=options)
  File "/home/ubuntu/.local/lib/python3.8/site-packages/selenium/webdriver/chrome/webdriver.py", line 73, in __init__
    self.service.start()
  File "/home/ubuntu/.local/lib/python3.8/site-packages/selenium/webdriver/common/service.py", line 104, in start
    raise WebDriverException("Can not connect to the Service %s" % self.path)
selenium.common.exceptions.WebDriverException: Message: Can not connect to the Service chromedriver

Traceback (most recent call last):
  File "/home/ubuntu/trends-script/scraper.py", line 260, in <module>
    main()
  File "/home/ubuntu/trends-script/scraper.py", line 253, in main
    htmlstring = get_html_from_site()
  File "/home/ubuntu/trends-script/scraper.py", line 31, in get_html_from_site
    driver.get(start_url)
  File "/home/ubuntu/.local/lib/python3.8/site-packages/selenium/webdriver/remote/webdriver.py", line 333, in get
    self.execute(Command.GET, {'url': url})
  File "/home/ubuntu/.local/lib/python3.8/site-packages/selenium/webdriver/remote/webdriver.py", line 321, in execute
    self.error_handler.check_response(response)
  File "/home/ubuntu/.local/lib/python3.8/site-packages/selenium/webdriver/remote/errorhandler.py", line 242, in check_response
    raise exception_class(message, screen, stacktrace)
selenium.common.exceptions.TimeoutException: Message: timeout: Timed out receiving message from renderer: 293.124
  (Session info: headless chrome=87.0.4280.88)

Traceback (most recent call last):
  File "/home/ubuntu/trends-script/scraper.py", line 260, in <module>
    main()
  File "/home/ubuntu/trends-script/scraper.py", line 253, in main
    htmlstring = get_html_from_site()
  File "/home/ubuntu/trends-script/scraper.py", line 28, in get_html_from_site
    driver = webdriver.Chrome(options=options)
  File "/home/ubuntu/.local/lib/python3.8/site-packages/selenium/webdriver/chrome/webdriver.py", line 73, in __init__
    self.service.start()
  File "/home/ubuntu/.local/lib/python3.8/site-packages/selenium/webdriver/common/service.py", line 104, in start
    raise WebDriverException("Can not connect to the Service %s" % self.path)
selenium.common.exceptions.WebDriverException: Message: Can not connect to the Service chromedriver

Traceback (most recent call last):
  File "/home/ubuntu/trends-script/scraper.py", line 260, in <module>
    main()
  File "/home/ubuntu/trends-script/scraper.py", line 253, in main
    htmlstring = get_html_from_site()
  File "/home/ubuntu/trends-script/scraper.py", line 31, in get_html_from_site
    driver.get(start_url)
  File "/home/ubuntu/.local/lib/python3.8/site-packages/selenium/webdriver/remote/webdriver.py", line 333, in get
    self.execute(Command.GET, {'url': url})
  File "/home/ubuntu/.local/lib/python3.8/site-packages/selenium/webdriver/remote/webdriver.py", line 321, in execute
    self.error_handler.check_response(response)
  File "/home/ubuntu/.local/lib/python3.8/site-packages/selenium/webdriver/remote/errorhandler.py", line 242, in check_response
    raise exception_class(message, screen, stacktrace)
selenium.common.exceptions.TimeoutException: Message: timeout: Timed out receiving message from renderer: 293.663
  (Session info: headless chrome=87.0.4280.88)

Traceback (most recent call last):
  File "/home/ubuntu/trends-script/scraper.py", line 260, in <module>
    main()
  File "/home/ubuntu/trends-script/scraper.py", line 253, in main
    htmlstring = get_html_from_site()
  File "/home/ubuntu/trends-script/scraper.py", line 28, in get_html_from_site
    driver = webdriver.Chrome(options=options)
  File "/home/ubuntu/.local/lib/python3.8/site-packages/selenium/webdriver/chrome/webdriver.py", line 73, in __init__
    self.service.start()
  File "/home/ubuntu/.local/lib/python3.8/site-packages/selenium/webdriver/common/service.py", line 104, in start
    raise WebDriverException("Can not connect to the Service %s" % self.path)
selenium.common.exceptions.WebDriverException: Message: Can not connect to the Service chromedriver

Traceback (most recent call last):
  File "/home/ubuntu/trends-script/scraper.py", line 260, in <module>
    main()
  File "/home/ubuntu/trends-script/scraper.py", line 253, in main
    htmlstring = get_html_from_site()
  File "/home/ubuntu/trends-script/scraper.py", line 31, in get_html_from_site
    driver.get(start_url)
  File "/home/ubuntu/.local/lib/python3.8/site-packages/selenium/webdriver/remote/webdriver.py", line 333, in get
    self.execute(Command.GET, {'url': url})
  File "/home/ubuntu/.local/lib/python3.8/site-packages/selenium/webdriver/remote/webdriver.py", line 321, in execute
    self.error_handler.check_response(response)
  File "/home/ubuntu/.local/lib/python3.8/site-packages/selenium/webdriver/remote/errorhandler.py", line 242, in check_response
    raise exception_class(message, screen, stacktrace)
selenium.common.exceptions.TimeoutException: Message: timeout: Timed out receiving message from renderer: 294.141
  (Session info: headless chrome=87.0.4280.88)

Traceback (most recent call last):
  File "/home/ubuntu/trends-script/scraper.py", line 260, in <module>
    main()
  File "/home/ubuntu/trends-script/scraper.py", line 253, in main
    htmlstring = get_html_from_site()
  File "/home/ubuntu/trends-script/scraper.py", line 28, in get_html_from_site
    driver = webdriver.Chrome(options=options)
  File "/home/ubuntu/.local/lib/python3.8/site-packages/selenium/webdriver/chrome/webdriver.py", line 73, in __init__
    self.service.start()
  File "/home/ubuntu/.local/lib/python3.8/site-packages/selenium/webdriver/common/service.py", line 104, in start
    raise WebDriverException("Can not connect to the Service %s" % self.path)
selenium.common.exceptions.WebDriverException: Message: Can not connect to the Service chromedriver

Traceback (most recent call last):
  File "/home/ubuntu/trends-script/scraper.py", line 260, in <module>
    main()
  File "/home/ubuntu/trends-script/scraper.py", line 253, in main
    htmlstring = get_html_from_site()
  File "/home/ubuntu/trends-script/scraper.py", line 31, in get_html_from_site
    driver.get(start_url)
  File "/home/ubuntu/.local/lib/python3.8/site-packages/selenium/webdriver/remote/webdriver.py", line 333, in get
    self.execute(Command.GET, {'url': url})
  File "/home/ubuntu/.local/lib/python3.8/site-packages/selenium/webdriver/remote/webdriver.py", line 321, in execute
    self.error_handler.check_response(response)
  File "/home/ubuntu/.local/lib/python3.8/site-packages/selenium/webdriver/remote/errorhandler.py", line 242, in check_response
    raise exception_class(message, screen, stacktrace)
selenium.common.exceptions.TimeoutException: Message: timeout: Timed out receiving message from renderer: 293.941
  (Session info: headless chrome=87.0.4280.88)

Traceback (most recent call last):
  File "/home/ubuntu/trends-script/scraper.py", line 260, in <module>
    main()
  File "/home/ubuntu/trends-script/scraper.py", line 253, in main
    htmlstring = get_html_from_site()
  File "/home/ubuntu/trends-script/scraper.py", line 28, in get_html_from_site
    driver = webdriver.Chrome(options=options)
  File "/home/ubuntu/.local/lib/python3.8/site-packages/selenium/webdriver/chrome/webdriver.py", line 73, in __init__
    self.service.start()
  File "/home/ubuntu/.local/lib/python3.8/site-packages/selenium/webdriver/common/service.py", line 104, in start
    raise WebDriverException("Can not connect to the Service %s" % self.path)
selenium.common.exceptions.WebDriverException: Message: Can not connect to the Service chromedriver

Traceback (most recent call last):
  File "/home/ubuntu/trends-script/scraper.py", line 260, in <module>
    main()
  File "/home/ubuntu/trends-script/scraper.py", line 253, in main
    htmlstring = get_html_from_site()
  File "/home/ubuntu/trends-script/scraper.py", line 31, in get_html_from_site
    driver.get(start_url)
  File "/home/ubuntu/.local/lib/python3.8/site-packages/selenium/webdriver/remote/webdriver.py", line 333, in get
    self.execute(Command.GET, {'url': url})
  File "/home/ubuntu/.local/lib/python3.8/site-packages/selenium/webdriver/remote/webdriver.py", line 321, in execute
    self.error_handler.check_response(response)
  File "/home/ubuntu/.local/lib/python3.8/site-packages/selenium/webdriver/remote/errorhandler.py", line 242, in check_response
    raise exception_class(message, screen, stacktrace)
selenium.common.exceptions.TimeoutException: Message: timeout: Timed out receiving message from renderer: 291.776
  (Session info: headless chrome=87.0.4280.88)

Traceback (most recent call last):
  File "/home/ubuntu/trends-script/scraper.py", line 260, in <module>
    main()
  File "/home/ubuntu/trends-script/scraper.py", line 253, in main
    htmlstring = get_html_from_site()
  File "/home/ubuntu/trends-script/scraper.py", line 28, in get_html_from_site
    driver = webdriver.Chrome(options=options)
  File "/home/ubuntu/.local/lib/python3.8/site-packages/selenium/webdriver/chrome/webdriver.py", line 73, in __init__
    self.service.start()
  File "/home/ubuntu/.local/lib/python3.8/site-packages/selenium/webdriver/common/service.py", line 104, in start
    raise WebDriverException("Can not connect to the Service %s" % self.path)
selenium.common.exceptions.WebDriverException: Message: Can not connect to the Service chromedriver

Traceback (most recent call last):
  File "/home/ubuntu/trends-script/scraper.py", line 260, in <module>
    main()
  File "/home/ubuntu/trends-script/scraper.py", line 253, in main
    htmlstring = get_html_from_site()
  File "/home/ubuntu/trends-script/scraper.py", line 31, in get_html_from_site
    driver.get(start_url)
  File "/home/ubuntu/.local/lib/python3.8/site-packages/selenium/webdriver/remote/webdriver.py", line 333, in get
    self.execute(Command.GET, {'url': url})
  File "/home/ubuntu/.local/lib/python3.8/site-packages/selenium/webdriver/remote/webdriver.py", line 321, in execute
    self.error_handler.check_response(response)
  File "/home/ubuntu/.local/lib/python3.8/site-packages/selenium/webdriver/remote/errorhandler.py", line 242, in check_response
    raise exception_class(message, screen, stacktrace)
selenium.common.exceptions.TimeoutException: Message: timeout: Timed out receiving message from renderer: 291.411
  (Session info: headless chrome=87.0.4280.88)

Traceback (most recent call last):
  File "/home/ubuntu/trends-script/scraper.py", line 260, in <module>
    main()
  File "/home/ubuntu/trends-script/scraper.py", line 253, in main
    htmlstring = get_html_from_site()
  File "/home/ubuntu/trends-script/scraper.py", line 28, in get_html_from_site
    driver = webdriver.Chrome(options=options)
  File "/home/ubuntu/.local/lib/python3.8/site-packages/selenium/webdriver/chrome/webdriver.py", line 73, in __init__
    self.service.start()
  File "/home/ubuntu/.local/lib/python3.8/site-packages/selenium/webdriver/common/service.py", line 104, in start
    raise WebDriverException("Can not connect to the Service %s" % self.path)
selenium.common.exceptions.WebDriverException: Message: Can not connect to the Service chromedriver

Traceback (most recent call last):
  File "/home/ubuntu/trends-script/scraper.py", line 260, in <module>
    main()
  File "/home/ubuntu/trends-script/scraper.py", line 253, in main
    htmlstring = get_html_from_site()
  File "/home/ubuntu/trends-script/scraper.py", line 31, in get_html_from_site
    driver.get(start_url)
  File "/home/ubuntu/.local/lib/python3.8/site-packages/selenium/webdriver/remote/webdriver.py", line 333, in get
    self.execute(Command.GET, {'url': url})
  File "/home/ubuntu/.local/lib/python3.8/site-packages/selenium/webdriver/remote/webdriver.py", line 321, in execute
    self.error_handler.check_response(response)
  File "/home/ubuntu/.local/lib/python3.8/site-packages/selenium/webdriver/remote/errorhandler.py", line 242, in check_response
    raise exception_class(message, screen, stacktrace)
selenium.common.exceptions.TimeoutException: Message: timeout: Timed out receiving message from renderer: 290.493
  (Session info: headless chrome=87.0.4280.88)

Traceback (most recent call last):
  File "/home/ubuntu/trends-script/scraper.py", line 260, in <module>
    main()
  File "/home/ubuntu/trends-script/scraper.py", line 253, in main
    htmlstring = get_html_from_site()
  File "/home/ubuntu/trends-script/scraper.py", line 28, in get_html_from_site
    driver = webdriver.Chrome(options=options)
  File "/home/ubuntu/.local/lib/python3.8/site-packages/selenium/webdriver/chrome/webdriver.py", line 73, in __init__
    self.service.start()
  File "/home/ubuntu/.local/lib/python3.8/site-packages/selenium/webdriver/common/service.py", line 104, in start
    raise WebDriverException("Can not connect to the Service %s" % self.path)
selenium.common.exceptions.WebDriverException: Message: Can not connect to the Service chromedriver

Traceback (most recent call last):
  File "/home/ubuntu/trends-script/scraper.py", line 260, in <module>
    main()
  File "/home/ubuntu/trends-script/scraper.py", line 253, in main
    htmlstring = get_html_from_site()
  File "/home/ubuntu/trends-script/scraper.py", line 31, in get_html_from_site
    driver.get(start_url)
  File "/home/ubuntu/.local/lib/python3.8/site-packages/selenium/webdriver/remote/webdriver.py", line 333, in get
    self.execute(Command.GET, {'url': url})
  File "/home/ubuntu/.local/lib/python3.8/site-packages/selenium/webdriver/remote/webdriver.py", line 321, in execute
    self.error_handler.check_response(response)
  File "/home/ubuntu/.local/lib/python3.8/site-packages/selenium/webdriver/remote/errorhandler.py", line 242, in check_response
    raise exception_class(message, screen, stacktrace)
selenium.common.exceptions.TimeoutException: Message: timeout: Timed out receiving message from renderer: 291.863
  (Session info: headless chrome=87.0.4280.88)

Traceback (most recent call last):
  File "/home/ubuntu/trends-script/scraper.py", line 260, in <module>
    main()
  File "/home/ubuntu/trends-script/scraper.py", line 253, in main
    htmlstring = get_html_from_site()
  File "/home/ubuntu/trends-script/scraper.py", line 28, in get_html_from_site
    driver = webdriver.Chrome(options=options)
  File "/home/ubuntu/.local/lib/python3.8/site-packages/selenium/webdriver/chrome/webdriver.py", line 73, in __init__
    self.service.start()
  File "/home/ubuntu/.local/lib/python3.8/site-packages/selenium/webdriver/common/service.py", line 104, in start
    raise WebDriverException("Can not connect to the Service %s" % self.path)
selenium.common.exceptions.WebDriverException: Message: Can not connect to the Service chromedriver

Traceback (most recent call last):
  File "/home/ubuntu/trends-script/scraper.py", line 260, in <module>
    main()
  File "/home/ubuntu/trends-script/scraper.py", line 253, in main
    htmlstring = get_html_from_site()
  File "/home/ubuntu/trends-script/scraper.py", line 31, in get_html_from_site
    driver.get(start_url)
  File "/home/ubuntu/.local/lib/python3.8/site-packages/selenium/webdriver/remote/webdriver.py", line 333, in get
    self.execute(Command.GET, {'url': url})
  File "/home/ubuntu/.local/lib/python3.8/site-packages/selenium/webdriver/remote/webdriver.py", line 321, in execute
    self.error_handler.check_response(response)
  File "/home/ubuntu/.local/lib/python3.8/site-packages/selenium/webdriver/remote/errorhandler.py", line 242, in check_response
    raise exception_class(message, screen, stacktrace)
selenium.common.exceptions.TimeoutException: Message: timeout: Timed out receiving message from renderer: 290.224
  (Session info: headless chrome=87.0.4280.88)

Traceback (most recent call last):
  File "/home/ubuntu/trends-script/scraper.py", line 260, in <module>
    main()
  File "/home/ubuntu/trends-script/scraper.py", line 253, in main
    htmlstring = get_html_from_site()
  File "/home/ubuntu/trends-script/scraper.py", line 28, in get_html_from_site
    driver = webdriver.Chrome(options=options)
  File "/home/ubuntu/.local/lib/python3.8/site-packages/selenium/webdriver/chrome/webdriver.py", line 73, in __init__
    self.service.start()
  File "/home/ubuntu/.local/lib/python3.8/site-packages/selenium/webdriver/common/service.py", line 104, in start
    raise WebDriverException("Can not connect to the Service %s" % self.path)
selenium.common.exceptions.WebDriverException: Message: Can not connect to the Service chromedriver

Traceback (most recent call last):
  File "/home/ubuntu/trends-script/scraper.py", line 260, in <module>
    main()
  File "/home/ubuntu/trends-script/scraper.py", line 253, in main
    htmlstring = get_html_from_site()
  File "/home/ubuntu/trends-script/scraper.py", line 31, in get_html_from_site
    driver.get(start_url)
  File "/home/ubuntu/.local/lib/python3.8/site-packages/selenium/webdriver/remote/webdriver.py", line 333, in get
    self.execute(Command.GET, {'url': url})
  File "/home/ubuntu/.local/lib/python3.8/site-packages/selenium/webdriver/remote/webdriver.py", line 321, in execute
    self.error_handler.check_response(response)
  File "/home/ubuntu/.local/lib/python3.8/site-packages/selenium/webdriver/remote/errorhandler.py", line 242, in check_response
    raise exception_class(message, screen, stacktrace)
selenium.common.exceptions.TimeoutException: Message: timeout: Timed out receiving message from renderer: 292.884
  (Session info: headless chrome=87.0.4280.88)

Traceback (most recent call last):
  File "/home/ubuntu/trends-script/scraper.py", line 260, in <module>
    main()
  File "/home/ubuntu/trends-script/scraper.py", line 253, in main
    htmlstring = get_html_from_site()
  File "/home/ubuntu/trends-script/scraper.py", line 28, in get_html_from_site
    driver = webdriver.Chrome(options=options)
  File "/home/ubuntu/.local/lib/python3.8/site-packages/selenium/webdriver/chrome/webdriver.py", line 73, in __init__
    self.service.start()
  File "/home/ubuntu/.local/lib/python3.8/site-packages/selenium/webdriver/common/service.py", line 104, in start
    raise WebDriverException("Can not connect to the Service %s" % self.path)
selenium.common.exceptions.WebDriverException: Message: Can not connect to the Service chromedriver

Traceback (most recent call last):
  File "/home/ubuntu/trends-script/scraper.py", line 260, in <module>
    main()
  File "/home/ubuntu/trends-script/scraper.py", line 253, in main
    htmlstring = get_html_from_site()
  File "/home/ubuntu/trends-script/scraper.py", line 31, in get_html_from_site
    driver.get(start_url)
  File "/home/ubuntu/.local/lib/python3.8/site-packages/selenium/webdriver/remote/webdriver.py", line 333, in get
    self.execute(Command.GET, {'url': url})
  File "/home/ubuntu/.local/lib/python3.8/site-packages/selenium/webdriver/remote/webdriver.py", line 321, in execute
    self.error_handler.check_response(response)
  File "/home/ubuntu/.local/lib/python3.8/site-packages/selenium/webdriver/remote/errorhandler.py", line 242, in check_response
    raise exception_class(message, screen, stacktrace)
selenium.common.exceptions.TimeoutException: Message: timeout: Timed out receiving message from renderer: 292.438
  (Session info: headless chrome=87.0.4280.88)

Traceback (most recent call last):
  File "/home/ubuntu/trends-script/scraper.py", line 260, in <module>
    main()
  File "/home/ubuntu/trends-script/scraper.py", line 253, in main
    htmlstring = get_html_from_site()
  File "/home/ubuntu/trends-script/scraper.py", line 28, in get_html_from_site
    driver = webdriver.Chrome(options=options)
  File "/home/ubuntu/.local/lib/python3.8/site-packages/selenium/webdriver/chrome/webdriver.py", line 73, in __init__
    self.service.start()
  File "/home/ubuntu/.local/lib/python3.8/site-packages/selenium/webdriver/common/service.py", line 104, in start
    raise WebDriverException("Can not connect to the Service %s" % self.path)
selenium.common.exceptions.WebDriverException: Message: Can not connect to the Service chromedriver

Traceback (most recent call last):
  File "/home/ubuntu/trends-script/scraper.py", line 260, in <module>
    main()
  File "/home/ubuntu/trends-script/scraper.py", line 253, in main
    htmlstring = get_html_from_site()
  File "/home/ubuntu/trends-script/scraper.py", line 31, in get_html_from_site
    driver.get(start_url)
  File "/home/ubuntu/.local/lib/python3.8/site-packages/selenium/webdriver/remote/webdriver.py", line 333, in get
    self.execute(Command.GET, {'url': url})
  File "/home/ubuntu/.local/lib/python3.8/site-packages/selenium/webdriver/remote/webdriver.py", line 321, in execute
    self.error_handler.check_response(response)
  File "/home/ubuntu/.local/lib/python3.8/site-packages/selenium/webdriver/remote/errorhandler.py", line 242, in check_response
    raise exception_class(message, screen, stacktrace)
selenium.common.exceptions.TimeoutException: Message: timeout: Timed out receiving message from renderer: 291.192
  (Session info: headless chrome=87.0.4280.88)

Traceback (most recent call last):
  File "/home/ubuntu/trends-script/scraper.py", line 260, in <module>
    main()
  File "/home/ubuntu/trends-script/scraper.py", line 253, in main
    htmlstring = get_html_from_site()
  File "/home/ubuntu/trends-script/scraper.py", line 28, in get_html_from_site
    driver = webdriver.Chrome(options=options)
  File "/home/ubuntu/.local/lib/python3.8/site-packages/selenium/webdriver/chrome/webdriver.py", line 73, in __init__
    self.service.start()
  File "/home/ubuntu/.local/lib/python3.8/site-packages/selenium/webdriver/common/service.py", line 104, in start
    raise WebDriverException("Can not connect to the Service %s" % self.path)
selenium.common.exceptions.WebDriverException: Message: Can not connect to the Service chromedriver

Traceback (most recent call last):
  File "/home/ubuntu/trends-script/scraper.py", line 260, in <module>
    main()
  File "/home/ubuntu/trends-script/scraper.py", line 253, in main
    htmlstring = get_html_from_site()
  File "/home/ubuntu/trends-script/scraper.py", line 31, in get_html_from_site
    driver.get(start_url)
  File "/home/ubuntu/.local/lib/python3.8/site-packages/selenium/webdriver/remote/webdriver.py", line 333, in get
    self.execute(Command.GET, {'url': url})
  File "/home/ubuntu/.local/lib/python3.8/site-packages/selenium/webdriver/remote/webdriver.py", line 321, in execute
    self.error_handler.check_response(response)
  File "/home/ubuntu/.local/lib/python3.8/site-packages/selenium/webdriver/remote/errorhandler.py", line 242, in check_response
    raise exception_class(message, screen, stacktrace)
selenium.common.exceptions.TimeoutException: Message: timeout: Timed out receiving message from renderer: 292.319
  (Session info: headless chrome=87.0.4280.88)

Traceback (most recent call last):
  File "/home/ubuntu/trends-script/scraper.py", line 260, in <module>
    main()
  File "/home/ubuntu/trends-script/scraper.py", line 253, in main
    htmlstring = get_html_from_site()
  File "/home/ubuntu/trends-script/scraper.py", line 28, in get_html_from_site
    driver = webdriver.Chrome(options=options)
  File "/home/ubuntu/.local/lib/python3.8/site-packages/selenium/webdriver/chrome/webdriver.py", line 73, in __init__
    self.service.start()
  File "/home/ubuntu/.local/lib/python3.8/site-packages/selenium/webdriver/common/service.py", line 104, in start
    raise WebDriverException("Can not connect to the Service %s" % self.path)
selenium.common.exceptions.WebDriverException: Message: Can not connect to the Service chromedriver

Traceback (most recent call last):
  File "/home/ubuntu/trends-script/scraper.py", line 260, in <module>
    main()
  File "/home/ubuntu/trends-script/scraper.py", line 253, in main
    htmlstring = get_html_from_site()
  File "/home/ubuntu/trends-script/scraper.py", line 31, in get_html_from_site
    driver.get(start_url)
  File "/home/ubuntu/.local/lib/python3.8/site-packages/selenium/webdriver/remote/webdriver.py", line 333, in get
    self.execute(Command.GET, {'url': url})
  File "/home/ubuntu/.local/lib/python3.8/site-packages/selenium/webdriver/remote/webdriver.py", line 321, in execute
    self.error_handler.check_response(response)
  File "/home/ubuntu/.local/lib/python3.8/site-packages/selenium/webdriver/remote/errorhandler.py", line 242, in check_response
    raise exception_class(message, screen, stacktrace)
selenium.common.exceptions.TimeoutException: Message: timeout: Timed out receiving message from renderer: 292.752
  (Session info: headless chrome=87.0.4280.88)

Traceback (most recent call last):
  File "/home/ubuntu/trends-script/scraper.py", line 260, in <module>
    main()
  File "/home/ubuntu/trends-script/scraper.py", line 253, in main
    htmlstring = get_html_from_site()
  File "/home/ubuntu/trends-script/scraper.py", line 28, in get_html_from_site
    driver = webdriver.Chrome(options=options)
  File "/home/ubuntu/.local/lib/python3.8/site-packages/selenium/webdriver/chrome/webdriver.py", line 73, in __init__
    self.service.start()
  File "/home/ubuntu/.local/lib/python3.8/site-packages/selenium/webdriver/common/service.py", line 104, in start
    raise WebDriverException("Can not connect to the Service %s" % self.path)
selenium.common.exceptions.WebDriverException: Message: Can not connect to the Service chromedriver

Traceback (most recent call last):
  File "/home/ubuntu/trends-script/scraper.py", line 260, in <module>
    main()
  File "/home/ubuntu/trends-script/scraper.py", line 253, in main
    htmlstring = get_html_from_site()
  File "/home/ubuntu/trends-script/scraper.py", line 31, in get_html_from_site
    driver.get(start_url)
  File "/home/ubuntu/.local/lib/python3.8/site-packages/selenium/webdriver/remote/webdriver.py", line 333, in get
    self.execute(Command.GET, {'url': url})
  File "/home/ubuntu/.local/lib/python3.8/site-packages/selenium/webdriver/remote/webdriver.py", line 321, in execute
    self.error_handler.check_response(response)
  File "/home/ubuntu/.local/lib/python3.8/site-packages/selenium/webdriver/remote/errorhandler.py", line 242, in check_response
    raise exception_class(message, screen, stacktrace)
selenium.common.exceptions.TimeoutException: Message: timeout: Timed out receiving message from renderer: 293.762
  (Session info: headless chrome=87.0.4280.88)

Traceback (most recent call last):
  File "/home/ubuntu/trends-script/scraper.py", line 260, in <module>
    main()
  File "/home/ubuntu/trends-script/scraper.py", line 253, in main
    htmlstring = get_html_from_site()
  File "/home/ubuntu/trends-script/scraper.py", line 28, in get_html_from_site
    driver = webdriver.Chrome(options=options)
  File "/home/ubuntu/.local/lib/python3.8/site-packages/selenium/webdriver/chrome/webdriver.py", line 73, in __init__
    self.service.start()
  File "/home/ubuntu/.local/lib/python3.8/site-packages/selenium/webdriver/common/service.py", line 104, in start
    raise WebDriverException("Can not connect to the Service %s" % self.path)
selenium.common.exceptions.WebDriverException: Message: Can not connect to the Service chromedriver

Traceback (most recent call last):
  File "/home/ubuntu/trends-script/scraper.py", line 260, in <module>
    main()
  File "/home/ubuntu/trends-script/scraper.py", line 253, in main
    htmlstring = get_html_from_site()
  File "/home/ubuntu/trends-script/scraper.py", line 31, in get_html_from_site
    driver.get(start_url)
  File "/home/ubuntu/.local/lib/python3.8/site-packages/selenium/webdriver/remote/webdriver.py", line 333, in get
    self.execute(Command.GET, {'url': url})
  File "/home/ubuntu/.local/lib/python3.8/site-packages/selenium/webdriver/remote/webdriver.py", line 321, in execute
    self.error_handler.check_response(response)
  File "/home/ubuntu/.local/lib/python3.8/site-packages/selenium/webdriver/remote/errorhandler.py", line 242, in check_response
    raise exception_class(message, screen, stacktrace)
selenium.common.exceptions.TimeoutException: Message: timeout: Timed out receiving message from renderer: 292.454
  (Session info: headless chrome=87.0.4280.88)

Traceback (most recent call last):
  File "/home/ubuntu/trends-script/scraper.py", line 260, in <module>
    main()
  File "/home/ubuntu/trends-script/scraper.py", line 253, in main
    htmlstring = get_html_from_site()
  File "/home/ubuntu/trends-script/scraper.py", line 28, in get_html_from_site
    driver = webdriver.Chrome(options=options)
  File "/home/ubuntu/.local/lib/python3.8/site-packages/selenium/webdriver/chrome/webdriver.py", line 73, in __init__
    self.service.start()
  File "/home/ubuntu/.local/lib/python3.8/site-packages/selenium/webdriver/common/service.py", line 104, in start
    raise WebDriverException("Can not connect to the Service %s" % self.path)
selenium.common.exceptions.WebDriverException: Message: Can not connect to the Service chromedriver

Traceback (most recent call last):
  File "/home/ubuntu/trends-script/scraper.py", line 260, in <module>
    main()
  File "/home/ubuntu/trends-script/scraper.py", line 253, in main
    htmlstring = get_html_from_site()
  File "/home/ubuntu/trends-script/scraper.py", line 31, in get_html_from_site
    driver.get(start_url)
  File "/home/ubuntu/.local/lib/python3.8/site-packages/selenium/webdriver/remote/webdriver.py", line 333, in get
    self.execute(Command.GET, {'url': url})
  File "/home/ubuntu/.local/lib/python3.8/site-packages/selenium/webdriver/remote/webdriver.py", line 321, in execute
    self.error_handler.check_response(response)
  File "/home/ubuntu/.local/lib/python3.8/site-packages/selenium/webdriver/remote/errorhandler.py", line 242, in check_response
    raise exception_class(message, screen, stacktrace)
selenium.common.exceptions.TimeoutException: Message: timeout: Timed out receiving message from renderer: 291.866
  (Session info: headless chrome=87.0.4280.88)

Traceback (most recent call last):
  File "/home/ubuntu/trends-script/scraper.py", line 260, in <module>
    main()
  File "/home/ubuntu/trends-script/scraper.py", line 253, in main
    htmlstring = get_html_from_site()
  File "/home/ubuntu/trends-script/scraper.py", line 28, in get_html_from_site
    driver = webdriver.Chrome(options=options)
  File "/home/ubuntu/.local/lib/python3.8/site-packages/selenium/webdriver/chrome/webdriver.py", line 73, in __init__
    self.service.start()
  File "/home/ubuntu/.local/lib/python3.8/site-packages/selenium/webdriver/common/service.py", line 104, in start
    raise WebDriverException("Can not connect to the Service %s" % self.path)
selenium.common.exceptions.WebDriverException: Message: Can not connect to the Service chromedriver

Traceback (most recent call last):
  File "/home/ubuntu/trends-script/scraper.py", line 260, in <module>
    main()
  File "/home/ubuntu/trends-script/scraper.py", line 253, in main
    htmlstring = get_html_from_site()
  File "/home/ubuntu/trends-script/scraper.py", line 31, in get_html_from_site
    driver.get(start_url)
  File "/home/ubuntu/.local/lib/python3.8/site-packages/selenium/webdriver/remote/webdriver.py", line 333, in get
    self.execute(Command.GET, {'url': url})
  File "/home/ubuntu/.local/lib/python3.8/site-packages/selenium/webdriver/remote/webdriver.py", line 321, in execute
    self.error_handler.check_response(response)
  File "/home/ubuntu/.local/lib/python3.8/site-packages/selenium/webdriver/remote/errorhandler.py", line 242, in check_response
    raise exception_class(message, screen, stacktrace)
selenium.common.exceptions.TimeoutException: Message: timeout: Timed out receiving message from renderer: 292.208
  (Session info: headless chrome=87.0.4280.88)

Traceback (most recent call last):
  File "/home/ubuntu/trends-script/scraper.py", line 260, in <module>
    main()
  File "/home/ubuntu/trends-script/scraper.py", line 253, in main
    htmlstring = get_html_from_site()
  File "/home/ubuntu/trends-script/scraper.py", line 28, in get_html_from_site
    driver = webdriver.Chrome(options=options)
  File "/home/ubuntu/.local/lib/python3.8/site-packages/selenium/webdriver/chrome/webdriver.py", line 73, in __init__
    self.service.start()
  File "/home/ubuntu/.local/lib/python3.8/site-packages/selenium/webdriver/common/service.py", line 104, in start
    raise WebDriverException("Can not connect to the Service %s" % self.path)
selenium.common.exceptions.WebDriverException: Message: Can not connect to the Service chromedriver

Traceback (most recent call last):
  File "/home/ubuntu/trends-script/scraper.py", line 260, in <module>
    main()
  File "/home/ubuntu/trends-script/scraper.py", line 253, in main
    htmlstring = get_html_from_site()
  File "/home/ubuntu/trends-script/scraper.py", line 31, in get_html_from_site
    driver.get(start_url)
  File "/home/ubuntu/.local/lib/python3.8/site-packages/selenium/webdriver/remote/webdriver.py", line 333, in get
    self.execute(Command.GET, {'url': url})
  File "/home/ubuntu/.local/lib/python3.8/site-packages/selenium/webdriver/remote/webdriver.py", line 321, in execute
    self.error_handler.check_response(response)
  File "/home/ubuntu/.local/lib/python3.8/site-packages/selenium/webdriver/remote/errorhandler.py", line 242, in check_response
    raise exception_class(message, screen, stacktrace)
selenium.common.exceptions.WebDriverException: Message: unknown error: session deleted because of page crash
from unknown error: cannot determine loading status
from tab crashed
  (Session info: headless chrome=87.0.4280.88)

Traceback (most recent call last):
  File "/home/ubuntu/trends-script/scraper.py", line 260, in <module>
    main()
  File "/home/ubuntu/trends-script/scraper.py", line 253, in main
    htmlstring = get_html_from_site()
  File "/home/ubuntu/trends-script/scraper.py", line 28, in get_html_from_site
    driver = webdriver.Chrome(options=options)
  File "/home/ubuntu/.local/lib/python3.8/site-packages/selenium/webdriver/chrome/webdriver.py", line 73, in __init__
    self.service.start()
  File "/home/ubuntu/.local/lib/python3.8/site-packages/selenium/webdriver/common/service.py", line 104, in start
    raise WebDriverException("Can not connect to the Service %s" % self.path)
selenium.common.exceptions.WebDriverException: Message: Can not connect to the Service chromedriver

Traceback (most recent call last):
  File "/home/ubuntu/trends-script/scraper.py", line 260, in <module>
    main()
  File "/home/ubuntu/trends-script/scraper.py", line 253, in main
    htmlstring = get_html_from_site()
  File "/home/ubuntu/trends-script/scraper.py", line 31, in get_html_from_site
    driver.get(start_url)
  File "/home/ubuntu/.local/lib/python3.8/site-packages/selenium/webdriver/remote/webdriver.py", line 333, in get
    self.execute(Command.GET, {'url': url})
  File "/home/ubuntu/.local/lib/python3.8/site-packages/selenium/webdriver/remote/webdriver.py", line 321, in execute
    self.error_handler.check_response(response)
  File "/home/ubuntu/.local/lib/python3.8/site-packages/selenium/webdriver/remote/errorhandler.py", line 242, in check_response
    raise exception_class(message, screen, stacktrace)
selenium.common.exceptions.TimeoutException: Message: timeout: Timed out receiving message from renderer: 290.575
  (Session info: headless chrome=87.0.4280.88)

Traceback (most recent call last):
  File "/home/ubuntu/trends-script/scraper.py", line 260, in <module>
    main()
  File "/home/ubuntu/trends-script/scraper.py", line 253, in main
    htmlstring = get_html_from_site()
  File "/home/ubuntu/trends-script/scraper.py", line 28, in get_html_from_site
    driver = webdriver.Chrome(options=options)
  File "/home/ubuntu/.local/lib/python3.8/site-packages/selenium/webdriver/chrome/webdriver.py", line 73, in __init__
    self.service.start()
  File "/home/ubuntu/.local/lib/python3.8/site-packages/selenium/webdriver/common/service.py", line 104, in start
    raise WebDriverException("Can not connect to the Service %s" % self.path)
selenium.common.exceptions.WebDriverException: Message: Can not connect to the Service chromedriver

Traceback (most recent call last):
  File "/home/ubuntu/trends-script/scraper.py", line 260, in <module>
    main()
  File "/home/ubuntu/trends-script/scraper.py", line 253, in main
    htmlstring = get_html_from_site()
  File "/home/ubuntu/trends-script/scraper.py", line 31, in get_html_from_site
    driver.get(start_url)
  File "/home/ubuntu/.local/lib/python3.8/site-packages/selenium/webdriver/remote/webdriver.py", line 333, in get
    self.execute(Command.GET, {'url': url})
  File "/home/ubuntu/.local/lib/python3.8/site-packages/selenium/webdriver/remote/webdriver.py", line 321, in execute
    self.error_handler.check_response(response)
  File "/home/ubuntu/.local/lib/python3.8/site-packages/selenium/webdriver/remote/errorhandler.py", line 242, in check_response
    raise exception_class(message, screen, stacktrace)
selenium.common.exceptions.TimeoutException: Message: timeout: Timed out receiving message from renderer: 276.359
  (Session info: headless chrome=87.0.4280.88)

