Traceback (most recent call last):
  File "/home/ubuntu/trends-script/scraper.py", line 260, in <module>
    main()
  File "/home/ubuntu/trends-script/scraper.py", line 253, in main
    htmlstring = get_html_from_site()
  File "/home/ubuntu/trends-script/scraper.py", line 28, in get_html_from_site
    driver = webdriver.Chrome(options=options)
  File "/home/ubuntu/.local/lib/python3.8/site-packages/selenium/webdriver/chrome/webdriver.py", line 73, in __init__
    self.service.start()
  File "/home/ubuntu/.local/lib/python3.8/site-packages/selenium/webdriver/common/service.py", line 104, in start
    raise WebDriverException("Can not connect to the Service %s" % self.path)
selenium.common.exceptions.WebDriverException: Message: Can not connect to the Service chromedriver

Traceback (most recent call last):
  File "/home/ubuntu/trends-script/scraper.py", line 260, in <module>
    main()
  File "/home/ubuntu/trends-script/scraper.py", line 253, in main
    htmlstring = get_html_from_site()
  File "/home/ubuntu/trends-script/scraper.py", line 28, in get_html_from_site
    driver = webdriver.Chrome(options=options)
  File "/home/ubuntu/.local/lib/python3.8/site-packages/selenium/webdriver/chrome/webdriver.py", line 73, in __init__
    self.service.start()
  File "/home/ubuntu/.local/lib/python3.8/site-packages/selenium/webdriver/common/service.py", line 104, in start
    raise WebDriverException("Can not connect to the Service %s" % self.path)
selenium.common.exceptions.WebDriverException: Message: Can not connect to the Service chromedriver

Traceback (most recent call last):
  File "/home/ubuntu/trends-script/scraper.py", line 260, in <module>
    main()
  File "/home/ubuntu/trends-script/scraper.py", line 253, in main
    htmlstring = get_html_from_site()
  File "/home/ubuntu/trends-script/scraper.py", line 31, in get_html_from_site
    driver.get(start_url)
  File "/home/ubuntu/.local/lib/python3.8/site-packages/selenium/webdriver/remote/webdriver.py", line 333, in get
    self.execute(Command.GET, {'url': url})
  File "/home/ubuntu/.local/lib/python3.8/site-packages/selenium/webdriver/remote/webdriver.py", line 321, in execute
    self.error_handler.check_response(response)
  File "/home/ubuntu/.local/lib/python3.8/site-packages/selenium/webdriver/remote/errorhandler.py", line 242, in check_response
    raise exception_class(message, screen, stacktrace)
selenium.common.exceptions.TimeoutException: Message: timeout: Timed out receiving message from renderer: 289.654
  (Session info: headless chrome=87.0.4280.88)

Traceback (most recent call last):
  File "/home/ubuntu/trends-script/scraper.py", line 260, in <module>
    main()
  File "/home/ubuntu/trends-script/scraper.py", line 253, in main
    htmlstring = get_html_from_site()
  File "/home/ubuntu/trends-script/scraper.py", line 28, in get_html_from_site
    driver = webdriver.Chrome(options=options)
  File "/home/ubuntu/.local/lib/python3.8/site-packages/selenium/webdriver/chrome/webdriver.py", line 73, in __init__
    self.service.start()
  File "/home/ubuntu/.local/lib/python3.8/site-packages/selenium/webdriver/common/service.py", line 104, in start
    raise WebDriverException("Can not connect to the Service %s" % self.path)
selenium.common.exceptions.WebDriverException: Message: Can not connect to the Service chromedriver

Traceback (most recent call last):
  File "/home/ubuntu/trends-script/scraper.py", line 260, in <module>
    main()
  File "/home/ubuntu/trends-script/scraper.py", line 253, in main
    htmlstring = get_html_from_site()
  File "/home/ubuntu/trends-script/scraper.py", line 31, in get_html_from_site
    driver.get(start_url)
  File "/home/ubuntu/.local/lib/python3.8/site-packages/selenium/webdriver/remote/webdriver.py", line 333, in get
    self.execute(Command.GET, {'url': url})
  File "/home/ubuntu/.local/lib/python3.8/site-packages/selenium/webdriver/remote/webdriver.py", line 321, in execute
    self.error_handler.check_response(response)
  File "/home/ubuntu/.local/lib/python3.8/site-packages/selenium/webdriver/remote/errorhandler.py", line 242, in check_response
    raise exception_class(message, screen, stacktrace)
selenium.common.exceptions.TimeoutException: Message: timeout: Timed out receiving message from renderer: 288.829
  (Session info: headless chrome=87.0.4280.88)

Traceback (most recent call last):
  File "/home/ubuntu/trends-script/scraper.py", line 260, in <module>
    main()
  File "/home/ubuntu/trends-script/scraper.py", line 253, in main
    htmlstring = get_html_from_site()
  File "/home/ubuntu/trends-script/scraper.py", line 28, in get_html_from_site
    driver = webdriver.Chrome(options=options)
  File "/home/ubuntu/.local/lib/python3.8/site-packages/selenium/webdriver/chrome/webdriver.py", line 73, in __init__
    self.service.start()
  File "/home/ubuntu/.local/lib/python3.8/site-packages/selenium/webdriver/common/service.py", line 104, in start
    raise WebDriverException("Can not connect to the Service %s" % self.path)
selenium.common.exceptions.WebDriverException: Message: Can not connect to the Service chromedriver

Traceback (most recent call last):
  File "/home/ubuntu/trends-script/scraper.py", line 260, in <module>
    main()
  File "/home/ubuntu/trends-script/scraper.py", line 253, in main
    htmlstring = get_html_from_site()
  File "/home/ubuntu/trends-script/scraper.py", line 31, in get_html_from_site
    driver.get(start_url)
  File "/home/ubuntu/.local/lib/python3.8/site-packages/selenium/webdriver/remote/webdriver.py", line 333, in get
    self.execute(Command.GET, {'url': url})
  File "/home/ubuntu/.local/lib/python3.8/site-packages/selenium/webdriver/remote/webdriver.py", line 321, in execute
    self.error_handler.check_response(response)
  File "/home/ubuntu/.local/lib/python3.8/site-packages/selenium/webdriver/remote/errorhandler.py", line 242, in check_response
    raise exception_class(message, screen, stacktrace)
selenium.common.exceptions.TimeoutException: Message: timeout: Timed out receiving message from renderer: 287.224
  (Session info: headless chrome=87.0.4280.88)

Traceback (most recent call last):
  File "/home/ubuntu/trends-script/scraper.py", line 260, in <module>
    main()
  File "/home/ubuntu/trends-script/scraper.py", line 253, in main
    htmlstring = get_html_from_site()
  File "/home/ubuntu/trends-script/scraper.py", line 28, in get_html_from_site
    driver = webdriver.Chrome(options=options)
  File "/home/ubuntu/.local/lib/python3.8/site-packages/selenium/webdriver/chrome/webdriver.py", line 73, in __init__
    self.service.start()
  File "/home/ubuntu/.local/lib/python3.8/site-packages/selenium/webdriver/common/service.py", line 104, in start
    raise WebDriverException("Can not connect to the Service %s" % self.path)
selenium.common.exceptions.WebDriverException: Message: Can not connect to the Service chromedriver

Traceback (most recent call last):
  File "/home/ubuntu/trends-script/scraper.py", line 260, in <module>
    main()
  File "/home/ubuntu/trends-script/scraper.py", line 253, in main
    htmlstring = get_html_from_site()
  File "/home/ubuntu/trends-script/scraper.py", line 31, in get_html_from_site
    driver.get(start_url)
  File "/home/ubuntu/.local/lib/python3.8/site-packages/selenium/webdriver/remote/webdriver.py", line 333, in get
    self.execute(Command.GET, {'url': url})
  File "/home/ubuntu/.local/lib/python3.8/site-packages/selenium/webdriver/remote/webdriver.py", line 321, in execute
    self.error_handler.check_response(response)
  File "/home/ubuntu/.local/lib/python3.8/site-packages/selenium/webdriver/remote/errorhandler.py", line 242, in check_response
    raise exception_class(message, screen, stacktrace)
selenium.common.exceptions.TimeoutException: Message: timeout: Timed out receiving message from renderer: 289.659
  (Session info: headless chrome=87.0.4280.88)

Traceback (most recent call last):
  File "/home/ubuntu/trends-script/scraper.py", line 260, in <module>
    main()
  File "/home/ubuntu/trends-script/scraper.py", line 253, in main
    htmlstring = get_html_from_site()
  File "/home/ubuntu/trends-script/scraper.py", line 28, in get_html_from_site
    driver = webdriver.Chrome(options=options)
  File "/home/ubuntu/.local/lib/python3.8/site-packages/selenium/webdriver/chrome/webdriver.py", line 73, in __init__
    self.service.start()
  File "/home/ubuntu/.local/lib/python3.8/site-packages/selenium/webdriver/common/service.py", line 104, in start
    raise WebDriverException("Can not connect to the Service %s" % self.path)
selenium.common.exceptions.WebDriverException: Message: Can not connect to the Service chromedriver

Traceback (most recent call last):
  File "/home/ubuntu/trends-script/scraper.py", line 260, in <module>
    main()
  File "/home/ubuntu/trends-script/scraper.py", line 253, in main
    htmlstring = get_html_from_site()
  File "/home/ubuntu/trends-script/scraper.py", line 31, in get_html_from_site
    driver.get(start_url)
  File "/home/ubuntu/.local/lib/python3.8/site-packages/selenium/webdriver/remote/webdriver.py", line 333, in get
    self.execute(Command.GET, {'url': url})
  File "/home/ubuntu/.local/lib/python3.8/site-packages/selenium/webdriver/remote/webdriver.py", line 321, in execute
    self.error_handler.check_response(response)
  File "/home/ubuntu/.local/lib/python3.8/site-packages/selenium/webdriver/remote/errorhandler.py", line 242, in check_response
    raise exception_class(message, screen, stacktrace)
selenium.common.exceptions.TimeoutException: Message: timeout: Timed out receiving message from renderer: 286.128
  (Session info: headless chrome=87.0.4280.88)

Traceback (most recent call last):
  File "/home/ubuntu/trends-script/scraper.py", line 260, in <module>
    main()
  File "/home/ubuntu/trends-script/scraper.py", line 253, in main
    htmlstring = get_html_from_site()
  File "/home/ubuntu/trends-script/scraper.py", line 28, in get_html_from_site
    driver = webdriver.Chrome(options=options)
  File "/home/ubuntu/.local/lib/python3.8/site-packages/selenium/webdriver/chrome/webdriver.py", line 73, in __init__
    self.service.start()
  File "/home/ubuntu/.local/lib/python3.8/site-packages/selenium/webdriver/common/service.py", line 104, in start
    raise WebDriverException("Can not connect to the Service %s" % self.path)
selenium.common.exceptions.WebDriverException: Message: Can not connect to the Service chromedriver

Traceback (most recent call last):
  File "/home/ubuntu/trends-script/scraper.py", line 260, in <module>
    main()
  File "/home/ubuntu/trends-script/scraper.py", line 253, in main
    htmlstring = get_html_from_site()
  File "/home/ubuntu/trends-script/scraper.py", line 31, in get_html_from_site
    driver.get(start_url)
  File "/home/ubuntu/.local/lib/python3.8/site-packages/selenium/webdriver/remote/webdriver.py", line 333, in get
    self.execute(Command.GET, {'url': url})
  File "/home/ubuntu/.local/lib/python3.8/site-packages/selenium/webdriver/remote/webdriver.py", line 321, in execute
    self.error_handler.check_response(response)
  File "/home/ubuntu/.local/lib/python3.8/site-packages/selenium/webdriver/remote/errorhandler.py", line 242, in check_response
    raise exception_class(message, screen, stacktrace)
selenium.common.exceptions.TimeoutException: Message: timeout: Timed out receiving message from renderer: 286.405
  (Session info: headless chrome=87.0.4280.88)

Traceback (most recent call last):
  File "/home/ubuntu/trends-script/scraper.py", line 260, in <module>
    main()
  File "/home/ubuntu/trends-script/scraper.py", line 253, in main
    htmlstring = get_html_from_site()
  File "/home/ubuntu/trends-script/scraper.py", line 28, in get_html_from_site
    driver = webdriver.Chrome(options=options)
  File "/home/ubuntu/.local/lib/python3.8/site-packages/selenium/webdriver/chrome/webdriver.py", line 73, in __init__
    self.service.start()
  File "/home/ubuntu/.local/lib/python3.8/site-packages/selenium/webdriver/common/service.py", line 104, in start
    raise WebDriverException("Can not connect to the Service %s" % self.path)
selenium.common.exceptions.WebDriverException: Message: Can not connect to the Service chromedriver

Traceback (most recent call last):
  File "/home/ubuntu/trends-script/scraper.py", line 260, in <module>
    main()
  File "/home/ubuntu/trends-script/scraper.py", line 253, in main
    htmlstring = get_html_from_site()
  File "/home/ubuntu/trends-script/scraper.py", line 31, in get_html_from_site
    driver.get(start_url)
  File "/home/ubuntu/.local/lib/python3.8/site-packages/selenium/webdriver/remote/webdriver.py", line 333, in get
    self.execute(Command.GET, {'url': url})
  File "/home/ubuntu/.local/lib/python3.8/site-packages/selenium/webdriver/remote/webdriver.py", line 321, in execute
    self.error_handler.check_response(response)
  File "/home/ubuntu/.local/lib/python3.8/site-packages/selenium/webdriver/remote/errorhandler.py", line 242, in check_response
    raise exception_class(message, screen, stacktrace)
selenium.common.exceptions.TimeoutException: Message: timeout: Timed out receiving message from renderer: 288.244
  (Session info: headless chrome=87.0.4280.88)

Traceback (most recent call last):
  File "/home/ubuntu/trends-script/scraper.py", line 260, in <module>
    main()
  File "/home/ubuntu/trends-script/scraper.py", line 253, in main
    htmlstring = get_html_from_site()
  File "/home/ubuntu/trends-script/scraper.py", line 28, in get_html_from_site
    driver = webdriver.Chrome(options=options)
  File "/home/ubuntu/.local/lib/python3.8/site-packages/selenium/webdriver/chrome/webdriver.py", line 73, in __init__
    self.service.start()
  File "/home/ubuntu/.local/lib/python3.8/site-packages/selenium/webdriver/common/service.py", line 104, in start
    raise WebDriverException("Can not connect to the Service %s" % self.path)
selenium.common.exceptions.WebDriverException: Message: Can not connect to the Service chromedriver

Traceback (most recent call last):
  File "/home/ubuntu/trends-script/scraper.py", line 260, in <module>
    main()
  File "/home/ubuntu/trends-script/scraper.py", line 253, in main
    htmlstring = get_html_from_site()
  File "/home/ubuntu/trends-script/scraper.py", line 31, in get_html_from_site
    driver.get(start_url)
  File "/home/ubuntu/.local/lib/python3.8/site-packages/selenium/webdriver/remote/webdriver.py", line 333, in get
    self.execute(Command.GET, {'url': url})
  File "/home/ubuntu/.local/lib/python3.8/site-packages/selenium/webdriver/remote/webdriver.py", line 321, in execute
    self.error_handler.check_response(response)
  File "/home/ubuntu/.local/lib/python3.8/site-packages/selenium/webdriver/remote/errorhandler.py", line 242, in check_response
    raise exception_class(message, screen, stacktrace)
selenium.common.exceptions.TimeoutException: Message: timeout: Timed out receiving message from renderer: 289.423
  (Session info: headless chrome=87.0.4280.88)

Traceback (most recent call last):
  File "/home/ubuntu/trends-script/scraper.py", line 260, in <module>
    main()
  File "/home/ubuntu/trends-script/scraper.py", line 253, in main
    htmlstring = get_html_from_site()
  File "/home/ubuntu/trends-script/scraper.py", line 28, in get_html_from_site
    driver = webdriver.Chrome(options=options)
  File "/home/ubuntu/.local/lib/python3.8/site-packages/selenium/webdriver/chrome/webdriver.py", line 73, in __init__
    self.service.start()
  File "/home/ubuntu/.local/lib/python3.8/site-packages/selenium/webdriver/common/service.py", line 104, in start
    raise WebDriverException("Can not connect to the Service %s" % self.path)
selenium.common.exceptions.WebDriverException: Message: Can not connect to the Service chromedriver

Traceback (most recent call last):
  File "/home/ubuntu/trends-script/scraper.py", line 260, in <module>
    main()
  File "/home/ubuntu/trends-script/scraper.py", line 253, in main
    htmlstring = get_html_from_site()
  File "/home/ubuntu/trends-script/scraper.py", line 31, in get_html_from_site
    driver.get(start_url)
  File "/home/ubuntu/.local/lib/python3.8/site-packages/selenium/webdriver/remote/webdriver.py", line 333, in get
    self.execute(Command.GET, {'url': url})
  File "/home/ubuntu/.local/lib/python3.8/site-packages/selenium/webdriver/remote/webdriver.py", line 321, in execute
    self.error_handler.check_response(response)
  File "/home/ubuntu/.local/lib/python3.8/site-packages/selenium/webdriver/remote/errorhandler.py", line 242, in check_response
    raise exception_class(message, screen, stacktrace)
selenium.common.exceptions.TimeoutException: Message: timeout: Timed out receiving message from renderer: 286.710
  (Session info: headless chrome=87.0.4280.88)

Traceback (most recent call last):
  File "/home/ubuntu/trends-script/scraper.py", line 260, in <module>
    main()
  File "/home/ubuntu/trends-script/scraper.py", line 253, in main
    htmlstring = get_html_from_site()
  File "/home/ubuntu/trends-script/scraper.py", line 28, in get_html_from_site
    driver = webdriver.Chrome(options=options)
  File "/home/ubuntu/.local/lib/python3.8/site-packages/selenium/webdriver/chrome/webdriver.py", line 73, in __init__
    self.service.start()
  File "/home/ubuntu/.local/lib/python3.8/site-packages/selenium/webdriver/common/service.py", line 104, in start
    raise WebDriverException("Can not connect to the Service %s" % self.path)
selenium.common.exceptions.WebDriverException: Message: Can not connect to the Service chromedriver

Traceback (most recent call last):
  File "/home/ubuntu/trends-script/scraper.py", line 260, in <module>
    main()
  File "/home/ubuntu/trends-script/scraper.py", line 253, in main
    htmlstring = get_html_from_site()
  File "/home/ubuntu/trends-script/scraper.py", line 31, in get_html_from_site
    driver.get(start_url)
  File "/home/ubuntu/.local/lib/python3.8/site-packages/selenium/webdriver/remote/webdriver.py", line 333, in get
    self.execute(Command.GET, {'url': url})
  File "/home/ubuntu/.local/lib/python3.8/site-packages/selenium/webdriver/remote/webdriver.py", line 321, in execute
    self.error_handler.check_response(response)
  File "/home/ubuntu/.local/lib/python3.8/site-packages/selenium/webdriver/remote/errorhandler.py", line 242, in check_response
    raise exception_class(message, screen, stacktrace)
selenium.common.exceptions.TimeoutException: Message: timeout: Timed out receiving message from renderer: 286.668
  (Session info: headless chrome=87.0.4280.88)

Traceback (most recent call last):
  File "/home/ubuntu/trends-script/scraper.py", line 260, in <module>
    main()
  File "/home/ubuntu/trends-script/scraper.py", line 253, in main
    htmlstring = get_html_from_site()
  File "/home/ubuntu/trends-script/scraper.py", line 28, in get_html_from_site
    driver = webdriver.Chrome(options=options)
  File "/home/ubuntu/.local/lib/python3.8/site-packages/selenium/webdriver/chrome/webdriver.py", line 73, in __init__
    self.service.start()
  File "/home/ubuntu/.local/lib/python3.8/site-packages/selenium/webdriver/common/service.py", line 104, in start
    raise WebDriverException("Can not connect to the Service %s" % self.path)
selenium.common.exceptions.WebDriverException: Message: Can not connect to the Service chromedriver

Traceback (most recent call last):
  File "/home/ubuntu/trends-script/scraper.py", line 260, in <module>
    main()
  File "/home/ubuntu/trends-script/scraper.py", line 253, in main
    htmlstring = get_html_from_site()
  File "/home/ubuntu/trends-script/scraper.py", line 31, in get_html_from_site
    driver.get(start_url)
  File "/home/ubuntu/.local/lib/python3.8/site-packages/selenium/webdriver/remote/webdriver.py", line 333, in get
    self.execute(Command.GET, {'url': url})
  File "/home/ubuntu/.local/lib/python3.8/site-packages/selenium/webdriver/remote/webdriver.py", line 321, in execute
    self.error_handler.check_response(response)
  File "/home/ubuntu/.local/lib/python3.8/site-packages/selenium/webdriver/remote/errorhandler.py", line 242, in check_response
    raise exception_class(message, screen, stacktrace)
selenium.common.exceptions.TimeoutException: Message: timeout: Timed out receiving message from renderer: 287.041
  (Session info: headless chrome=87.0.4280.88)

Traceback (most recent call last):
  File "/home/ubuntu/trends-script/scraper.py", line 260, in <module>
    main()
  File "/home/ubuntu/trends-script/scraper.py", line 253, in main
    htmlstring = get_html_from_site()
  File "/home/ubuntu/trends-script/scraper.py", line 28, in get_html_from_site
    driver = webdriver.Chrome(options=options)
  File "/home/ubuntu/.local/lib/python3.8/site-packages/selenium/webdriver/chrome/webdriver.py", line 73, in __init__
    self.service.start()
  File "/home/ubuntu/.local/lib/python3.8/site-packages/selenium/webdriver/common/service.py", line 104, in start
    raise WebDriverException("Can not connect to the Service %s" % self.path)
selenium.common.exceptions.WebDriverException: Message: Can not connect to the Service chromedriver

Traceback (most recent call last):
  File "/home/ubuntu/trends-script/scraper.py", line 260, in <module>
    main()
  File "/home/ubuntu/trends-script/scraper.py", line 253, in main
    htmlstring = get_html_from_site()
  File "/home/ubuntu/trends-script/scraper.py", line 31, in get_html_from_site
    driver.get(start_url)
  File "/home/ubuntu/.local/lib/python3.8/site-packages/selenium/webdriver/remote/webdriver.py", line 333, in get
    self.execute(Command.GET, {'url': url})
  File "/home/ubuntu/.local/lib/python3.8/site-packages/selenium/webdriver/remote/webdriver.py", line 321, in execute
    self.error_handler.check_response(response)
  File "/home/ubuntu/.local/lib/python3.8/site-packages/selenium/webdriver/remote/errorhandler.py", line 242, in check_response
    raise exception_class(message, screen, stacktrace)
selenium.common.exceptions.TimeoutException: Message: timeout: Timed out receiving message from renderer: 290.457
  (Session info: headless chrome=87.0.4280.88)

Traceback (most recent call last):
  File "/home/ubuntu/trends-script/scraper.py", line 260, in <module>
    main()
  File "/home/ubuntu/trends-script/scraper.py", line 253, in main
    htmlstring = get_html_from_site()
  File "/home/ubuntu/trends-script/scraper.py", line 28, in get_html_from_site
    driver = webdriver.Chrome(options=options)
  File "/home/ubuntu/.local/lib/python3.8/site-packages/selenium/webdriver/chrome/webdriver.py", line 73, in __init__
    self.service.start()
  File "/home/ubuntu/.local/lib/python3.8/site-packages/selenium/webdriver/common/service.py", line 104, in start
    raise WebDriverException("Can not connect to the Service %s" % self.path)
selenium.common.exceptions.WebDriverException: Message: Can not connect to the Service chromedriver

Traceback (most recent call last):
  File "/home/ubuntu/trends-script/scraper.py", line 260, in <module>
    main()
  File "/home/ubuntu/trends-script/scraper.py", line 253, in main
    htmlstring = get_html_from_site()
  File "/home/ubuntu/trends-script/scraper.py", line 31, in get_html_from_site
    driver.get(start_url)
  File "/home/ubuntu/.local/lib/python3.8/site-packages/selenium/webdriver/remote/webdriver.py", line 333, in get
    self.execute(Command.GET, {'url': url})
  File "/home/ubuntu/.local/lib/python3.8/site-packages/selenium/webdriver/remote/webdriver.py", line 321, in execute
    self.error_handler.check_response(response)
  File "/home/ubuntu/.local/lib/python3.8/site-packages/selenium/webdriver/remote/errorhandler.py", line 242, in check_response
    raise exception_class(message, screen, stacktrace)
selenium.common.exceptions.TimeoutException: Message: timeout: Timed out receiving message from renderer: 285.714
  (Session info: headless chrome=87.0.4280.88)

Traceback (most recent call last):
  File "/home/ubuntu/trends-script/scraper.py", line 260, in <module>
    main()
  File "/home/ubuntu/trends-script/scraper.py", line 253, in main
    htmlstring = get_html_from_site()
  File "/home/ubuntu/trends-script/scraper.py", line 28, in get_html_from_site
    driver = webdriver.Chrome(options=options)
  File "/home/ubuntu/.local/lib/python3.8/site-packages/selenium/webdriver/chrome/webdriver.py", line 73, in __init__
    self.service.start()
  File "/home/ubuntu/.local/lib/python3.8/site-packages/selenium/webdriver/common/service.py", line 104, in start
    raise WebDriverException("Can not connect to the Service %s" % self.path)
selenium.common.exceptions.WebDriverException: Message: Can not connect to the Service chromedriver

Traceback (most recent call last):
  File "/home/ubuntu/trends-script/scraper.py", line 260, in <module>
    main()
  File "/home/ubuntu/trends-script/scraper.py", line 253, in main
    htmlstring = get_html_from_site()
  File "/home/ubuntu/trends-script/scraper.py", line 31, in get_html_from_site
    driver.get(start_url)
  File "/home/ubuntu/.local/lib/python3.8/site-packages/selenium/webdriver/remote/webdriver.py", line 333, in get
    self.execute(Command.GET, {'url': url})
  File "/home/ubuntu/.local/lib/python3.8/site-packages/selenium/webdriver/remote/webdriver.py", line 321, in execute
    self.error_handler.check_response(response)
  File "/home/ubuntu/.local/lib/python3.8/site-packages/selenium/webdriver/remote/errorhandler.py", line 242, in check_response
    raise exception_class(message, screen, stacktrace)
selenium.common.exceptions.TimeoutException: Message: timeout: Timed out receiving message from renderer: 283.630
  (Session info: headless chrome=87.0.4280.88)

Traceback (most recent call last):
  File "/home/ubuntu/trends-script/scraper.py", line 260, in <module>
    main()
  File "/home/ubuntu/trends-script/scraper.py", line 253, in main
    htmlstring = get_html_from_site()
  File "/home/ubuntu/trends-script/scraper.py", line 28, in get_html_from_site
    driver = webdriver.Chrome(options=options)
  File "/home/ubuntu/.local/lib/python3.8/site-packages/selenium/webdriver/chrome/webdriver.py", line 73, in __init__
    self.service.start()
  File "/home/ubuntu/.local/lib/python3.8/site-packages/selenium/webdriver/common/service.py", line 104, in start
    raise WebDriverException("Can not connect to the Service %s" % self.path)
selenium.common.exceptions.WebDriverException: Message: Can not connect to the Service chromedriver

Traceback (most recent call last):
  File "/home/ubuntu/trends-script/scraper.py", line 260, in <module>
    main()
  File "/home/ubuntu/trends-script/scraper.py", line 253, in main
    htmlstring = get_html_from_site()
  File "/home/ubuntu/trends-script/scraper.py", line 31, in get_html_from_site
    driver.get(start_url)
  File "/home/ubuntu/.local/lib/python3.8/site-packages/selenium/webdriver/remote/webdriver.py", line 333, in get
    self.execute(Command.GET, {'url': url})
  File "/home/ubuntu/.local/lib/python3.8/site-packages/selenium/webdriver/remote/webdriver.py", line 321, in execute
    self.error_handler.check_response(response)
  File "/home/ubuntu/.local/lib/python3.8/site-packages/selenium/webdriver/remote/errorhandler.py", line 242, in check_response
    raise exception_class(message, screen, stacktrace)
selenium.common.exceptions.TimeoutException: Message: timeout: Timed out receiving message from renderer: 289.269
  (Session info: headless chrome=87.0.4280.88)

Traceback (most recent call last):
  File "/home/ubuntu/trends-script/scraper.py", line 260, in <module>
    main()
  File "/home/ubuntu/trends-script/scraper.py", line 253, in main
    htmlstring = get_html_from_site()
  File "/home/ubuntu/trends-script/scraper.py", line 28, in get_html_from_site
    driver = webdriver.Chrome(options=options)
  File "/home/ubuntu/.local/lib/python3.8/site-packages/selenium/webdriver/chrome/webdriver.py", line 73, in __init__
    self.service.start()
  File "/home/ubuntu/.local/lib/python3.8/site-packages/selenium/webdriver/common/service.py", line 104, in start
    raise WebDriverException("Can not connect to the Service %s" % self.path)
selenium.common.exceptions.WebDriverException: Message: Can not connect to the Service chromedriver

Traceback (most recent call last):
  File "/home/ubuntu/trends-script/scraper.py", line 260, in <module>
    main()
  File "/home/ubuntu/trends-script/scraper.py", line 253, in main
    htmlstring = get_html_from_site()
  File "/home/ubuntu/trends-script/scraper.py", line 31, in get_html_from_site
    driver.get(start_url)
  File "/home/ubuntu/.local/lib/python3.8/site-packages/selenium/webdriver/remote/webdriver.py", line 333, in get
    self.execute(Command.GET, {'url': url})
  File "/home/ubuntu/.local/lib/python3.8/site-packages/selenium/webdriver/remote/webdriver.py", line 321, in execute
    self.error_handler.check_response(response)
  File "/home/ubuntu/.local/lib/python3.8/site-packages/selenium/webdriver/remote/errorhandler.py", line 242, in check_response
    raise exception_class(message, screen, stacktrace)
selenium.common.exceptions.TimeoutException: Message: timeout: Timed out receiving message from renderer: 288.181
  (Session info: headless chrome=87.0.4280.88)

Traceback (most recent call last):
  File "/home/ubuntu/trends-script/scraper.py", line 260, in <module>
    main()
  File "/home/ubuntu/trends-script/scraper.py", line 253, in main
    htmlstring = get_html_from_site()
  File "/home/ubuntu/trends-script/scraper.py", line 28, in get_html_from_site
    driver = webdriver.Chrome(options=options)
  File "/home/ubuntu/.local/lib/python3.8/site-packages/selenium/webdriver/chrome/webdriver.py", line 73, in __init__
    self.service.start()
  File "/home/ubuntu/.local/lib/python3.8/site-packages/selenium/webdriver/common/service.py", line 104, in start
    raise WebDriverException("Can not connect to the Service %s" % self.path)
selenium.common.exceptions.WebDriverException: Message: Can not connect to the Service chromedriver

Traceback (most recent call last):
  File "/home/ubuntu/trends-script/scraper.py", line 260, in <module>
    main()
  File "/home/ubuntu/trends-script/scraper.py", line 253, in main
    htmlstring = get_html_from_site()
  File "/home/ubuntu/trends-script/scraper.py", line 31, in get_html_from_site
    driver.get(start_url)
  File "/home/ubuntu/.local/lib/python3.8/site-packages/selenium/webdriver/remote/webdriver.py", line 333, in get
    self.execute(Command.GET, {'url': url})
  File "/home/ubuntu/.local/lib/python3.8/site-packages/selenium/webdriver/remote/webdriver.py", line 321, in execute
    self.error_handler.check_response(response)
  File "/home/ubuntu/.local/lib/python3.8/site-packages/selenium/webdriver/remote/errorhandler.py", line 242, in check_response
    raise exception_class(message, screen, stacktrace)
selenium.common.exceptions.TimeoutException: Message: timeout: Timed out receiving message from renderer: 287.524
  (Session info: headless chrome=87.0.4280.88)

Traceback (most recent call last):
  File "/home/ubuntu/trends-script/scraper.py", line 260, in <module>
    main()
  File "/home/ubuntu/trends-script/scraper.py", line 253, in main
    htmlstring = get_html_from_site()
  File "/home/ubuntu/trends-script/scraper.py", line 28, in get_html_from_site
    driver = webdriver.Chrome(options=options)
  File "/home/ubuntu/.local/lib/python3.8/site-packages/selenium/webdriver/chrome/webdriver.py", line 73, in __init__
    self.service.start()
  File "/home/ubuntu/.local/lib/python3.8/site-packages/selenium/webdriver/common/service.py", line 104, in start
    raise WebDriverException("Can not connect to the Service %s" % self.path)
selenium.common.exceptions.WebDriverException: Message: Can not connect to the Service chromedriver

Traceback (most recent call last):
  File "/home/ubuntu/trends-script/scraper.py", line 260, in <module>
    main()
  File "/home/ubuntu/trends-script/scraper.py", line 253, in main
    htmlstring = get_html_from_site()
  File "/home/ubuntu/trends-script/scraper.py", line 31, in get_html_from_site
    driver.get(start_url)
  File "/home/ubuntu/.local/lib/python3.8/site-packages/selenium/webdriver/remote/webdriver.py", line 333, in get
    self.execute(Command.GET, {'url': url})
  File "/home/ubuntu/.local/lib/python3.8/site-packages/selenium/webdriver/remote/webdriver.py", line 321, in execute
    self.error_handler.check_response(response)
  File "/home/ubuntu/.local/lib/python3.8/site-packages/selenium/webdriver/remote/errorhandler.py", line 242, in check_response
    raise exception_class(message, screen, stacktrace)
selenium.common.exceptions.TimeoutException: Message: timeout: Timed out receiving message from renderer: 289.981
  (Session info: headless chrome=87.0.4280.88)

Traceback (most recent call last):
  File "/home/ubuntu/trends-script/scraper.py", line 260, in <module>
    main()
  File "/home/ubuntu/trends-script/scraper.py", line 253, in main
    htmlstring = get_html_from_site()
  File "/home/ubuntu/trends-script/scraper.py", line 28, in get_html_from_site
    driver = webdriver.Chrome(options=options)
  File "/home/ubuntu/.local/lib/python3.8/site-packages/selenium/webdriver/chrome/webdriver.py", line 73, in __init__
    self.service.start()
  File "/home/ubuntu/.local/lib/python3.8/site-packages/selenium/webdriver/common/service.py", line 104, in start
    raise WebDriverException("Can not connect to the Service %s" % self.path)
selenium.common.exceptions.WebDriverException: Message: Can not connect to the Service chromedriver

Traceback (most recent call last):
  File "/home/ubuntu/trends-script/scraper.py", line 260, in <module>
    main()
  File "/home/ubuntu/trends-script/scraper.py", line 253, in main
    htmlstring = get_html_from_site()
  File "/home/ubuntu/trends-script/scraper.py", line 31, in get_html_from_site
    driver.get(start_url)
  File "/home/ubuntu/.local/lib/python3.8/site-packages/selenium/webdriver/remote/webdriver.py", line 333, in get
    self.execute(Command.GET, {'url': url})
  File "/home/ubuntu/.local/lib/python3.8/site-packages/selenium/webdriver/remote/webdriver.py", line 321, in execute
    self.error_handler.check_response(response)
  File "/home/ubuntu/.local/lib/python3.8/site-packages/selenium/webdriver/remote/errorhandler.py", line 242, in check_response
    raise exception_class(message, screen, stacktrace)
selenium.common.exceptions.TimeoutException: Message: timeout: Timed out receiving message from renderer: 287.637
  (Session info: headless chrome=87.0.4280.88)

Traceback (most recent call last):
  File "/home/ubuntu/trends-script/scraper.py", line 260, in <module>
    main()
  File "/home/ubuntu/trends-script/scraper.py", line 253, in main
    htmlstring = get_html_from_site()
  File "/home/ubuntu/trends-script/scraper.py", line 28, in get_html_from_site
    driver = webdriver.Chrome(options=options)
  File "/home/ubuntu/.local/lib/python3.8/site-packages/selenium/webdriver/chrome/webdriver.py", line 73, in __init__
    self.service.start()
  File "/home/ubuntu/.local/lib/python3.8/site-packages/selenium/webdriver/common/service.py", line 104, in start
    raise WebDriverException("Can not connect to the Service %s" % self.path)
selenium.common.exceptions.WebDriverException: Message: Can not connect to the Service chromedriver

Traceback (most recent call last):
  File "/home/ubuntu/trends-script/scraper.py", line 260, in <module>
    main()
  File "/home/ubuntu/trends-script/scraper.py", line 253, in main
    htmlstring = get_html_from_site()
  File "/home/ubuntu/trends-script/scraper.py", line 31, in get_html_from_site
    driver.get(start_url)
  File "/home/ubuntu/.local/lib/python3.8/site-packages/selenium/webdriver/remote/webdriver.py", line 333, in get
    self.execute(Command.GET, {'url': url})
  File "/home/ubuntu/.local/lib/python3.8/site-packages/selenium/webdriver/remote/webdriver.py", line 321, in execute
    self.error_handler.check_response(response)
  File "/home/ubuntu/.local/lib/python3.8/site-packages/selenium/webdriver/remote/errorhandler.py", line 242, in check_response
    raise exception_class(message, screen, stacktrace)
selenium.common.exceptions.TimeoutException: Message: timeout: Timed out receiving message from renderer: 289.576
  (Session info: headless chrome=87.0.4280.88)

Traceback (most recent call last):
  File "/home/ubuntu/trends-script/scraper.py", line 260, in <module>
    main()
  File "/home/ubuntu/trends-script/scraper.py", line 253, in main
    htmlstring = get_html_from_site()
  File "/home/ubuntu/trends-script/scraper.py", line 28, in get_html_from_site
    driver = webdriver.Chrome(options=options)
  File "/home/ubuntu/.local/lib/python3.8/site-packages/selenium/webdriver/chrome/webdriver.py", line 73, in __init__
    self.service.start()
  File "/home/ubuntu/.local/lib/python3.8/site-packages/selenium/webdriver/common/service.py", line 104, in start
    raise WebDriverException("Can not connect to the Service %s" % self.path)
selenium.common.exceptions.WebDriverException: Message: Can not connect to the Service chromedriver

Traceback (most recent call last):
  File "/home/ubuntu/trends-script/scraper.py", line 260, in <module>
    main()
  File "/home/ubuntu/trends-script/scraper.py", line 253, in main
    htmlstring = get_html_from_site()
  File "/home/ubuntu/trends-script/scraper.py", line 31, in get_html_from_site
    driver.get(start_url)
  File "/home/ubuntu/.local/lib/python3.8/site-packages/selenium/webdriver/remote/webdriver.py", line 333, in get
    self.execute(Command.GET, {'url': url})
  File "/home/ubuntu/.local/lib/python3.8/site-packages/selenium/webdriver/remote/webdriver.py", line 321, in execute
    self.error_handler.check_response(response)
  File "/home/ubuntu/.local/lib/python3.8/site-packages/selenium/webdriver/remote/errorhandler.py", line 242, in check_response
    raise exception_class(message, screen, stacktrace)
selenium.common.exceptions.TimeoutException: Message: timeout: Timed out receiving message from renderer: 288.763
  (Session info: headless chrome=87.0.4280.88)

Traceback (most recent call last):
  File "/home/ubuntu/trends-script/scraper.py", line 260, in <module>
    main()
  File "/home/ubuntu/trends-script/scraper.py", line 253, in main
    htmlstring = get_html_from_site()
  File "/home/ubuntu/trends-script/scraper.py", line 28, in get_html_from_site
    driver = webdriver.Chrome(options=options)
  File "/home/ubuntu/.local/lib/python3.8/site-packages/selenium/webdriver/chrome/webdriver.py", line 73, in __init__
    self.service.start()
  File "/home/ubuntu/.local/lib/python3.8/site-packages/selenium/webdriver/common/service.py", line 104, in start
    raise WebDriverException("Can not connect to the Service %s" % self.path)
selenium.common.exceptions.WebDriverException: Message: Can not connect to the Service chromedriver

Traceback (most recent call last):
  File "/home/ubuntu/trends-script/scraper.py", line 260, in <module>
    main()
  File "/home/ubuntu/trends-script/scraper.py", line 253, in main
    htmlstring = get_html_from_site()
  File "/home/ubuntu/trends-script/scraper.py", line 31, in get_html_from_site
    driver.get(start_url)
  File "/home/ubuntu/.local/lib/python3.8/site-packages/selenium/webdriver/remote/webdriver.py", line 333, in get
    self.execute(Command.GET, {'url': url})
  File "/home/ubuntu/.local/lib/python3.8/site-packages/selenium/webdriver/remote/webdriver.py", line 321, in execute
    self.error_handler.check_response(response)
  File "/home/ubuntu/.local/lib/python3.8/site-packages/selenium/webdriver/remote/errorhandler.py", line 242, in check_response
    raise exception_class(message, screen, stacktrace)
selenium.common.exceptions.TimeoutException: Message: timeout: Timed out receiving message from renderer: 289.813
  (Session info: headless chrome=87.0.4280.88)

Traceback (most recent call last):
  File "/home/ubuntu/trends-script/scraper.py", line 260, in <module>
    main()
  File "/home/ubuntu/trends-script/scraper.py", line 253, in main
    htmlstring = get_html_from_site()
  File "/home/ubuntu/trends-script/scraper.py", line 28, in get_html_from_site
    driver = webdriver.Chrome(options=options)
  File "/home/ubuntu/.local/lib/python3.8/site-packages/selenium/webdriver/chrome/webdriver.py", line 73, in __init__
    self.service.start()
  File "/home/ubuntu/.local/lib/python3.8/site-packages/selenium/webdriver/common/service.py", line 104, in start
    raise WebDriverException("Can not connect to the Service %s" % self.path)
selenium.common.exceptions.WebDriverException: Message: Can not connect to the Service chromedriver

Traceback (most recent call last):
  File "/home/ubuntu/trends-script/scraper.py", line 260, in <module>
    main()
  File "/home/ubuntu/trends-script/scraper.py", line 253, in main
    htmlstring = get_html_from_site()
  File "/home/ubuntu/trends-script/scraper.py", line 31, in get_html_from_site
    driver.get(start_url)
  File "/home/ubuntu/.local/lib/python3.8/site-packages/selenium/webdriver/remote/webdriver.py", line 333, in get
    self.execute(Command.GET, {'url': url})
  File "/home/ubuntu/.local/lib/python3.8/site-packages/selenium/webdriver/remote/webdriver.py", line 321, in execute
    self.error_handler.check_response(response)
  File "/home/ubuntu/.local/lib/python3.8/site-packages/selenium/webdriver/remote/errorhandler.py", line 242, in check_response
    raise exception_class(message, screen, stacktrace)
selenium.common.exceptions.TimeoutException: Message: timeout: Timed out receiving message from renderer: 288.831
  (Session info: headless chrome=87.0.4280.88)

Traceback (most recent call last):
  File "/home/ubuntu/trends-script/scraper.py", line 260, in <module>
    main()
  File "/home/ubuntu/trends-script/scraper.py", line 253, in main
    htmlstring = get_html_from_site()
  File "/home/ubuntu/trends-script/scraper.py", line 28, in get_html_from_site
    driver = webdriver.Chrome(options=options)
  File "/home/ubuntu/.local/lib/python3.8/site-packages/selenium/webdriver/chrome/webdriver.py", line 73, in __init__
    self.service.start()
  File "/home/ubuntu/.local/lib/python3.8/site-packages/selenium/webdriver/common/service.py", line 104, in start
    raise WebDriverException("Can not connect to the Service %s" % self.path)
selenium.common.exceptions.WebDriverException: Message: Can not connect to the Service chromedriver

Traceback (most recent call last):
  File "/home/ubuntu/trends-script/scraper.py", line 260, in <module>
    main()
  File "/home/ubuntu/trends-script/scraper.py", line 253, in main
    htmlstring = get_html_from_site()
  File "/home/ubuntu/trends-script/scraper.py", line 31, in get_html_from_site
    driver.get(start_url)
  File "/home/ubuntu/.local/lib/python3.8/site-packages/selenium/webdriver/remote/webdriver.py", line 333, in get
    self.execute(Command.GET, {'url': url})
  File "/home/ubuntu/.local/lib/python3.8/site-packages/selenium/webdriver/remote/webdriver.py", line 321, in execute
    self.error_handler.check_response(response)
  File "/home/ubuntu/.local/lib/python3.8/site-packages/selenium/webdriver/remote/errorhandler.py", line 242, in check_response
    raise exception_class(message, screen, stacktrace)
selenium.common.exceptions.TimeoutException: Message: timeout: Timed out receiving message from renderer: 287.257
  (Session info: headless chrome=87.0.4280.88)

Traceback (most recent call last):
  File "/home/ubuntu/trends-script/scraper.py", line 260, in <module>
    main()
  File "/home/ubuntu/trends-script/scraper.py", line 253, in main
    htmlstring = get_html_from_site()
  File "/home/ubuntu/trends-script/scraper.py", line 28, in get_html_from_site
    driver = webdriver.Chrome(options=options)
  File "/home/ubuntu/.local/lib/python3.8/site-packages/selenium/webdriver/chrome/webdriver.py", line 73, in __init__
    self.service.start()
  File "/home/ubuntu/.local/lib/python3.8/site-packages/selenium/webdriver/common/service.py", line 104, in start
    raise WebDriverException("Can not connect to the Service %s" % self.path)
selenium.common.exceptions.WebDriverException: Message: Can not connect to the Service chromedriver

Traceback (most recent call last):
  File "/home/ubuntu/trends-script/scraper.py", line 260, in <module>
    main()
  File "/home/ubuntu/trends-script/scraper.py", line 253, in main
    htmlstring = get_html_from_site()
  File "/home/ubuntu/trends-script/scraper.py", line 31, in get_html_from_site
    driver.get(start_url)
  File "/home/ubuntu/.local/lib/python3.8/site-packages/selenium/webdriver/remote/webdriver.py", line 333, in get
    self.execute(Command.GET, {'url': url})
  File "/home/ubuntu/.local/lib/python3.8/site-packages/selenium/webdriver/remote/webdriver.py", line 321, in execute
    self.error_handler.check_response(response)
  File "/home/ubuntu/.local/lib/python3.8/site-packages/selenium/webdriver/remote/errorhandler.py", line 242, in check_response
    raise exception_class(message, screen, stacktrace)
selenium.common.exceptions.TimeoutException: Message: timeout: Timed out receiving message from renderer: 290.360
  (Session info: headless chrome=87.0.4280.88)

Traceback (most recent call last):
  File "/home/ubuntu/trends-script/scraper.py", line 260, in <module>
    main()
  File "/home/ubuntu/trends-script/scraper.py", line 253, in main
    htmlstring = get_html_from_site()
  File "/home/ubuntu/trends-script/scraper.py", line 28, in get_html_from_site
    driver = webdriver.Chrome(options=options)
  File "/home/ubuntu/.local/lib/python3.8/site-packages/selenium/webdriver/chrome/webdriver.py", line 73, in __init__
    self.service.start()
  File "/home/ubuntu/.local/lib/python3.8/site-packages/selenium/webdriver/common/service.py", line 104, in start
    raise WebDriverException("Can not connect to the Service %s" % self.path)
selenium.common.exceptions.WebDriverException: Message: Can not connect to the Service chromedriver

Traceback (most recent call last):
  File "/home/ubuntu/trends-script/scraper.py", line 260, in <module>
    main()
  File "/home/ubuntu/trends-script/scraper.py", line 253, in main
    htmlstring = get_html_from_site()
  File "/home/ubuntu/trends-script/scraper.py", line 31, in get_html_from_site
    driver.get(start_url)
  File "/home/ubuntu/.local/lib/python3.8/site-packages/selenium/webdriver/remote/webdriver.py", line 333, in get
    self.execute(Command.GET, {'url': url})
  File "/home/ubuntu/.local/lib/python3.8/site-packages/selenium/webdriver/remote/webdriver.py", line 321, in execute
    self.error_handler.check_response(response)
  File "/home/ubuntu/.local/lib/python3.8/site-packages/selenium/webdriver/remote/errorhandler.py", line 242, in check_response
    raise exception_class(message, screen, stacktrace)
selenium.common.exceptions.TimeoutException: Message: timeout: Timed out receiving message from renderer: 290.041
  (Session info: headless chrome=87.0.4280.88)

Traceback (most recent call last):
  File "/home/ubuntu/trends-script/scraper.py", line 260, in <module>
    main()
  File "/home/ubuntu/trends-script/scraper.py", line 253, in main
    htmlstring = get_html_from_site()
  File "/home/ubuntu/trends-script/scraper.py", line 28, in get_html_from_site
    driver = webdriver.Chrome(options=options)
  File "/home/ubuntu/.local/lib/python3.8/site-packages/selenium/webdriver/chrome/webdriver.py", line 73, in __init__
    self.service.start()
  File "/home/ubuntu/.local/lib/python3.8/site-packages/selenium/webdriver/common/service.py", line 104, in start
    raise WebDriverException("Can not connect to the Service %s" % self.path)
selenium.common.exceptions.WebDriverException: Message: Can not connect to the Service chromedriver

Traceback (most recent call last):
  File "/home/ubuntu/trends-script/scraper.py", line 260, in <module>
    main()
  File "/home/ubuntu/trends-script/scraper.py", line 253, in main
    htmlstring = get_html_from_site()
  File "/home/ubuntu/trends-script/scraper.py", line 31, in get_html_from_site
    driver.get(start_url)
  File "/home/ubuntu/.local/lib/python3.8/site-packages/selenium/webdriver/remote/webdriver.py", line 333, in get
    self.execute(Command.GET, {'url': url})
  File "/home/ubuntu/.local/lib/python3.8/site-packages/selenium/webdriver/remote/webdriver.py", line 321, in execute
    self.error_handler.check_response(response)
  File "/home/ubuntu/.local/lib/python3.8/site-packages/selenium/webdriver/remote/errorhandler.py", line 242, in check_response
    raise exception_class(message, screen, stacktrace)
selenium.common.exceptions.TimeoutException: Message: timeout: Timed out receiving message from renderer: 289.013
  (Session info: headless chrome=87.0.4280.88)

Traceback (most recent call last):
  File "/home/ubuntu/trends-script/scraper.py", line 260, in <module>
    main()
  File "/home/ubuntu/trends-script/scraper.py", line 253, in main
    htmlstring = get_html_from_site()
  File "/home/ubuntu/trends-script/scraper.py", line 28, in get_html_from_site
    driver = webdriver.Chrome(options=options)
  File "/home/ubuntu/.local/lib/python3.8/site-packages/selenium/webdriver/chrome/webdriver.py", line 73, in __init__
    self.service.start()
  File "/home/ubuntu/.local/lib/python3.8/site-packages/selenium/webdriver/common/service.py", line 104, in start
    raise WebDriverException("Can not connect to the Service %s" % self.path)
selenium.common.exceptions.WebDriverException: Message: Can not connect to the Service chromedriver

Traceback (most recent call last):
  File "/home/ubuntu/trends-script/scraper.py", line 260, in <module>
    main()
  File "/home/ubuntu/trends-script/scraper.py", line 253, in main
    htmlstring = get_html_from_site()
  File "/home/ubuntu/trends-script/scraper.py", line 31, in get_html_from_site
    driver.get(start_url)
  File "/home/ubuntu/.local/lib/python3.8/site-packages/selenium/webdriver/remote/webdriver.py", line 333, in get
    self.execute(Command.GET, {'url': url})
  File "/home/ubuntu/.local/lib/python3.8/site-packages/selenium/webdriver/remote/webdriver.py", line 321, in execute
    self.error_handler.check_response(response)
  File "/home/ubuntu/.local/lib/python3.8/site-packages/selenium/webdriver/remote/errorhandler.py", line 242, in check_response
    raise exception_class(message, screen, stacktrace)
selenium.common.exceptions.TimeoutException: Message: timeout: Timed out receiving message from renderer: 289.568
  (Session info: headless chrome=87.0.4280.88)

Traceback (most recent call last):
  File "/home/ubuntu/trends-script/scraper.py", line 260, in <module>
    main()
  File "/home/ubuntu/trends-script/scraper.py", line 253, in main
    htmlstring = get_html_from_site()
  File "/home/ubuntu/trends-script/scraper.py", line 28, in get_html_from_site
    driver = webdriver.Chrome(options=options)
  File "/home/ubuntu/.local/lib/python3.8/site-packages/selenium/webdriver/chrome/webdriver.py", line 73, in __init__
    self.service.start()
  File "/home/ubuntu/.local/lib/python3.8/site-packages/selenium/webdriver/common/service.py", line 104, in start
    raise WebDriverException("Can not connect to the Service %s" % self.path)
selenium.common.exceptions.WebDriverException: Message: Can not connect to the Service chromedriver

Traceback (most recent call last):
  File "/home/ubuntu/trends-script/scraper.py", line 260, in <module>
    main()
  File "/home/ubuntu/trends-script/scraper.py", line 253, in main
    htmlstring = get_html_from_site()
  File "/home/ubuntu/trends-script/scraper.py", line 31, in get_html_from_site
    driver.get(start_url)
  File "/home/ubuntu/.local/lib/python3.8/site-packages/selenium/webdriver/remote/webdriver.py", line 333, in get
    self.execute(Command.GET, {'url': url})
  File "/home/ubuntu/.local/lib/python3.8/site-packages/selenium/webdriver/remote/webdriver.py", line 321, in execute
    self.error_handler.check_response(response)
  File "/home/ubuntu/.local/lib/python3.8/site-packages/selenium/webdriver/remote/errorhandler.py", line 242, in check_response
    raise exception_class(message, screen, stacktrace)
selenium.common.exceptions.TimeoutException: Message: timeout: Timed out receiving message from renderer: 289.530
  (Session info: headless chrome=87.0.4280.88)

Traceback (most recent call last):
  File "/home/ubuntu/trends-script/scraper.py", line 260, in <module>
    main()
  File "/home/ubuntu/trends-script/scraper.py", line 253, in main
    htmlstring = get_html_from_site()
  File "/home/ubuntu/trends-script/scraper.py", line 28, in get_html_from_site
    driver = webdriver.Chrome(options=options)
  File "/home/ubuntu/.local/lib/python3.8/site-packages/selenium/webdriver/chrome/webdriver.py", line 73, in __init__
    self.service.start()
  File "/home/ubuntu/.local/lib/python3.8/site-packages/selenium/webdriver/common/service.py", line 104, in start
    raise WebDriverException("Can not connect to the Service %s" % self.path)
selenium.common.exceptions.WebDriverException: Message: Can not connect to the Service chromedriver

Traceback (most recent call last):
  File "/home/ubuntu/trends-script/scraper.py", line 260, in <module>
    main()
  File "/home/ubuntu/trends-script/scraper.py", line 253, in main
    htmlstring = get_html_from_site()
  File "/home/ubuntu/trends-script/scraper.py", line 31, in get_html_from_site
    driver.get(start_url)
  File "/home/ubuntu/.local/lib/python3.8/site-packages/selenium/webdriver/remote/webdriver.py", line 333, in get
    self.execute(Command.GET, {'url': url})
  File "/home/ubuntu/.local/lib/python3.8/site-packages/selenium/webdriver/remote/webdriver.py", line 321, in execute
    self.error_handler.check_response(response)
  File "/home/ubuntu/.local/lib/python3.8/site-packages/selenium/webdriver/remote/errorhandler.py", line 242, in check_response
    raise exception_class(message, screen, stacktrace)
selenium.common.exceptions.TimeoutException: Message: timeout: Timed out receiving message from renderer: 288.472
  (Session info: headless chrome=87.0.4280.88)

Traceback (most recent call last):
  File "/home/ubuntu/trends-script/scraper.py", line 260, in <module>
    main()
  File "/home/ubuntu/trends-script/scraper.py", line 253, in main
    htmlstring = get_html_from_site()
  File "/home/ubuntu/trends-script/scraper.py", line 28, in get_html_from_site
    driver = webdriver.Chrome(options=options)
  File "/home/ubuntu/.local/lib/python3.8/site-packages/selenium/webdriver/chrome/webdriver.py", line 73, in __init__
    self.service.start()
  File "/home/ubuntu/.local/lib/python3.8/site-packages/selenium/webdriver/common/service.py", line 104, in start
    raise WebDriverException("Can not connect to the Service %s" % self.path)
selenium.common.exceptions.WebDriverException: Message: Can not connect to the Service chromedriver

Traceback (most recent call last):
  File "/home/ubuntu/trends-script/scraper.py", line 260, in <module>
    main()
  File "/home/ubuntu/trends-script/scraper.py", line 253, in main
    htmlstring = get_html_from_site()
  File "/home/ubuntu/trends-script/scraper.py", line 31, in get_html_from_site
    driver.get(start_url)
  File "/home/ubuntu/.local/lib/python3.8/site-packages/selenium/webdriver/remote/webdriver.py", line 333, in get
    self.execute(Command.GET, {'url': url})
  File "/home/ubuntu/.local/lib/python3.8/site-packages/selenium/webdriver/remote/webdriver.py", line 321, in execute
    self.error_handler.check_response(response)
  File "/home/ubuntu/.local/lib/python3.8/site-packages/selenium/webdriver/remote/errorhandler.py", line 242, in check_response
    raise exception_class(message, screen, stacktrace)
selenium.common.exceptions.TimeoutException: Message: timeout: Timed out receiving message from renderer: 286.862
  (Session info: headless chrome=87.0.4280.88)

Traceback (most recent call last):
  File "/home/ubuntu/trends-script/scraper.py", line 260, in <module>
    main()
  File "/home/ubuntu/trends-script/scraper.py", line 253, in main
    htmlstring = get_html_from_site()
  File "/home/ubuntu/trends-script/scraper.py", line 28, in get_html_from_site
    driver = webdriver.Chrome(options=options)
  File "/home/ubuntu/.local/lib/python3.8/site-packages/selenium/webdriver/chrome/webdriver.py", line 73, in __init__
    self.service.start()
  File "/home/ubuntu/.local/lib/python3.8/site-packages/selenium/webdriver/common/service.py", line 104, in start
    raise WebDriverException("Can not connect to the Service %s" % self.path)
selenium.common.exceptions.WebDriverException: Message: Can not connect to the Service chromedriver

Traceback (most recent call last):
  File "/home/ubuntu/trends-script/scraper.py", line 260, in <module>
    main()
  File "/home/ubuntu/trends-script/scraper.py", line 253, in main
    htmlstring = get_html_from_site()
  File "/home/ubuntu/trends-script/scraper.py", line 31, in get_html_from_site
    driver.get(start_url)
  File "/home/ubuntu/.local/lib/python3.8/site-packages/selenium/webdriver/remote/webdriver.py", line 333, in get
    self.execute(Command.GET, {'url': url})
  File "/home/ubuntu/.local/lib/python3.8/site-packages/selenium/webdriver/remote/webdriver.py", line 321, in execute
    self.error_handler.check_response(response)
  File "/home/ubuntu/.local/lib/python3.8/site-packages/selenium/webdriver/remote/errorhandler.py", line 242, in check_response
    raise exception_class(message, screen, stacktrace)
selenium.common.exceptions.TimeoutException: Message: timeout: Timed out receiving message from renderer: 287.589
  (Session info: headless chrome=87.0.4280.88)

Traceback (most recent call last):
  File "/home/ubuntu/trends-script/scraper.py", line 260, in <module>
    main()
  File "/home/ubuntu/trends-script/scraper.py", line 253, in main
    htmlstring = get_html_from_site()
  File "/home/ubuntu/trends-script/scraper.py", line 28, in get_html_from_site
    driver = webdriver.Chrome(options=options)
  File "/home/ubuntu/.local/lib/python3.8/site-packages/selenium/webdriver/chrome/webdriver.py", line 73, in __init__
    self.service.start()
  File "/home/ubuntu/.local/lib/python3.8/site-packages/selenium/webdriver/common/service.py", line 104, in start
    raise WebDriverException("Can not connect to the Service %s" % self.path)
selenium.common.exceptions.WebDriverException: Message: Can not connect to the Service chromedriver

Traceback (most recent call last):
  File "/home/ubuntu/trends-script/scraper.py", line 260, in <module>
    main()
  File "/home/ubuntu/trends-script/scraper.py", line 253, in main
    htmlstring = get_html_from_site()
  File "/home/ubuntu/trends-script/scraper.py", line 31, in get_html_from_site
    driver.get(start_url)
  File "/home/ubuntu/.local/lib/python3.8/site-packages/selenium/webdriver/remote/webdriver.py", line 333, in get
    self.execute(Command.GET, {'url': url})
  File "/home/ubuntu/.local/lib/python3.8/site-packages/selenium/webdriver/remote/webdriver.py", line 321, in execute
    self.error_handler.check_response(response)
  File "/home/ubuntu/.local/lib/python3.8/site-packages/selenium/webdriver/remote/errorhandler.py", line 242, in check_response
    raise exception_class(message, screen, stacktrace)
selenium.common.exceptions.TimeoutException: Message: timeout: Timed out receiving message from renderer: 286.690
  (Session info: headless chrome=87.0.4280.88)

Traceback (most recent call last):
  File "/home/ubuntu/trends-script/scraper.py", line 260, in <module>
    main()
  File "/home/ubuntu/trends-script/scraper.py", line 253, in main
    htmlstring = get_html_from_site()
  File "/home/ubuntu/trends-script/scraper.py", line 28, in get_html_from_site
    driver = webdriver.Chrome(options=options)
  File "/home/ubuntu/.local/lib/python3.8/site-packages/selenium/webdriver/chrome/webdriver.py", line 73, in __init__
    self.service.start()
  File "/home/ubuntu/.local/lib/python3.8/site-packages/selenium/webdriver/common/service.py", line 104, in start
    raise WebDriverException("Can not connect to the Service %s" % self.path)
selenium.common.exceptions.WebDriverException: Message: Can not connect to the Service chromedriver

Traceback (most recent call last):
  File "/home/ubuntu/trends-script/scraper.py", line 260, in <module>
    main()
  File "/home/ubuntu/trends-script/scraper.py", line 253, in main
    htmlstring = get_html_from_site()
  File "/home/ubuntu/trends-script/scraper.py", line 31, in get_html_from_site
    driver.get(start_url)
  File "/home/ubuntu/.local/lib/python3.8/site-packages/selenium/webdriver/remote/webdriver.py", line 333, in get
    self.execute(Command.GET, {'url': url})
  File "/home/ubuntu/.local/lib/python3.8/site-packages/selenium/webdriver/remote/webdriver.py", line 321, in execute
    self.error_handler.check_response(response)
  File "/home/ubuntu/.local/lib/python3.8/site-packages/selenium/webdriver/remote/errorhandler.py", line 242, in check_response
    raise exception_class(message, screen, stacktrace)
selenium.common.exceptions.TimeoutException: Message: timeout: Timed out receiving message from renderer: 288.464
  (Session info: headless chrome=87.0.4280.88)

Traceback (most recent call last):
  File "/home/ubuntu/trends-script/scraper.py", line 260, in <module>
    main()
  File "/home/ubuntu/trends-script/scraper.py", line 253, in main
    htmlstring = get_html_from_site()
  File "/home/ubuntu/trends-script/scraper.py", line 28, in get_html_from_site
    driver = webdriver.Chrome(options=options)
  File "/home/ubuntu/.local/lib/python3.8/site-packages/selenium/webdriver/chrome/webdriver.py", line 73, in __init__
    self.service.start()
  File "/home/ubuntu/.local/lib/python3.8/site-packages/selenium/webdriver/common/service.py", line 104, in start
    raise WebDriverException("Can not connect to the Service %s" % self.path)
selenium.common.exceptions.WebDriverException: Message: Can not connect to the Service chromedriver

Traceback (most recent call last):
  File "/home/ubuntu/trends-script/scraper.py", line 260, in <module>
    main()
  File "/home/ubuntu/trends-script/scraper.py", line 253, in main
    htmlstring = get_html_from_site()
  File "/home/ubuntu/trends-script/scraper.py", line 31, in get_html_from_site
    driver.get(start_url)
  File "/home/ubuntu/.local/lib/python3.8/site-packages/selenium/webdriver/remote/webdriver.py", line 333, in get
    self.execute(Command.GET, {'url': url})
  File "/home/ubuntu/.local/lib/python3.8/site-packages/selenium/webdriver/remote/webdriver.py", line 321, in execute
    self.error_handler.check_response(response)
  File "/home/ubuntu/.local/lib/python3.8/site-packages/selenium/webdriver/remote/errorhandler.py", line 242, in check_response
    raise exception_class(message, screen, stacktrace)
selenium.common.exceptions.TimeoutException: Message: timeout: Timed out receiving message from renderer: 286.023
  (Session info: headless chrome=87.0.4280.88)

Traceback (most recent call last):
  File "/home/ubuntu/trends-script/scraper.py", line 260, in <module>
    main()
  File "/home/ubuntu/trends-script/scraper.py", line 253, in main
    htmlstring = get_html_from_site()
  File "/home/ubuntu/trends-script/scraper.py", line 28, in get_html_from_site
    driver = webdriver.Chrome(options=options)
  File "/home/ubuntu/.local/lib/python3.8/site-packages/selenium/webdriver/chrome/webdriver.py", line 73, in __init__
    self.service.start()
  File "/home/ubuntu/.local/lib/python3.8/site-packages/selenium/webdriver/common/service.py", line 104, in start
    raise WebDriverException("Can not connect to the Service %s" % self.path)
selenium.common.exceptions.WebDriverException: Message: Can not connect to the Service chromedriver

Traceback (most recent call last):
  File "/home/ubuntu/trends-script/scraper.py", line 260, in <module>
    main()
  File "/home/ubuntu/trends-script/scraper.py", line 253, in main
    htmlstring = get_html_from_site()
  File "/home/ubuntu/trends-script/scraper.py", line 31, in get_html_from_site
    driver.get(start_url)
  File "/home/ubuntu/.local/lib/python3.8/site-packages/selenium/webdriver/remote/webdriver.py", line 333, in get
    self.execute(Command.GET, {'url': url})
  File "/home/ubuntu/.local/lib/python3.8/site-packages/selenium/webdriver/remote/webdriver.py", line 321, in execute
    self.error_handler.check_response(response)
  File "/home/ubuntu/.local/lib/python3.8/site-packages/selenium/webdriver/remote/errorhandler.py", line 242, in check_response
    raise exception_class(message, screen, stacktrace)
selenium.common.exceptions.TimeoutException: Message: timeout: Timed out receiving message from renderer: 290.660
  (Session info: headless chrome=87.0.4280.88)

Traceback (most recent call last):
  File "/home/ubuntu/trends-script/scraper.py", line 260, in <module>
    main()
  File "/home/ubuntu/trends-script/scraper.py", line 253, in main
    htmlstring = get_html_from_site()
  File "/home/ubuntu/trends-script/scraper.py", line 28, in get_html_from_site
    driver = webdriver.Chrome(options=options)
  File "/home/ubuntu/.local/lib/python3.8/site-packages/selenium/webdriver/chrome/webdriver.py", line 73, in __init__
    self.service.start()
  File "/home/ubuntu/.local/lib/python3.8/site-packages/selenium/webdriver/common/service.py", line 104, in start
    raise WebDriverException("Can not connect to the Service %s" % self.path)
selenium.common.exceptions.WebDriverException: Message: Can not connect to the Service chromedriver

Traceback (most recent call last):
  File "/home/ubuntu/trends-script/scraper.py", line 260, in <module>
    main()
  File "/home/ubuntu/trends-script/scraper.py", line 253, in main
    htmlstring = get_html_from_site()
  File "/home/ubuntu/trends-script/scraper.py", line 31, in get_html_from_site
    driver.get(start_url)
  File "/home/ubuntu/.local/lib/python3.8/site-packages/selenium/webdriver/remote/webdriver.py", line 333, in get
    self.execute(Command.GET, {'url': url})
  File "/home/ubuntu/.local/lib/python3.8/site-packages/selenium/webdriver/remote/webdriver.py", line 321, in execute
    self.error_handler.check_response(response)
  File "/home/ubuntu/.local/lib/python3.8/site-packages/selenium/webdriver/remote/errorhandler.py", line 242, in check_response
    raise exception_class(message, screen, stacktrace)
selenium.common.exceptions.TimeoutException: Message: timeout: Timed out receiving message from renderer: 287.100
  (Session info: headless chrome=87.0.4280.88)

Traceback (most recent call last):
  File "/home/ubuntu/trends-script/scraper.py", line 260, in <module>
    main()
  File "/home/ubuntu/trends-script/scraper.py", line 253, in main
    htmlstring = get_html_from_site()
  File "/home/ubuntu/trends-script/scraper.py", line 28, in get_html_from_site
    driver = webdriver.Chrome(options=options)
  File "/home/ubuntu/.local/lib/python3.8/site-packages/selenium/webdriver/chrome/webdriver.py", line 73, in __init__
    self.service.start()
  File "/home/ubuntu/.local/lib/python3.8/site-packages/selenium/webdriver/common/service.py", line 104, in start
    raise WebDriverException("Can not connect to the Service %s" % self.path)
selenium.common.exceptions.WebDriverException: Message: Can not connect to the Service chromedriver

Traceback (most recent call last):
  File "/home/ubuntu/trends-script/scraper.py", line 260, in <module>
    main()
  File "/home/ubuntu/trends-script/scraper.py", line 253, in main
    htmlstring = get_html_from_site()
  File "/home/ubuntu/trends-script/scraper.py", line 31, in get_html_from_site
    driver.get(start_url)
  File "/home/ubuntu/.local/lib/python3.8/site-packages/selenium/webdriver/remote/webdriver.py", line 333, in get
    self.execute(Command.GET, {'url': url})
  File "/home/ubuntu/.local/lib/python3.8/site-packages/selenium/webdriver/remote/webdriver.py", line 321, in execute
    self.error_handler.check_response(response)
  File "/home/ubuntu/.local/lib/python3.8/site-packages/selenium/webdriver/remote/errorhandler.py", line 242, in check_response
    raise exception_class(message, screen, stacktrace)
selenium.common.exceptions.TimeoutException: Message: timeout: Timed out receiving message from renderer: 286.593
  (Session info: headless chrome=87.0.4280.88)

Traceback (most recent call last):
  File "/home/ubuntu/trends-script/scraper.py", line 260, in <module>
    main()
  File "/home/ubuntu/trends-script/scraper.py", line 253, in main
    htmlstring = get_html_from_site()
  File "/home/ubuntu/trends-script/scraper.py", line 28, in get_html_from_site
    driver = webdriver.Chrome(options=options)
  File "/home/ubuntu/.local/lib/python3.8/site-packages/selenium/webdriver/chrome/webdriver.py", line 73, in __init__
    self.service.start()
  File "/home/ubuntu/.local/lib/python3.8/site-packages/selenium/webdriver/common/service.py", line 104, in start
    raise WebDriverException("Can not connect to the Service %s" % self.path)
selenium.common.exceptions.WebDriverException: Message: Can not connect to the Service chromedriver

Traceback (most recent call last):
  File "/home/ubuntu/trends-script/scraper.py", line 260, in <module>
    main()
  File "/home/ubuntu/trends-script/scraper.py", line 253, in main
    htmlstring = get_html_from_site()
  File "/home/ubuntu/trends-script/scraper.py", line 31, in get_html_from_site
    driver.get(start_url)
  File "/home/ubuntu/.local/lib/python3.8/site-packages/selenium/webdriver/remote/webdriver.py", line 333, in get
    self.execute(Command.GET, {'url': url})
  File "/home/ubuntu/.local/lib/python3.8/site-packages/selenium/webdriver/remote/webdriver.py", line 321, in execute
    self.error_handler.check_response(response)
  File "/home/ubuntu/.local/lib/python3.8/site-packages/selenium/webdriver/remote/errorhandler.py", line 242, in check_response
    raise exception_class(message, screen, stacktrace)
selenium.common.exceptions.TimeoutException: Message: timeout: Timed out receiving message from renderer: 289.769
  (Session info: headless chrome=87.0.4280.88)

Traceback (most recent call last):
  File "/home/ubuntu/trends-script/scraper.py", line 260, in <module>
    main()
  File "/home/ubuntu/trends-script/scraper.py", line 253, in main
    htmlstring = get_html_from_site()
  File "/home/ubuntu/trends-script/scraper.py", line 28, in get_html_from_site
    driver = webdriver.Chrome(options=options)
  File "/home/ubuntu/.local/lib/python3.8/site-packages/selenium/webdriver/chrome/webdriver.py", line 73, in __init__
    self.service.start()
  File "/home/ubuntu/.local/lib/python3.8/site-packages/selenium/webdriver/common/service.py", line 104, in start
    raise WebDriverException("Can not connect to the Service %s" % self.path)
selenium.common.exceptions.WebDriverException: Message: Can not connect to the Service chromedriver

Traceback (most recent call last):
  File "/home/ubuntu/trends-script/scraper.py", line 260, in <module>
    main()
  File "/home/ubuntu/trends-script/scraper.py", line 253, in main
    htmlstring = get_html_from_site()
  File "/home/ubuntu/trends-script/scraper.py", line 31, in get_html_from_site
    driver.get(start_url)
  File "/home/ubuntu/.local/lib/python3.8/site-packages/selenium/webdriver/remote/webdriver.py", line 333, in get
    self.execute(Command.GET, {'url': url})
  File "/home/ubuntu/.local/lib/python3.8/site-packages/selenium/webdriver/remote/webdriver.py", line 321, in execute
    self.error_handler.check_response(response)
  File "/home/ubuntu/.local/lib/python3.8/site-packages/selenium/webdriver/remote/errorhandler.py", line 242, in check_response
    raise exception_class(message, screen, stacktrace)
selenium.common.exceptions.TimeoutException: Message: timeout: Timed out receiving message from renderer: 290.690
  (Session info: headless chrome=87.0.4280.88)

Traceback (most recent call last):
  File "/home/ubuntu/trends-script/scraper.py", line 260, in <module>
    main()
  File "/home/ubuntu/trends-script/scraper.py", line 253, in main
    htmlstring = get_html_from_site()
  File "/home/ubuntu/trends-script/scraper.py", line 28, in get_html_from_site
    driver = webdriver.Chrome(options=options)
  File "/home/ubuntu/.local/lib/python3.8/site-packages/selenium/webdriver/chrome/webdriver.py", line 73, in __init__
    self.service.start()
  File "/home/ubuntu/.local/lib/python3.8/site-packages/selenium/webdriver/common/service.py", line 104, in start
    raise WebDriverException("Can not connect to the Service %s" % self.path)
selenium.common.exceptions.WebDriverException: Message: Can not connect to the Service chromedriver

Traceback (most recent call last):
  File "/home/ubuntu/trends-script/scraper.py", line 260, in <module>
    main()
  File "/home/ubuntu/trends-script/scraper.py", line 253, in main
    htmlstring = get_html_from_site()
  File "/home/ubuntu/trends-script/scraper.py", line 31, in get_html_from_site
    driver.get(start_url)
  File "/home/ubuntu/.local/lib/python3.8/site-packages/selenium/webdriver/remote/webdriver.py", line 333, in get
    self.execute(Command.GET, {'url': url})
  File "/home/ubuntu/.local/lib/python3.8/site-packages/selenium/webdriver/remote/webdriver.py", line 321, in execute
    self.error_handler.check_response(response)
  File "/home/ubuntu/.local/lib/python3.8/site-packages/selenium/webdriver/remote/errorhandler.py", line 242, in check_response
    raise exception_class(message, screen, stacktrace)
selenium.common.exceptions.TimeoutException: Message: timeout: Timed out receiving message from renderer: 291.558
  (Session info: headless chrome=87.0.4280.88)

Traceback (most recent call last):
  File "/home/ubuntu/trends-script/scraper.py", line 260, in <module>
    main()
  File "/home/ubuntu/trends-script/scraper.py", line 253, in main
    htmlstring = get_html_from_site()
  File "/home/ubuntu/trends-script/scraper.py", line 28, in get_html_from_site
    driver = webdriver.Chrome(options=options)
  File "/home/ubuntu/.local/lib/python3.8/site-packages/selenium/webdriver/chrome/webdriver.py", line 73, in __init__
    self.service.start()
  File "/home/ubuntu/.local/lib/python3.8/site-packages/selenium/webdriver/common/service.py", line 104, in start
    raise WebDriverException("Can not connect to the Service %s" % self.path)
selenium.common.exceptions.WebDriverException: Message: Can not connect to the Service chromedriver

Traceback (most recent call last):
  File "/home/ubuntu/trends-script/scraper.py", line 260, in <module>
    main()
  File "/home/ubuntu/trends-script/scraper.py", line 253, in main
    htmlstring = get_html_from_site()
  File "/home/ubuntu/trends-script/scraper.py", line 31, in get_html_from_site
    driver.get(start_url)
  File "/home/ubuntu/.local/lib/python3.8/site-packages/selenium/webdriver/remote/webdriver.py", line 333, in get
    self.execute(Command.GET, {'url': url})
  File "/home/ubuntu/.local/lib/python3.8/site-packages/selenium/webdriver/remote/webdriver.py", line 321, in execute
    self.error_handler.check_response(response)
  File "/home/ubuntu/.local/lib/python3.8/site-packages/selenium/webdriver/remote/errorhandler.py", line 242, in check_response
    raise exception_class(message, screen, stacktrace)
selenium.common.exceptions.TimeoutException: Message: timeout: Timed out receiving message from renderer: 289.569
  (Session info: headless chrome=87.0.4280.88)

Traceback (most recent call last):
  File "/home/ubuntu/trends-script/scraper.py", line 260, in <module>
    main()
  File "/home/ubuntu/trends-script/scraper.py", line 253, in main
    htmlstring = get_html_from_site()
  File "/home/ubuntu/trends-script/scraper.py", line 28, in get_html_from_site
    driver = webdriver.Chrome(options=options)
  File "/home/ubuntu/.local/lib/python3.8/site-packages/selenium/webdriver/chrome/webdriver.py", line 73, in __init__
    self.service.start()
  File "/home/ubuntu/.local/lib/python3.8/site-packages/selenium/webdriver/common/service.py", line 104, in start
    raise WebDriverException("Can not connect to the Service %s" % self.path)
selenium.common.exceptions.WebDriverException: Message: Can not connect to the Service chromedriver

Traceback (most recent call last):
  File "/home/ubuntu/trends-script/scraper.py", line 260, in <module>
    main()
  File "/home/ubuntu/trends-script/scraper.py", line 253, in main
    htmlstring = get_html_from_site()
  File "/home/ubuntu/trends-script/scraper.py", line 31, in get_html_from_site
    driver.get(start_url)
  File "/home/ubuntu/.local/lib/python3.8/site-packages/selenium/webdriver/remote/webdriver.py", line 333, in get
    self.execute(Command.GET, {'url': url})
  File "/home/ubuntu/.local/lib/python3.8/site-packages/selenium/webdriver/remote/webdriver.py", line 321, in execute
    self.error_handler.check_response(response)
  File "/home/ubuntu/.local/lib/python3.8/site-packages/selenium/webdriver/remote/errorhandler.py", line 242, in check_response
    raise exception_class(message, screen, stacktrace)
selenium.common.exceptions.TimeoutException: Message: timeout: Timed out receiving message from renderer: 288.336
  (Session info: headless chrome=87.0.4280.88)

Traceback (most recent call last):
  File "/home/ubuntu/trends-script/scraper.py", line 260, in <module>
    main()
  File "/home/ubuntu/trends-script/scraper.py", line 253, in main
    htmlstring = get_html_from_site()
  File "/home/ubuntu/trends-script/scraper.py", line 28, in get_html_from_site
    driver = webdriver.Chrome(options=options)
  File "/home/ubuntu/.local/lib/python3.8/site-packages/selenium/webdriver/chrome/webdriver.py", line 73, in __init__
    self.service.start()
  File "/home/ubuntu/.local/lib/python3.8/site-packages/selenium/webdriver/common/service.py", line 104, in start
    raise WebDriverException("Can not connect to the Service %s" % self.path)
selenium.common.exceptions.WebDriverException: Message: Can not connect to the Service chromedriver

Traceback (most recent call last):
  File "/home/ubuntu/trends-script/scraper.py", line 260, in <module>
    main()
  File "/home/ubuntu/trends-script/scraper.py", line 253, in main
    htmlstring = get_html_from_site()
  File "/home/ubuntu/trends-script/scraper.py", line 31, in get_html_from_site
    driver.get(start_url)
  File "/home/ubuntu/.local/lib/python3.8/site-packages/selenium/webdriver/remote/webdriver.py", line 333, in get
    self.execute(Command.GET, {'url': url})
  File "/home/ubuntu/.local/lib/python3.8/site-packages/selenium/webdriver/remote/webdriver.py", line 321, in execute
    self.error_handler.check_response(response)
  File "/home/ubuntu/.local/lib/python3.8/site-packages/selenium/webdriver/remote/errorhandler.py", line 242, in check_response
    raise exception_class(message, screen, stacktrace)
selenium.common.exceptions.TimeoutException: Message: timeout: Timed out receiving message from renderer: 286.723
  (Session info: headless chrome=87.0.4280.88)

Traceback (most recent call last):
  File "/home/ubuntu/trends-script/scraper.py", line 260, in <module>
    main()
  File "/home/ubuntu/trends-script/scraper.py", line 253, in main
    htmlstring = get_html_from_site()
  File "/home/ubuntu/trends-script/scraper.py", line 28, in get_html_from_site
    driver = webdriver.Chrome(options=options)
  File "/home/ubuntu/.local/lib/python3.8/site-packages/selenium/webdriver/chrome/webdriver.py", line 73, in __init__
    self.service.start()
  File "/home/ubuntu/.local/lib/python3.8/site-packages/selenium/webdriver/common/service.py", line 104, in start
    raise WebDriverException("Can not connect to the Service %s" % self.path)
selenium.common.exceptions.WebDriverException: Message: Can not connect to the Service chromedriver

Traceback (most recent call last):
  File "/home/ubuntu/trends-script/scraper.py", line 260, in <module>
    main()
  File "/home/ubuntu/trends-script/scraper.py", line 253, in main
    htmlstring = get_html_from_site()
  File "/home/ubuntu/trends-script/scraper.py", line 31, in get_html_from_site
    driver.get(start_url)
  File "/home/ubuntu/.local/lib/python3.8/site-packages/selenium/webdriver/remote/webdriver.py", line 333, in get
    self.execute(Command.GET, {'url': url})
  File "/home/ubuntu/.local/lib/python3.8/site-packages/selenium/webdriver/remote/webdriver.py", line 321, in execute
    self.error_handler.check_response(response)
  File "/home/ubuntu/.local/lib/python3.8/site-packages/selenium/webdriver/remote/errorhandler.py", line 242, in check_response
    raise exception_class(message, screen, stacktrace)
selenium.common.exceptions.TimeoutException: Message: timeout: Timed out receiving message from renderer: 287.117
  (Session info: headless chrome=87.0.4280.88)

Traceback (most recent call last):
  File "/home/ubuntu/trends-script/scraper.py", line 260, in <module>
    main()
  File "/home/ubuntu/trends-script/scraper.py", line 253, in main
    htmlstring = get_html_from_site()
  File "/home/ubuntu/trends-script/scraper.py", line 28, in get_html_from_site
    driver = webdriver.Chrome(options=options)
  File "/home/ubuntu/.local/lib/python3.8/site-packages/selenium/webdriver/chrome/webdriver.py", line 73, in __init__
    self.service.start()
  File "/home/ubuntu/.local/lib/python3.8/site-packages/selenium/webdriver/common/service.py", line 104, in start
    raise WebDriverException("Can not connect to the Service %s" % self.path)
selenium.common.exceptions.WebDriverException: Message: Can not connect to the Service chromedriver

Traceback (most recent call last):
  File "/home/ubuntu/trends-script/scraper.py", line 260, in <module>
    main()
  File "/home/ubuntu/trends-script/scraper.py", line 253, in main
    htmlstring = get_html_from_site()
  File "/home/ubuntu/trends-script/scraper.py", line 31, in get_html_from_site
    driver.get(start_url)
  File "/home/ubuntu/.local/lib/python3.8/site-packages/selenium/webdriver/remote/webdriver.py", line 333, in get
    self.execute(Command.GET, {'url': url})
  File "/home/ubuntu/.local/lib/python3.8/site-packages/selenium/webdriver/remote/webdriver.py", line 321, in execute
    self.error_handler.check_response(response)
  File "/home/ubuntu/.local/lib/python3.8/site-packages/selenium/webdriver/remote/errorhandler.py", line 242, in check_response
    raise exception_class(message, screen, stacktrace)
selenium.common.exceptions.TimeoutException: Message: timeout: Timed out receiving message from renderer: 289.638
  (Session info: headless chrome=87.0.4280.88)

Traceback (most recent call last):
  File "/home/ubuntu/trends-script/scraper.py", line 260, in <module>
    main()
  File "/home/ubuntu/trends-script/scraper.py", line 253, in main
    htmlstring = get_html_from_site()
  File "/home/ubuntu/trends-script/scraper.py", line 28, in get_html_from_site
    driver = webdriver.Chrome(options=options)
  File "/home/ubuntu/.local/lib/python3.8/site-packages/selenium/webdriver/chrome/webdriver.py", line 73, in __init__
    self.service.start()
  File "/home/ubuntu/.local/lib/python3.8/site-packages/selenium/webdriver/common/service.py", line 104, in start
    raise WebDriverException("Can not connect to the Service %s" % self.path)
selenium.common.exceptions.WebDriverException: Message: Can not connect to the Service chromedriver

Traceback (most recent call last):
  File "/home/ubuntu/trends-script/scraper.py", line 260, in <module>
    main()
  File "/home/ubuntu/trends-script/scraper.py", line 253, in main
    htmlstring = get_html_from_site()
  File "/home/ubuntu/trends-script/scraper.py", line 31, in get_html_from_site
    driver.get(start_url)
  File "/home/ubuntu/.local/lib/python3.8/site-packages/selenium/webdriver/remote/webdriver.py", line 333, in get
    self.execute(Command.GET, {'url': url})
  File "/home/ubuntu/.local/lib/python3.8/site-packages/selenium/webdriver/remote/webdriver.py", line 321, in execute
    self.error_handler.check_response(response)
  File "/home/ubuntu/.local/lib/python3.8/site-packages/selenium/webdriver/remote/errorhandler.py", line 242, in check_response
    raise exception_class(message, screen, stacktrace)
selenium.common.exceptions.TimeoutException: Message: timeout: Timed out receiving message from renderer: 289.223
  (Session info: headless chrome=87.0.4280.88)

Traceback (most recent call last):
  File "/home/ubuntu/trends-script/scraper.py", line 260, in <module>
    main()
  File "/home/ubuntu/trends-script/scraper.py", line 253, in main
    htmlstring = get_html_from_site()
  File "/home/ubuntu/trends-script/scraper.py", line 28, in get_html_from_site
    driver = webdriver.Chrome(options=options)
  File "/home/ubuntu/.local/lib/python3.8/site-packages/selenium/webdriver/chrome/webdriver.py", line 73, in __init__
    self.service.start()
  File "/home/ubuntu/.local/lib/python3.8/site-packages/selenium/webdriver/common/service.py", line 104, in start
    raise WebDriverException("Can not connect to the Service %s" % self.path)
selenium.common.exceptions.WebDriverException: Message: Can not connect to the Service chromedriver

Traceback (most recent call last):
  File "/home/ubuntu/trends-script/scraper.py", line 260, in <module>
    main()
  File "/home/ubuntu/trends-script/scraper.py", line 253, in main
    htmlstring = get_html_from_site()
  File "/home/ubuntu/trends-script/scraper.py", line 31, in get_html_from_site
    driver.get(start_url)
  File "/home/ubuntu/.local/lib/python3.8/site-packages/selenium/webdriver/remote/webdriver.py", line 333, in get
    self.execute(Command.GET, {'url': url})
  File "/home/ubuntu/.local/lib/python3.8/site-packages/selenium/webdriver/remote/webdriver.py", line 321, in execute
    self.error_handler.check_response(response)
  File "/home/ubuntu/.local/lib/python3.8/site-packages/selenium/webdriver/remote/errorhandler.py", line 242, in check_response
    raise exception_class(message, screen, stacktrace)
selenium.common.exceptions.TimeoutException: Message: timeout: Timed out receiving message from renderer: 288.888
  (Session info: headless chrome=87.0.4280.88)

Traceback (most recent call last):
  File "/home/ubuntu/trends-script/scraper.py", line 260, in <module>
    main()
  File "/home/ubuntu/trends-script/scraper.py", line 253, in main
    htmlstring = get_html_from_site()
  File "/home/ubuntu/trends-script/scraper.py", line 28, in get_html_from_site
    driver = webdriver.Chrome(options=options)
  File "/home/ubuntu/.local/lib/python3.8/site-packages/selenium/webdriver/chrome/webdriver.py", line 73, in __init__
    self.service.start()
  File "/home/ubuntu/.local/lib/python3.8/site-packages/selenium/webdriver/common/service.py", line 104, in start
    raise WebDriverException("Can not connect to the Service %s" % self.path)
selenium.common.exceptions.WebDriverException: Message: Can not connect to the Service chromedriver

Traceback (most recent call last):
  File "/home/ubuntu/trends-script/scraper.py", line 260, in <module>
    main()
  File "/home/ubuntu/trends-script/scraper.py", line 253, in main
    htmlstring = get_html_from_site()
  File "/home/ubuntu/trends-script/scraper.py", line 31, in get_html_from_site
    driver.get(start_url)
  File "/home/ubuntu/.local/lib/python3.8/site-packages/selenium/webdriver/remote/webdriver.py", line 333, in get
    self.execute(Command.GET, {'url': url})
  File "/home/ubuntu/.local/lib/python3.8/site-packages/selenium/webdriver/remote/webdriver.py", line 321, in execute
    self.error_handler.check_response(response)
  File "/home/ubuntu/.local/lib/python3.8/site-packages/selenium/webdriver/remote/errorhandler.py", line 242, in check_response
    raise exception_class(message, screen, stacktrace)
selenium.common.exceptions.TimeoutException: Message: timeout: Timed out receiving message from renderer: 286.744
  (Session info: headless chrome=87.0.4280.88)

Traceback (most recent call last):
  File "/home/ubuntu/trends-script/scraper.py", line 260, in <module>
    main()
  File "/home/ubuntu/trends-script/scraper.py", line 253, in main
    htmlstring = get_html_from_site()
  File "/home/ubuntu/trends-script/scraper.py", line 28, in get_html_from_site
    driver = webdriver.Chrome(options=options)
  File "/home/ubuntu/.local/lib/python3.8/site-packages/selenium/webdriver/chrome/webdriver.py", line 73, in __init__
    self.service.start()
  File "/home/ubuntu/.local/lib/python3.8/site-packages/selenium/webdriver/common/service.py", line 104, in start
    raise WebDriverException("Can not connect to the Service %s" % self.path)
selenium.common.exceptions.WebDriverException: Message: Can not connect to the Service chromedriver

Traceback (most recent call last):
  File "/home/ubuntu/trends-script/scraper.py", line 260, in <module>
    main()
  File "/home/ubuntu/trends-script/scraper.py", line 253, in main
    htmlstring = get_html_from_site()
  File "/home/ubuntu/trends-script/scraper.py", line 31, in get_html_from_site
    driver.get(start_url)
  File "/home/ubuntu/.local/lib/python3.8/site-packages/selenium/webdriver/remote/webdriver.py", line 333, in get
    self.execute(Command.GET, {'url': url})
  File "/home/ubuntu/.local/lib/python3.8/site-packages/selenium/webdriver/remote/webdriver.py", line 321, in execute
    self.error_handler.check_response(response)
  File "/home/ubuntu/.local/lib/python3.8/site-packages/selenium/webdriver/remote/errorhandler.py", line 242, in check_response
    raise exception_class(message, screen, stacktrace)
selenium.common.exceptions.TimeoutException: Message: timeout: Timed out receiving message from renderer: 289.871
  (Session info: headless chrome=87.0.4280.88)

Traceback (most recent call last):
  File "/home/ubuntu/trends-script/scraper.py", line 260, in <module>
    main()
  File "/home/ubuntu/trends-script/scraper.py", line 253, in main
    htmlstring = get_html_from_site()
  File "/home/ubuntu/trends-script/scraper.py", line 28, in get_html_from_site
    driver = webdriver.Chrome(options=options)
  File "/home/ubuntu/.local/lib/python3.8/site-packages/selenium/webdriver/chrome/webdriver.py", line 73, in __init__
    self.service.start()
  File "/home/ubuntu/.local/lib/python3.8/site-packages/selenium/webdriver/common/service.py", line 104, in start
    raise WebDriverException("Can not connect to the Service %s" % self.path)
selenium.common.exceptions.WebDriverException: Message: Can not connect to the Service chromedriver

Traceback (most recent call last):
  File "/home/ubuntu/trends-script/scraper.py", line 260, in <module>
    main()
  File "/home/ubuntu/trends-script/scraper.py", line 253, in main
    htmlstring = get_html_from_site()
  File "/home/ubuntu/trends-script/scraper.py", line 31, in get_html_from_site
    driver.get(start_url)
  File "/home/ubuntu/.local/lib/python3.8/site-packages/selenium/webdriver/remote/webdriver.py", line 333, in get
    self.execute(Command.GET, {'url': url})
  File "/home/ubuntu/.local/lib/python3.8/site-packages/selenium/webdriver/remote/webdriver.py", line 321, in execute
    self.error_handler.check_response(response)
  File "/home/ubuntu/.local/lib/python3.8/site-packages/selenium/webdriver/remote/errorhandler.py", line 242, in check_response
    raise exception_class(message, screen, stacktrace)
selenium.common.exceptions.TimeoutException: Message: timeout: Timed out receiving message from renderer: 291.371
  (Session info: headless chrome=87.0.4280.88)

Traceback (most recent call last):
  File "/home/ubuntu/trends-script/scraper.py", line 260, in <module>
    main()
  File "/home/ubuntu/trends-script/scraper.py", line 253, in main
    htmlstring = get_html_from_site()
  File "/home/ubuntu/trends-script/scraper.py", line 28, in get_html_from_site
    driver = webdriver.Chrome(options=options)
  File "/home/ubuntu/.local/lib/python3.8/site-packages/selenium/webdriver/chrome/webdriver.py", line 73, in __init__
    self.service.start()
  File "/home/ubuntu/.local/lib/python3.8/site-packages/selenium/webdriver/common/service.py", line 104, in start
    raise WebDriverException("Can not connect to the Service %s" % self.path)
selenium.common.exceptions.WebDriverException: Message: Can not connect to the Service chromedriver

Traceback (most recent call last):
  File "/home/ubuntu/trends-script/scraper.py", line 260, in <module>
    main()
  File "/home/ubuntu/trends-script/scraper.py", line 253, in main
    htmlstring = get_html_from_site()
  File "/home/ubuntu/trends-script/scraper.py", line 31, in get_html_from_site
    driver.get(start_url)
  File "/home/ubuntu/.local/lib/python3.8/site-packages/selenium/webdriver/remote/webdriver.py", line 333, in get
    self.execute(Command.GET, {'url': url})
  File "/home/ubuntu/.local/lib/python3.8/site-packages/selenium/webdriver/remote/webdriver.py", line 321, in execute
    self.error_handler.check_response(response)
  File "/home/ubuntu/.local/lib/python3.8/site-packages/selenium/webdriver/remote/errorhandler.py", line 242, in check_response
    raise exception_class(message, screen, stacktrace)
selenium.common.exceptions.TimeoutException: Message: timeout: Timed out receiving message from renderer: 286.484
  (Session info: headless chrome=87.0.4280.88)

Traceback (most recent call last):
  File "/home/ubuntu/trends-script/scraper.py", line 260, in <module>
    main()
  File "/home/ubuntu/trends-script/scraper.py", line 253, in main
    htmlstring = get_html_from_site()
  File "/home/ubuntu/trends-script/scraper.py", line 28, in get_html_from_site
    driver = webdriver.Chrome(options=options)
  File "/home/ubuntu/.local/lib/python3.8/site-packages/selenium/webdriver/chrome/webdriver.py", line 73, in __init__
    self.service.start()
  File "/home/ubuntu/.local/lib/python3.8/site-packages/selenium/webdriver/common/service.py", line 104, in start
    raise WebDriverException("Can not connect to the Service %s" % self.path)
selenium.common.exceptions.WebDriverException: Message: Can not connect to the Service chromedriver

Traceback (most recent call last):
  File "/home/ubuntu/trends-script/scraper.py", line 260, in <module>
    main()
  File "/home/ubuntu/trends-script/scraper.py", line 253, in main
    htmlstring = get_html_from_site()
  File "/home/ubuntu/trends-script/scraper.py", line 31, in get_html_from_site
    driver.get(start_url)
  File "/home/ubuntu/.local/lib/python3.8/site-packages/selenium/webdriver/remote/webdriver.py", line 333, in get
    self.execute(Command.GET, {'url': url})
  File "/home/ubuntu/.local/lib/python3.8/site-packages/selenium/webdriver/remote/webdriver.py", line 321, in execute
    self.error_handler.check_response(response)
  File "/home/ubuntu/.local/lib/python3.8/site-packages/selenium/webdriver/remote/errorhandler.py", line 242, in check_response
    raise exception_class(message, screen, stacktrace)
selenium.common.exceptions.TimeoutException: Message: timeout: Timed out receiving message from renderer: 290.146
  (Session info: headless chrome=87.0.4280.88)

Traceback (most recent call last):
  File "/home/ubuntu/trends-script/scraper.py", line 260, in <module>
    main()
  File "/home/ubuntu/trends-script/scraper.py", line 253, in main
    htmlstring = get_html_from_site()
  File "/home/ubuntu/trends-script/scraper.py", line 28, in get_html_from_site
    driver = webdriver.Chrome(options=options)
  File "/home/ubuntu/.local/lib/python3.8/site-packages/selenium/webdriver/chrome/webdriver.py", line 73, in __init__
    self.service.start()
  File "/home/ubuntu/.local/lib/python3.8/site-packages/selenium/webdriver/common/service.py", line 104, in start
    raise WebDriverException("Can not connect to the Service %s" % self.path)
selenium.common.exceptions.WebDriverException: Message: Can not connect to the Service chromedriver

Traceback (most recent call last):
  File "/home/ubuntu/trends-script/scraper.py", line 260, in <module>
    main()
  File "/home/ubuntu/trends-script/scraper.py", line 253, in main
    htmlstring = get_html_from_site()
  File "/home/ubuntu/trends-script/scraper.py", line 28, in get_html_from_site
    driver = webdriver.Chrome(options=options)
  File "/home/ubuntu/.local/lib/python3.8/site-packages/selenium/webdriver/chrome/webdriver.py", line 73, in __init__
    self.service.start()
  File "/home/ubuntu/.local/lib/python3.8/site-packages/selenium/webdriver/common/service.py", line 104, in start
    raise WebDriverException("Can not connect to the Service %s" % self.path)
selenium.common.exceptions.WebDriverException: Message: Can not connect to the Service chromedriver

Traceback (most recent call last):
  File "/home/ubuntu/trends-script/scraper.py", line 260, in <module>
    main()
  File "/home/ubuntu/trends-script/scraper.py", line 253, in main
    htmlstring = get_html_from_site()
  File "/home/ubuntu/trends-script/scraper.py", line 31, in get_html_from_site
    driver.get(start_url)
  File "/home/ubuntu/.local/lib/python3.8/site-packages/selenium/webdriver/remote/webdriver.py", line 333, in get
    self.execute(Command.GET, {'url': url})
  File "/home/ubuntu/.local/lib/python3.8/site-packages/selenium/webdriver/remote/webdriver.py", line 321, in execute
    self.error_handler.check_response(response)
  File "/home/ubuntu/.local/lib/python3.8/site-packages/selenium/webdriver/remote/errorhandler.py", line 242, in check_response
    raise exception_class(message, screen, stacktrace)
selenium.common.exceptions.TimeoutException: Message: timeout: Timed out receiving message from renderer: 288.566
  (Session info: headless chrome=87.0.4280.88)

Traceback (most recent call last):
  File "/home/ubuntu/trends-script/scraper.py", line 260, in <module>
    main()
  File "/home/ubuntu/trends-script/scraper.py", line 253, in main
    htmlstring = get_html_from_site()
  File "/home/ubuntu/trends-script/scraper.py", line 28, in get_html_from_site
    driver = webdriver.Chrome(options=options)
  File "/home/ubuntu/.local/lib/python3.8/site-packages/selenium/webdriver/chrome/webdriver.py", line 73, in __init__
    self.service.start()
  File "/home/ubuntu/.local/lib/python3.8/site-packages/selenium/webdriver/common/service.py", line 104, in start
    raise WebDriverException("Can not connect to the Service %s" % self.path)
selenium.common.exceptions.WebDriverException: Message: Can not connect to the Service chromedriver

Traceback (most recent call last):
  File "/home/ubuntu/trends-script/scraper.py", line 260, in <module>
    main()
  File "/home/ubuntu/trends-script/scraper.py", line 253, in main
    htmlstring = get_html_from_site()
  File "/home/ubuntu/trends-script/scraper.py", line 31, in get_html_from_site
    driver.get(start_url)
  File "/home/ubuntu/.local/lib/python3.8/site-packages/selenium/webdriver/remote/webdriver.py", line 333, in get
    self.execute(Command.GET, {'url': url})
  File "/home/ubuntu/.local/lib/python3.8/site-packages/selenium/webdriver/remote/webdriver.py", line 321, in execute
    self.error_handler.check_response(response)
  File "/home/ubuntu/.local/lib/python3.8/site-packages/selenium/webdriver/remote/errorhandler.py", line 242, in check_response
    raise exception_class(message, screen, stacktrace)
selenium.common.exceptions.TimeoutException: Message: timeout: Timed out receiving message from renderer: 287.907
  (Session info: headless chrome=87.0.4280.88)

Traceback (most recent call last):
  File "/home/ubuntu/trends-script/scraper.py", line 260, in <module>
    main()
  File "/home/ubuntu/trends-script/scraper.py", line 253, in main
    htmlstring = get_html_from_site()
  File "/home/ubuntu/trends-script/scraper.py", line 28, in get_html_from_site
    driver = webdriver.Chrome(options=options)
  File "/home/ubuntu/.local/lib/python3.8/site-packages/selenium/webdriver/chrome/webdriver.py", line 73, in __init__
    self.service.start()
  File "/home/ubuntu/.local/lib/python3.8/site-packages/selenium/webdriver/common/service.py", line 104, in start
    raise WebDriverException("Can not connect to the Service %s" % self.path)
selenium.common.exceptions.WebDriverException: Message: Can not connect to the Service chromedriver

Traceback (most recent call last):
  File "/home/ubuntu/trends-script/scraper.py", line 260, in <module>
    main()
  File "/home/ubuntu/trends-script/scraper.py", line 253, in main
    htmlstring = get_html_from_site()
  File "/home/ubuntu/trends-script/scraper.py", line 31, in get_html_from_site
    driver.get(start_url)
  File "/home/ubuntu/.local/lib/python3.8/site-packages/selenium/webdriver/remote/webdriver.py", line 333, in get
    self.execute(Command.GET, {'url': url})
  File "/home/ubuntu/.local/lib/python3.8/site-packages/selenium/webdriver/remote/webdriver.py", line 321, in execute
    self.error_handler.check_response(response)
  File "/home/ubuntu/.local/lib/python3.8/site-packages/selenium/webdriver/remote/errorhandler.py", line 242, in check_response
    raise exception_class(message, screen, stacktrace)
selenium.common.exceptions.TimeoutException: Message: timeout: Timed out receiving message from renderer: 287.419
  (Session info: headless chrome=87.0.4280.88)

Traceback (most recent call last):
  File "/home/ubuntu/trends-script/scraper.py", line 260, in <module>
    main()
  File "/home/ubuntu/trends-script/scraper.py", line 253, in main
    htmlstring = get_html_from_site()
  File "/home/ubuntu/trends-script/scraper.py", line 28, in get_html_from_site
    driver = webdriver.Chrome(options=options)
  File "/home/ubuntu/.local/lib/python3.8/site-packages/selenium/webdriver/chrome/webdriver.py", line 73, in __init__
    self.service.start()
  File "/home/ubuntu/.local/lib/python3.8/site-packages/selenium/webdriver/common/service.py", line 104, in start
    raise WebDriverException("Can not connect to the Service %s" % self.path)
selenium.common.exceptions.WebDriverException: Message: Can not connect to the Service chromedriver

Traceback (most recent call last):
  File "/home/ubuntu/trends-script/scraper.py", line 260, in <module>
    main()
  File "/home/ubuntu/trends-script/scraper.py", line 253, in main
    htmlstring = get_html_from_site()
  File "/home/ubuntu/trends-script/scraper.py", line 31, in get_html_from_site
    driver.get(start_url)
  File "/home/ubuntu/.local/lib/python3.8/site-packages/selenium/webdriver/remote/webdriver.py", line 333, in get
    self.execute(Command.GET, {'url': url})
  File "/home/ubuntu/.local/lib/python3.8/site-packages/selenium/webdriver/remote/webdriver.py", line 321, in execute
    self.error_handler.check_response(response)
  File "/home/ubuntu/.local/lib/python3.8/site-packages/selenium/webdriver/remote/errorhandler.py", line 242, in check_response
    raise exception_class(message, screen, stacktrace)
selenium.common.exceptions.TimeoutException: Message: timeout: Timed out receiving message from renderer: 288.191
  (Session info: headless chrome=87.0.4280.88)

Traceback (most recent call last):
  File "/home/ubuntu/trends-script/scraper.py", line 260, in <module>
    main()
  File "/home/ubuntu/trends-script/scraper.py", line 253, in main
    htmlstring = get_html_from_site()
  File "/home/ubuntu/trends-script/scraper.py", line 28, in get_html_from_site
    driver = webdriver.Chrome(options=options)
  File "/home/ubuntu/.local/lib/python3.8/site-packages/selenium/webdriver/chrome/webdriver.py", line 73, in __init__
    self.service.start()
  File "/home/ubuntu/.local/lib/python3.8/site-packages/selenium/webdriver/common/service.py", line 104, in start
    raise WebDriverException("Can not connect to the Service %s" % self.path)
selenium.common.exceptions.WebDriverException: Message: Can not connect to the Service chromedriver

Traceback (most recent call last):
  File "/home/ubuntu/trends-script/scraper.py", line 260, in <module>
    main()
  File "/home/ubuntu/trends-script/scraper.py", line 253, in main
    htmlstring = get_html_from_site()
  File "/home/ubuntu/trends-script/scraper.py", line 31, in get_html_from_site
    driver.get(start_url)
  File "/home/ubuntu/.local/lib/python3.8/site-packages/selenium/webdriver/remote/webdriver.py", line 333, in get
    self.execute(Command.GET, {'url': url})
  File "/home/ubuntu/.local/lib/python3.8/site-packages/selenium/webdriver/remote/webdriver.py", line 321, in execute
    self.error_handler.check_response(response)
  File "/home/ubuntu/.local/lib/python3.8/site-packages/selenium/webdriver/remote/errorhandler.py", line 242, in check_response
    raise exception_class(message, screen, stacktrace)
selenium.common.exceptions.TimeoutException: Message: timeout: Timed out receiving message from renderer: 288.695
  (Session info: headless chrome=87.0.4280.88)

Traceback (most recent call last):
  File "/home/ubuntu/trends-script/scraper.py", line 260, in <module>
    main()
  File "/home/ubuntu/trends-script/scraper.py", line 253, in main
    htmlstring = get_html_from_site()
  File "/home/ubuntu/trends-script/scraper.py", line 28, in get_html_from_site
    driver = webdriver.Chrome(options=options)
  File "/home/ubuntu/.local/lib/python3.8/site-packages/selenium/webdriver/chrome/webdriver.py", line 73, in __init__
    self.service.start()
  File "/home/ubuntu/.local/lib/python3.8/site-packages/selenium/webdriver/common/service.py", line 104, in start
    raise WebDriverException("Can not connect to the Service %s" % self.path)
selenium.common.exceptions.WebDriverException: Message: Can not connect to the Service chromedriver

Traceback (most recent call last):
  File "/home/ubuntu/trends-script/scraper.py", line 260, in <module>
    main()
  File "/home/ubuntu/trends-script/scraper.py", line 253, in main
    htmlstring = get_html_from_site()
  File "/home/ubuntu/trends-script/scraper.py", line 31, in get_html_from_site
    driver.get(start_url)
  File "/home/ubuntu/.local/lib/python3.8/site-packages/selenium/webdriver/remote/webdriver.py", line 333, in get
    self.execute(Command.GET, {'url': url})
  File "/home/ubuntu/.local/lib/python3.8/site-packages/selenium/webdriver/remote/webdriver.py", line 321, in execute
    self.error_handler.check_response(response)
  File "/home/ubuntu/.local/lib/python3.8/site-packages/selenium/webdriver/remote/errorhandler.py", line 242, in check_response
    raise exception_class(message, screen, stacktrace)
selenium.common.exceptions.TimeoutException: Message: timeout: Timed out receiving message from renderer: 287.153
  (Session info: headless chrome=87.0.4280.88)

Traceback (most recent call last):
  File "/home/ubuntu/trends-script/scraper.py", line 260, in <module>
    main()
  File "/home/ubuntu/trends-script/scraper.py", line 253, in main
    htmlstring = get_html_from_site()
  File "/home/ubuntu/trends-script/scraper.py", line 28, in get_html_from_site
    driver = webdriver.Chrome(options=options)
  File "/home/ubuntu/.local/lib/python3.8/site-packages/selenium/webdriver/chrome/webdriver.py", line 73, in __init__
    self.service.start()
  File "/home/ubuntu/.local/lib/python3.8/site-packages/selenium/webdriver/common/service.py", line 104, in start
    raise WebDriverException("Can not connect to the Service %s" % self.path)
selenium.common.exceptions.WebDriverException: Message: Can not connect to the Service chromedriver

Traceback (most recent call last):
  File "/home/ubuntu/trends-script/scraper.py", line 260, in <module>
    main()
  File "/home/ubuntu/trends-script/scraper.py", line 253, in main
    htmlstring = get_html_from_site()
  File "/home/ubuntu/trends-script/scraper.py", line 31, in get_html_from_site
    driver.get(start_url)
  File "/home/ubuntu/.local/lib/python3.8/site-packages/selenium/webdriver/remote/webdriver.py", line 333, in get
    self.execute(Command.GET, {'url': url})
  File "/home/ubuntu/.local/lib/python3.8/site-packages/selenium/webdriver/remote/webdriver.py", line 321, in execute
    self.error_handler.check_response(response)
  File "/home/ubuntu/.local/lib/python3.8/site-packages/selenium/webdriver/remote/errorhandler.py", line 242, in check_response
    raise exception_class(message, screen, stacktrace)
selenium.common.exceptions.TimeoutException: Message: timeout: Timed out receiving message from renderer: 287.254
  (Session info: headless chrome=87.0.4280.88)

Traceback (most recent call last):
  File "/home/ubuntu/trends-script/scraper.py", line 260, in <module>
    main()
  File "/home/ubuntu/trends-script/scraper.py", line 253, in main
    htmlstring = get_html_from_site()
  File "/home/ubuntu/trends-script/scraper.py", line 28, in get_html_from_site
    driver = webdriver.Chrome(options=options)
  File "/home/ubuntu/.local/lib/python3.8/site-packages/selenium/webdriver/chrome/webdriver.py", line 73, in __init__
    self.service.start()
  File "/home/ubuntu/.local/lib/python3.8/site-packages/selenium/webdriver/common/service.py", line 104, in start
    raise WebDriverException("Can not connect to the Service %s" % self.path)
selenium.common.exceptions.WebDriverException: Message: Can not connect to the Service chromedriver

Traceback (most recent call last):
  File "/home/ubuntu/trends-script/scraper.py", line 260, in <module>
    main()
  File "/home/ubuntu/trends-script/scraper.py", line 253, in main
    htmlstring = get_html_from_site()
  File "/home/ubuntu/trends-script/scraper.py", line 31, in get_html_from_site
    driver.get(start_url)
  File "/home/ubuntu/.local/lib/python3.8/site-packages/selenium/webdriver/remote/webdriver.py", line 333, in get
    self.execute(Command.GET, {'url': url})
  File "/home/ubuntu/.local/lib/python3.8/site-packages/selenium/webdriver/remote/webdriver.py", line 321, in execute
    self.error_handler.check_response(response)
  File "/home/ubuntu/.local/lib/python3.8/site-packages/selenium/webdriver/remote/errorhandler.py", line 242, in check_response
    raise exception_class(message, screen, stacktrace)
selenium.common.exceptions.TimeoutException: Message: timeout: Timed out receiving message from renderer: 286.218
  (Session info: headless chrome=87.0.4280.88)

Traceback (most recent call last):
  File "/home/ubuntu/trends-script/scraper.py", line 260, in <module>
    main()
  File "/home/ubuntu/trends-script/scraper.py", line 253, in main
    htmlstring = get_html_from_site()
  File "/home/ubuntu/trends-script/scraper.py", line 28, in get_html_from_site
    driver = webdriver.Chrome(options=options)
  File "/home/ubuntu/.local/lib/python3.8/site-packages/selenium/webdriver/chrome/webdriver.py", line 73, in __init__
    self.service.start()
  File "/home/ubuntu/.local/lib/python3.8/site-packages/selenium/webdriver/common/service.py", line 104, in start
    raise WebDriverException("Can not connect to the Service %s" % self.path)
selenium.common.exceptions.WebDriverException: Message: Can not connect to the Service chromedriver

Traceback (most recent call last):
  File "/home/ubuntu/trends-script/scraper.py", line 260, in <module>
    main()
  File "/home/ubuntu/trends-script/scraper.py", line 253, in main
    htmlstring = get_html_from_site()
  File "/home/ubuntu/trends-script/scraper.py", line 31, in get_html_from_site
    driver.get(start_url)
  File "/home/ubuntu/.local/lib/python3.8/site-packages/selenium/webdriver/remote/webdriver.py", line 333, in get
    self.execute(Command.GET, {'url': url})
  File "/home/ubuntu/.local/lib/python3.8/site-packages/selenium/webdriver/remote/webdriver.py", line 321, in execute
    self.error_handler.check_response(response)
  File "/home/ubuntu/.local/lib/python3.8/site-packages/selenium/webdriver/remote/errorhandler.py", line 242, in check_response
    raise exception_class(message, screen, stacktrace)
selenium.common.exceptions.TimeoutException: Message: timeout: Timed out receiving message from renderer: 287.808
  (Session info: headless chrome=87.0.4280.88)

Traceback (most recent call last):
  File "/home/ubuntu/trends-script/scraper.py", line 260, in <module>
    main()
  File "/home/ubuntu/trends-script/scraper.py", line 253, in main
    htmlstring = get_html_from_site()
  File "/home/ubuntu/trends-script/scraper.py", line 28, in get_html_from_site
    driver = webdriver.Chrome(options=options)
  File "/home/ubuntu/.local/lib/python3.8/site-packages/selenium/webdriver/chrome/webdriver.py", line 73, in __init__
    self.service.start()
  File "/home/ubuntu/.local/lib/python3.8/site-packages/selenium/webdriver/common/service.py", line 104, in start
    raise WebDriverException("Can not connect to the Service %s" % self.path)
selenium.common.exceptions.WebDriverException: Message: Can not connect to the Service chromedriver

Traceback (most recent call last):
  File "/home/ubuntu/trends-script/scraper.py", line 260, in <module>
    main()
  File "/home/ubuntu/trends-script/scraper.py", line 253, in main
    htmlstring = get_html_from_site()
  File "/home/ubuntu/trends-script/scraper.py", line 31, in get_html_from_site
    driver.get(start_url)
  File "/home/ubuntu/.local/lib/python3.8/site-packages/selenium/webdriver/remote/webdriver.py", line 333, in get
    self.execute(Command.GET, {'url': url})
  File "/home/ubuntu/.local/lib/python3.8/site-packages/selenium/webdriver/remote/webdriver.py", line 321, in execute
    self.error_handler.check_response(response)
  File "/home/ubuntu/.local/lib/python3.8/site-packages/selenium/webdriver/remote/errorhandler.py", line 242, in check_response
    raise exception_class(message, screen, stacktrace)
selenium.common.exceptions.TimeoutException: Message: timeout: Timed out receiving message from renderer: 285.025
  (Session info: headless chrome=87.0.4280.88)

Traceback (most recent call last):
  File "/home/ubuntu/trends-script/scraper.py", line 260, in <module>
    main()
  File "/home/ubuntu/trends-script/scraper.py", line 253, in main
    htmlstring = get_html_from_site()
  File "/home/ubuntu/trends-script/scraper.py", line 28, in get_html_from_site
    driver = webdriver.Chrome(options=options)
  File "/home/ubuntu/.local/lib/python3.8/site-packages/selenium/webdriver/chrome/webdriver.py", line 73, in __init__
    self.service.start()
  File "/home/ubuntu/.local/lib/python3.8/site-packages/selenium/webdriver/common/service.py", line 104, in start
    raise WebDriverException("Can not connect to the Service %s" % self.path)
selenium.common.exceptions.WebDriverException: Message: Can not connect to the Service chromedriver

Traceback (most recent call last):
  File "/home/ubuntu/trends-script/scraper.py", line 260, in <module>
    main()
  File "/home/ubuntu/trends-script/scraper.py", line 253, in main
    htmlstring = get_html_from_site()
  File "/home/ubuntu/trends-script/scraper.py", line 31, in get_html_from_site
    driver.get(start_url)
  File "/home/ubuntu/.local/lib/python3.8/site-packages/selenium/webdriver/remote/webdriver.py", line 333, in get
    self.execute(Command.GET, {'url': url})
  File "/home/ubuntu/.local/lib/python3.8/site-packages/selenium/webdriver/remote/webdriver.py", line 321, in execute
    self.error_handler.check_response(response)
  File "/home/ubuntu/.local/lib/python3.8/site-packages/selenium/webdriver/remote/errorhandler.py", line 242, in check_response
    raise exception_class(message, screen, stacktrace)
selenium.common.exceptions.TimeoutException: Message: timeout: Timed out receiving message from renderer: 290.202
  (Session info: headless chrome=87.0.4280.88)

Traceback (most recent call last):
  File "/home/ubuntu/trends-script/scraper.py", line 260, in <module>
    main()
  File "/home/ubuntu/trends-script/scraper.py", line 253, in main
    htmlstring = get_html_from_site()
  File "/home/ubuntu/trends-script/scraper.py", line 28, in get_html_from_site
    driver = webdriver.Chrome(options=options)
  File "/home/ubuntu/.local/lib/python3.8/site-packages/selenium/webdriver/chrome/webdriver.py", line 73, in __init__
    self.service.start()
  File "/home/ubuntu/.local/lib/python3.8/site-packages/selenium/webdriver/common/service.py", line 104, in start
    raise WebDriverException("Can not connect to the Service %s" % self.path)
selenium.common.exceptions.WebDriverException: Message: Can not connect to the Service chromedriver

Traceback (most recent call last):
  File "/home/ubuntu/trends-script/scraper.py", line 260, in <module>
    main()
  File "/home/ubuntu/trends-script/scraper.py", line 253, in main
    htmlstring = get_html_from_site()
  File "/home/ubuntu/trends-script/scraper.py", line 31, in get_html_from_site
    driver.get(start_url)
  File "/home/ubuntu/.local/lib/python3.8/site-packages/selenium/webdriver/remote/webdriver.py", line 333, in get
    self.execute(Command.GET, {'url': url})
  File "/home/ubuntu/.local/lib/python3.8/site-packages/selenium/webdriver/remote/webdriver.py", line 321, in execute
    self.error_handler.check_response(response)
  File "/home/ubuntu/.local/lib/python3.8/site-packages/selenium/webdriver/remote/errorhandler.py", line 242, in check_response
    raise exception_class(message, screen, stacktrace)
selenium.common.exceptions.TimeoutException: Message: timeout: Timed out receiving message from renderer: 285.247
  (Session info: headless chrome=87.0.4280.88)

Traceback (most recent call last):
  File "/home/ubuntu/trends-script/scraper.py", line 260, in <module>
    main()
  File "/home/ubuntu/trends-script/scraper.py", line 253, in main
    htmlstring = get_html_from_site()
  File "/home/ubuntu/trends-script/scraper.py", line 28, in get_html_from_site
    driver = webdriver.Chrome(options=options)
  File "/home/ubuntu/.local/lib/python3.8/site-packages/selenium/webdriver/chrome/webdriver.py", line 73, in __init__
    self.service.start()
  File "/home/ubuntu/.local/lib/python3.8/site-packages/selenium/webdriver/common/service.py", line 104, in start
    raise WebDriverException("Can not connect to the Service %s" % self.path)
selenium.common.exceptions.WebDriverException: Message: Can not connect to the Service chromedriver

Traceback (most recent call last):
  File "/home/ubuntu/trends-script/scraper.py", line 260, in <module>
    main()
  File "/home/ubuntu/trends-script/scraper.py", line 253, in main
    htmlstring = get_html_from_site()
  File "/home/ubuntu/trends-script/scraper.py", line 31, in get_html_from_site
    driver.get(start_url)
  File "/home/ubuntu/.local/lib/python3.8/site-packages/selenium/webdriver/remote/webdriver.py", line 333, in get
    self.execute(Command.GET, {'url': url})
  File "/home/ubuntu/.local/lib/python3.8/site-packages/selenium/webdriver/remote/webdriver.py", line 321, in execute
    self.error_handler.check_response(response)
  File "/home/ubuntu/.local/lib/python3.8/site-packages/selenium/webdriver/remote/errorhandler.py", line 242, in check_response
    raise exception_class(message, screen, stacktrace)
selenium.common.exceptions.TimeoutException: Message: timeout: Timed out receiving message from renderer: 288.759
  (Session info: headless chrome=87.0.4280.88)

Traceback (most recent call last):
  File "/home/ubuntu/trends-script/scraper.py", line 260, in <module>
    main()
  File "/home/ubuntu/trends-script/scraper.py", line 253, in main
    htmlstring = get_html_from_site()
  File "/home/ubuntu/trends-script/scraper.py", line 28, in get_html_from_site
    driver = webdriver.Chrome(options=options)
  File "/home/ubuntu/.local/lib/python3.8/site-packages/selenium/webdriver/chrome/webdriver.py", line 73, in __init__
    self.service.start()
  File "/home/ubuntu/.local/lib/python3.8/site-packages/selenium/webdriver/common/service.py", line 104, in start
    raise WebDriverException("Can not connect to the Service %s" % self.path)
selenium.common.exceptions.WebDriverException: Message: Can not connect to the Service chromedriver

Traceback (most recent call last):
  File "/home/ubuntu/trends-script/scraper.py", line 260, in <module>
    main()
  File "/home/ubuntu/trends-script/scraper.py", line 253, in main
    htmlstring = get_html_from_site()
  File "/home/ubuntu/trends-script/scraper.py", line 31, in get_html_from_site
    driver.get(start_url)
  File "/home/ubuntu/.local/lib/python3.8/site-packages/selenium/webdriver/remote/webdriver.py", line 333, in get
    self.execute(Command.GET, {'url': url})
  File "/home/ubuntu/.local/lib/python3.8/site-packages/selenium/webdriver/remote/webdriver.py", line 321, in execute
    self.error_handler.check_response(response)
  File "/home/ubuntu/.local/lib/python3.8/site-packages/selenium/webdriver/remote/errorhandler.py", line 242, in check_response
    raise exception_class(message, screen, stacktrace)
selenium.common.exceptions.TimeoutException: Message: timeout: Timed out receiving message from renderer: 289.245
  (Session info: headless chrome=87.0.4280.88)

Traceback (most recent call last):
  File "/home/ubuntu/trends-script/scraper.py", line 260, in <module>
    main()
  File "/home/ubuntu/trends-script/scraper.py", line 253, in main
    htmlstring = get_html_from_site()
  File "/home/ubuntu/trends-script/scraper.py", line 28, in get_html_from_site
    driver = webdriver.Chrome(options=options)
  File "/home/ubuntu/.local/lib/python3.8/site-packages/selenium/webdriver/chrome/webdriver.py", line 73, in __init__
    self.service.start()
  File "/home/ubuntu/.local/lib/python3.8/site-packages/selenium/webdriver/common/service.py", line 104, in start
    raise WebDriverException("Can not connect to the Service %s" % self.path)
selenium.common.exceptions.WebDriverException: Message: Can not connect to the Service chromedriver

Traceback (most recent call last):
  File "/home/ubuntu/trends-script/scraper.py", line 260, in <module>
    main()
  File "/home/ubuntu/trends-script/scraper.py", line 253, in main
    htmlstring = get_html_from_site()
  File "/home/ubuntu/trends-script/scraper.py", line 28, in get_html_from_site
    driver = webdriver.Chrome(options=options)
  File "/home/ubuntu/.local/lib/python3.8/site-packages/selenium/webdriver/chrome/webdriver.py", line 73, in __init__
    self.service.start()
  File "/home/ubuntu/.local/lib/python3.8/site-packages/selenium/webdriver/common/service.py", line 104, in start
    raise WebDriverException("Can not connect to the Service %s" % self.path)
selenium.common.exceptions.WebDriverException: Message: Can not connect to the Service chromedriver

Traceback (most recent call last):
  File "/home/ubuntu/trends-script/scraper.py", line 260, in <module>
    main()
  File "/home/ubuntu/trends-script/scraper.py", line 253, in main
    htmlstring = get_html_from_site()
  File "/home/ubuntu/trends-script/scraper.py", line 28, in get_html_from_site
    driver = webdriver.Chrome(options=options)
  File "/home/ubuntu/.local/lib/python3.8/site-packages/selenium/webdriver/chrome/webdriver.py", line 73, in __init__
    self.service.start()
  File "/home/ubuntu/.local/lib/python3.8/site-packages/selenium/webdriver/common/service.py", line 104, in start
    raise WebDriverException("Can not connect to the Service %s" % self.path)
selenium.common.exceptions.WebDriverException: Message: Can not connect to the Service chromedriver

Traceback (most recent call last):
  File "/home/ubuntu/trends-script/scraper.py", line 260, in <module>
    main()
  File "/home/ubuntu/trends-script/scraper.py", line 253, in main
    htmlstring = get_html_from_site()
  File "/home/ubuntu/trends-script/scraper.py", line 31, in get_html_from_site
    driver.get(start_url)
  File "/home/ubuntu/.local/lib/python3.8/site-packages/selenium/webdriver/remote/webdriver.py", line 333, in get
    self.execute(Command.GET, {'url': url})
  File "/home/ubuntu/.local/lib/python3.8/site-packages/selenium/webdriver/remote/webdriver.py", line 321, in execute
    self.error_handler.check_response(response)
  File "/home/ubuntu/.local/lib/python3.8/site-packages/selenium/webdriver/remote/errorhandler.py", line 242, in check_response
    raise exception_class(message, screen, stacktrace)
selenium.common.exceptions.TimeoutException: Message: timeout: Timed out receiving message from renderer: 288.997
  (Session info: headless chrome=87.0.4280.88)

Traceback (most recent call last):
  File "/home/ubuntu/trends-script/scraper.py", line 260, in <module>
    main()
  File "/home/ubuntu/trends-script/scraper.py", line 253, in main
    htmlstring = get_html_from_site()
  File "/home/ubuntu/trends-script/scraper.py", line 28, in get_html_from_site
    driver = webdriver.Chrome(options=options)
  File "/home/ubuntu/.local/lib/python3.8/site-packages/selenium/webdriver/chrome/webdriver.py", line 73, in __init__
    self.service.start()
  File "/home/ubuntu/.local/lib/python3.8/site-packages/selenium/webdriver/common/service.py", line 104, in start
    raise WebDriverException("Can not connect to the Service %s" % self.path)
selenium.common.exceptions.WebDriverException: Message: Can not connect to the Service chromedriver

Traceback (most recent call last):
  File "/home/ubuntu/trends-script/scraper.py", line 260, in <module>
    main()
  File "/home/ubuntu/trends-script/scraper.py", line 253, in main
    htmlstring = get_html_from_site()
  File "/home/ubuntu/trends-script/scraper.py", line 31, in get_html_from_site
    driver.get(start_url)
  File "/home/ubuntu/.local/lib/python3.8/site-packages/selenium/webdriver/remote/webdriver.py", line 333, in get
    self.execute(Command.GET, {'url': url})
  File "/home/ubuntu/.local/lib/python3.8/site-packages/selenium/webdriver/remote/webdriver.py", line 321, in execute
    self.error_handler.check_response(response)
  File "/home/ubuntu/.local/lib/python3.8/site-packages/selenium/webdriver/remote/errorhandler.py", line 242, in check_response
    raise exception_class(message, screen, stacktrace)
selenium.common.exceptions.TimeoutException: Message: timeout: Timed out receiving message from renderer: 288.298
  (Session info: headless chrome=87.0.4280.88)

Traceback (most recent call last):
  File "/home/ubuntu/trends-script/scraper.py", line 260, in <module>
    main()
  File "/home/ubuntu/trends-script/scraper.py", line 253, in main
    htmlstring = get_html_from_site()
  File "/home/ubuntu/trends-script/scraper.py", line 28, in get_html_from_site
    driver = webdriver.Chrome(options=options)
  File "/home/ubuntu/.local/lib/python3.8/site-packages/selenium/webdriver/chrome/webdriver.py", line 73, in __init__
    self.service.start()
  File "/home/ubuntu/.local/lib/python3.8/site-packages/selenium/webdriver/common/service.py", line 104, in start
    raise WebDriverException("Can not connect to the Service %s" % self.path)
selenium.common.exceptions.WebDriverException: Message: Can not connect to the Service chromedriver

Traceback (most recent call last):
  File "/home/ubuntu/trends-script/scraper.py", line 260, in <module>
    main()
  File "/home/ubuntu/trends-script/scraper.py", line 253, in main
    htmlstring = get_html_from_site()
  File "/home/ubuntu/trends-script/scraper.py", line 31, in get_html_from_site
    driver.get(start_url)
  File "/home/ubuntu/.local/lib/python3.8/site-packages/selenium/webdriver/remote/webdriver.py", line 333, in get
    self.execute(Command.GET, {'url': url})
  File "/home/ubuntu/.local/lib/python3.8/site-packages/selenium/webdriver/remote/webdriver.py", line 321, in execute
    self.error_handler.check_response(response)
  File "/home/ubuntu/.local/lib/python3.8/site-packages/selenium/webdriver/remote/errorhandler.py", line 242, in check_response
    raise exception_class(message, screen, stacktrace)
selenium.common.exceptions.TimeoutException: Message: timeout: Timed out receiving message from renderer: 285.938
  (Session info: headless chrome=87.0.4280.88)

Traceback (most recent call last):
  File "/home/ubuntu/trends-script/scraper.py", line 260, in <module>
    main()
  File "/home/ubuntu/trends-script/scraper.py", line 253, in main
    htmlstring = get_html_from_site()
  File "/home/ubuntu/trends-script/scraper.py", line 28, in get_html_from_site
    driver = webdriver.Chrome(options=options)
  File "/home/ubuntu/.local/lib/python3.8/site-packages/selenium/webdriver/chrome/webdriver.py", line 73, in __init__
    self.service.start()
  File "/home/ubuntu/.local/lib/python3.8/site-packages/selenium/webdriver/common/service.py", line 104, in start
    raise WebDriverException("Can not connect to the Service %s" % self.path)
selenium.common.exceptions.WebDriverException: Message: Can not connect to the Service chromedriver

Traceback (most recent call last):
  File "/home/ubuntu/trends-script/scraper.py", line 260, in <module>
    main()
  File "/home/ubuntu/trends-script/scraper.py", line 253, in main
    htmlstring = get_html_from_site()
  File "/home/ubuntu/trends-script/scraper.py", line 31, in get_html_from_site
    driver.get(start_url)
  File "/home/ubuntu/.local/lib/python3.8/site-packages/selenium/webdriver/remote/webdriver.py", line 333, in get
    self.execute(Command.GET, {'url': url})
  File "/home/ubuntu/.local/lib/python3.8/site-packages/selenium/webdriver/remote/webdriver.py", line 321, in execute
    self.error_handler.check_response(response)
  File "/home/ubuntu/.local/lib/python3.8/site-packages/selenium/webdriver/remote/errorhandler.py", line 242, in check_response
    raise exception_class(message, screen, stacktrace)
selenium.common.exceptions.TimeoutException: Message: timeout: Timed out receiving message from renderer: 286.802
  (Session info: headless chrome=87.0.4280.88)

Traceback (most recent call last):
  File "/home/ubuntu/trends-script/scraper.py", line 260, in <module>
    main()
  File "/home/ubuntu/trends-script/scraper.py", line 253, in main
    htmlstring = get_html_from_site()
  File "/home/ubuntu/trends-script/scraper.py", line 28, in get_html_from_site
    driver = webdriver.Chrome(options=options)
  File "/home/ubuntu/.local/lib/python3.8/site-packages/selenium/webdriver/chrome/webdriver.py", line 73, in __init__
    self.service.start()
  File "/home/ubuntu/.local/lib/python3.8/site-packages/selenium/webdriver/common/service.py", line 104, in start
    raise WebDriverException("Can not connect to the Service %s" % self.path)
selenium.common.exceptions.WebDriverException: Message: Can not connect to the Service chromedriver

Traceback (most recent call last):
  File "/home/ubuntu/trends-script/scraper.py", line 260, in <module>
    main()
  File "/home/ubuntu/trends-script/scraper.py", line 253, in main
    htmlstring = get_html_from_site()
  File "/home/ubuntu/trends-script/scraper.py", line 31, in get_html_from_site
    driver.get(start_url)
  File "/home/ubuntu/.local/lib/python3.8/site-packages/selenium/webdriver/remote/webdriver.py", line 333, in get
    self.execute(Command.GET, {'url': url})
  File "/home/ubuntu/.local/lib/python3.8/site-packages/selenium/webdriver/remote/webdriver.py", line 321, in execute
    self.error_handler.check_response(response)
  File "/home/ubuntu/.local/lib/python3.8/site-packages/selenium/webdriver/remote/errorhandler.py", line 242, in check_response
    raise exception_class(message, screen, stacktrace)
selenium.common.exceptions.TimeoutException: Message: timeout: Timed out receiving message from renderer: 287.689
  (Session info: headless chrome=87.0.4280.88)

Traceback (most recent call last):
  File "/home/ubuntu/trends-script/scraper.py", line 260, in <module>
    main()
  File "/home/ubuntu/trends-script/scraper.py", line 253, in main
    htmlstring = get_html_from_site()
  File "/home/ubuntu/trends-script/scraper.py", line 28, in get_html_from_site
    driver = webdriver.Chrome(options=options)
  File "/home/ubuntu/.local/lib/python3.8/site-packages/selenium/webdriver/chrome/webdriver.py", line 73, in __init__
    self.service.start()
  File "/home/ubuntu/.local/lib/python3.8/site-packages/selenium/webdriver/common/service.py", line 104, in start
    raise WebDriverException("Can not connect to the Service %s" % self.path)
selenium.common.exceptions.WebDriverException: Message: Can not connect to the Service chromedriver

Traceback (most recent call last):
  File "/home/ubuntu/trends-script/scraper.py", line 260, in <module>
    main()
  File "/home/ubuntu/trends-script/scraper.py", line 253, in main
    htmlstring = get_html_from_site()
  File "/home/ubuntu/trends-script/scraper.py", line 31, in get_html_from_site
    driver.get(start_url)
  File "/home/ubuntu/.local/lib/python3.8/site-packages/selenium/webdriver/remote/webdriver.py", line 333, in get
    self.execute(Command.GET, {'url': url})
  File "/home/ubuntu/.local/lib/python3.8/site-packages/selenium/webdriver/remote/webdriver.py", line 321, in execute
    self.error_handler.check_response(response)
  File "/home/ubuntu/.local/lib/python3.8/site-packages/selenium/webdriver/remote/errorhandler.py", line 242, in check_response
    raise exception_class(message, screen, stacktrace)
selenium.common.exceptions.TimeoutException: Message: timeout: Timed out receiving message from renderer: 289.553
  (Session info: headless chrome=87.0.4280.88)

Traceback (most recent call last):
  File "/home/ubuntu/trends-script/scraper.py", line 260, in <module>
    main()
  File "/home/ubuntu/trends-script/scraper.py", line 253, in main
    htmlstring = get_html_from_site()
  File "/home/ubuntu/trends-script/scraper.py", line 28, in get_html_from_site
    driver = webdriver.Chrome(options=options)
  File "/home/ubuntu/.local/lib/python3.8/site-packages/selenium/webdriver/chrome/webdriver.py", line 73, in __init__
    self.service.start()
  File "/home/ubuntu/.local/lib/python3.8/site-packages/selenium/webdriver/common/service.py", line 104, in start
    raise WebDriverException("Can not connect to the Service %s" % self.path)
selenium.common.exceptions.WebDriverException: Message: Can not connect to the Service chromedriver

Traceback (most recent call last):
  File "/home/ubuntu/trends-script/scraper.py", line 260, in <module>
    main()
  File "/home/ubuntu/trends-script/scraper.py", line 253, in main
    htmlstring = get_html_from_site()
  File "/home/ubuntu/trends-script/scraper.py", line 31, in get_html_from_site
    driver.get(start_url)
  File "/home/ubuntu/.local/lib/python3.8/site-packages/selenium/webdriver/remote/webdriver.py", line 333, in get
    self.execute(Command.GET, {'url': url})
  File "/home/ubuntu/.local/lib/python3.8/site-packages/selenium/webdriver/remote/webdriver.py", line 321, in execute
    self.error_handler.check_response(response)
  File "/home/ubuntu/.local/lib/python3.8/site-packages/selenium/webdriver/remote/errorhandler.py", line 242, in check_response
    raise exception_class(message, screen, stacktrace)
selenium.common.exceptions.TimeoutException: Message: timeout: Timed out receiving message from renderer: 285.407
  (Session info: headless chrome=87.0.4280.88)

Traceback (most recent call last):
  File "/home/ubuntu/trends-script/scraper.py", line 260, in <module>
    main()
  File "/home/ubuntu/trends-script/scraper.py", line 253, in main
    htmlstring = get_html_from_site()
  File "/home/ubuntu/trends-script/scraper.py", line 28, in get_html_from_site
    driver = webdriver.Chrome(options=options)
  File "/home/ubuntu/.local/lib/python3.8/site-packages/selenium/webdriver/chrome/webdriver.py", line 73, in __init__
    self.service.start()
  File "/home/ubuntu/.local/lib/python3.8/site-packages/selenium/webdriver/common/service.py", line 104, in start
    raise WebDriverException("Can not connect to the Service %s" % self.path)
selenium.common.exceptions.WebDriverException: Message: Can not connect to the Service chromedriver

Traceback (most recent call last):
  File "/home/ubuntu/trends-script/scraper.py", line 260, in <module>
    main()
  File "/home/ubuntu/trends-script/scraper.py", line 253, in main
    htmlstring = get_html_from_site()
  File "/home/ubuntu/trends-script/scraper.py", line 31, in get_html_from_site
    driver.get(start_url)
  File "/home/ubuntu/.local/lib/python3.8/site-packages/selenium/webdriver/remote/webdriver.py", line 333, in get
    self.execute(Command.GET, {'url': url})
  File "/home/ubuntu/.local/lib/python3.8/site-packages/selenium/webdriver/remote/webdriver.py", line 321, in execute
    self.error_handler.check_response(response)
  File "/home/ubuntu/.local/lib/python3.8/site-packages/selenium/webdriver/remote/errorhandler.py", line 242, in check_response
    raise exception_class(message, screen, stacktrace)
selenium.common.exceptions.TimeoutException: Message: timeout: Timed out receiving message from renderer: 286.150
  (Session info: headless chrome=87.0.4280.88)

Traceback (most recent call last):
  File "/home/ubuntu/trends-script/scraper.py", line 260, in <module>
    main()
  File "/home/ubuntu/trends-script/scraper.py", line 253, in main
    htmlstring = get_html_from_site()
  File "/home/ubuntu/trends-script/scraper.py", line 28, in get_html_from_site
    driver = webdriver.Chrome(options=options)
  File "/home/ubuntu/.local/lib/python3.8/site-packages/selenium/webdriver/chrome/webdriver.py", line 73, in __init__
    self.service.start()
  File "/home/ubuntu/.local/lib/python3.8/site-packages/selenium/webdriver/common/service.py", line 104, in start
    raise WebDriverException("Can not connect to the Service %s" % self.path)
selenium.common.exceptions.WebDriverException: Message: Can not connect to the Service chromedriver

Traceback (most recent call last):
  File "/home/ubuntu/trends-script/scraper.py", line 260, in <module>
    main()
  File "/home/ubuntu/trends-script/scraper.py", line 253, in main
    htmlstring = get_html_from_site()
  File "/home/ubuntu/trends-script/scraper.py", line 31, in get_html_from_site
    driver.get(start_url)
  File "/home/ubuntu/.local/lib/python3.8/site-packages/selenium/webdriver/remote/webdriver.py", line 333, in get
    self.execute(Command.GET, {'url': url})
  File "/home/ubuntu/.local/lib/python3.8/site-packages/selenium/webdriver/remote/webdriver.py", line 321, in execute
    self.error_handler.check_response(response)
  File "/home/ubuntu/.local/lib/python3.8/site-packages/selenium/webdriver/remote/errorhandler.py", line 242, in check_response
    raise exception_class(message, screen, stacktrace)
selenium.common.exceptions.TimeoutException: Message: timeout: Timed out receiving message from renderer: 282.142
  (Session info: headless chrome=87.0.4280.88)

Traceback (most recent call last):
  File "/home/ubuntu/trends-script/scraper.py", line 260, in <module>
    main()
  File "/home/ubuntu/trends-script/scraper.py", line 253, in main
    htmlstring = get_html_from_site()
  File "/home/ubuntu/trends-script/scraper.py", line 28, in get_html_from_site
    driver = webdriver.Chrome(options=options)
  File "/home/ubuntu/.local/lib/python3.8/site-packages/selenium/webdriver/chrome/webdriver.py", line 73, in __init__
    self.service.start()
  File "/home/ubuntu/.local/lib/python3.8/site-packages/selenium/webdriver/common/service.py", line 104, in start
    raise WebDriverException("Can not connect to the Service %s" % self.path)
selenium.common.exceptions.WebDriverException: Message: Can not connect to the Service chromedriver

Traceback (most recent call last):
  File "/home/ubuntu/trends-script/scraper.py", line 260, in <module>
    main()
  File "/home/ubuntu/trends-script/scraper.py", line 253, in main
    htmlstring = get_html_from_site()
  File "/home/ubuntu/trends-script/scraper.py", line 31, in get_html_from_site
    driver.get(start_url)
  File "/home/ubuntu/.local/lib/python3.8/site-packages/selenium/webdriver/remote/webdriver.py", line 333, in get
    self.execute(Command.GET, {'url': url})
  File "/home/ubuntu/.local/lib/python3.8/site-packages/selenium/webdriver/remote/webdriver.py", line 321, in execute
    self.error_handler.check_response(response)
  File "/home/ubuntu/.local/lib/python3.8/site-packages/selenium/webdriver/remote/errorhandler.py", line 242, in check_response
    raise exception_class(message, screen, stacktrace)
selenium.common.exceptions.TimeoutException: Message: timeout: Timed out receiving message from renderer: 289.472
  (Session info: headless chrome=87.0.4280.88)

Traceback (most recent call last):
  File "/home/ubuntu/trends-script/scraper.py", line 260, in <module>
    main()
  File "/home/ubuntu/trends-script/scraper.py", line 253, in main
    htmlstring = get_html_from_site()
  File "/home/ubuntu/trends-script/scraper.py", line 28, in get_html_from_site
    driver = webdriver.Chrome(options=options)
  File "/home/ubuntu/.local/lib/python3.8/site-packages/selenium/webdriver/chrome/webdriver.py", line 73, in __init__
    self.service.start()
  File "/home/ubuntu/.local/lib/python3.8/site-packages/selenium/webdriver/common/service.py", line 104, in start
    raise WebDriverException("Can not connect to the Service %s" % self.path)
selenium.common.exceptions.WebDriverException: Message: Can not connect to the Service chromedriver

Traceback (most recent call last):
  File "/home/ubuntu/trends-script/scraper.py", line 260, in <module>
    main()
  File "/home/ubuntu/trends-script/scraper.py", line 253, in main
    htmlstring = get_html_from_site()
  File "/home/ubuntu/trends-script/scraper.py", line 31, in get_html_from_site
    driver.get(start_url)
  File "/home/ubuntu/.local/lib/python3.8/site-packages/selenium/webdriver/remote/webdriver.py", line 333, in get
    self.execute(Command.GET, {'url': url})
  File "/home/ubuntu/.local/lib/python3.8/site-packages/selenium/webdriver/remote/webdriver.py", line 321, in execute
    self.error_handler.check_response(response)
  File "/home/ubuntu/.local/lib/python3.8/site-packages/selenium/webdriver/remote/errorhandler.py", line 242, in check_response
    raise exception_class(message, screen, stacktrace)
selenium.common.exceptions.TimeoutException: Message: timeout: Timed out receiving message from renderer: 288.437
  (Session info: headless chrome=87.0.4280.88)

Traceback (most recent call last):
  File "/home/ubuntu/trends-script/scraper.py", line 260, in <module>
    main()
  File "/home/ubuntu/trends-script/scraper.py", line 253, in main
    htmlstring = get_html_from_site()
  File "/home/ubuntu/trends-script/scraper.py", line 28, in get_html_from_site
    driver = webdriver.Chrome(options=options)
  File "/home/ubuntu/.local/lib/python3.8/site-packages/selenium/webdriver/chrome/webdriver.py", line 73, in __init__
    self.service.start()
  File "/home/ubuntu/.local/lib/python3.8/site-packages/selenium/webdriver/common/service.py", line 104, in start
    raise WebDriverException("Can not connect to the Service %s" % self.path)
selenium.common.exceptions.WebDriverException: Message: Can not connect to the Service chromedriver

Traceback (most recent call last):
  File "/home/ubuntu/trends-script/scraper.py", line 260, in <module>
    main()
  File "/home/ubuntu/trends-script/scraper.py", line 253, in main
    htmlstring = get_html_from_site()
  File "/home/ubuntu/trends-script/scraper.py", line 31, in get_html_from_site
    driver.get(start_url)
  File "/home/ubuntu/.local/lib/python3.8/site-packages/selenium/webdriver/remote/webdriver.py", line 333, in get
    self.execute(Command.GET, {'url': url})
  File "/home/ubuntu/.local/lib/python3.8/site-packages/selenium/webdriver/remote/webdriver.py", line 321, in execute
    self.error_handler.check_response(response)
  File "/home/ubuntu/.local/lib/python3.8/site-packages/selenium/webdriver/remote/errorhandler.py", line 242, in check_response
    raise exception_class(message, screen, stacktrace)
selenium.common.exceptions.TimeoutException: Message: timeout: Timed out receiving message from renderer: 287.838
  (Session info: headless chrome=87.0.4280.88)

